Workbook

Sheet Başla
B2: EXCEL KLİNİĞİ
B3: NAKİT | 13 haftalık nakit akış tahmini
B4: Önümüzdeki üç ayda kasaya ne girecek, ne çıkacak; hangi hafta paran yetmeyecek, şimdiden gör.
B6: NASIL KULLANILIR
B7: 1. Tahmin | C7: Bugün elindeki nakdi ve ilk haftanın pazartesi tarihini yaz.
B8: 2. Kalemler | C8: Beklediğin tahsilatları ve yapacağın ödemeleri tutarı, tarihi, tekrarı ve kesinliğiyle gir.
B9: 3. Tahmin sayfasına dön | C9: 13 haftanın giriş, çıkış ve hafta sonu nakdini gör. Nakdin eksiye düştüğü hafta kırmızı uyarı verir.
B11: BİLMEN GEREKENLER
B12: İki senaryo | C12: Soldaki tablo bütün kalemleri sayar. Sağdaki tablo olası girişleri saymaz ama bütün çıkışları sayar; kötü günü gösterir.
B13: Aylık tekrar | C13: Aylık kalem, ilk tarihin ayın kaçı olduğuna bakılarak her ay o güne yazılır. Kısa aylarda ayın son gününe kayar.
B14: Tahmin | C14: Sonuç, yazdığın tutar ve tarihlerin doğruluğu kadar doğrudur. Her hafta güncelle.
B15: Kapasite | C15: Kalemler: 200 satır; 13 hafta.
B17: RENKLER
B18: Sarı hücre | C18: Senin dolduracağın hücre. İçindeki örnekleri silip kendi bilgini yaz.
B19: Beyaz hücre, açık başlık | C19: Formül. Değiştirme, kendiliğinden hesaplanır.

Sheet Tahmin
A1: 13 Haftalık Tahmin
A2: Başlangıç nakdini ve ilk haftanın pazartesi tarihini yaz.
B3: Bugün kasada ve bankada olan (₺) | C3: 40000
B4: İlk haftanın pazartesi tarihi | C4: 46300
B6: 13 hafta girişi | C6: 13 hafta çıkışı | D6: En düşük nakit | E6: En düşük olduğu hafta | F6: Kesinlerle en düşük nakit
B7: =SUM(C10:C22) -> 465000 | C7: =SUM(D10:D22) -> 571000 | D7: =MIN(F10:F22) -> -66000 | E7: =INDEX(B10:B22,MATCH(MIN(F10:F22),F10:F22,0)) -> 46384 | F7: =MIN(J10:J22) -> -146000
B8: Bütün kalemlerle | I8: Yalnız kesin girişlerle (çıkışların tümü)
B9: Hafta başı | C9: Giriş (₺) | D9: Çıkış (₺) | E9: Net (₺) | F9: Hafta sonu nakit (₺) | I9: Kesin giriş (₺) | J9: Hafta sonu nakit (₺) | K9: Uyarı
B10: =$C$4+0 -> 46300 | C10: =SUMIFS(Dağılım!$B$5:$B$204,Kalemler!$B$5:$B$204,"Giriş") -> 85000 | D10: =SUMIFS(Dağılım!$B$5:$B$204,Kalemler!$B$5:$B$204,"Çıkış") -> 42000 | E10: =C10-D10 -> 43000 | F10: =$C$3+E10 -> 83000 | I10: =SUMIFS(Dağılım!$B$5:$B$204,Kalemler!$B$5:$B$204,"Giriş",Kalemler!$F$5:$F$204,"Kesin") -> 85000 | J10: =$C$3+I10-D10 -> 83000 | K10: =IF(J10<0,"Nakit yetmiyor",IF(F10<0,"Nakit yetmiyor",""))
B11: =$C$4+7 -> 46307 | C11: =SUMIFS(Dağılım!$C$5:$C$204,Kalemler!$B$5:$B$204,"Giriş") -> 25000 | D11: =SUMIFS(Dağılım!$C$5:$C$204,Kalemler!$B$5:$B$204,"Çıkış") -> 12000 | E11: =C11-D11 -> 13000 | F11: =F10+E11 -> 96000 | I11: =SUMIFS(Dağılım!$C$5:$C$204,Kalemler!$B$5:$B$204,"Giriş",Kalemler!$F$5:$F$204,"Kesin") -> 25000 | J11: =J10+I11-D11 -> 96000 | K11: =IF(J11<0,"Nakit yetmiyor",IF(F11<0,"Nakit yetmiyor",""))
B12: =$C$4+14 -> 46314 | C12: =SUMIFS(Dağılım!$D$5:$D$204,Kalemler!$B$5:$B$204,"Giriş") -> 25000 | D12: =SUMIFS(Dağılım!$D$5:$D$204,Kalemler!$B$5:$B$204,"Çıkış") -> 82000 | E12: =C12-D12 -> -57000 | F12: =F11+E12 -> 39000 | I12: =SUMIFS(Dağılım!$D$5:$D$204,Kalemler!$B$5:$B$204,"Giriş",Kalemler!$F$5:$F$204,"Kesin") -> 25000 | J12: =J11+I12-D12 -> 39000 | K12: =IF(J12<0,"Nakit yetmiyor",IF(F12<0,"Nakit yetmiyor",""))
B13: =$C$4+21 -> 46321 | C13: =SUMIFS(Dağılım!$E$5:$E$204,Kalemler!$B$5:$B$204,"Giriş") -> 25000 | D13: =SUMIFS(Dağılım!$E$5:$E$204,Kalemler!$B$5:$B$204,"Çıkış") -> 97000 | E13: =C13-D13 -> -72000 | F13: =F12+E13 -> -33000 | I13: =SUMIFS(Dağılım!$E$5:$E$204,Kalemler!$B$5:$B$204,"Giriş",Kalemler!$F$5:$F$204,"Kesin") -> 25000 | J13: =J12+I13-D13 -> -33000 | K13: =IF(J13<0,"Nakit yetmiyor",IF(F13<0,"Nakit yetmiyor","")) -> Nakit yetmiyor
B14: =$C$4+28 -> 46328 | C14: =SUMIFS(Dağılım!$F$5:$F$204,Kalemler!$B$5:$B$204,"Giriş") -> 25000 | D14: =SUMIFS(Dağılım!$F$5:$F$204,Kalemler!$B$5:$B$204,"Çıkış") -> 42000 | E14: =C14-D14 -> -17000 | F14: =F13+E14 -> -50000 | I14: =SUMIFS(Dağılım!$F$5:$F$204,Kalemler!$B$5:$B$204,"Giriş",Kalemler!$F$5:$F$204,"Kesin") -> 25000 | J14: =J13+I14-D14 -> -50000 | K14: =IF(J14<0,"Nakit yetmiyor",IF(F14<0,"Nakit yetmiyor","")) -> Nakit yetmiyor
B15: =$C$4+35 -> 46335 | C15: =SUMIFS(Dağılım!$G$5:$G$204,Kalemler!$B$5:$B$204,"Giriş") -> 105000 | D15: =SUMIFS(Dağılım!$G$5:$G$204,Kalemler!$B$5:$B$204,"Çıkış") -> 12000 | E15: =C15-D15 -> 93000 | F15: =F14+E15 -> 43000 | I15: =SUMIFS(Dağılım!$G$5:$G$204,Kalemler!$B$5:$B$204,"Giriş",Kalemler!$F$5:$F$204,"Kesin") -> 25000 | J15: =J14+I15-D15 -> -37000 | K15: =IF(J15<0,"Nakit yetmiyor",IF(F15<0,"Nakit yetmiyor","")) -> Nakit yetmiyor
B16: =$C$4+42 -> 46342 | C16: =SUMIFS(Dağılım!$H$5:$H$204,Kalemler!$B$5:$B$204,"Giriş") -> 25000 | D16: =SUMIFS(Dağılım!$H$5:$H$204,Kalemler!$B$5:$B$204,"Çıkış") -> 12000 | E16: =C16-D16 -> 13000 | F16: =F15+E16 -> 56000 | I16: =SUMIFS(Dağılım!$H$5:$H$204,Kalemler!$B$5:$B$204,"Giriş",Kalemler!$F$5:$F$204,"Kesin") -> 25000 | J16: =J15+I16-D16 -> -24000 | K16: =IF(J16<0,"Nakit yetmiyor",IF(F16<0,"Nakit yetmiyor","")) -> Nakit yetmiyor
B17: =$C$4+49 -> 46349 | C17: =SUMIFS(Dağılım!$I$5:$I$204,Kalemler!$B$5:$B$204,"Giriş") -> 25000 | D17: =SUMIFS(Dağılım!$I$5:$I$204,Kalemler!$B$5:$B$204,"Çıkış") -> 12000 | E17: =C17-D17 -> 13000 | F17: =F16+E17 -> 69000 | I17: =SUMIFS(Dağılım!$I$5:$I$204,Kalemler!$B$5:$B$204,"Giriş",Kalemler!$F$5:$F$204,"Kesin") -> 25000 | J17: =J16+I17-D17 -> -11000 | K17: =IF(J17<0,"Nakit yetmiyor",IF(F17<0,"Nakit yetmiyor","")) -> Nakit yetmiyor
B18: =$C$4+56 -> 46356 | C18: =SUMIFS(Dağılım!$J$5:$J$204,Kalemler!$B$5:$B$204,"Giriş") -> 25000 | D18: =SUMIFS(Dağılım!$J$5:$J$204,Kalemler!$B$5:$B$204,"Çıkış") -> 127000 | E18: =C18-D18 -> -102000 | F18: =F17+E18 -> -33000 | I18: =SUMIFS(Dağılım!$J$5:$J$204,Kalemler!$B$5:$B$204,"Giriş",Kalemler!$F$5:$F$204,"Kesin") -> 25000 | J18: =J17+I18-D18 -> -113000 | K18: =IF(J18<0,"Nakit yetmiyor",IF(F18<0,"Nakit yetmiyor","")) -> Nakit yetmiyor
B19: =$C$4+63 -> 46363 | C19: =SUMIFS(Dağılım!$K$5:$K$204,Kalemler!$B$5:$B$204,"Giriş") -> 25000 | D19: =SUMIFS(Dağılım!$K$5:$K$204,Kalemler!$B$5:$B$204,"Çıkış") -> 12000 | E19: =C19-D19 -> 13000 | F19: =F18+E19 -> -20000 | I19: =SUMIFS(Dağılım!$K$5:$K$204,Kalemler!$B$5:$B$204,"Giriş",Kalemler!$F$5:$F$204,"Kesin") -> 25000 | J19: =J18+I19-D19 -> -100000 | K19: =IF(J19<0,"Nakit yetmiyor",IF(F19<0,"Nakit yetmiyor","")) -> Nakit yetmiyor
B20: =$C$4+70 -> 46370 | C20: =SUMIFS(Dağılım!$L$5:$L$204,Kalemler!$B$5:$B$204,"Giriş") -> 25000 | D20: =SUMIFS(Dağılım!$L$5:$L$204,Kalemler!$B$5:$B$204,"Çıkış") -> 12000 | E20: =C20-D20 -> 13000 | F20: =F19+E20 -> -7000 | I20: =SUMIFS(Dağılım!$L$5:$L$204,Kalemler!$B$5:$B$204,"Giriş",Kalemler!$F$5:$F$204,"Kesin") -> 25000 | J20: =J19+I20-D20 -> -87000 | K20: =IF(J20<0,"Nakit yetmiyor",IF(F20<0,"Nakit yetmiyor","")) -> Nakit yetmiyor
B21: =$C$4+77 -> 46377 | C21: =SUMIFS(Dağılım!$M$5:$M$204,Kalemler!$B$5:$B$204,"Giriş") -> 25000 | D21: =SUMIFS(Dağılım!$M$5:$M$204,Kalemler!$B$5:$B$204,"Çıkış") -> 12000 | E21: =C21-D21 -> 13000 | F21: =F20+E21 -> 6000 | I21: =SUMIFS(Dağılım!$M$5:$M$204,Kalemler!$B$5:$B$204,"Giriş",Kalemler!$F$5:$F$204,"Kesin") -> 25000 | J21: =J20+I21-D21 -> -74000 | K21: =IF(J21<0,"Nakit yetmiyor",IF(F21<0,"Nakit yetmiyor","")) -> Nakit yetmiyor
B22: =$C$4+84 -> 46384 | C22: =SUMIFS(Dağılım!$N$5:$N$204,Kalemler!$B$5:$B$204,"Giriş") -> 25000 | D22: =SUMIFS(Dağılım!$N$5:$N$204,Kalemler!$B$5:$B$204,"Çıkış") -> 97000 | E22: =C22-D22 -> -72000 | F22: =F21+E22 -> -66000 | I22: =SUMIFS(Dağılım!$N$5:$N$204,Kalemler!$B$5:$B$204,"Giriş",Kalemler!$F$5:$F$204,"Kesin") -> 25000 | J22: =J21+I22-D22 -> -146000 | K22: =IF(J22<0,"Nakit yetmiyor",IF(F22<0,"Nakit yetmiyor","")) -> Nakit yetmiyor

Sheet Kalemler
A1: Kalemler
A2: Beklediğin her girişi ve çıkışı yaz. Tekrar eden ödemeler için ilk tarihi ve sıklığı seç.
A4: Kalem | B4: Tür | C4: Tutar (₺) | D4: İlk tarih | E4: Tekrar | F4: Kesinlik
A5: Müşteri Alfa tahsilatı | B5: Giriş | C5: 60000 | D5: 46304 | E5: Tek sefer | F5: Kesin
A6: Haftalık nakit satış | B6: Giriş | C6: 25000 | D6: 46300 | E6: Haftalık | F6: Kesin
A7: Yeni sipariş (beklenen) | B7: Giriş | C7: 80000 | D7: 46336 | E7: Tek sefer | F7: Olası
A8: Kira | B8: Çıkış | C8: 30000 | D8: 46300 | E8: Aylık | F8: Kesin
A9: Maaşlar | B9: Çıkış | C9: 85000 | D9: 46326 | E9: Aylık | F9: Kesin
A10: Tedarikçi ödemesi | B10: Çıkış | C10: 70000 | D10: 46315 | E10: Tek sefer | F10: Kesin
A11: Haftalık malzeme | B11: Çıkış | C11: 12000 | D11: 46302 | E11: Haftalık | F11: Kesin

Sheet Dağılım
A1: Dağılım (dokunma)
A2: Her kalemin hangi haftaya ne kadar düştüğünün ara hesabı. Değiştirme.
A5: =IF(Kalemler!A5="","",Kalemler!A5) -> Müşteri Alfa tahsilatı | B5: =IF(OR(Kalemler!$A5="",Kalemler!$C5="",Kalemler!$D5=""),0,Kalemler!$C5*IF(Kalemler!$E5="Haftalık",IF(Kalemler!$D5<=(Tahmin!$C$4+6),1,0),IF(Kalemler!$E5="Aylık",IF(OR(AND(DATE(YEAR((Tahmin!$C$4+0)),MONTH((Tahmin!$C$4+0)),MIN(DAY(Kalemler!$D5),DAY(EOMONTH((Tahmin!$C$4+0),0))))>=(Tahmin!$C$4+0),DATE(YEAR((Tahmin!$C$4+0)),MONTH((Tahmin!$C$4+0)),MIN(DAY(Kalemler!$D5),DAY(EOMONTH((Tahmin!$C$4+0),0))))<=(Tahmin!$C$4+6),DATE(YEAR((Tahmin!$C$4+0)),MONTH((Tahmin!$C$4+0)),MIN(DAY(Kalemler!$D5),DAY(EOMONTH((Tahmin!$C$4+0),0))))>=Kalemler!$D5),AND(DATE(YEAR((Tahmin!$C$4+6)),MONTH((Tahmin!$C$4+6)),MIN(DAY(Kalemler!$D5),DAY(EOMONTH((Tahmin!$C$4+6),0))))>=(Tahmin!$C$4+0),DATE(YEAR((Tahmin!$C$4+6)),MONTH((Tahmin!$C$4+6)),MIN(DAY(Kalemler!$D5),DAY(EOMONTH((Tahmin!$C$4+6),0))))<=(Tahmin!$C$4+6),DATE(YEAR((Tahmin!$C$4+6)),MONTH((Tahmin!$C$4+6)),MIN(DAY(Kalemler!$D5),DAY(EOMONTH((Tahmin!$C$4+6),0))))<>DATE(YEAR((Tahmin!$C$4+0)),MONTH((Tahmin!$C$4+0)),MIN(DAY(Kalemler!$D5),DAY(EOMONTH((Tahmin!$C$4+0),0)))),DATE(YEAR((Tahmin!$C$4+6)),MONTH((Tahmin!$C$4+6)),MIN(DAY(Kalemler!$D5),DAY(EOMONTH((Tahmin!$C$4+6),0))))>=Kalemler!$D5)),1,0),IF(AND(Kalemler!$D5>=(Tahmin!$C$4+0),Kalemler!$D5<=(Tahmin!$C$4+6)),1,0)))) -> 60000 | C5: =IF(OR(Kalemler!$A5="",Kalemler!$C5="",Kalemler!$D5=""),0,Kalemler!$C5*IF(Kalemler!$E5="Haftalık",IF(Kalemler!$D5<=(Tahmin!$C$4+13),1,0),IF(Kalemler!$E5="Aylık",IF(OR(AND(DATE(YEAR((Tahmin!$C$4+7)),MONTH((Tahmin!$C$4+7)),MIN(DAY(Kalemler!$D5),DAY(EOMONTH((Tahmin!$C$4+7),0))))>=(Tahmin!$C$4+7),DATE(YEAR((Tahmin!$C$4+7)),MONTH((Tahmin!$C$4+7)),MIN(DAY(Kalemler!$D5),DAY(EOMONTH((Tahmin!$C$4+7),0))))<=(Tahmin!$C$4+13),DATE(YEAR((Tahmin!$C$4+7)),MONTH((Tahmin!$C$4+7)),MIN(DAY(Kalemler!$D5),DAY(EOMONTH((Tahmin!$C$4+7),0))))>=Kalemler!$D5),AND(DATE(YEAR((Tahmin!$C$4+13)),MONTH((Tahmin!$C$4+13)),MIN(DAY(Kalemler!$D5),DAY(EOMONTH((Tahmin!$C$4+13),0))))>=(Tahmin!$C$4+7),DATE(YEAR((Tahmin!$C$4+13)),MONTH((Tahmin!$C$4+13)),MIN(DAY(Kalemler!$D5),DAY(EOMONTH((Tahmin!$C$4+13),0))))<=(Tahmin!$C$4+13),DATE(YEAR((Tahmin!$C$4+13)),MONTH((Tahmin!$C$4+13)),MIN(DAY(Kalemler!$D5),DAY(EOMONTH((Tahmin!$C$4+13),0))))<>DATE(YEAR((Tahmin!$C$4+7)),MONTH((Tahmin!$C$4+7)),MIN(DAY(Kalemler!$D5),DAY(EOMONTH((Tahmin!$C$4+7),0)))),DATE(YEAR((Tahmin!$C$4+13)),MONTH((Tahmin!$C$4+13)),MIN(DAY(Kalemler!$D5),DAY(EOMONTH((Tahmin!$C$4+13),0))))>=Kalemler!$D5)),1,0),IF(AND(Kalemler!$D5>=(Tahmin!$C$4+7),Kalemler!$D5<=(Tahmin!$C$4+13)),1,0)))) -> 0 | D5: =IF(OR(Kalemler!$A5="",Kalemler!$C5="",Kalemler!$D5=""),0,Kalemler!$C5*IF(Kalemler!$E5="Haftalık",IF(Kalemler!$D5<=(Tahmin!$C$4+20),1,0),IF(Kalemler!$E5="Aylık",IF(OR(AND(DATE(YEAR((Tahmin!$C$4+14)),MONTH((Tahmin!$C$4+14)),MIN(DAY(Kalemler!$D5),DAY(EOMONTH((Tahmin!$C$4+14),0))))>=(Tahmin!$C$4+14),DATE(YEAR((Tahmin!$C$4+14)),MONTH((Tahmin!$C$4+14)),MIN(DAY(Kalemler!$D5),DAY(EOMONTH((Tahmin!$C$4+14),0))))<=(Tahmin!$C$4+20),DATE(YEAR((Tahmin!$C$4+14)),MONTH((Tahmin!$C$4+14)),MIN(DAY(Kalemler!$D5),DAY(EOMONTH((Tahmin!$C$4+14),0))))>=Kalemler!$D5),AND(DATE(YEAR((Tahmin!$C$4+20)),MONTH((Tahmin!$C$4+20)),MIN(DAY(Kalemler!$D5),DAY(EOMONTH((Tahmin!$C$4+20),0))))>=(Tahmin!$C$4+14),DATE(YEAR((Tahmin!$C$4+20)),MONTH((Tahmin!$C$4+20)),MIN(DAY(Kalemler!$D5),DAY(EOMONTH((Tahmin!$C$4+20),0))))<=(Tahmin!$C$4+20),DATE(YEAR((Tahmin!$C$4+20)),MONTH((Tahmin!$C$4+20)),MIN(DAY(Kalemler!$D5),DAY(EOMONTH((Tahmin!$C$4+20),0))))<>DATE(YEAR((Tahmin!$C$4+14)),MONTH((Tahmin!$C$4+14)),MIN(DAY(Kalemler!$D5),DAY(EOMONTH((Tahmin!$C$4+14),0)))),DATE(YEAR((Tahmin!$C$4+20)),MONTH((Tahmin!$C$4+20)),MIN(DAY(Kalemler!$D5),DAY(EOMONTH((Tahmin!$C$4+20),0))))>=Kalemler!$D5)),1,0),IF(AND(Kalemler!$D5>=(Tahmin!$C$4+14),Kalemler!$D5<=(Tahmin!$C$4+20)),1,0)))) -> 0 | E5: =IF(OR(Kalemler!$A5="",Kalemler!$C5="",Kalemler!$D5=""),0,Kalemler!$C5*IF(Kalemler!$E5="Haftalık",IF(Kalemler!$D5<=(Tahmin!$C$4+27),1,0),IF(Kalemler!$E5="Aylık",IF(OR(AND(DATE(YEAR((Tahmin!$C$4+21)),MONTH((Tahmin!$C$4+21)),MIN(DAY(Kalemler!$D5),DAY(EOMONTH((Tahmin!$C$4+21),0))))>=(Tahmin!$C$4+21),DATE(YEAR((Tahmin!$C$4+21)),MONTH((Tahmin!$C$4+21)),MIN(DAY(Kalemler!$D5),DAY(EOMONTH((Tahmin!$C$4+21),0))))<=(Tahmin!$C$4+27),DATE(YEAR((Tahmin!$C$4+21)),MONTH((Tahmin!$C$4+21)),MIN(DAY(Kalemler!$D5),DAY(EOMONTH((Tahmin!$C$4+21),0))))>=Kalemler!$D5),AND(DATE(YEAR((Tahmin!$C$4+27)),MONTH((Tahmin!$C$4+27)),MIN(DAY(Kalemler!$D5),DAY(EOMONTH((Tahmin!$C$4+27),0))))>=(Tahmin!$C$4+21),DATE(YEAR((Tahmin!$C$4+27)),MONTH((Tahmin!$C$4+27)),MIN(DAY(Kalemler!$D5),DAY(EOMONTH((Tahmin!$C$4+27),0))))<=(Tahmin!$C$4+27),DATE(YEAR((Tahmin!$C$4+27)),MONTH((Tahmin!$C$4+27)),MIN(DAY(Kalemler!$D5),DAY(EOMONTH((Tahmin!$C$4+27),0))))<>DATE(YEAR((Tahmin!$C$4+21)),MONTH((Tahmin!$C$4+21)),MIN(DAY(Kalemler!$D5),DAY(EOMONTH((Tahmin!$C$4+21),0)))),DATE(YEAR((Tahmin!$C$4+27)),MONTH((Tahmin!$C$4+27)),MIN(DAY(Kalemler!$D5),DAY(EOMONTH((Tahmin!$C$4+27),0))))>=Kalemler!$D5)),1,0),IF(AND(Kalemler!$D5>=(Tahmin!$C$4+21),Kalemler!$D5<=(Tahmin!$C$4+27)),1,0)))) -> 0 | F5: =IF(OR(Kalemler!$A5="",Kalemler!$C5="",Kalemler!$D5=""),0,Kalemler!$C5*IF(Kalemler!$E5="Haftalık",IF(Kalemler!$D5<=(Tahmin!$C$4+34),1,0),IF(Kalemler!$E5="Aylık",IF(OR(AND(DATE(YEAR((Tahmin!$C$4+28)),MONTH((Tahmin!$C$4+28)),MIN(DAY(Kalemler!$D5),DAY(EOMONTH((Tahmin!$C$4+28),0))))>=(Tahmin!$C$4+28),DATE(YEAR((Tahmin!$C$4+28)),MONTH((Tahmin!$C$4+28)),MIN(DAY(Kalemler!$D5),DAY(EOMONTH((Tahmin!$C$4+28),0))))<=(Tahmin!$C$4+34),DATE(YEAR((Tahmin!$C$4+28)),MONTH((Tahmin!$C$4+28)),MIN(DAY(Kalemler!$D5),DAY(EOMONTH((Tahmin!$C$4+28),0))))>=Kalemler!$D5),AND(DATE(YEAR((Tahmin!$C$4+34)),MONTH((Tahmin!$C$4+34)),MIN(DAY(Kalemler!$D5),DAY(EOMONTH((Tahmin!$C$4+34),0))))>=(Tahmin!$C$4+28),DATE(YEAR((Tahmin!$C$4+34)),MONTH((Tahmin!$C$4+34)),MIN(DAY(Kalemler!$D5),DAY(EOMONTH((Tahmin!$C$4+34),0))))<=(Tahmin!$C$4+34),DATE(YEAR((Tahmin!$C$4+34)),MONTH((Tahmin!$C$4+34)),MIN(DAY(Kalemler!$D5),DAY(EOMONTH((Tahmin!$C$4+34),0))))<>DATE(YEAR((Tahmin!$C$4+28)),MONTH((Tahmin!$C$4+28)),MIN(DAY(Kalemler!$D5),DAY(EOMONTH((Tahmin!$C$4+28),0)))),DATE(YEAR((Tahmin!$C$4+34)),MONTH((Tahmin!$C$4+34)),MIN(DAY(Kalemler!$D5),DAY(EOMONTH((Tahmin!$C$4+34),0))))>=Kalemler!$D5)),1,0),IF(AND(Kalemler!$D5>=(Tahmin!$C$4+28),Kalemler!$D5<=(Tahmin!$C$4+34)),1,0)))) -> 0 | G5: =IF(OR(Kalemler!$A5="",Kalemler!$C5="",Kalemler!$D5=""),0,Kalemler!$C5*IF(Kalemler!$E5="Haftalık",IF(Kalemler!$D5<=(Tahmin!$C$4+41),1,0),IF(Kalemler!$E5="Aylık",IF(OR(AND(DATE(YEAR((Tahmin!$C$4+35)),MONTH((Tahmin!$C$4+35)),MIN(DAY(Kalemler!$D5),DAY(EOMONTH((Tahmin!$C$4+35),0))))>=(Tahmin!$C$4+35),DATE(YEAR((Tahmin!$C$4+35)),MONTH((Tahmin!$C$4+35)),MIN(DAY(Kalemler!$D5),DAY(EOMONTH((Tahmin!$C$4+35),0))))<=(Tahmin!$C$4+41),DATE(YEAR((Tahmin!$C$4+35)),MONTH((Tahmin!$C$4+35)),MIN(DAY(Kalemler!$D5),DAY(EOMONTH((Tahmin!$C$4+35),0))))>=Kalemler!$D5),AND(DATE(YEAR((Tahmin!$C$4+41)),MONTH((Tahmin!$C$4+41)),MIN(DAY(Kalemler!$D5),DAY(EOMONTH((Tahmin!$C$4+41),0))))>=(Tahmin!$C$4+35),DATE(YEAR((Tahmin!$C$4+41)),MONTH((Tahmin!$C$4+41)),MIN(DAY(Kalemler!$D5),DAY(EOMONTH((Tahmin!$C$4+41),0))))<=(Tahmin!$C$4+41),DATE(YEAR((Tahmin!$C$4+41)),MONTH((Tahmin!$C$4+41)),MIN(DAY(Kalemler!$D5),DAY(EOMONTH((Tahmin!$C$4+41),0))))<>DATE(YEAR((Tahmin!$C$4+35)),MONTH((Tahmin!$C$4+35)),MIN(DAY(Kalemler!$D5),DAY(EOMONTH((Tahmin!$C$4+35),0)))),DATE(YEAR((Tahmin!$C$4+41)),MONTH((Tahmin!$C$4+41)),MIN(DAY(Kalemler!$D5),DAY(EOMONTH((Tahmin!$C$4+41),0))))>=Kalemler!$D5)),1,0),IF(AND(Kalemler!$D5>=(Tahmin!$C$4+35),Kalemler!$D5<=(Tahmin!$C$4+41)),1,0)))) -> 0 | H5: =IF(OR(Kalemler!$A5="",Kalemler!$C5="",Kalemler!$D5=""),0,Kalemler!$C5*IF(Kalemler!$E5="Haftalık",IF(Kalemler!$D5<=(Tahmin!$C$4+48),1,0),IF(Kalemler!$E5="Aylık",IF(OR(AND(DATE(YEAR((Tahmin!$C$4+42)),MONTH((Tahmin!$C$4+42)),MIN(DAY(Kalemler!$D5),DAY(EOMONTH((Tahmin!$C$4+42),0))))>=(Tahmin!$C$4+42),DATE(YEAR((Tahmin!$C$4+42)),MONTH((Tahmin!$C$4+42)),MIN(DAY(Kalemler!$D5),DAY(EOMONTH((Tahmin!$C$4+42),0))))<=(Tahmin!$C$4+48),DATE(YEAR((Tahmin!$C$4+42)),MONTH((Tahmin!$C$4+42)),MIN(DAY(Kalemler!$D5),DAY(EOMONTH((Tahmin!$C$4+42),0))))>=Kalemler!$D5),AND(DATE(YEAR((Tahmin!$C$4+48)),MONTH((Tahmin!$C$4+48)),MIN(DAY(Kalemler!$D5),DAY(EOMONTH((Tahmin!$C$4+48),0))))>=(Tahmin!$C$4+42),DATE(YEAR((Tahmin!$C$4+48)),MONTH((Tahmin!$C$4+48)),MIN(DAY(Kalemler!$D5),DAY(EOMONTH((Tahmin!$C$4+48),0))))<=(Tahmin!$C$4+48),DATE(YEAR((Tahmin!$C$4+48)),MONTH((Tahmin!$C$4+48)),MIN(DAY(Kalemler!$D5),DAY(EOMONTH((Tahmin!$C$4+48),0))))<>DATE(YEAR((Tahmin!$C$4+42)),MONTH((Tahmin!$C$4+42)),MIN(DAY(Kalemler!$D5),DAY(EOMONTH((Tahmin!$C$4+42),0)))),DATE(YEAR((Tahmin!$C$4+48)),MONTH((Tahmin!$C$4+48)),MIN(DAY(Kalemler!$D5),DAY(EOMONTH((Tahmin!$C$4+48),0))))>=Kalemler!$D5)),1,0),IF(AND(Kalemler!$D5>=(Tahmin!$C$4+42),Kalemler!$D5<=(Tahmin!$C$4+48)),1,0)))) -> 0 | I5: =IF(OR(Kalemler!$A5="",Kalemler!$C5="",Kalemler!$D5=""),0,Kalemler!$C5*IF(Kalemler!$E5="Haftalık",IF(Kalemler!$D5<=(Tahmin!$C$4+55),1,0),IF(Kalemler!$E5="Aylık",IF(OR(AND(DATE(YEAR((Tahmin!$C$4+49)),MONTH((Tahmin!$C$4+49)),MIN(DAY(Kalemler!$D5),DAY(EOMONTH((Tahmin!$C$4+49),0))))>=(Tahmin!$C$4+49),DATE(YEAR((Tahmin!$C$4+49)),MONTH((Tahmin!$C$4+49)),MIN(DAY(Kalemler!$D5),DAY(EOMONTH((Tahmin!$C$4+49),0))))<=(Tahmin!$C$4+55),DATE(YEAR((Tahmin!$C$4+49)),MONTH((Tahmin!$C$4+49)),MIN(DAY(Kalemler!$D5),DAY(EOMONTH((Tahmin!$C$4+49),0))))>=Kalemler!$D5),AND(DATE(YEAR((Tahmin!$C$4+55)),MONTH((Tahmin!$C$4+55)),MIN(DAY(Kalemler!$D5),DAY(EOMONTH((Tahmin!$C$4+55),0))))>=(Tahmin!$C$4+49),DATE(YEAR((Tahmin!$C$4+55)),MONTH((Tahmin!$C$4+55)),MIN(DAY(Kalemler!$D5),DAY(EOMONTH((Tahmin!$C$4+55),0))))<=(Tahmin!$C$4+55),DATE(YEAR((Tahmin!$C$4+55)),MONTH((Tahmin!$C$4+55)),MIN(DAY(Kalemler!$D5),DAY(EOMONTH((Tahmin!$C$4+55),0))))<>DATE(YEAR((Tahmin!$C$4+49)),MONTH((Tahmin!$C$4+49)),MIN(DAY(Kalemler!$D5),DAY(EOMONTH((Tahmin!$C$4+49),0)))),DATE(YEAR((Tahmin!$C$4+55)),MONTH((Tahmin!$C$4+55)),MIN(DAY(Kalemler!$D5),DAY(EOMONTH((Tahmin!$C$4+55),0))))>=Kalemler!$D5)),1,0),IF(AND(Kalemler!$D5>=(Tahmin!$C$4+49),Kalemler!$D5<=(Tahmin!$C$4+55)),1,0)))) -> 0 | J5: =IF(OR(Kalemler!$A5="",Kalemler!$C5="",Kalemler!$D5=""),0,Kalemler!$C5*IF(Kalemler!$E5="Haftalık",IF(Kalemler!$D5<=(Tahmin!$C$4+62),1,0),IF(Kalemler!$E5="Aylık",IF(OR(AND(DATE(YEAR((Tahmin!$C$4+56)),MONTH((Tahmin!$C$4+56)),MIN(DAY(Kalemler!$D5),DAY(EOMONTH((Tahmin!$C$4+56),0))))>=(Tahmin!$C$4+56),DATE(YEAR((Tahmin!$C$4+56)),MONTH((Tahmin!$C$4+56)),MIN(DAY(Kalemler!$D5),DAY(EOMONTH((Tahmin!$C$4+56),0))))<=(Tahmin!$C$4+62),DATE(YEAR((Tahmin!$C$4+56)),MONTH((Tahmin!$C$4+56)),MIN(DAY(Kalemler!$D5),DAY(EOMONTH((Tahmin!$C$4+56),0))))>=Kalemler!$D5),AND(DATE(YEAR((Tahmin!$C$4+62)),MONTH((Tahmin!$C$4+62)),MIN(DAY(Kalemler!$D5),DAY(EOMONTH((Tahmin!$C$4+62),0))))>=(Tahmin!$C$4+56),DATE(YEAR((Tahmin!$C$4+62)),MONTH((Tahmin!$C$4+62)),MIN(DAY(Kalemler!$D5),DAY(EOMONTH((Tahmin!$C$4+62),0))))<=(Tahmin!$C$4+62),DATE(YEAR((Tahmin!$C$4+62)),MONTH((Tahmin!$C$4+62)),MIN(DAY(Kalemler!$D5),DAY(EOMONTH((Tahmin!$C$4+62),0))))<>DATE(YEAR((Tahmin!$C$4+56)),MONTH((Tahmin!$C$4+56)),MIN(DAY(Kalemler!$D5),DAY(EOMONTH((Tahmin!$C$4+56),0)))),DATE(YEAR((Tahmin!$C$4+62)),MONTH((Tahmin!$C$4+62)),MIN(DAY(Kalemler!$D5),DAY(EOMONTH((Tahmin!$C$4+62),0))))>=Kalemler!$D5)),1,0),IF(AND(Kalemler!$D5>=(Tahmin!$C$4+56),Kalemler!$D5<=(Tahmin!$C$4+62)),1,0)))) -> 0 | K5: =IF(OR(Kalemler!$A5="",Kalemler!$C5="",Kalemler!$D5=""),0,Kalemler!$C5*IF(Kalemler!$E5="Haftalık",IF(Kalemler!$D5<=(Tahmin!$C$4+69),1,0),IF(Kalemler!$E5="Aylık",IF(OR(AND(DATE(YEAR((Tahmin!$C$4+63)),MONTH((Tahmin!$C$4+63)),MIN(DAY(Kalemler!$D5),DAY(EOMONTH((Tahmin!$C$4+63),0))))>=(Tahmin!$C$4+63),DATE(YEAR((Tahmin!$C$4+63)),MONTH((Tahmin!$C$4+63)),MIN(DAY(Kalemler!$D5),DAY(EOMONTH((Tahmin!$C$4+63),0))))<=(Tahmin!$C$4+69),DATE(YEAR((Tahmin!$C$4+63)),MONTH((Tahmin!$C$4+63)),MIN(DAY(Kalemler!$D5),DAY(EOMONTH((Tahmin!$C$4+63),0))))>=Kalemler!$D5),AND(DATE(YEAR((Tahmin!$C$4+69)),MONTH((Tahmin!$C$4+69)),MIN(DAY(Kalemler!$D5),DAY(EOMONTH((Tahmin!$C$4+69),0))))>=(Tahmin!$C$4+63),DATE(YEAR((Tahmin!$C$4+69)),MONTH((Tahmin!$C$4+69)),MIN(DAY(Kalemler!$D5),DAY(EOMONTH((Tahmin!$C$4+69),0))))<=(Tahmin!$C$4+69),DATE(YEAR((Tahmin!$C$4+69)),MONTH((Tahmin!$C$4+69)),MIN(DAY(Kalemler!$D5),DAY(EOMONTH((Tahmin!$C$4+69),0))))<>DATE(YEAR((Tahmin!$C$4+63)),MONTH((Tahmin!$C$4+63)),MIN(DAY(Kalemler!$D5),DAY(EOMONTH((Tahmin!$C$4+63),0)))),DATE(YEAR((Tahmin!$C$4+69)),MONTH((Tahmin!$C$4+69)),MIN(DAY(Kalemler!$D5),DAY(EOMONTH((Tahmin!$C$4+69),0))))>=Kalemler!$D5)),1,0),IF(AND(Kalemler!$D5>=(Tahmin!$C$4+63),Kalemler!$D5<=(Tahmin!$C$4+69)),1,0)))) -> 0 | L5: =IF(OR(Kalemler!$A5="",Kalemler!$C5="",Kalemler!$D5=""),0,Kalemler!$C5*IF(Kalemler!$E5="Haftalık",IF(Kalemler!$D5<=(Tahmin!$C$4+76),1,0),IF(Kalemler!$E5="Aylık",IF(OR(AND(DATE(YEAR((Tahmin!$C$4+70)),MONTH((Tahmin!$C$4+70)),MIN(DAY(Kalemler!$D5),DAY(EOMONTH((Tahmin!$C$4+70),0))))>=(Tahmin!$C$4+70),DATE(YEAR((Tahmin!$C$4+70)),MONTH((Tahmin!$C$4+70)),MIN(DAY(Kalemler!$D5),DAY(EOMONTH((Tahmin!$C$4+70),0))))<=(Tahmin!$C$4+76),DATE(YEAR((Tahmin!$C$4+70)),MONTH((Tahmin!$C$4+70)),MIN(DAY(Kalemler!$D5),DAY(EOMONTH((Tahmin!$C$4+70),0))))>=Kalemler!$D5),AND(DATE(YEAR((Tahmin!$C$4+76)),MONTH((Tahmin!$C$4+76)),MIN(DAY(Kalemler!$D5),DAY(EOMONTH((Tahmin!$C$4+76),0))))>=(Tahmin!$C$4+70),DATE(YEAR((Tahmin!$C$4+76)),MONTH((Tahmin!$C$4+76)),MIN(DAY(Kalemler!$D5),DAY(EOMONTH((Tahmin!$C$4+76),0))))<=(Tahmin!$C$4+76),DATE(YEAR((Tahmin!$C$4+76)),MONTH((Tahmin!$C$4+76)),MIN(DAY(Kalemler!$D5),DAY(EOMONTH((Tahmin!$C$4+76),0))))<>DATE(YEAR((Tahmin!$C$4+70)),MONTH((Tahmin!$C$4+70)),MIN(DAY(Kalemler!$D5),DAY(EOMONTH((Tahmin!$C$4+70),0)))),DATE(YEAR((Tahmin!$C$4+76)),MONTH((Tahmin!$C$4+76)),MIN(DAY(Kalemler!$D5),DAY(EOMONTH((Tahmin!$C$4+76),0))))>=Kalemler!$D5)),1,0),IF(AND(Kalemler!$D5>=(Tahmin!$C$4+70),Kalemler!$D5<=(Tahmin!$C$4+76)),1,0)))) -> 0 | M5: =IF(OR(Kalemler!$A5="",Kalemler!$C5="",Kalemler!$D5=""),0,Kalemler!$C5*IF(Kalemler!$E5="Haftalık",IF(Kalemler!$D5<=(Tahmin!$C$4+83),1,0),IF(Kalemler!$E5="Aylık",IF(OR(AND(DATE(YEAR((Tahmin!$C$4+77)),MONTH((Tahmin!$C$4+77)),MIN(DAY(Kalemler!$D5),DAY(EOMONTH((Tahmin!$C$4+77),0))))>=(Tahmin!$C$4+77),DATE(YEAR((Tahmin!$C$4+77)),MONTH((Tahmin!$C$4+77)),MIN(DAY(Kalemler!$D5),DAY(EOMONTH((Tahmin!$C$4+77),0))))<=(Tahmin!$C$4+83),DATE(YEAR((Tahmin!$C$4+77)),MONTH((Tahmin!$C$4+77)),MIN(DAY(Kalemler!$D5),DAY(EOMONTH((Tahmin!$C$4+77),0))))>=Kalemler!$D5),AND(DATE(YEAR((Tahmin!$C$4+83)),MONTH((Tahmin!$C$4+83)),MIN(DAY(Kalemler!$D5),DAY(EOMONTH((Tahmin!$C$4+83),0))))>=(Tahmin!$C$4+77),DATE(YEAR((Tahmin!$C$4+83)),MONTH((Tahmin!$C$4+83)),MIN(DAY(Kalemler!$D5),DAY(EOMONTH((Tahmin!$C$4+83),0))))<=(Tahmin!$C$4+83),DATE(YEAR((Tahmin!$C$4+83)),MONTH((Tahmin!$C$4+83)),MIN(DAY(Kalemler!$D5),DAY(EOMONTH((Tahmin!$C$4+83),0))))<>DATE(YEAR((Tahmin!$C$4+77)),MONTH((Tahmin!$C$4+77)),MIN(DAY(Kalemler!$D5),DAY(EOMONTH((Tahmin!$C$4+77),0)))),DATE(YEAR((Tahmin!$C$4+83)),MONTH((Tahmin!$C$4+83)),MIN(DAY(Kalemler!$D5),DAY(EOMONTH((Tahmin!$C$4+83),0))))>=Kalemler!$D5)),1,0),IF(AND(Kalemler!$D5>=(Tahmin!$C$4+77),Kalemler!$D5<=(Tahmin!$C$4+83)),1,0)))) -> 0 | N5: =IF(OR(Kalemler!$A5="",Kalemler!$C5="",Kalemler!$D5=""),0,Kalemler!$C5*IF(Kalemler!$E5="Haftalık",IF(Kalemler!$D5<=(Tahmin!$C$4+90),1,0),IF(Kalemler!$E5="Aylık",IF(OR(AND(DATE(YEAR((Tahmin!$C$4+84)),MONTH((Tahmin!$C$4+84)),MIN(DAY(Kalemler!$D5),DAY(EOMONTH((Tahmin!$C$4+84),0))))>=(Tahmin!$C$4+84),DATE(YEAR((Tahmin!$C$4+84)),MONTH((Tahmin!$C$4+84)),MIN(DAY(Kalemler!$D5),DAY(EOMONTH((Tahmin!$C$4+84),0))))<=(Tahmin!$C$4+90),DATE(YEAR((Tahmin!$C$4+84)),MONTH((Tahmin!$C$4+84)),MIN(DAY(Kalemler!$D5),DAY(EOMONTH((Tahmin!$C$4+84),0))))>=Kalemler!$D5),AND(DATE(YEAR((Tahmin!$C$4+90)),MONTH((Tahmin!$C$4+90)),MIN(DAY(Kalemler!$D5),DAY(EOMONTH((Tahmin!$C$4+90),0))))>=(Tahmin!$C$4+84),DATE(YEAR((Tahmin!$C$4+90)),MONTH((Tahmin!$C$4+90)),MIN(DAY(Kalemler!$D5),DAY(EOMONTH((Tahmin!$C$4+90),0))))<=(Tahmin!$C$4+90),DATE(YEAR((Tahmin!$C$4+90)),MONTH((Tahmin!$C$4+90)),MIN(DAY(Kalemler!$D5),DAY(EOMONTH((Tahmin!$C$4+90),0))))<>DATE(YEAR((Tahmin!$C$4+84)),MONTH((Tahmin!$C$4+84)),MIN(DAY(Kalemler!$D5),DAY(EOMONTH((Tahmin!$C$4+84),0)))),DATE(YEAR((Tahmin!$C$4+90)),MONTH((Tahmin!$C$4+90)),MIN(DAY(Kalemler!$D5),DAY(EOMONTH((Tahmin!$C$4+90),0))))>=Kalemler!$D5)),1,0),IF(AND(Kalemler!$D5>=(Tahmin!$C$4+84),Kalemler!$D5<=(Tahmin!$C$4+90)),1,0)))) -> 0
A6: =IF(Kalemler!A6="","",Kalemler!A6) -> Haftalık nakit satış | B6: =IF(OR(Kalemler!$A6="",Kalemler!$C6="",Kalemler!$D6=""),0,Kalemler!$C6*IF(Kalemler!$E6="Haftalık",IF(Kalemler!$D6<=(Tahmin!$C$4+6),1,0),IF(Kalemler!$E6="Aylık",IF(OR(AND(DATE(YEAR((Tahmin!$C$4+0)),MONTH((Tahmin!$C$4+0)),MIN(DAY(Kalemler!$D6),DAY(EOMONTH((Tahmin!$C$4+0),0))))>=(Tahmin!$C$4+0),DATE(YEAR((Tahmin!$C$4+0)),MONTH((Tahmin!$C$4+0)),MIN(DAY(Kalemler!$D6),DAY(EOMONTH((Tahmin!$C$4+0),0))))<=(Tahmin!$C$4+6),DATE(YEAR((Tahmin!$C$4+0)),MONTH((Tahmin!$C$4+0)),MIN(DAY(Kalemler!$D6),DAY(EOMONTH((Tahmin!$C$4+0),0))))>=Kalemler!$D6),AND(DATE(YEAR((Tahmin!$C$4+6)),MONTH((Tahmin!$C$4+6)),MIN(DAY(Kalemler!$D6),DAY(EOMONTH((Tahmin!$C$4+6),0))))>=(Tahmin!$C$4+0),DATE(YEAR((Tahmin!$C$4+6)),MONTH((Tahmin!$C$4+6)),MIN(DAY(Kalemler!$D6),DAY(EOMONTH((Tahmin!$C$4+6),0))))<=(Tahmin!$C$4+6),DATE(YEAR((Tahmin!$C$4+6)),MONTH((Tahmin!$C$4+6)),MIN(DAY(Kalemler!$D6),DAY(EOMONTH((Tahmin!$C$4+6),0))))<>DATE(YEAR((Tahmin!$C$4+0)),MONTH((Tahmin!$C$4+0)),MIN(DAY(Kalemler!$D6),DAY(EOMONTH((Tahmin!$C$4+0),0)))),DATE(YEAR((Tahmin!$C$4+6)),MONTH((Tahmin!$C$4+6)),MIN(DAY(Kalemler!$D6),DAY(EOMONTH((Tahmin!$C$4+6),0))))>=Kalemler!$D6)),1,0),IF(AND(Kalemler!$D6>=(Tahmin!$C$4+0),Kalemler!$D6<=(Tahmin!$C$4+6)),1,0)))) -> 25000 | C6: =IF(OR(Kalemler!$A6="",Kalemler!$C6="",Kalemler!$D6=""),0,Kalemler!$C6*IF(Kalemler!$E6="Haftalık",IF(Kalemler!$D6<=(Tahmin!$C$4+13),1,0),IF(Kalemler!$E6="Aylık",IF(OR(AND(DATE(YEAR((Tahmin!$C$4+7)),MONTH((Tahmin!$C$4+7)),MIN(DAY(Kalemler!$D6),DAY(EOMONTH((Tahmin!$C$4+7),0))))>=(Tahmin!$C$4+7),DATE(YEAR((Tahmin!$C$4+7)),MONTH((Tahmin!$C$4+7)),MIN(DAY(Kalemler!$D6),DAY(EOMONTH((Tahmin!$C$4+7),0))))<=(Tahmin!$C$4+13),DATE(YEAR((Tahmin!$C$4+7)),MONTH((Tahmin!$C$4+7)),MIN(DAY(Kalemler!$D6),DAY(EOMONTH((Tahmin!$C$4+7),0))))>=Kalemler!$D6),AND(DATE(YEAR((Tahmin!$C$4+13)),MONTH((Tahmin!$C$4+13)),MIN(DAY(Kalemler!$D6),DAY(EOMONTH((Tahmin!$C$4+13),0))))>=(Tahmin!$C$4+7),DATE(YEAR((Tahmin!$C$4+13)),MONTH((Tahmin!$C$4+13)),MIN(DAY(Kalemler!$D6),DAY(EOMONTH((Tahmin!$C$4+13),0))))<=(Tahmin!$C$4+13),DATE(YEAR((Tahmin!$C$4+13)),MONTH((Tahmin!$C$4+13)),MIN(DAY(Kalemler!$D6),DAY(EOMONTH((Tahmin!$C$4+13),0))))<>DATE(YEAR((Tahmin!$C$4+7)),MONTH((Tahmin!$C$4+7)),MIN(DAY(Kalemler!$D6),DAY(EOMONTH((Tahmin!$C$4+7),0)))),DATE(YEAR((Tahmin!$C$4+13)),MONTH((Tahmin!$C$4+13)),MIN(DAY(Kalemler!$D6),DAY(EOMONTH((Tahmin!$C$4+13),0))))>=Kalemler!$D6)),1,0),IF(AND(Kalemler!$D6>=(Tahmin!$C$4+7),Kalemler!$D6<=(Tahmin!$C$4+13)),1,0)))) -> 25000 | D6: =IF(OR(Kalemler!$A6="",Kalemler!$C6="",Kalemler!$D6=""),0,Kalemler!$C6*IF(Kalemler!$E6="Haftalık",IF(Kalemler!$D6<=(Tahmin!$C$4+20),1,0),IF(Kalemler!$E6="Aylık",IF(OR(AND(DATE(YEAR((Tahmin!$C$4+14)),MONTH((Tahmin!$C$4+14)),MIN(DAY(Kalemler!$D6),DAY(EOMONTH((Tahmin!$C$4+14),0))))>=(Tahmin!$C$4+14),DATE(YEAR((Tahmin!$C$4+14)),MONTH((Tahmin!$C$4+14)),MIN(DAY(Kalemler!$D6),DAY(EOMONTH((Tahmin!$C$4+14),0))))<=(Tahmin!$C$4+20),DATE(YEAR((Tahmin!$C$4+14)),MONTH((Tahmin!$C$4+14)),MIN(DAY(Kalemler!$D6),DAY(EOMONTH((Tahmin!$C$4+14),0))))>=Kalemler!$D6),AND(DATE(YEAR((Tahmin!$C$4+20)),MONTH((Tahmin!$C$4+20)),MIN(DAY(Kalemler!$D6),DAY(EOMONTH((Tahmin!$C$4+20),0))))>=(Tahmin!$C$4+14),DATE(YEAR((Tahmin!$C$4+20)),MONTH((Tahmin!$C$4+20)),MIN(DAY(Kalemler!$D6),DAY(EOMONTH((Tahmin!$C$4+20),0))))<=(Tahmin!$C$4+20),DATE(YEAR((Tahmin!$C$4+20)),MONTH((Tahmin!$C$4+20)),MIN(DAY(Kalemler!$D6),DAY(EOMONTH((Tahmin!$C$4+20),0))))<>DATE(YEAR((Tahmin!$C$4+14)),MONTH((Tahmin!$C$4+14)),MIN(DAY(Kalemler!$D6),DAY(EOMONTH((Tahmin!$C$4+14),0)))),DATE(YEAR((Tahmin!$C$4+20)),MONTH((Tahmin!$C$4+20)),MIN(DAY(Kalemler!$D6),DAY(EOMONTH((Tahmin!$C$4+20),0))))>=Kalemler!$D6)),1,0),IF(AND(Kalemler!$D6>=(Tahmin!$C$4+14),Kalemler!$D6<=(Tahmin!$C$4+20)),1,0)))) -> 25000 | E6: =IF(OR(Kalemler!$A6="",Kalemler!$C6="",Kalemler!$D6=""),0,Kalemler!$C6*IF(Kalemler!$E6="Haftalık",IF(Kalemler!$D6<=(Tahmin!$C$4+27),1,0),IF(Kalemler!$E6="Aylık",IF(OR(AND(DATE(YEAR((Tahmin!$C$4+21)),MONTH((Tahmin!$C$4+21)),MIN(DAY(Kalemler!$D6),DAY(EOMONTH((Tahmin!$C$4+21),0))))>=(Tahmin!$C$4+21),DATE(YEAR((Tahmin!$C$4+21)),MONTH((Tahmin!$C$4+21)),MIN(DAY(Kalemler!$D6),DAY(EOMONTH((Tahmin!$C$4+21),0))))<=(Tahmin!$C$4+27),DATE(YEAR((Tahmin!$C$4+21)),MONTH((Tahmin!$C$4+21)),MIN(DAY(Kalemler!$D6),DAY(EOMONTH((Tahmin!$C$4+21),0))))>=Kalemler!$D6),AND(DATE(YEAR((Tahmin!$C$4+27)),MONTH((Tahmin!$C$4+27)),MIN(DAY(Kalemler!$D6),DAY(EOMONTH((Tahmin!$C$4+27),0))))>=(Tahmin!$C$4+21),DATE(YEAR((Tahmin!$C$4+27)),MONTH((Tahmin!$C$4+27)),MIN(DAY(Kalemler!$D6),DAY(EOMONTH((Tahmin!$C$4+27),0))))<=(Tahmin!$C$4+27),DATE(YEAR((Tahmin!$C$4+27)),MONTH((Tahmin!$C$4+27)),MIN(DAY(Kalemler!$D6),DAY(EOMONTH((Tahmin!$C$4+27),0))))<>DATE(YEAR((Tahmin!$C$4+21)),MONTH((Tahmin!$C$4+21)),MIN(DAY(Kalemler!$D6),DAY(EOMONTH((Tahmin!$C$4+21),0)))),DATE(YEAR((Tahmin!$C$4+27)),MONTH((Tahmin!$C$4+27)),MIN(DAY(Kalemler!$D6),DAY(EOMONTH((Tahmin!$C$4+27),0))))>=Kalemler!$D6)),1,0),IF(AND(Kalemler!$D6>=(Tahmin!$C$4+21),Kalemler!$D6<=(Tahmin!$C$4+27)),1,0)))) -> 25000 | F6: =IF(OR(Kalemler!$A6="",Kalemler!$C6="",Kalemler!$D6=""),0,Kalemler!$C6*IF(Kalemler!$E6="Haftalık",IF(Kalemler!$D6<=(Tahmin!$C$4+34),1,0),IF(Kalemler!$E6="Aylık",IF(OR(AND(DATE(YEAR((Tahmin!$C$4+28)),MONTH((Tahmin!$C$4+28)),MIN(DAY(Kalemler!$D6),DAY(EOMONTH((Tahmin!$C$4+28),0))))>=(Tahmin!$C$4+28),DATE(YEAR((Tahmin!$C$4+28)),MONTH((Tahmin!$C$4+28)),MIN(DAY(Kalemler!$D6),DAY(EOMONTH((Tahmin!$C$4+28),0))))<=(Tahmin!$C$4+34),DATE(YEAR((Tahmin!$C$4+28)),MONTH((Tahmin!$C$4+28)),MIN(DAY(Kalemler!$D6),DAY(EOMONTH((Tahmin!$C$4+28),0))))>=Kalemler!$D6),AND(DATE(YEAR((Tahmin!$C$4+34)),MONTH((Tahmin!$C$4+34)),MIN(DAY(Kalemler!$D6),DAY(EOMONTH((Tahmin!$C$4+34),0))))>=(Tahmin!$C$4+28),DATE(YEAR((Tahmin!$C$4+34)),MONTH((Tahmin!$C$4+34)),MIN(DAY(Kalemler!$D6),DAY(EOMONTH((Tahmin!$C$4+34),0))))<=(Tahmin!$C$4+34),DATE(YEAR((Tahmin!$C$4+34)),MONTH((Tahmin!$C$4+34)),MIN(DAY(Kalemler!$D6),DAY(EOMONTH((Tahmin!$C$4+34),0))))<>DATE(YEAR((Tahmin!$C$4+28)),MONTH((Tahmin!$C$4+28)),MIN(DAY(Kalemler!$D6),DAY(EOMONTH((Tahmin!$C$4+28),0)))),DATE(YEAR((Tahmin!$C$4+34)),MONTH((Tahmin!$C$4+34)),MIN(DAY(Kalemler!$D6),DAY(EOMONTH((Tahmin!$C$4+34),0))))>=Kalemler!$D6)),1,0),IF(AND(Kalemler!$D6>=(Tahmin!$C$4+28),Kalemler!$D6<=(Tahmin!$C$4+34)),1,0)))) -> 25000 | G6: =IF(OR(Kalemler!$A6="",Kalemler!$C6="",Kalemler!$D6=""),0,Kalemler!$C6*IF(Kalemler!$E6="Haftalık",IF(Kalemler!$D6<=(Tahmin!$C$4+41),1,0),IF(Kalemler!$E6="Aylık",IF(OR(AND(DATE(YEAR((Tahmin!$C$4+35)),MONTH((Tahmin!$C$4+35)),MIN(DAY(Kalemler!$D6),DAY(EOMONTH((Tahmin!$C$4+35),0))))>=(Tahmin!$C$4+35),DATE(YEAR((Tahmin!$C$4+35)),MONTH((Tahmin!$C$4+35)),MIN(DAY(Kalemler!$D6),DAY(EOMONTH((Tahmin!$C$4+35),0))))<=(Tahmin!$C$4+41),DATE(YEAR((Tahmin!$C$4+35)),MONTH((Tahmin!$C$4+35)),MIN(DAY(Kalemler!$D6),DAY(EOMONTH((Tahmin!$C$4+35),0))))>=Kalemler!$D6),AND(DATE(YEAR((Tahmin!$C$4+41)),MONTH((Tahmin!$C$4+41)),MIN(DAY(Kalemler!$D6),DAY(EOMONTH((Tahmin!$C$4+41),0))))>=(Tahmin!$C$4+35),DATE(YEAR((Tahmin!$C$4+41)),MONTH((Tahmin!$C$4+41)),MIN(DAY(Kalemler!$D6),DAY(EOMONTH((Tahmin!$C$4+41),0))))<=(Tahmin!$C$4+41),DATE(YEAR((Tahmin!$C$4+41)),MONTH((Tahmin!$C$4+41)),MIN(DAY(Kalemler!$D6),DAY(EOMONTH((Tahmin!$C$4+41),0))))<>DATE(YEAR((Tahmin!$C$4+35)),MONTH((Tahmin!$C$4+35)),MIN(DAY(Kalemler!$D6),DAY(EOMONTH((Tahmin!$C$4+35),0)))),DATE(YEAR((Tahmin!$C$4+41)),MONTH((Tahmin!$C$4+41)),MIN(DAY(Kalemler!$D6),DAY(EOMONTH((Tahmin!$C$4+41),0))))>=Kalemler!$D6)),1,0),IF(AND(Kalemler!$D6>=(Tahmin!$C$4+35),Kalemler!$D6<=(Tahmin!$C$4+41)),1,0)))) -> 25000 | H6: =IF(OR(Kalemler!$A6="",Kalemler!$C6="",Kalemler!$D6=""),0,Kalemler!$C6*IF(Kalemler!$E6="Haftalık",IF(Kalemler!$D6<=(Tahmin!$C$4+48),1,0),IF(Kalemler!$E6="Aylık",IF(OR(AND(DATE(YEAR((Tahmin!$C$4+42)),MONTH((Tahmin!$C$4+42)),MIN(DAY(Kalemler!$D6),DAY(EOMONTH((Tahmin!$C$4+42),0))))>=(Tahmin!$C$4+42),DATE(YEAR((Tahmin!$C$4+42)),MONTH((Tahmin!$C$4+42)),MIN(DAY(Kalemler!$D6),DAY(EOMONTH((Tahmin!$C$4+42),0))))<=(Tahmin!$C$4+48),DATE(YEAR((Tahmin!$C$4+42)),MONTH((Tahmin!$C$4+42)),MIN(DAY(Kalemler!$D6),DAY(EOMONTH((Tahmin!$C$4+42),0))))>=Kalemler!$D6),AND(DATE(YEAR((Tahmin!$C$4+48)),MONTH((Tahmin!$C$4+48)),MIN(DAY(Kalemler!$D6),DAY(EOMONTH((Tahmin!$C$4+48),0))))>=(Tahmin!$C$4+42),DATE(YEAR((Tahmin!$C$4+48)),MONTH((Tahmin!$C$4+48)),MIN(DAY(Kalemler!$D6),DAY(EOMONTH((Tahmin!$C$4+48),0))))<=(Tahmin!$C$4+48),DATE(YEAR((Tahmin!$C$4+48)),MONTH((Tahmin!$C$4+48)),MIN(DAY(Kalemler!$D6),DAY(EOMONTH((Tahmin!$C$4+48),0))))<>DATE(YEAR((Tahmin!$C$4+42)),MONTH((Tahmin!$C$4+42)),MIN(DAY(Kalemler!$D6),DAY(EOMONTH((Tahmin!$C$4+42),0)))),DATE(YEAR((Tahmin!$C$4+48)),MONTH((Tahmin!$C$4+48)),MIN(DAY(Kalemler!$D6),DAY(EOMONTH((Tahmin!$C$4+48),0))))>=Kalemler!$D6)),1,0),IF(AND(Kalemler!$D6>=(Tahmin!$C$4+42),Kalemler!$D6<=(Tahmin!$C$4+48)),1,0)))) -> 25000 | I6: =IF(OR(Kalemler!$A6="",Kalemler!$C6="",Kalemler!$D6=""),0,Kalemler!$C6*IF(Kalemler!$E6="Haftalık",IF(Kalemler!$D6<=(Tahmin!$C$4+55),1,0),IF(Kalemler!$E6="Aylık",IF(OR(AND(DATE(YEAR((Tahmin!$C$4+49)),MONTH((Tahmin!$C$4+49)),MIN(DAY(Kalemler!$D6),DAY(EOMONTH((Tahmin!$C$4+49),0))))>=(Tahmin!$C$4+49),DATE(YEAR((Tahmin!$C$4+49)),MONTH((Tahmin!$C$4+49)),MIN(DAY(Kalemler!$D6),DAY(EOMONTH((Tahmin!$C$4+49),0))))<=(Tahmin!$C$4+55),DATE(YEAR((Tahmin!$C$4+49)),MONTH((Tahmin!$C$4+49)),MIN(DAY(Kalemler!$D6),DAY(EOMONTH((Tahmin!$C$4+49),0))))>=Kalemler!$D6),AND(DATE(YEAR((Tahmin!$C$4+55)),MONTH((Tahmin!$C$4+55)),MIN(DAY(Kalemler!$D6),DAY(EOMONTH((Tahmin!$C$4+55),0))))>=(Tahmin!$C$4+49),DATE(YEAR((Tahmin!$C$4+55)),MONTH((Tahmin!$C$4+55)),MIN(DAY(Kalemler!$D6),DAY(EOMONTH((Tahmin!$C$4+55),0))))<=(Tahmin!$C$4+55),DATE(YEAR((Tahmin!$C$4+55)),MONTH((Tahmin!$C$4+55)),MIN(DAY(Kalemler!$D6),DAY(EOMONTH((Tahmin!$C$4+55),0))))<>DATE(YEAR((Tahmin!$C$4+49)),MONTH((Tahmin!$C$4+49)),MIN(DAY(Kalemler!$D6),DAY(EOMONTH((Tahmin!$C$4+49),0)))),DATE(YEAR((Tahmin!$C$4+55)),MONTH((Tahmin!$C$4+55)),MIN(DAY(Kalemler!$D6),DAY(EOMONTH((Tahmin!$C$4+55),0))))>=Kalemler!$D6)),1,0),IF(AND(Kalemler!$D6>=(Tahmin!$C$4+49),Kalemler!$D6<=(Tahmin!$C$4+55)),1,0)))) -> 25000 | J6: =IF(OR(Kalemler!$A6="",Kalemler!$C6="",Kalemler!$D6=""),0,Kalemler!$C6*IF(Kalemler!$E6="Haftalık",IF(Kalemler!$D6<=(Tahmin!$C$4+62),1,0),IF(Kalemler!$E6="Aylık",IF(OR(AND(DATE(YEAR((Tahmin!$C$4+56)),MONTH((Tahmin!$C$4+56)),MIN(DAY(Kalemler!$D6),DAY(EOMONTH((Tahmin!$C$4+56),0))))>=(Tahmin!$C$4+56),DATE(YEAR((Tahmin!$C$4+56)),MONTH((Tahmin!$C$4+56)),MIN(DAY(Kalemler!$D6),DAY(EOMONTH((Tahmin!$C$4+56),0))))<=(Tahmin!$C$4+62),DATE(YEAR((Tahmin!$C$4+56)),MONTH((Tahmin!$C$4+56)),MIN(DAY(Kalemler!$D6),DAY(EOMONTH((Tahmin!$C$4+56),0))))>=Kalemler!$D6),AND(DATE(YEAR((Tahmin!$C$4+62)),MONTH((Tahmin!$C$4+62)),MIN(DAY(Kalemler!$D6),DAY(EOMONTH((Tahmin!$C$4+62),0))))>=(Tahmin!$C$4+56),DATE(YEAR((Tahmin!$C$4+62)),MONTH((Tahmin!$C$4+62)),MIN(DAY(Kalemler!$D6),DAY(EOMONTH((Tahmin!$C$4+62),0))))<=(Tahmin!$C$4+62),DATE(YEAR((Tahmin!$C$4+62)),MONTH((Tahmin!$C$4+62)),MIN(DAY(Kalemler!$D6),DAY(EOMONTH((Tahmin!$C$4+62),0))))<>DATE(YEAR((Tahmin!$C$4+56)),MONTH((Tahmin!$C$4+56)),MIN(DAY(Kalemler!$D6),DAY(EOMONTH((Tahmin!$C$4+56),0)))),DATE(YEAR((Tahmin!$C$4+62)),MONTH((Tahmin!$C$4+62)),MIN(DAY(Kalemler!$D6),DAY(EOMONTH((Tahmin!$C$4+62),0))))>=Kalemler!$D6)),1,0),IF(AND(Kalemler!$D6>=(Tahmin!$C$4+56),Kalemler!$D6<=(Tahmin!$C$4+62)),1,0)))) -> 25000 | K6: =IF(OR(Kalemler!$A6="",Kalemler!$C6="",Kalemler!$D6=""),0,Kalemler!$C6*IF(Kalemler!$E6="Haftalık",IF(Kalemler!$D6<=(Tahmin!$C$4+69),1,0),IF(Kalemler!$E6="Aylık",IF(OR(AND(DATE(YEAR((Tahmin!$C$4+63)),MONTH((Tahmin!$C$4+63)),MIN(DAY(Kalemler!$D6),DAY(EOMONTH((Tahmin!$C$4+63),0))))>=(Tahmin!$C$4+63),DATE(YEAR((Tahmin!$C$4+63)),MONTH((Tahmin!$C$4+63)),MIN(DAY(Kalemler!$D6),DAY(EOMONTH((Tahmin!$C$4+63),0))))<=(Tahmin!$C$4+69),DATE(YEAR((Tahmin!$C$4+63)),MONTH((Tahmin!$C$4+63)),MIN(DAY(Kalemler!$D6),DAY(EOMONTH((Tahmin!$C$4+63),0))))>=Kalemler!$D6),AND(DATE(YEAR((Tahmin!$C$4+69)),MONTH((Tahmin!$C$4+69)),MIN(DAY(Kalemler!$D6),DAY(EOMONTH((Tahmin!$C$4+69),0))))>=(Tahmin!$C$4+63),DATE(YEAR((Tahmin!$C$4+69)),MONTH((Tahmin!$C$4+69)),MIN(DAY(Kalemler!$D6),DAY(EOMONTH((Tahmin!$C$4+69),0))))<=(Tahmin!$C$4+69),DATE(YEAR((Tahmin!$C$4+69)),MONTH((Tahmin!$C$4+69)),MIN(DAY(Kalemler!$D6),DAY(EOMONTH((Tahmin!$C$4+69),0))))<>DATE(YEAR((Tahmin!$C$4+63)),MONTH((Tahmin!$C$4+63)),MIN(DAY(Kalemler!$D6),DAY(EOMONTH((Tahmin!$C$4+63),0)))),DATE(YEAR((Tahmin!$C$4+69)),MONTH((Tahmin!$C$4+69)),MIN(DAY(Kalemler!$D6),DAY(EOMONTH((Tahmin!$C$4+69),0))))>=Kalemler!$D6)),1,0),IF(AND(Kalemler!$D6>=(Tahmin!$C$4+63),Kalemler!$D6<=(Tahmin!$C$4+69)),1,0)))) -> 25000 | L6: =IF(OR(Kalemler!$A6="",Kalemler!$C6="",Kalemler!$D6=""),0,Kalemler!$C6*IF(Kalemler!$E6="Haftalık",IF(Kalemler!$D6<=(Tahmin!$C$4+76),1,0),IF(Kalemler!$E6="Aylık",IF(OR(AND(DATE(YEAR((Tahmin!$C$4+70)),MONTH((Tahmin!$C$4+70)),MIN(DAY(Kalemler!$D6),DAY(EOMONTH((Tahmin!$C$4+70),0))))>=(Tahmin!$C$4+70),DATE(YEAR((Tahmin!$C$4+70)),MONTH((Tahmin!$C$4+70)),MIN(DAY(Kalemler!$D6),DAY(EOMONTH((Tahmin!$C$4+70),0))))<=(Tahmin!$C$4+76),DATE(YEAR((Tahmin!$C$4+70)),MONTH((Tahmin!$C$4+70)),MIN(DAY(Kalemler!$D6),DAY(EOMONTH((Tahmin!$C$4+70),0))))>=Kalemler!$D6),AND(DATE(YEAR((Tahmin!$C$4+76)),MONTH((Tahmin!$C$4+76)),MIN(DAY(Kalemler!$D6),DAY(EOMONTH((Tahmin!$C$4+76),0))))>=(Tahmin!$C$4+70),DATE(YEAR((Tahmin!$C$4+76)),MONTH((Tahmin!$C$4+76)),MIN(DAY(Kalemler!$D6),DAY(EOMONTH((Tahmin!$C$4+76),0))))<=(Tahmin!$C$4+76),DATE(YEAR((Tahmin!$C$4+76)),MONTH((Tahmin!$C$4+76)),MIN(DAY(Kalemler!$D6),DAY(EOMONTH((Tahmin!$C$4+76),0))))<>DATE(YEAR((Tahmin!$C$4+70)),MONTH((Tahmin!$C$4+70)),MIN(DAY(Kalemler!$D6),DAY(EOMONTH((Tahmin!$C$4+70),0)))),DATE(YEAR((Tahmin!$C$4+76)),MONTH((Tahmin!$C$4+76)),MIN(DAY(Kalemler!$D6),DAY(EOMONTH((Tahmin!$C$4+76),0))))>=Kalemler!$D6)),1,0),IF(AND(Kalemler!$D6>=(Tahmin!$C$4+70),Kalemler!$D6<=(Tahmin!$C$4+76)),1,0)))) -> 25000 | M6: =IF(OR(Kalemler!$A6="",Kalemler!$C6="",Kalemler!$D6=""),0,Kalemler!$C6*IF(Kalemler!$E6="Haftalık",IF(Kalemler!$D6<=(Tahmin!$C$4+83),1,0),IF(Kalemler!$E6="Aylık",IF(OR(AND(DATE(YEAR((Tahmin!$C$4+77)),MONTH((Tahmin!$C$4+77)),MIN(DAY(Kalemler!$D6),DAY(EOMONTH((Tahmin!$C$4+77),0))))>=(Tahmin!$C$4+77),DATE(YEAR((Tahmin!$C$4+77)),MONTH((Tahmin!$C$4+77)),MIN(DAY(Kalemler!$D6),DAY(EOMONTH((Tahmin!$C$4+77),0))))<=(Tahmin!$C$4+83),DATE(YEAR((Tahmin!$C$4+77)),MONTH((Tahmin!$C$4+77)),MIN(DAY(Kalemler!$D6),DAY(EOMONTH((Tahmin!$C$4+77),0))))>=Kalemler!$D6),AND(DATE(YEAR((Tahmin!$C$4+83)),MONTH((Tahmin!$C$4+83)),MIN(DAY(Kalemler!$D6),DAY(EOMONTH((Tahmin!$C$4+83),0))))>=(Tahmin!$C$4+77),DATE(YEAR((Tahmin!$C$4+83)),MONTH((Tahmin!$C$4+83)),MIN(DAY(Kalemler!$D6),DAY(EOMONTH((Tahmin!$C$4+83),0))))<=(Tahmin!$C$4+83),DATE(YEAR((Tahmin!$C$4+83)),MONTH((Tahmin!$C$4+83)),MIN(DAY(Kalemler!$D6),DAY(EOMONTH((Tahmin!$C$4+83),0))))<>DATE(YEAR((Tahmin!$C$4+77)),MONTH((Tahmin!$C$4+77)),MIN(DAY(Kalemler!$D6),DAY(EOMONTH((Tahmin!$C$4+77),0)))),DATE(YEAR((Tahmin!$C$4+83)),MONTH((Tahmin!$C$4+83)),MIN(DAY(Kalemler!$D6),DAY(EOMONTH((Tahmin!$C$4+83),0))))>=Kalemler!$D6)),1,0),IF(AND(Kalemler!$D6>=(Tahmin!$C$4+77),Kalemler!$D6<=(Tahmin!$C$4+83)),1,0)))) -> 25000 | N6: =IF(OR(Kalemler!$A6="",Kalemler!$C6="",Kalemler!$D6=""),0,Kalemler!$C6*IF(Kalemler!$E6="Haftalık",IF(Kalemler!$D6<=(Tahmin!$C$4+90),1,0),IF(Kalemler!$E6="Aylık",IF(OR(AND(DATE(YEAR((Tahmin!$C$4+84)),MONTH((Tahmin!$C$4+84)),MIN(DAY(Kalemler!$D6),DAY(EOMONTH((Tahmin!$C$4+84),0))))>=(Tahmin!$C$4+84),DATE(YEAR((Tahmin!$C$4+84)),MONTH((Tahmin!$C$4+84)),MIN(DAY(Kalemler!$D6),DAY(EOMONTH((Tahmin!$C$4+84),0))))<=(Tahmin!$C$4+90),DATE(YEAR((Tahmin!$C$4+84)),MONTH((Tahmin!$C$4+84)),MIN(DAY(Kalemler!$D6),DAY(EOMONTH((Tahmin!$C$4+84),0))))>=Kalemler!$D6),AND(DATE(YEAR((Tahmin!$C$4+90)),MONTH((Tahmin!$C$4+90)),MIN(DAY(Kalemler!$D6),DAY(EOMONTH((Tahmin!$C$4+90),0))))>=(Tahmin!$C$4+84),DATE(YEAR((Tahmin!$C$4+90)),MONTH((Tahmin!$C$4+90)),MIN(DAY(Kalemler!$D6),DAY(EOMONTH((Tahmin!$C$4+90),0))))<=(Tahmin!$C$4+90),DATE(YEAR((Tahmin!$C$4+90)),MONTH((Tahmin!$C$4+90)),MIN(DAY(Kalemler!$D6),DAY(EOMONTH((Tahmin!$C$4+90),0))))<>DATE(YEAR((Tahmin!$C$4+84)),MONTH((Tahmin!$C$4+84)),MIN(DAY(Kalemler!$D6),DAY(EOMONTH((Tahmin!$C$4+84),0)))),DATE(YEAR((Tahmin!$C$4+90)),MONTH((Tahmin!$C$4+90)),MIN(DAY(Kalemler!$D6),DAY(EOMONTH((Tahmin!$C$4+90),0))))>=Kalemler!$D6)),1,0),IF(AND(Kalemler!$D6>=(Tahmin!$C$4+84),Kalemler!$D6<=(Tahmin!$C$4+90)),1,0)))) -> 25000
A7: =IF(Kalemler!A7="","",Kalemler!A7) -> Yeni sipariş (beklenen) | B7: =IF(OR(Kalemler!$A7="",Kalemler!$C7="",Kalemler!$D7=""),0,Kalemler!$C7*IF(Kalemler!$E7="Haftalık",IF(Kalemler!$D7<=(Tahmin!$C$4+6),1,0),IF(Kalemler!$E7="Aylık",IF(OR(AND(DATE(YEAR((Tahmin!$C$4+0)),MONTH((Tahmin!$C$4+0)),MIN(DAY(Kalemler!$D7),DAY(EOMONTH((Tahmin!$C$4+0),0))))>=(Tahmin!$C$4+0),DATE(YEAR((Tahmin!$C$4+0)),MONTH((Tahmin!$C$4+0)),MIN(DAY(Kalemler!$D7),DAY(EOMONTH((Tahmin!$C$4+0),0))))<=(Tahmin!$C$4+6),DATE(YEAR((Tahmin!$C$4+0)),MONTH((Tahmin!$C$4+0)),MIN(DAY(Kalemler!$D7),DAY(EOMONTH((Tahmin!$C$4+0),0))))>=Kalemler!$D7),AND(DATE(YEAR((Tahmin!$C$4+6)),MONTH((Tahmin!$C$4+6)),MIN(DAY(Kalemler!$D7),DAY(EOMONTH((Tahmin!$C$4+6),0))))>=(Tahmin!$C$4+0),DATE(YEAR((Tahmin!$C$4+6)),MONTH((Tahmin!$C$4+6)),MIN(DAY(Kalemler!$D7),DAY(EOMONTH((Tahmin!$C$4+6),0))))<=(Tahmin!$C$4+6),DATE(YEAR((Tahmin!$C$4+6)),MONTH((Tahmin!$C$4+6)),MIN(DAY(Kalemler!$D7),DAY(EOMONTH((Tahmin!$C$4+6),0))))<>DATE(YEAR((Tahmin!$C$4+0)),MONTH((Tahmin!$C$4+0)),MIN(DAY(Kalemler!$D7),DAY(EOMONTH((Tahmin!$C$4+0),0)))),DATE(YEAR((Tahmin!$C$4+6)),MONTH((Tahmin!$C$4+6)),MIN(DAY(Kalemler!$D7),DAY(EOMONTH((Tahmin!$C$4+6),0))))>=Kalemler!$D7)),1,0),IF(AND(Kalemler!$D7>=(Tahmin!$C$4+0),Kalemler!$D7<=(Tahmin!$C$4+6)),1,0)))) -> 0 | C7: =IF(OR(Kalemler!$A7="",Kalemler!$C7="",Kalemler!$D7=""),0,Kalemler!$C7*IF(Kalemler!$E7="Haftalık",IF(Kalemler!$D7<=(Tahmin!$C$4+13),1,0),IF(Kalemler!$E7="Aylık",IF(OR(AND(DATE(YEAR((Tahmin!$C$4+7)),MONTH((Tahmin!$C$4+7)),MIN(DAY(Kalemler!$D7),DAY(EOMONTH((Tahmin!$C$4+7),0))))>=(Tahmin!$C$4+7),DATE(YEAR((Tahmin!$C$4+7)),MONTH((Tahmin!$C$4+7)),MIN(DAY(Kalemler!$D7),DAY(EOMONTH((Tahmin!$C$4+7),0))))<=(Tahmin!$C$4+13),DATE(YEAR((Tahmin!$C$4+7)),MONTH((Tahmin!$C$4+7)),MIN(DAY(Kalemler!$D7),DAY(EOMONTH((Tahmin!$C$4+7),0))))>=Kalemler!$D7),AND(DATE(YEAR((Tahmin!$C$4+13)),MONTH((Tahmin!$C$4+13)),MIN(DAY(Kalemler!$D7),DAY(EOMONTH((Tahmin!$C$4+13),0))))>=(Tahmin!$C$4+7),DATE(YEAR((Tahmin!$C$4+13)),MONTH((Tahmin!$C$4+13)),MIN(DAY(Kalemler!$D7),DAY(EOMONTH((Tahmin!$C$4+13),0))))<=(Tahmin!$C$4+13),DATE(YEAR((Tahmin!$C$4+13)),MONTH((Tahmin!$C$4+13)),MIN(DAY(Kalemler!$D7),DAY(EOMONTH((Tahmin!$C$4+13),0))))<>DATE(YEAR((Tahmin!$C$4+7)),MONTH((Tahmin!$C$4+7)),MIN(DAY(Kalemler!$D7),DAY(EOMONTH((Tahmin!$C$4+7),0)))),DATE(YEAR((Tahmin!$C$4+13)),MONTH((Tahmin!$C$4+13)),MIN(DAY(Kalemler!$D7),DAY(EOMONTH((Tahmin!$C$4+13),0))))>=Kalemler!$D7)),1,0),IF(AND(Kalemler!$D7>=(Tahmin!$C$4+7),Kalemler!$D7<=(Tahmin!$C$4+13)),1,0)))) -> 0 | D7: =IF(OR(Kalemler!$A7="",Kalemler!$C7="",Kalemler!$D7=""),0,Kalemler!$C7*IF(Kalemler!$E7="Haftalık",IF(Kalemler!$D7<=(Tahmin!$C$4+20),1,0),IF(Kalemler!$E7="Aylık",IF(OR(AND(DATE(YEAR((Tahmin!$C$4+14)),MONTH((Tahmin!$C$4+14)),MIN(DAY(Kalemler!$D7),DAY(EOMONTH((Tahmin!$C$4+14),0))))>=(Tahmin!$C$4+14),DATE(YEAR((Tahmin!$C$4+14)),MONTH((Tahmin!$C$4+14)),MIN(DAY(Kalemler!$D7),DAY(EOMONTH((Tahmin!$C$4+14),0))))<=(Tahmin!$C$4+20),DATE(YEAR((Tahmin!$C$4+14)),MONTH((Tahmin!$C$4+14)),MIN(DAY(Kalemler!$D7),DAY(EOMONTH((Tahmin!$C$4+14),0))))>=Kalemler!$D7),AND(DATE(YEAR((Tahmin!$C$4+20)),MONTH((Tahmin!$C$4+20)),MIN(DAY(Kalemler!$D7),DAY(EOMONTH((Tahmin!$C$4+20),0))))>=(Tahmin!$C$4+14),DATE(YEAR((Tahmin!$C$4+20)),MONTH((Tahmin!$C$4+20)),MIN(DAY(Kalemler!$D7),DAY(EOMONTH((Tahmin!$C$4+20),0))))<=(Tahmin!$C$4+20),DATE(YEAR((Tahmin!$C$4+20)),MONTH((Tahmin!$C$4+20)),MIN(DAY(Kalemler!$D7),DAY(EOMONTH((Tahmin!$C$4+20),0))))<>DATE(YEAR((Tahmin!$C$4+14)),MONTH((Tahmin!$C$4+14)),MIN(DAY(Kalemler!$D7),DAY(EOMONTH((Tahmin!$C$4+14),0)))),DATE(YEAR((Tahmin!$C$4+20)),MONTH((Tahmin!$C$4+20)),MIN(DAY(Kalemler!$D7),DAY(EOMONTH((Tahmin!$C$4+20),0))))>=Kalemler!$D7)),1,0),IF(AND(Kalemler!$D7>=(Tahmin!$C$4+14),Kalemler!$D7<=(Tahmin!$C$4+20)),1,0)))) -> 0 | E7: =IF(OR(Kalemler!$A7="",Kalemler!$C7="",Kalemler!$D7=""),0,Kalemler!$C7*IF(Kalemler!$E7="Haftalık",IF(Kalemler!$D7<=(Tahmin!$C$4+27),1,0),IF(Kalemler!$E7="Aylık",IF(OR(AND(DATE(YEAR((Tahmin!$C$4+21)),MONTH((Tahmin!$C$4+21)),MIN(DAY(Kalemler!$D7),DAY(EOMONTH((Tahmin!$C$4+21),0))))>=(Tahmin!$C$4+21),DATE(YEAR((Tahmin!$C$4+21)),MONTH((Tahmin!$C$4+21)),MIN(DAY(Kalemler!$D7),DAY(EOMONTH((Tahmin!$C$4+21),0))))<=(Tahmin!$C$4+27),DATE(YEAR((Tahmin!$C$4+21)),MONTH((Tahmin!$C$4+21)),MIN(DAY(Kalemler!$D7),DAY(EOMONTH((Tahmin!$C$4+21),0))))>=Kalemler!$D7),AND(DATE(YEAR((Tahmin!$C$4+27)),MONTH((Tahmin!$C$4+27)),MIN(DAY(Kalemler!$D7),DAY(EOMONTH((Tahmin!$C$4+27),0))))>=(Tahmin!$C$4+21),DATE(YEAR((Tahmin!$C$4+27)),MONTH((Tahmin!$C$4+27)),MIN(DAY(Kalemler!$D7),DAY(EOMONTH((Tahmin!$C$4+27),0))))<=(Tahmin!$C$4+27),DATE(YEAR((Tahmin!$C$4+27)),MONTH((Tahmin!$C$4+27)),MIN(DAY(Kalemler!$D7),DAY(EOMONTH((Tahmin!$C$4+27),0))))<>DATE(YEAR((Tahmin!$C$4+21)),MONTH((Tahmin!$C$4+21)),MIN(DAY(Kalemler!$D7),DAY(EOMONTH((Tahmin!$C$4+21),0)))),DATE(YEAR((Tahmin!$C$4+27)),MONTH((Tahmin!$C$4+27)),MIN(DAY(Kalemler!$D7),DAY(EOMONTH((Tahmin!$C$4+27),0))))>=Kalemler!$D7)),1,0),IF(AND(Kalemler!$D7>=(Tahmin!$C$4+21),Kalemler!$D7<=(Tahmin!$C$4+27)),1,0)))) -> 0 | F7: =IF(OR(Kalemler!$A7="",Kalemler!$C7="",Kalemler!$D7=""),0,Kalemler!$C7*IF(Kalemler!$E7="Haftalık",IF(Kalemler!$D7<=(Tahmin!$C$4+34),1,0),IF(Kalemler!$E7="Aylık",IF(OR(AND(DATE(YEAR((Tahmin!$C$4+28)),MONTH((Tahmin!$C$4+28)),MIN(DAY(Kalemler!$D7),DAY(EOMONTH((Tahmin!$C$4+28),0))))>=(Tahmin!$C$4+28),DATE(YEAR((Tahmin!$C$4+28)),MONTH((Tahmin!$C$4+28)),MIN(DAY(Kalemler!$D7),DAY(EOMONTH((Tahmin!$C$4+28),0))))<=(Tahmin!$C$4+34),DATE(YEAR((Tahmin!$C$4+28)),MONTH((Tahmin!$C$4+28)),MIN(DAY(Kalemler!$D7),DAY(EOMONTH((Tahmin!$C$4+28),0))))>=Kalemler!$D7),AND(DATE(YEAR((Tahmin!$C$4+34)),MONTH((Tahmin!$C$4+34)),MIN(DAY(Kalemler!$D7),DAY(EOMONTH((Tahmin!$C$4+34),0))))>=(Tahmin!$C$4+28),DATE(YEAR((Tahmin!$C$4+34)),MONTH((Tahmin!$C$4+34)),MIN(DAY(Kalemler!$D7),DAY(EOMONTH((Tahmin!$C$4+34),0))))<=(Tahmin!$C$4+34),DATE(YEAR((Tahmin!$C$4+34)),MONTH((Tahmin!$C$4+34)),MIN(DAY(Kalemler!$D7),DAY(EOMONTH((Tahmin!$C$4+34),0))))<>DATE(YEAR((Tahmin!$C$4+28)),MONTH((Tahmin!$C$4+28)),MIN(DAY(Kalemler!$D7),DAY(EOMONTH((Tahmin!$C$4+28),0)))),DATE(YEAR((Tahmin!$C$4+34)),MONTH((Tahmin!$C$4+34)),MIN(DAY(Kalemler!$D7),DAY(EOMONTH((Tahmin!$C$4+34),0))))>=Kalemler!$D7)),1,0),IF(AND(Kalemler!$D7>=(Tahmin!$C$4+28),Kalemler!$D7<=(Tahmin!$C$4+34)),1,0)))) -> 0 | G7: =IF(OR(Kalemler!$A7="",Kalemler!$C7="",Kalemler!$D7=""),0,Kalemler!$C7*IF(Kalemler!$E7="Haftalık",IF(Kalemler!$D7<=(Tahmin!$C$4+41),1,0),IF(Kalemler!$E7="Aylık",IF(OR(AND(DATE(YEAR((Tahmin!$C$4+35)),MONTH((Tahmin!$C$4+35)),MIN(DAY(Kalemler!$D7),DAY(EOMONTH((Tahmin!$C$4+35),0))))>=(Tahmin!$C$4+35),DATE(YEAR((Tahmin!$C$4+35)),MONTH((Tahmin!$C$4+35)),MIN(DAY(Kalemler!$D7),DAY(EOMONTH((Tahmin!$C$4+35),0))))<=(Tahmin!$C$4+41),DATE(YEAR((Tahmin!$C$4+35)),MONTH((Tahmin!$C$4+35)),MIN(DAY(Kalemler!$D7),DAY(EOMONTH((Tahmin!$C$4+35),0))))>=Kalemler!$D7),AND(DATE(YEAR((Tahmin!$C$4+41)),MONTH((Tahmin!$C$4+41)),MIN(DAY(Kalemler!$D7),DAY(EOMONTH((Tahmin!$C$4+41),0))))>=(Tahmin!$C$4+35),DATE(YEAR((Tahmin!$C$4+41)),MONTH((Tahmin!$C$4+41)),MIN(DAY(Kalemler!$D7),DAY(EOMONTH((Tahmin!$C$4+41),0))))<=(Tahmin!$C$4+41),DATE(YEAR((Tahmin!$C$4+41)),MONTH((Tahmin!$C$4+41)),MIN(DAY(Kalemler!$D7),DAY(EOMONTH((Tahmin!$C$4+41),0))))<>DATE(YEAR((Tahmin!$C$4+35)),MONTH((Tahmin!$C$4+35)),MIN(DAY(Kalemler!$D7),DAY(EOMONTH((Tahmin!$C$4+35),0)))),DATE(YEAR((Tahmin!$C$4+41)),MONTH((Tahmin!$C$4+41)),MIN(DAY(Kalemler!$D7),DAY(EOMONTH((Tahmin!$C$4+41),0))))>=Kalemler!$D7)),1,0),IF(AND(Kalemler!$D7>=(Tahmin!$C$4+35),Kalemler!$D7<=(Tahmin!$C$4+41)),1,0)))) -> 80000 | H7: =IF(OR(Kalemler!$A7="",Kalemler!$C7="",Kalemler!$D7=""),0,Kalemler!$C7*IF(Kalemler!$E7="Haftalık",IF(Kalemler!$D7<=(Tahmin!$C$4+48),1,0),IF(Kalemler!$E7="Aylık",IF(OR(AND(DATE(YEAR((Tahmin!$C$4+42)),MONTH((Tahmin!$C$4+42)),MIN(DAY(Kalemler!$D7),DAY(EOMONTH((Tahmin!$C$4+42),0))))>=(Tahmin!$C$4+42),DATE(YEAR((Tahmin!$C$4+42)),MONTH((Tahmin!$C$4+42)),MIN(DAY(Kalemler!$D7),DAY(EOMONTH((Tahmin!$C$4+42),0))))<=(Tahmin!$C$4+48),DATE(YEAR((Tahmin!$C$4+42)),MONTH((Tahmin!$C$4+42)),MIN(DAY(Kalemler!$D7),DAY(EOMONTH((Tahmin!$C$4+42),0))))>=Kalemler!$D7),AND(DATE(YEAR((Tahmin!$C$4+48)),MONTH((Tahmin!$C$4+48)),MIN(DAY(Kalemler!$D7),DAY(EOMONTH((Tahmin!$C$4+48),0))))>=(Tahmin!$C$4+42),DATE(YEAR((Tahmin!$C$4+48)),MONTH((Tahmin!$C$4+48)),MIN(DAY(Kalemler!$D7),DAY(EOMONTH((Tahmin!$C$4+48),0))))<=(Tahmin!$C$4+48),DATE(YEAR((Tahmin!$C$4+48)),MONTH((Tahmin!$C$4+48)),MIN(DAY(Kalemler!$D7),DAY(EOMONTH((Tahmin!$C$4+48),0))))<>DATE(YEAR((Tahmin!$C$4+42)),MONTH((Tahmin!$C$4+42)),MIN(DAY(Kalemler!$D7),DAY(EOMONTH((Tahmin!$C$4+42),0)))),DATE(YEAR((Tahmin!$C$4+48)),MONTH((Tahmin!$C$4+48)),MIN(DAY(Kalemler!$D7),DAY(EOMONTH((Tahmin!$C$4+48),0))))>=Kalemler!$D7)),1,0),IF(AND(Kalemler!$D7>=(Tahmin!$C$4+42),Kalemler!$D7<=(Tahmin!$C$4+48)),1,0)))) -> 0 | I7: =IF(OR(Kalemler!$A7="",Kalemler!$C7="",Kalemler!$D7=""),0,Kalemler!$C7*IF(Kalemler!$E7="Haftalık",IF(Kalemler!$D7<=(Tahmin!$C$4+55),1,0),IF(Kalemler!$E7="Aylık",IF(OR(AND(DATE(YEAR((Tahmin!$C$4+49)),MONTH((Tahmin!$C$4+49)),MIN(DAY(Kalemler!$D7),DAY(EOMONTH((Tahmin!$C$4+49),0))))>=(Tahmin!$C$4+49),DATE(YEAR((Tahmin!$C$4+49)),MONTH((Tahmin!$C$4+49)),MIN(DAY(Kalemler!$D7),DAY(EOMONTH((Tahmin!$C$4+49),0))))<=(Tahmin!$C$4+55),DATE(YEAR((Tahmin!$C$4+49)),MONTH((Tahmin!$C$4+49)),MIN(DAY(Kalemler!$D7),DAY(EOMONTH((Tahmin!$C$4+49),0))))>=Kalemler!$D7),AND(DATE(YEAR((Tahmin!$C$4+55)),MONTH((Tahmin!$C$4+55)),MIN(DAY(Kalemler!$D7),DAY(EOMONTH((Tahmin!$C$4+55),0))))>=(Tahmin!$C$4+49),DATE(YEAR((Tahmin!$C$4+55)),MONTH((Tahmin!$C$4+55)),MIN(DAY(Kalemler!$D7),DAY(EOMONTH((Tahmin!$C$4+55),0))))<=(Tahmin!$C$4+55),DATE(YEAR((Tahmin!$C$4+55)),MONTH((Tahmin!$C$4+55)),MIN(DAY(Kalemler!$D7),DAY(EOMONTH((Tahmin!$C$4+55),0))))<>DATE(YEAR((Tahmin!$C$4+49)),MONTH((Tahmin!$C$4+49)),MIN(DAY(Kalemler!$D7),DAY(EOMONTH((Tahmin!$C$4+49),0)))),DATE(YEAR((Tahmin!$C$4+55)),MONTH((Tahmin!$C$4+55)),MIN(DAY(Kalemler!$D7),DAY(EOMONTH((Tahmin!$C$4+55),0))))>=Kalemler!$D7)),1,0),IF(AND(Kalemler!$D7>=(Tahmin!$C$4+49),Kalemler!$D7<=(Tahmin!$C$4+55)),1,0)))) -> 0 | J7: =IF(OR(Kalemler!$A7="",Kalemler!$C7="",Kalemler!$D7=""),0,Kalemler!$C7*IF(Kalemler!$E7="Haftalık",IF(Kalemler!$D7<=(Tahmin!$C$4+62),1,0),IF(Kalemler!$E7="Aylık",IF(OR(AND(DATE(YEAR((Tahmin!$C$4+56)),MONTH((Tahmin!$C$4+56)),MIN(DAY(Kalemler!$D7),DAY(EOMONTH((Tahmin!$C$4+56),0))))>=(Tahmin!$C$4+56),DATE(YEAR((Tahmin!$C$4+56)),MONTH((Tahmin!$C$4+56)),MIN(DAY(Kalemler!$D7),DAY(EOMONTH((Tahmin!$C$4+56),0))))<=(Tahmin!$C$4+62),DATE(YEAR((Tahmin!$C$4+56)),MONTH((Tahmin!$C$4+56)),MIN(DAY(Kalemler!$D7),DAY(EOMONTH((Tahmin!$C$4+56),0))))>=Kalemler!$D7),AND(DATE(YEAR((Tahmin!$C$4+62)),MONTH((Tahmin!$C$4+62)),MIN(DAY(Kalemler!$D7),DAY(EOMONTH((Tahmin!$C$4+62),0))))>=(Tahmin!$C$4+56),DATE(YEAR((Tahmin!$C$4+62)),MONTH((Tahmin!$C$4+62)),MIN(DAY(Kalemler!$D7),DAY(EOMONTH((Tahmin!$C$4+62),0))))<=(Tahmin!$C$4+62),DATE(YEAR((Tahmin!$C$4+62)),MONTH((Tahmin!$C$4+62)),MIN(DAY(Kalemler!$D7),DAY(EOMONTH((Tahmin!$C$4+62),0))))<>DATE(YEAR((Tahmin!$C$4+56)),MONTH((Tahmin!$C$4+56)),MIN(DAY(Kalemler!$D7),DAY(EOMONTH((Tahmin!$C$4+56),0)))),DATE(YEAR((Tahmin!$C$4+62)),MONTH((Tahmin!$C$4+62)),MIN(DAY(Kalemler!$D7),DAY(EOMONTH((Tahmin!$C$4+62),0))))>=Kalemler!$D7)),1,0),IF(AND(Kalemler!$D7>=(Tahmin!$C$4+56),Kalemler!$D7<=(Tahmin!$C$4+62)),1,0)))) -> 0 | K7: =IF(OR(Kalemler!$A7="",Kalemler!$C7="",Kalemler!$D7=""),0,Kalemler!$C7*IF(Kalemler!$E7="Haftalık",IF(Kalemler!$D7<=(Tahmin!$C$4+69),1,0),IF(Kalemler!$E7="Aylık",IF(OR(AND(DATE(YEAR((Tahmin!$C$4+63)),MONTH((Tahmin!$C$4+63)),MIN(DAY(Kalemler!$D7),DAY(EOMONTH((Tahmin!$C$4+63),0))))>=(Tahmin!$C$4+63),DATE(YEAR((Tahmin!$C$4+63)),MONTH((Tahmin!$C$4+63)),MIN(DAY(Kalemler!$D7),DAY(EOMONTH((Tahmin!$C$4+63),0))))<=(Tahmin!$C$4+69),DATE(YEAR((Tahmin!$C$4+63)),MONTH((Tahmin!$C$4+63)),MIN(DAY(Kalemler!$D7),DAY(EOMONTH((Tahmin!$C$4+63),0))))>=Kalemler!$D7),AND(DATE(YEAR((Tahmin!$C$4+69)),MONTH((Tahmin!$C$4+69)),MIN(DAY(Kalemler!$D7),DAY(EOMONTH((Tahmin!$C$4+69),0))))>=(Tahmin!$C$4+63),DATE(YEAR((Tahmin!$C$4+69)),MONTH((Tahmin!$C$4+69)),MIN(DAY(Kalemler!$D7),DAY(EOMONTH((Tahmin!$C$4+69),0))))<=(Tahmin!$C$4+69),DATE(YEAR((Tahmin!$C$4+69)),MONTH((Tahmin!$C$4+69)),MIN(DAY(Kalemler!$D7),DAY(EOMONTH((Tahmin!$C$4+69),0))))<>DATE(YEAR((Tahmin!$C$4+63)),MONTH((Tahmin!$C$4+63)),MIN(DAY(Kalemler!$D7),DAY(EOMONTH((Tahmin!$C$4+63),0)))),DATE(YEAR((Tahmin!$C$4+69)),MONTH((Tahmin!$C$4+69)),MIN(DAY(Kalemler!$D7),DAY(EOMONTH((Tahmin!$C$4+69),0))))>=Kalemler!$D7)),1,0),IF(AND(Kalemler!$D7>=(Tahmin!$C$4+63),Kalemler!$D7<=(Tahmin!$C$4+69)),1,0)))) -> 0 | L7: =IF(OR(Kalemler!$A7="",Kalemler!$C7="",Kalemler!$D7=""),0,Kalemler!$C7*IF(Kalemler!$E7="Haftalık",IF(Kalemler!$D7<=(Tahmin!$C$4+76),1,0),IF(Kalemler!$E7="Aylık",IF(OR(AND(DATE(YEAR((Tahmin!$C$4+70)),MONTH((Tahmin!$C$4+70)),MIN(DAY(Kalemler!$D7),DAY(EOMONTH((Tahmin!$C$4+70),0))))>=(Tahmin!$C$4+70),DATE(YEAR((Tahmin!$C$4+70)),MONTH((Tahmin!$C$4+70)),MIN(DAY(Kalemler!$D7),DAY(EOMONTH((Tahmin!$C$4+70),0))))<=(Tahmin!$C$4+76),DATE(YEAR((Tahmin!$C$4+70)),MONTH((Tahmin!$C$4+70)),MIN(DAY(Kalemler!$D7),DAY(EOMONTH((Tahmin!$C$4+70),0))))>=Kalemler!$D7),AND(DATE(YEAR((Tahmin!$C$4+76)),MONTH((Tahmin!$C$4+76)),MIN(DAY(Kalemler!$D7),DAY(EOMONTH((Tahmin!$C$4+76),0))))>=(Tahmin!$C$4+70),DATE(YEAR((Tahmin!$C$4+76)),MONTH((Tahmin!$C$4+76)),MIN(DAY(Kalemler!$D7),DAY(EOMONTH((Tahmin!$C$4+76),0))))<=(Tahmin!$C$4+76),DATE(YEAR((Tahmin!$C$4+76)),MONTH((Tahmin!$C$4+76)),MIN(DAY(Kalemler!$D7),DAY(EOMONTH((Tahmin!$C$4+76),0))))<>DATE(YEAR((Tahmin!$C$4+70)),MONTH((Tahmin!$C$4+70)),MIN(DAY(Kalemler!$D7),DAY(EOMONTH((Tahmin!$C$4+70),0)))),DATE(YEAR((Tahmin!$C$4+76)),MONTH((Tahmin!$C$4+76)),MIN(DAY(Kalemler!$D7),DAY(EOMONTH((Tahmin!$C$4+76),0))))>=Kalemler!$D7)),1,0),IF(AND(Kalemler!$D7>=(Tahmin!$C$4+70),Kalemler!$D7<=(Tahmin!$C$4+76)),1,0)))) -> 0 | M7: =IF(OR(Kalemler!$A7="",Kalemler!$C7="",Kalemler!$D7=""),0,Kalemler!$C7*IF(Kalemler!$E7="Haftalık",IF(Kalemler!$D7<=(Tahmin!$C$4+83),1,0),IF(Kalemler!$E7="Aylık",IF(OR(AND(DATE(YEAR((Tahmin!$C$4+77)),MONTH((Tahmin!$C$4+77)),MIN(DAY(Kalemler!$D7),DAY(EOMONTH((Tahmin!$C$4+77),0))))>=(Tahmin!$C$4+77),DATE(YEAR((Tahmin!$C$4+77)),MONTH((Tahmin!$C$4+77)),MIN(DAY(Kalemler!$D7),DAY(EOMONTH((Tahmin!$C$4+77),0))))<=(Tahmin!$C$4+83),DATE(YEAR((Tahmin!$C$4+77)),MONTH((Tahmin!$C$4+77)),MIN(DAY(Kalemler!$D7),DAY(EOMONTH((Tahmin!$C$4+77),0))))>=Kalemler!$D7),AND(DATE(YEAR((Tahmin!$C$4+83)),MONTH((Tahmin!$C$4+83)),MIN(DAY(Kalemler!$D7),DAY(EOMONTH((Tahmin!$C$4+83),0))))>=(Tahmin!$C$4+77),DATE(YEAR((Tahmin!$C$4+83)),MONTH((Tahmin!$C$4+83)),MIN(DAY(Kalemler!$D7),DAY(EOMONTH((Tahmin!$C$4+83),0))))<=(Tahmin!$C$4+83),DATE(YEAR((Tahmin!$C$4+83)),MONTH((Tahmin!$C$4+83)),MIN(DAY(Kalemler!$D7),DAY(EOMONTH((Tahmin!$C$4+83),0))))<>DATE(YEAR((Tahmin!$C$4+77)),MONTH((Tahmin!$C$4+77)),MIN(DAY(Kalemler!$D7),DAY(EOMONTH((Tahmin!$C$4+77),0)))),DATE(YEAR((Tahmin!$C$4+83)),MONTH((Tahmin!$C$4+83)),MIN(DAY(Kalemler!$D7),DAY(EOMONTH((Tahmin!$C$4+83),0))))>=Kalemler!$D7)),1,0),IF(AND(Kalemler!$D7>=(Tahmin!$C$4+77),Kalemler!$D7<=(Tahmin!$C$4+83)),1,0)))) -> 0 | N7: =IF(OR(Kalemler!$A7="",Kalemler!$C7="",Kalemler!$D7=""),0,Kalemler!$C7*IF(Kalemler!$E7="Haftalık",IF(Kalemler!$D7<=(Tahmin!$C$4+90),1,0),IF(Kalemler!$E7="Aylık",IF(OR(AND(DATE(YEAR((Tahmin!$C$4+84)),MONTH((Tahmin!$C$4+84)),MIN(DAY(Kalemler!$D7),DAY(EOMONTH((Tahmin!$C$4+84),0))))>=(Tahmin!$C$4+84),DATE(YEAR((Tahmin!$C$4+84)),MONTH((Tahmin!$C$4+84)),MIN(DAY(Kalemler!$D7),DAY(EOMONTH((Tahmin!$C$4+84),0))))<=(Tahmin!$C$4+90),DATE(YEAR((Tahmin!$C$4+84)),MONTH((Tahmin!$C$4+84)),MIN(DAY(Kalemler!$D7),DAY(EOMONTH((Tahmin!$C$4+84),0))))>=Kalemler!$D7),AND(DATE(YEAR((Tahmin!$C$4+90)),MONTH((Tahmin!$C$4+90)),MIN(DAY(Kalemler!$D7),DAY(EOMONTH((Tahmin!$C$4+90),0))))>=(Tahmin!$C$4+84),DATE(YEAR((Tahmin!$C$4+90)),MONTH((Tahmin!$C$4+90)),MIN(DAY(Kalemler!$D7),DAY(EOMONTH((Tahmin!$C$4+90),0))))<=(Tahmin!$C$4+90),DATE(YEAR((Tahmin!$C$4+90)),MONTH((Tahmin!$C$4+90)),MIN(DAY(Kalemler!$D7),DAY(EOMONTH((Tahmin!$C$4+90),0))))<>DATE(YEAR((Tahmin!$C$4+84)),MONTH((Tahmin!$C$4+84)),MIN(DAY(Kalemler!$D7),DAY(EOMONTH((Tahmin!$C$4+84),0)))),DATE(YEAR((Tahmin!$C$4+90)),MONTH((Tahmin!$C$4+90)),MIN(DAY(Kalemler!$D7),DAY(EOMONTH((Tahmin!$C$4+90),0))))>=Kalemler!$D7)),1,0),IF(AND(Kalemler!$D7>=(Tahmin!$C$4+84),Kalemler!$D7<=(Tahmin!$C$4+90)),1,0)))) -> 0
