Workbook

Sheet Başla
B2: EXCEL KLİNİĞİ
B3: DOZ | Düzenli ödeme ve abonelik takibi
B4: Kira, fatura, abonelik, taksit: her ay ne kadar çıkıyor, sırada hangisi var, yıl boyunca hangi ay ağır.
B6: NASIL KULLANILIR
B7: 1. Ödemeler | C7: Kira, fatura, abonelik, sigorta, taksit: düzenli ödediğin her şeyi tutarı, sıklığı ve ilk ödeme tarihiyle yaz.
B8: 2. Özet | C8: Aylık ortalama yükün, önümüzdeki 7 ve 30 günde ödeyeceklerin, kategori dağılımı ve sıradaki 10 ödeme.
B9: 3. Takvim | C9: Seçtiğin yılda her ödemenin hangi aya düştüğü ve ayların toplamı. Yıllık ve altı aylık ödemelerin ağırlaştırdığı ayları buradan görürsün.
B11: BİLMEN GEREKENLER
B12: Aylık karşılığı | C12: Yıllık 1.200 liralık bir ödemenin aylık karşılığı 100 liradır. Bitmiş ödemeler toplama girmez.
B13: Sıradaki ödeme | C13: İlk ödeme tarihinden sıklığa göre ileri sayılır. Ayın 31'i gibi günlerde kısa aylarda ayın son gününe kayar.
B14: Tutar değişirse | C14: Fatura gibi değişen ödemelerde ortalama tutarı yaz. Dosya geçmiş tutarları ayrı ayrı tutmaz.
B15: Kapasite | C15: 100 ödeme, 20 kategori.
B17: RENKLER
B18: Sarı hücre | C18: Senin dolduracağın hücre. İçindeki örnekleri silip kendi bilgini yaz.
B19: Beyaz hücre, açık başlık | C19: Formül. Değiştirme, kendiliğinden hesaplanır.

Sheet Ödemeler
A1: Ödemeler
A2: Düzenli ödediğin her şeyi bir satıra yaz. Bitiş tarihini yalnızca taksit gibi sonu belli ödemelerde doldur.
A4: Ödeme | B4: Kategori | C4: Tutar (₺) | D4: Sıklık | E4: İlk ödeme tarihi | F4: Bitiş tarihi (varsa) | G4: ay | H4: Aylık karşılığı (₺) | I4: Yıllık karşılığı (₺) | J4: Sıradaki ödeme | K4: Kalan gün | L4: Durum | M4: y1 | N4: y2 | O4: y3
A5: Ev kirası | B5: Konut | C5: 22000 | D5: Aylık | E5: 46027 | G5: =IF(D5="Aylık",1,IF(D5="3 Aylık",3,IF(D5="6 Aylık",6,IF(D5="Yıllık",12,"")))) -> 1 | H5: =IF(OR(J5="",J5="Bitti"),"",C5/G5) -> 22000 | I5: =IF(H5="","",H5*12) -> 264000 | J5: =IF(N5="","",IF(AND(F5<>"",N5>F5),"Bitti",N5)) -> 46300 | K5: =IF(ISNUMBER(J5),J5-Özet!$C$3,"") -> 1 | L5: =IF(J5="","",IF(J5="Bitti","Bitti",IF(K5<=7,"Bu hafta",IF(K5<=30,"Bu ay","Bekliyor")))) -> Bu hafta | M5: =IF(OR(A5="",C5="",G5="",E5=""),"",MAX(0,ROUNDUP(((YEAR(Özet!$C$3)-YEAR(E5))*12+MONTH(Özet!$C$3)-MONTH(E5))/G5,0))) -> 9 | N5: =IF(M5="","",IF(EDATE(E5,G5*M5)<Özet!$C$3,EDATE(E5,G5*(M5+1)),EDATE(E5,G5*M5))) -> 46300 | O5: =IF(ISNUMBER(J5),J5+ROW()/1000000,"") -> 46300
A6: Elektrik | B6: Faturalar | C6: 1400 | D6: Aylık | E6: 46042 | G6: =IF(D6="Aylık",1,IF(D6="3 Aylık",3,IF(D6="6 Aylık",6,IF(D6="Yıllık",12,"")))) -> 1 | H6: =IF(OR(J6="",J6="Bitti"),"",C6/G6) -> 1400 | I6: =IF(H6="","",H6*12) -> 16800 | J6: =IF(N6="","",IF(AND(F6<>"",N6>F6),"Bitti",N6)) -> 46315 | K6: =IF(ISNUMBER(J6),J6-Özet!$C$3,"") -> 16 | L6: =IF(J6="","",IF(J6="Bitti","Bitti",IF(K6<=7,"Bu hafta",IF(K6<=30,"Bu ay","Bekliyor")))) -> Bu ay | M6: =IF(OR(A6="",C6="",G6="",E6=""),"",MAX(0,ROUNDUP(((YEAR(Özet!$C$3)-YEAR(E6))*12+MONTH(Özet!$C$3)-MONTH(E6))/G6,0))) -> 9 | N6: =IF(M6="","",IF(EDATE(E6,G6*M6)<Özet!$C$3,EDATE(E6,G6*(M6+1)),EDATE(E6,G6*M6))) -> 46315 | O6: =IF(ISNUMBER(J6),J6+ROW()/1000000,"") -> 46315
A7: İnternet | B7: Faturalar | C7: 650 | D7: Aylık | E7: 46065 | G7: =IF(D7="Aylık",1,IF(D7="3 Aylık",3,IF(D7="6 Aylık",6,IF(D7="Yıllık",12,"")))) -> 1 | H7: =IF(OR(J7="",J7="Bitti"),"",C7/G7) -> 650 | I7: =IF(H7="","",H7*12) -> 7800 | J7: =IF(N7="","",IF(AND(F7<>"",N7>F7),"Bitti",N7)) -> 46307 | K7: =IF(ISNUMBER(J7),J7-Özet!$C$3,"") -> 8 | L7: =IF(J7="","",IF(J7="Bitti","Bitti",IF(K7<=7,"Bu hafta",IF(K7<=30,"Bu ay","Bekliyor")))) -> Bu ay | M7: =IF(OR(A7="",C7="",G7="",E7=""),"",MAX(0,ROUNDUP(((YEAR(Özet!$C$3)-YEAR(E7))*12+MONTH(Özet!$C$3)-MONTH(E7))/G7,0))) -> 8 | N7: =IF(M7="","",IF(EDATE(E7,G7*M7)<Özet!$C$3,EDATE(E7,G7*(M7+1)),EDATE(E7,G7*M7))) -> 46307 | O7: =IF(ISNUMBER(J7),J7+ROW()/1000000,"") -> 46307
A8: Film ve dizi aboneliği | B8: Abonelik | C8: 230 | D8: Aylık | E8: 45969 | G8: =IF(D8="Aylık",1,IF(D8="3 Aylık",3,IF(D8="6 Aylık",6,IF(D8="Yıllık",12,"")))) -> 1 | H8: =IF(OR(J8="",J8="Bitti"),"",C8/G8) -> 230 | I8: =IF(H8="","",H8*12) -> 2760 | J8: =IF(N8="","",IF(AND(F8<>"",N8>F8),"Bitti",N8)) -> 46303 | K8: =IF(ISNUMBER(J8),J8-Özet!$C$3,"") -> 4 | L8: =IF(J8="","",IF(J8="Bitti","Bitti",IF(K8<=7,"Bu hafta",IF(K8<=30,"Bu ay","Bekliyor")))) -> Bu hafta | M8: =IF(OR(A8="",C8="",G8="",E8=""),"",MAX(0,ROUNDUP(((YEAR(Özet!$C$3)-YEAR(E8))*12+MONTH(Özet!$C$3)-MONTH(E8))/G8,0))) -> 11 | N8: =IF(M8="","",IF(EDATE(E8,G8*M8)<Özet!$C$3,EDATE(E8,G8*(M8+1)),EDATE(E8,G8*M8))) -> 46303 | O8: =IF(ISNUMBER(J8),J8+ROW()/1000000,"") -> 46303
A9: Bulut depolama | B9: Abonelik | C9: 1200 | D9: Yıllık | E9: 46096 | G9: =IF(D9="Aylık",1,IF(D9="3 Aylık",3,IF(D9="6 Aylık",6,IF(D9="Yıllık",12,"")))) -> 12 | H9: =IF(OR(J9="",J9="Bitti"),"",C9/G9) -> 100 | I9: =IF(H9="","",H9*12) -> 1200 | J9: =IF(N9="","",IF(AND(F9<>"",N9>F9),"Bitti",N9)) -> 46461 | K9: =IF(ISNUMBER(J9),J9-Özet!$C$3,"") -> 162 | L9: =IF(J9="","",IF(J9="Bitti","Bitti",IF(K9<=7,"Bu hafta",IF(K9<=30,"Bu ay","Bekliyor")))) -> Bekliyor | M9: =IF(OR(A9="",C9="",G9="",E9=""),"",MAX(0,ROUNDUP(((YEAR(Özet!$C$3)-YEAR(E9))*12+MONTH(Özet!$C$3)-MONTH(E9))/G9,0))) -> 1 | N9: =IF(M9="","",IF(EDATE(E9,G9*M9)<Özet!$C$3,EDATE(E9,G9*(M9+1)),EDATE(E9,G9*M9))) -> 46461 | O9: =IF(ISNUMBER(J9),J9+ROW()/1000000,"") -> 46461
A10: Telefon taksidi | B10: Taksit | C10: 2500 | D10: Aylık | E10: 46122 | F10: 46456 | G10: =IF(D10="Aylık",1,IF(D10="3 Aylık",3,IF(D10="6 Aylık",6,IF(D10="Yıllık",12,"")))) -> 1 | H10: =IF(OR(J10="",J10="Bitti"),"",C10/G10) -> 2500 | I10: =IF(H10="","",H10*12) -> 30000 | J10: =IF(N10="","",IF(AND(F10<>"",N10>F10),"Bitti",N10)) -> 46305 | K10: =IF(ISNUMBER(J10),J10-Özet!$C$3,"") -> 6 | L10: =IF(J10="","",IF(J10="Bitti","Bitti",IF(K10<=7,"Bu hafta",IF(K10<=30,"Bu ay","Bekliyor")))) -> Bu hafta | M10: =IF(OR(A10="",C10="",G10="",E10=""),"",MAX(0,ROUNDUP(((YEAR(Özet!$C$3)-YEAR(E10))*12+MONTH(Özet!$C$3)-MONTH(E10))/G10,0))) -> 6 | N10: =IF(M10="","",IF(EDATE(E10,G10*M10)<Özet!$C$3,EDATE(E10,G10*(M10+1)),EDATE(E10,G10*M10))) -> 46305 | O10: =IF(ISNUMBER(J10),J10+ROW()/1000000,"") -> 46305
A11: Kasko | B11: Sigorta | C11: 9000 | D11: 6 Aylık | E11: 46174 | G11: =IF(D11="Aylık",1,IF(D11="3 Aylık",3,IF(D11="6 Aylık",6,IF(D11="Yıllık",12,"")))) -> 6 | H11: =IF(OR(J11="",J11="Bitti"),"",C11/G11) -> 1500 | I11: =IF(H11="","",H11*12) -> 18000 | J11: =IF(N11="","",IF(AND(F11<>"",N11>F11),"Bitti",N11)) -> 46357 | K11: =IF(ISNUMBER(J11),J11-Özet!$C$3,"") -> 58 | L11: =IF(J11="","",IF(J11="Bitti","Bitti",IF(K11<=7,"Bu hafta",IF(K11<=30,"Bu ay","Bekliyor")))) -> Bekliyor | M11: =IF(OR(A11="",C11="",G11="",E11=""),"",MAX(0,ROUNDUP(((YEAR(Özet!$C$3)-YEAR(E11))*12+MONTH(Özet!$C$3)-MONTH(E11))/G11,0))) -> 1 | N11: =IF(M11="","",IF(EDATE(E11,G11*M11)<Özet!$C$3,EDATE(E11,G11*(M11+1)),EDATE(E11,G11*M11))) -> 46357 | O11: =IF(ISNUMBER(J11),J11+ROW()/1000000,"") -> 46357
A12: Spor salonu | B12: Sağlık | C12: 4500 | D12: 3 Aylık | E12: 46235 | G12: =IF(D12="Aylık",1,IF(D12="3 Aylık",3,IF(D12="6 Aylık",6,IF(D12="Yıllık",12,"")))) -> 3 | H12: =IF(OR(J12="",J12="Bitti"),"",C12/G12) -> 1500 | I12: =IF(H12="","",H12*12) -> 18000 | J12: =IF(N12="","",IF(AND(F12<>"",N12>F12),"Bitti",N12)) -> 46327 | K12: =IF(ISNUMBER(J12),J12-Özet!$C$3,"") -> 28 | L12: =IF(J12="","",IF(J12="Bitti","Bitti",IF(K12<=7,"Bu hafta",IF(K12<=30,"Bu ay","Bekliyor")))) -> Bu ay | M12: =IF(OR(A12="",C12="",G12="",E12=""),"",MAX(0,ROUNDUP(((YEAR(Özet!$C$3)-YEAR(E12))*12+MONTH(Özet!$C$3)-MONTH(E12))/G12,0))) -> 1 | N12: =IF(M12="","",IF(EDATE(E12,G12*M12)<Özet!$C$3,EDATE(E12,G12*(M12+1)),EDATE(E12,G12*M12))) -> 46327 | O12: =IF(ISNUMBER(J12),J12+ROW()/1000000,"") -> 46327
A13: Eski taksit | B13: Taksit | C13: 1000 | D13: Aylık | E13: 45667 | F13: 46001 | G13: =IF(D13="Aylık",1,IF(D13="3 Aylık",3,IF(D13="6 Aylık",6,IF(D13="Yıllık",12,"")))) -> 1 | H13: =IF(OR(J13="",J13="Bitti"),"",C13/G13) | I13: =IF(H13="","",H13*12) | J13: =IF(N13="","",IF(AND(F13<>"",N13>F13),"Bitti",N13)) -> Bitti | K13: =IF(ISNUMBER(J13),J13-Özet!$C$3,"") | L13: =IF(J13="","",IF(J13="Bitti","Bitti",IF(K13<=7,"Bu hafta",IF(K13<=30,"Bu ay","Bekliyor")))) -> Bitti | M13: =IF(OR(A13="",C13="",G13="",E13=""),"",MAX(0,ROUNDUP(((YEAR(Özet!$C$3)-YEAR(E13))*12+MONTH(Özet!$C$3)-MONTH(E13))/G13,0))) -> 21 | N13: =IF(M13="","",IF(EDATE(E13,G13*M13)<Özet!$C$3,EDATE(E13,G13*(M13+1)),EDATE(E13,G13*M13))) -> 46305 | O13: =IF(ISNUMBER(J13),J13+ROW()/1000000,"")
G14: =IF(D14="Aylık",1,IF(D14="3 Aylık",3,IF(D14="6 Aylık",6,IF(D14="Yıllık",12,"")))) | H14: =IF(OR(J14="",J14="Bitti"),"",C14/G14) | I14: =IF(H14="","",H14*12) | J14: =IF(N14="","",IF(AND(F14<>"",N14>F14),"Bitti",N14)) | K14: =IF(ISNUMBER(J14),J14-Özet!$C$3,"") | L14: =IF(J14="","",IF(J14="Bitti","Bitti",IF(K14<=7,"Bu hafta",IF(K14<=30,"Bu ay","Bekliyor")))) | M14: =IF(OR(A14="",C14="",G14="",E14=""),"",MAX(0,ROUNDUP(((YEAR(Özet!$C$3)-YEAR(E14))*12+MONTH(Özet!$C$3)-MONTH(E14))/G14,0))) | N14: =IF(M14="","",IF(EDATE(E14,G14*M14)<Özet!$C$3,EDATE(E14,G14*(M14+1)),EDATE(E14,G14*M14))) | O14: =IF(ISNUMBER(J14),J14+ROW()/1000000,"")
G15: =IF(D15="Aylık",1,IF(D15="3 Aylık",3,IF(D15="6 Aylık",6,IF(D15="Yıllık",12,"")))) | H15: =IF(OR(J15="",J15="Bitti"),"",C15/G15) | I15: =IF(H15="","",H15*12) | J15: =IF(N15="","",IF(AND(F15<>"",N15>F15),"Bitti",N15)) | K15: =IF(ISNUMBER(J15),J15-Özet!$C$3,"") | L15: =IF(J15="","",IF(J15="Bitti","Bitti",IF(K15<=7,"Bu hafta",IF(K15<=30,"Bu ay","Bekliyor")))) | M15: =IF(OR(A15="",C15="",G15="",E15=""),"",MAX(0,ROUNDUP(((YEAR(Özet!$C$3)-YEAR(E15))*12+MONTH(Özet!$C$3)-MONTH(E15))/G15,0))) | N15: =IF(M15="","",IF(EDATE(E15,G15*M15)<Özet!$C$3,EDATE(E15,G15*(M15+1)),EDATE(E15,G15*M15))) | O15: =IF(ISNUMBER(J15),J15+ROW()/1000000,"")
G16: =IF(D16="Aylık",1,IF(D16="3 Aylık",3,IF(D16="6 Aylık",6,IF(D16="Yıllık",12,"")))) | H16: =IF(OR(J16="",J16="Bitti"),"",C16/G16) | I16: =IF(H16="","",H16*12) | J16: =IF(N16="","",IF(AND(F16<>"",N16>F16),"Bitti",N16)) | K16: =IF(ISNUMBER(J16),J16-Özet!$C$3,"") | L16: =IF(J16="","",IF(J16="Bitti","Bitti",IF(K16<=7,"Bu hafta",IF(K16<=30,"Bu ay","Bekliyor")))) | M16: =IF(OR(A16="",C16="",G16="",E16=""),"",MAX(0,ROUNDUP(((YEAR(Özet!$C$3)-YEAR(E16))*12+MONTH(Özet!$C$3)-MONTH(E16))/G16,0))) | N16: =IF(M16="","",IF(EDATE(E16,G16*M16)<Özet!$C$3,EDATE(E16,G16*(M16+1)),EDATE(E16,G16*M16))) | O16: =IF(ISNUMBER(J16),J16+ROW()/1000000,"")
G17: =IF(D17="Aylık",1,IF(D17="3 Aylık",3,IF(D17="6 Aylık",6,IF(D17="Yıllık",12,"")))) | H17: =IF(OR(J17="",J17="Bitti"),"",C17/G17) | I17: =IF(H17="","",H17*12) | J17: =IF(N17="","",IF(AND(F17<>"",N17>F17),"Bitti",N17)) | K17: =IF(ISNUMBER(J17),J17-Özet!$C$3,"") | L17: =IF(J17="","",IF(J17="Bitti","Bitti",IF(K17<=7,"Bu hafta",IF(K17<=30,"Bu ay","Bekliyor")))) | M17: =IF(OR(A17="",C17="",G17="",E17=""),"",MAX(0,ROUNDUP(((YEAR(Özet!$C$3)-YEAR(E17))*12+MONTH(Özet!$C$3)-MONTH(E17))/G17,0))) | N17: =IF(M17="","",IF(EDATE(E17,G17*M17)<Özet!$C$3,EDATE(E17,G17*(M17+1)),EDATE(E17,G17*M17))) | O17: =IF(ISNUMBER(J17),J17+ROW()/1000000,"")
G18: =IF(D18="Aylık",1,IF(D18="3 Aylık",3,IF(D18="6 Aylık",6,IF(D18="Yıllık",12,"")))) | H18: =IF(OR(J18="",J18="Bitti"),"",C18/G18) | I18: =IF(H18="","",H18*12) | J18: =IF(N18="","",IF(AND(F18<>"",N18>F18),"Bitti",N18)) | K18: =IF(ISNUMBER(J18),J18-Özet!$C$3,"") | L18: =IF(J18="","",IF(J18="Bitti","Bitti",IF(K18<=7,"Bu hafta",IF(K18<=30,"Bu ay","Bekliyor")))) | M18: =IF(OR(A18="",C18="",G18="",E18=""),"",MAX(0,ROUNDUP(((YEAR(Özet!$C$3)-YEAR(E18))*12+MONTH(Özet!$C$3)-MONTH(E18))/G18,0))) | N18: =IF(M18="","",IF(EDATE(E18,G18*M18)<Özet!$C$3,EDATE(E18,G18*(M18+1)),EDATE(E18,G18*M18))) | O18: =IF(ISNUMBER(J18),J18+ROW()/1000000,"")
G19: =IF(D19="Aylık",1,IF(D19="3 Aylık",3,IF(D19="6 Aylık",6,IF(D19="Yıllık",12,"")))) | H19: =IF(OR(J19="",J19="Bitti"),"",C19/G19) | I19: =IF(H19="","",H19*12) | J19: =IF(N19="","",IF(AND(F19<>"",N19>F19),"Bitti",N19)) | K19: =IF(ISNUMBER(J19),J19-Özet!$C$3,"") | L19: =IF(J19="","",IF(J19="Bitti","Bitti",IF(K19<=7,"Bu hafta",IF(K19<=30,"Bu ay","Bekliyor")))) | M19: =IF(OR(A19="",C19="",G19="",E19=""),"",MAX(0,ROUNDUP(((YEAR(Özet!$C$3)-YEAR(E19))*12+MONTH(Özet!$C$3)-MONTH(E19))/G19,0))) | N19: =IF(M19="","",IF(EDATE(E19,G19*M19)<Özet!$C$3,EDATE(E19,G19*(M19+1)),EDATE(E19,G19*M19))) | O19: =IF(ISNUMBER(J19),J19+ROW()/1000000,"")
G20: =IF(D20="Aylık",1,IF(D20="3 Aylık",3,IF(D20="6 Aylık",6,IF(D20="Yıllık",12,"")))) | H20: =IF(OR(J20="",J20="Bitti"),"",C20/G20) | I20: =IF(H20="","",H20*12) | J20: =IF(N20="","",IF(AND(F20<>"",N20>F20),"Bitti",N20)) | K20: =IF(ISNUMBER(J20),J20-Özet!$C$3,"") | L20: =IF(J20="","",IF(J20="Bitti","Bitti",IF(K20<=7,"Bu hafta",IF(K20<=30,"Bu ay","Bekliyor")))) | M20: =IF(OR(A20="",C20="",G20="",E20=""),"",MAX(0,ROUNDUP(((YEAR(Özet!$C$3)-YEAR(E20))*12+MONTH(Özet!$C$3)-MONTH(E20))/G20,0))) | N20: =IF(M20="","",IF(EDATE(E20,G20*M20)<Özet!$C$3,EDATE(E20,G20*(M20+1)),EDATE(E20,G20*M20))) | O20: =IF(ISNUMBER(J20),J20+ROW()/1000000,"")
G21: =IF(D21="Aylık",1,IF(D21="3 Aylık",3,IF(D21="6 Aylık",6,IF(D21="Yıllık",12,"")))) | H21: =IF(OR(J21="",J21="Bitti"),"",C21/G21) | I21: =IF(H21="","",H21*12) | J21: =IF(N21="","",IF(AND(F21<>"",N21>F21),"Bitti",N21)) | K21: =IF(ISNUMBER(J21),J21-Özet!$C$3,"") | L21: =IF(J21="","",IF(J21="Bitti","Bitti",IF(K21<=7,"Bu hafta",IF(K21<=30,"Bu ay","Bekliyor")))) | M21: =IF(OR(A21="",C21="",G21="",E21=""),"",MAX(0,ROUNDUP(((YEAR(Özet!$C$3)-YEAR(E21))*12+MONTH(Özet!$C$3)-MONTH(E21))/G21,0))) | N21: =IF(M21="","",IF(EDATE(E21,G21*M21)<Özet!$C$3,EDATE(E21,G21*(M21+1)),EDATE(E21,G21*M21))) | O21: =IF(ISNUMBER(J21),J21+ROW()/1000000,"")
G22: =IF(D22="Aylık",1,IF(D22="3 Aylık",3,IF(D22="6 Aylık",6,IF(D22="Yıllık",12,"")))) | H22: =IF(OR(J22="",J22="Bitti"),"",C22/G22) | I22: =IF(H22="","",H22*12) | J22: =IF(N22="","",IF(AND(F22<>"",N22>F22),"Bitti",N22)) | K22: =IF(ISNUMBER(J22),J22-Özet!$C$3,"") | L22: =IF(J22="","",IF(J22="Bitti","Bitti",IF(K22<=7,"Bu hafta",IF(K22<=30,"Bu ay","Bekliyor")))) | M22: =IF(OR(A22="",C22="",G22="",E22=""),"",MAX(0,ROUNDUP(((YEAR(Özet!$C$3)-YEAR(E22))*12+MONTH(Özet!$C$3)-MONTH(E22))/G22,0))) | N22: =IF(M22="","",IF(EDATE(E22,G22*M22)<Özet!$C$3,EDATE(E22,G22*(M22+1)),EDATE(E22,G22*M22))) | O22: =IF(ISNUMBER(J22),J22+ROW()/1000000,"")
G23: =IF(D23="Aylık",1,IF(D23="3 Aylık",3,IF(D23="6 Aylık",6,IF(D23="Yıllık",12,"")))) | H23: =IF(OR(J23="",J23="Bitti"),"",C23/G23) | I23: =IF(H23="","",H23*12) | J23: =IF(N23="","",IF(AND(F23<>"",N23>F23),"Bitti",N23)) | K23: =IF(ISNUMBER(J23),J23-Özet!$C$3,"") | L23: =IF(J23="","",IF(J23="Bitti","Bitti",IF(K23<=7,"Bu hafta",IF(K23<=30,"Bu ay","Bekliyor")))) | M23: =IF(OR(A23="",C23="",G23="",E23=""),"",MAX(0,ROUNDUP(((YEAR(Özet!$C$3)-YEAR(E23))*12+MONTH(Özet!$C$3)-MONTH(E23))/G23,0))) | N23: =IF(M23="","",IF(EDATE(E23,G23*M23)<Özet!$C$3,EDATE(E23,G23*(M23+1)),EDATE(E23,G23*M23))) | O23: =IF(ISNUMBER(J23),J23+ROW()/1000000,"")
G24: =IF(D24="Aylık",1,IF(D24="3 Aylık",3,IF(D24="6 Aylık",6,IF(D24="Yıllık",12,"")))) | H24: =IF(OR(J24="",J24="Bitti"),"",C24/G24) | I24: =IF(H24="","",H24*12) | J24: =IF(N24="","",IF(AND(F24<>"",N24>F24),"Bitti",N24)) | K24: =IF(ISNUMBER(J24),J24-Özet!$C$3,"") | L24: =IF(J24="","",IF(J24="Bitti","Bitti",IF(K24<=7,"Bu hafta",IF(K24<=30,"Bu ay","Bekliyor")))) | M24: =IF(OR(A24="",C24="",G24="",E24=""),"",MAX(0,ROUNDUP(((YEAR(Özet!$C$3)-YEAR(E24))*12+MONTH(Özet!$C$3)-MONTH(E24))/G24,0))) | N24: =IF(M24="","",IF(EDATE(E24,G24*M24)<Özet!$C$3,EDATE(E24,G24*(M24+1)),EDATE(E24,G24*M24))) | O24: =IF(ISNUMBER(J24),J24+ROW()/1000000,"")
G25: =IF(D25="Aylık",1,IF(D25="3 Aylık",3,IF(D25="6 Aylık",6,IF(D25="Yıllık",12,"")))) | H25: =IF(OR(J25="",J25="Bitti"),"",C25/G25) | I25: =IF(H25="","",H25*12) | J25: =IF(N25="","",IF(AND(F25<>"",N25>F25),"Bitti",N25)) | K25: =IF(ISNUMBER(J25),J25-Özet!$C$3,"") | L25: =IF(J25="","",IF(J25="Bitti","Bitti",IF(K25<=7,"Bu hafta",IF(K25<=30,"Bu ay","Bekliyor")))) | M25: =IF(OR(A25="",C25="",G25="",E25=""),"",MAX(0,ROUNDUP(((YEAR(Özet!$C$3)-YEAR(E25))*12+MONTH(Özet!$C$3)-MONTH(E25))/G25,0))) | N25: =IF(M25="","",IF(EDATE(E25,G25*M25)<Özet!$C$3,EDATE(E25,G25*(M25+1)),EDATE(E25,G25*M25))) | O25: =IF(ISNUMBER(J25),J25+ROW()/1000000,"")
... G104: =IF(D104="Aylık",1,IF(D104="3 Aylık",3,IF(D104="6 Aylık",6,IF(D104="Yıllık",12,"")))) | H104: =IF(OR(J104="",J104="Bitti"),"",C104/G104) | I104: =IF(H104="","",H104*12) | J104: =IF(N104="","",IF(AND(F104<>"",N104>F104),"Bitti",N104)) | K104: =IF(ISNUMBER(J104),J104-Özet!$C$3,"") | L104: =IF(J104="","",IF(J104="Bitti","Bitti",IF(K104<=7,"Bu hafta",IF(K104<=30,"Bu ay","Bekliyor")))) | M104: =IF(OR(A104="",C104="",G104="",E104=""),"",MAX(0,ROUNDUP(((YEAR(Özet!$C$3)-YEAR(E104))*12+MONTH(Özet!$C$3)-MONTH(E104))/G104,0))) | N104: =IF(M104="","",IF(EDATE(E104,G104*M104)<Özet!$C$3,EDATE(E104,G104*(M104+1)),EDATE(E104,G104*M104))) | O104: =IF(ISNUMBER(J104),J104+ROW()/1000000,"")

Sheet Özet
A1: Özet
A2: Bugünün tarihi kendiliğinden gelir. Takvim için yılı değiştirebilirsin.
B3: Bugün | C3: =TODAY() -> 46299
B4: Takvim yılı | C4: 2026
B6: Aylık ortalama yük | C6: Yıllık karşılığı | D6: 7 gün içinde ödenecek | E6: 30 gün içinde ödenecek | F6: Süren ödeme sayısı
B7: =SUM(Ödemeler!$H$5:$H$104) -> 29880 | C7: =SUM(Ödemeler!$I$5:$I$104) -> 358560 | D7: =SUMIFS(Ödemeler!$C$5:$C$104,Ödemeler!$K$5:$K$104,">=0",Ödemeler!$K$5:$K$104,"<=7") -> 24730 | E7: =SUMIFS(Ödemeler!$C$5:$C$104,Ödemeler!$K$5:$K$104,">=0",Ödemeler!$K$5:$K$104,"<=30") -> 31280 | F7: =COUNT(Ödemeler!$H$5:$H$104) -> 8
B10: Kategoriye göre aylık yük | H10: Sıradaki 10 ödeme
B11: Kategori | C11: Aylık (₺) | D11: Pay | H11: Ödeme | I11: Tarih | J11: Tutar (₺)
B12: =IF(Kategoriler!A5="","",Kategoriler!A5) -> Konut | C12: =IF(B12="","",SUMIFS(Ödemeler!$H$5:$H$104,Ödemeler!$B$5:$B$104,B12)) -> 22000 | D12: =IF(OR(B12="",$B$7=0),"",C12/$B$7) -> 0.73627845 | H12: =IFERROR(INDEX(Ödemeler!$A$5:$A$104,MATCH(SMALL(Ödemeler!$O$5:$O$104,1),Ödemeler!$O$5:$O$104,0)),"") -> Ev kirası | I12: =IF(H12="","",INDEX(Ödemeler!$J$5:$J$104,MATCH(SMALL(Ödemeler!$O$5:$O$104,1),Ödemeler!$O$5:$O$104,0))) -> 46300 | J12: =IF(H12="","",INDEX(Ödemeler!$C$5:$C$104,MATCH(SMALL(Ödemeler!$O$5:$O$104,1),Ödemeler!$O$5:$O$104,0))) -> 22000
B13: =IF(Kategoriler!A6="","",Kategoriler!A6) -> Faturalar | C13: =IF(B13="","",SUMIFS(Ödemeler!$H$5:$H$104,Ödemeler!$B$5:$B$104,B13)) -> 2050 | D13: =IF(OR(B13="",$B$7=0),"",C13/$B$7) -> 0.068607764 | H13: =IFERROR(INDEX(Ödemeler!$A$5:$A$104,MATCH(SMALL(Ödemeler!$O$5:$O$104,2),Ödemeler!$O$5:$O$104,0)),"") -> Film ve dizi aboneliği | I13: =IF(H13="","",INDEX(Ödemeler!$J$5:$J$104,MATCH(SMALL(Ödemeler!$O$5:$O$104,2),Ödemeler!$O$5:$O$104,0))) -> 46303 | J13: =IF(H13="","",INDEX(Ödemeler!$C$5:$C$104,MATCH(SMALL(Ödemeler!$O$5:$O$104,2),Ödemeler!$O$5:$O$104,0))) -> 230
B14: =IF(Kategoriler!A7="","",Kategoriler!A7) -> Abonelik | C14: =IF(B14="","",SUMIFS(Ödemeler!$H$5:$H$104,Ödemeler!$B$5:$B$104,B14)) -> 330 | D14: =IF(OR(B14="",$B$7=0),"",C14/$B$7) -> 0.011044177 | H14: =IFERROR(INDEX(Ödemeler!$A$5:$A$104,MATCH(SMALL(Ödemeler!$O$5:$O$104,3),Ödemeler!$O$5:$O$104,0)),"") -> Telefon taksidi | I14: =IF(H14="","",INDEX(Ödemeler!$J$5:$J$104,MATCH(SMALL(Ödemeler!$O$5:$O$104,3),Ödemeler!$O$5:$O$104,0))) -> 46305 | J14: =IF(H14="","",INDEX(Ödemeler!$C$5:$C$104,MATCH(SMALL(Ödemeler!$O$5:$O$104,3),Ödemeler!$O$5:$O$104,0))) -> 2500
B15: =IF(Kategoriler!A8="","",Kategoriler!A8) -> Taksit | C15: =IF(B15="","",SUMIFS(Ödemeler!$H$5:$H$104,Ödemeler!$B$5:$B$104,B15)) -> 2500 | D15: =IF(OR(B15="",$B$7=0),"",C15/$B$7) -> 0.083668005 | H15: =IFERROR(INDEX(Ödemeler!$A$5:$A$104,MATCH(SMALL(Ödemeler!$O$5:$O$104,4),Ödemeler!$O$5:$O$104,0)),"") -> İnternet | I15: =IF(H15="","",INDEX(Ödemeler!$J$5:$J$104,MATCH(SMALL(Ödemeler!$O$5:$O$104,4),Ödemeler!$O$5:$O$104,0))) -> 46307 | J15: =IF(H15="","",INDEX(Ödemeler!$C$5:$C$104,MATCH(SMALL(Ödemeler!$O$5:$O$104,4),Ödemeler!$O$5:$O$104,0))) -> 650
B16: =IF(Kategoriler!A9="","",Kategoriler!A9) -> Sigorta | C16: =IF(B16="","",SUMIFS(Ödemeler!$H$5:$H$104,Ödemeler!$B$5:$B$104,B16)) -> 1500 | D16: =IF(OR(B16="",$B$7=0),"",C16/$B$7) -> 0.050200803 | H16: =IFERROR(INDEX(Ödemeler!$A$5:$A$104,MATCH(SMALL(Ödemeler!$O$5:$O$104,5),Ödemeler!$O$5:$O$104,0)),"") -> Elektrik | I16: =IF(H16="","",INDEX(Ödemeler!$J$5:$J$104,MATCH(SMALL(Ödemeler!$O$5:$O$104,5),Ödemeler!$O$5:$O$104,0))) -> 46315 | J16: =IF(H16="","",INDEX(Ödemeler!$C$5:$C$104,MATCH(SMALL(Ödemeler!$O$5:$O$104,5),Ödemeler!$O$5:$O$104,0))) -> 1400
B17: =IF(Kategoriler!A10="","",Kategoriler!A10) -> Sağlık | C17: =IF(B17="","",SUMIFS(Ödemeler!$H$5:$H$104,Ödemeler!$B$5:$B$104,B17)) -> 1500 | D17: =IF(OR(B17="",$B$7=0),"",C17/$B$7) -> 0.050200803 | H17: =IFERROR(INDEX(Ödemeler!$A$5:$A$104,MATCH(SMALL(Ödemeler!$O$5:$O$104,6),Ödemeler!$O$5:$O$104,0)),"") -> Spor salonu | I17: =IF(H17="","",INDEX(Ödemeler!$J$5:$J$104,MATCH(SMALL(Ödemeler!$O$5:$O$104,6),Ödemeler!$O$5:$O$104,0))) -> 46327 | J17: =IF(H17="","",INDEX(Ödemeler!$C$5:$C$104,MATCH(SMALL(Ödemeler!$O$5:$O$104,6),Ödemeler!$O$5:$O$104,0))) -> 4500
B18: =IF(Kategoriler!A11="","",Kategoriler!A11) -> Eğitim | C18: =IF(B18="","",SUMIFS(Ödemeler!$H$5:$H$104,Ödemeler!$B$5:$B$104,B18)) -> 0 | D18: =IF(OR(B18="",$B$7=0),"",C18/$B$7) -> 0 | H18: =IFERROR(INDEX(Ödemeler!$A$5:$A$104,MATCH(SMALL(Ödemeler!$O$5:$O$104,7),Ödemeler!$O$5:$O$104,0)),"") -> Kasko | I18: =IF(H18="","",INDEX(Ödemeler!$J$5:$J$104,MATCH(SMALL(Ödemeler!$O$5:$O$104,7),Ödemeler!$O$5:$O$104,0))) -> 46357 | J18: =IF(H18="","",INDEX(Ödemeler!$C$5:$C$104,MATCH(SMALL(Ödemeler!$O$5:$O$104,7),Ödemeler!$O$5:$O$104,0))) -> 9000
B19: =IF(Kategoriler!A12="","",Kategoriler!A12) -> Diğer | C19: =IF(B19="","",SUMIFS(Ödemeler!$H$5:$H$104,Ödemeler!$B$5:$B$104,B19)) -> 0 | D19: =IF(OR(B19="",$B$7=0),"",C19/$B$7) -> 0 | H19: =IFERROR(INDEX(Ödemeler!$A$5:$A$104,MATCH(SMALL(Ödemeler!$O$5:$O$104,8),Ödemeler!$O$5:$O$104,0)),"") -> Bulut depolama | I19: =IF(H19="","",INDEX(Ödemeler!$J$5:$J$104,MATCH(SMALL(Ödemeler!$O$5:$O$104,8),Ödemeler!$O$5:$O$104,0))) -> 46461 | J19: =IF(H19="","",INDEX(Ödemeler!$C$5:$C$104,MATCH(SMALL(Ödemeler!$O$5:$O$104,8),Ödemeler!$O$5:$O$104,0))) -> 1200
B20: =IF(Kategoriler!A13="","",Kategoriler!A13) | C20: =IF(B20="","",SUMIFS(Ödemeler!$H$5:$H$104,Ödemeler!$B$5:$B$104,B20)) | D20: =IF(OR(B20="",$B$7=0),"",C20/$B$7) | H20: =IFERROR(INDEX(Ödemeler!$A$5:$A$104,MATCH(SMALL(Ödemeler!$O$5:$O$104,9),Ödemeler!$O$5:$O$104,0)),"") | I20: =IF(H20="","",INDEX(Ödemeler!$J$5:$J$104,MATCH(SMALL(Ödemeler!$O$5:$O$104,9),Ödemeler!$O$5:$O$104,0))) | J20: =IF(H20="","",INDEX(Ödemeler!$C$5:$C$104,MATCH(SMALL(Ödemeler!$O$5:$O$104,9),Ödemeler!$O$5:$O$104,0)))
B21: =IF(Kategoriler!A14="","",Kategoriler!A14) | C21: =IF(B21="","",SUMIFS(Ödemeler!$H$5:$H$104,Ödemeler!$B$5:$B$104,B21)) | D21: =IF(OR(B21="",$B$7=0),"",C21/$B$7) | H21: =IFERROR(INDEX(Ödemeler!$A$5:$A$104,MATCH(SMALL(Ödemeler!$O$5:$O$104,10),Ödemeler!$O$5:$O$104,0)),"") | I21: =IF(H21="","",INDEX(Ödemeler!$J$5:$J$104,MATCH(SMALL(Ödemeler!$O$5:$O$104,10),Ödemeler!$O$5:$O$104,0))) | J21: =IF(H21="","",INDEX(Ödemeler!$C$5:$C$104,MATCH(SMALL(Ödemeler!$O$5:$O$104,10),Ödemeler!$O$5:$O$104,0)))
B22: =IF(Kategoriler!A15="","",Kategoriler!A15) | C22: =IF(B22="","",SUMIFS(Ödemeler!$H$5:$H$104,Ödemeler!$B$5:$B$104,B22)) | D22: =IF(OR(B22="",$B$7=0),"",C22/$B$7)
B23: =IF(Kategoriler!A16="","",Kategoriler!A16) | C23: =IF(B23="","",SUMIFS(Ödemeler!$H$5:$H$104,Ödemeler!$B$5:$B$104,B23)) | D23: =IF(OR(B23="",$B$7=0),"",C23/$B$7)

Sheet Takvim
A1: Yıllık Takvim
A2: Yılı Özet sayfasından değiştir. Her ödemenin hangi ay düştüğünü ve ayların toplam yükünü gösterir.
A4: Ödeme | B4: Ocak | C4: Şubat | D4: Mart | E4: Nisan | F4: Mayıs | G4: Haziran | H4: Temmuz | I4: Ağustos | J4: Eylül | K4: Ekim | L4: Kasım | M4: Aralık | N4: Yıl toplamı
A5: AY TOPLAMI | B5: =SUM(B6:B105) -> 23630 | C5: =SUM(C6:C105) -> 24280 | D5: =SUM(D6:D105) -> 25480 | E5: =SUM(E6:E105) -> 26780 | F5: =SUM(F6:F105) -> 26780 | G5: =SUM(G6:G105) -> 35780 | H5: =SUM(H6:H105) -> 26780 | I5: =SUM(I6:I105) -> 31280 | ... M5: =SUM(M6:M105) -> 35780 | N5: =IF(COUNT(B5:M5)=0,"",SUM(B5:M5)) -> 341410
A6: =IF(Ödemeler!A5="","",Ödemeler!A5) -> Ev kirası | B6: =IF(OR(Ödemeler!$A5="",Ödemeler!$G5="",Ödemeler!$E5=""),"",IF(AND(((Özet!$C$4*12+1)-(YEAR(Ödemeler!$E5)*12+MONTH(Ödemeler!$E5)))>=0,MOD(((Özet!$C$4*12+1)-(YEAR(Ödemeler!$E5)*12+MONTH(Ödemeler!$E5))),Ödemeler!$G5)=0,OR(Ödemeler!$F5="",DATE(Özet!$C$4,1,1)<=Ödemeler!$F5)),Ödemeler!$C5,0)) -> 22000 | C6: =IF(OR(Ödemeler!$A5="",Ödemeler!$G5="",Ödemeler!$E5=""),"",IF(AND(((Özet!$C$4*12+2)-(YEAR(Ödemeler!$E5)*12+MONTH(Ödemeler!$E5)))>=0,MOD(((Özet!$C$4*12+2)-(YEAR(Ödemeler!$E5)*12+MONTH(Ödemeler!$E5))),Ödemeler!$G5)=0,OR(Ödemeler!$F5="",DATE(Özet!$C$4,2,1)<=Ödemeler!$F5)),Ödemeler!$C5,0)) -> 22000 | D6: =IF(OR(Ödemeler!$A5="",Ödemeler!$G5="",Ödemeler!$E5=""),"",IF(AND(((Özet!$C$4*12+3)-(YEAR(Ödemeler!$E5)*12+MONTH(Ödemeler!$E5)))>=0,MOD(((Özet!$C$4*12+3)-(YEAR(Ödemeler!$E5)*12+MONTH(Ödemeler!$E5))),Ödemeler!$G5)=0,OR(Ödemeler!$F5="",DATE(Özet!$C$4,3,1)<=Ödemeler!$F5)),Ödemeler!$C5,0)) -> 22000 | E6: =IF(OR(Ödemeler!$A5="",Ödemeler!$G5="",Ödemeler!$E5=""),"",IF(AND(((Özet!$C$4*12+4)-(YEAR(Ödemeler!$E5)*12+MONTH(Ödemeler!$E5)))>=0,MOD(((Özet!$C$4*12+4)-(YEAR(Ödemeler!$E5)*12+MONTH(Ödemeler!$E5))),Ödemeler!$G5)=0,OR(Ödemeler!$F5="",DATE(Özet!$C$4,4,1)<=Ödemeler!$F5)),Ödemeler!$C5,0)) -> 22000 | F6: =IF(OR(Ödemeler!$A5="",Ödemeler!$G5="",Ödemeler!$E5=""),"",IF(AND(((Özet!$C$4*12+5)-(YEAR(Ödemeler!$E5)*12+MONTH(Ödemeler!$E5)))>=0,MOD(((Özet!$C$4*12+5)-(YEAR(Ödemeler!$E5)*12+MONTH(Ödemeler!$E5))),Ödemeler!$G5)=0,OR(Ödemeler!$F5="",DATE(Özet!$C$4,5,1)<=Ödemeler!$F5)),Ödemeler!$C5,0)) -> 22000 | G6: =IF(OR(Ödemeler!$A5="",Ödemeler!$G5="",Ödemeler!$E5=""),"",IF(AND(((Özet!$C$4*12+6)-(YEAR(Ödemeler!$E5)*12+MONTH(Ödemeler!$E5)))>=0,MOD(((Özet!$C$4*12+6)-(YEAR(Ödemeler!$E5)*12+MONTH(Ödemeler!$E5))),Ödemeler!$G5)=0,OR(Ödemeler!$F5="",DATE(Özet!$C$4,6,1)<=Ödemeler!$F5)),Ödemeler!$C5,0)) -> 22000 | H6: =IF(OR(Ödemeler!$A5="",Ödemeler!$G5="",Ödemeler!$E5=""),"",IF(AND(((Özet!$C$4*12+7)-(YEAR(Ödemeler!$E5)*12+MONTH(Ödemeler!$E5)))>=0,MOD(((Özet!$C$4*12+7)-(YEAR(Ödemeler!$E5)*12+MONTH(Ödemeler!$E5))),Ödemeler!$G5)=0,OR(Ödemeler!$F5="",DATE(Özet!$C$4,7,1)<=Ödemeler!$F5)),Ödemeler!$C5,0)) -> 22000 | I6: =IF(OR(Ödemeler!$A5="",Ödemeler!$G5="",Ödemeler!$E5=""),"",IF(AND(((Özet!$C$4*12+8)-(YEAR(Ödemeler!$E5)*12+MONTH(Ödemeler!$E5)))>=0,MOD(((Özet!$C$4*12+8)-(YEAR(Ödemeler!$E5)*12+MONTH(Ödemeler!$E5))),Ödemeler!$G5)=0,OR(Ödemeler!$F5="",DATE(Özet!$C$4,8,1)<=Ödemeler!$F5)),Ödemeler!$C5,0)) -> 22000 | J6: =IF(OR(Ödemeler!$A5="",Ödemeler!$G5="",Ödemeler!$E5=""),"",IF(AND(((Özet!$C$4*12+9)-(YEAR(Ödemeler!$E5)*12+MONTH(Ödemeler!$E5)))>=0,MOD(((Özet!$C$4*12+9)-(YEAR(Ödemeler!$E5)*12+MONTH(Ödemeler!$E5))),Ödemeler!$G5)=0,OR(Ödemeler!$F5="",DATE(Özet!$C$4,9,1)<=Ödemeler!$F5)),Ödemeler!$C5,0)) -> 22000 | K6: =IF(OR(Ödemeler!$A5="",Ödemeler!$G5="",Ödemeler!$E5=""),"",IF(AND(((Özet!$C$4*12+10)-(YEAR(Ödemeler!$E5)*12+MONTH(Ödemeler!$E5)))>=0,MOD(((Özet!$C$4*12+10)-(YEAR(Ödemeler!$E5)*12+MONTH(Ödemeler!$E5))),Ödemeler!$G5)=0,OR(Ödemeler!$F5="",DATE(Özet!$C$4,10,1)<=Ödemeler!$F5)),Ödemeler!$C5,0)) -> 22000 | L6: =IF(OR(Ödemeler!$A5="",Ödemeler!$G5="",Ödemeler!$E5=""),"",IF(AND(((Özet!$C$4*12+11)-(YEAR(Ödemeler!$E5)*12+MONTH(Ödemeler!$E5)))>=0,MOD(((Özet!$C$4*12+11)-(YEAR(Ödemeler!$E5)*12+MONTH(Ödemeler!$E5))),Ödemeler!$G5)=0,OR(Ödemeler!$F5="",DATE(Özet!$C$4,11,1)<=Ödemeler!$F5)),Ödemeler!$C5,0)) -> 22000 | M6: =IF(OR(Ödemeler!$A5="",Ödemeler!$G5="",Ödemeler!$E5=""),"",IF(AND(((Özet!$C$4*12+12)-(YEAR(Ödemeler!$E5)*12+MONTH(Ödemeler!$E5)))>=0,MOD(((Özet!$C$4*12+12)-(YEAR(Ödemeler!$E5)*12+MONTH(Ödemeler!$E5))),Ödemeler!$G5)=0,OR(Ödemeler!$F5="",DATE(Özet!$C$4,12,1)<=Ödemeler!$F5)),Ödemeler!$C5,0)) -> 22000 | N6: =IF(COUNT(B6:M6)=0,"",SUM(B6:M6)) -> 264000
A7: =IF(Ödemeler!A6="","",Ödemeler!A6) -> Elektrik | B7: =IF(OR(Ödemeler!$A6="",Ödemeler!$G6="",Ödemeler!$E6=""),"",IF(AND(((Özet!$C$4*12+1)-(YEAR(Ödemeler!$E6)*12+MONTH(Ödemeler!$E6)))>=0,MOD(((Özet!$C$4*12+1)-(YEAR(Ödemeler!$E6)*12+MONTH(Ödemeler!$E6))),Ödemeler!$G6)=0,OR(Ödemeler!$F6="",DATE(Özet!$C$4,1,1)<=Ödemeler!$F6)),Ödemeler!$C6,0)) -> 1400 | C7: =IF(OR(Ödemeler!$A6="",Ödemeler!$G6="",Ödemeler!$E6=""),"",IF(AND(((Özet!$C$4*12+2)-(YEAR(Ödemeler!$E6)*12+MONTH(Ödemeler!$E6)))>=0,MOD(((Özet!$C$4*12+2)-(YEAR(Ödemeler!$E6)*12+MONTH(Ödemeler!$E6))),Ödemeler!$G6)=0,OR(Ödemeler!$F6="",DATE(Özet!$C$4,2,1)<=Ödemeler!$F6)),Ödemeler!$C6,0)) -> 1400 | D7: =IF(OR(Ödemeler!$A6="",Ödemeler!$G6="",Ödemeler!$E6=""),"",IF(AND(((Özet!$C$4*12+3)-(YEAR(Ödemeler!$E6)*12+MONTH(Ödemeler!$E6)))>=0,MOD(((Özet!$C$4*12+3)-(YEAR(Ödemeler!$E6)*12+MONTH(Ödemeler!$E6))),Ödemeler!$G6)=0,OR(Ödemeler!$F6="",DATE(Özet!$C$4,3,1)<=Ödemeler!$F6)),Ödemeler!$C6,0)) -> 1400 | E7: =IF(OR(Ödemeler!$A6="",Ödemeler!$G6="",Ödemeler!$E6=""),"",IF(AND(((Özet!$C$4*12+4)-(YEAR(Ödemeler!$E6)*12+MONTH(Ödemeler!$E6)))>=0,MOD(((Özet!$C$4*12+4)-(YEAR(Ödemeler!$E6)*12+MONTH(Ödemeler!$E6))),Ödemeler!$G6)=0,OR(Ödemeler!$F6="",DATE(Özet!$C$4,4,1)<=Ödemeler!$F6)),Ödemeler!$C6,0)) -> 1400 | F7: =IF(OR(Ödemeler!$A6="",Ödemeler!$G6="",Ödemeler!$E6=""),"",IF(AND(((Özet!$C$4*12+5)-(YEAR(Ödemeler!$E6)*12+MONTH(Ödemeler!$E6)))>=0,MOD(((Özet!$C$4*12+5)-(YEAR(Ödemeler!$E6)*12+MONTH(Ödemeler!$E6))),Ödemeler!$G6)=0,OR(Ödemeler!$F6="",DATE(Özet!$C$4,5,1)<=Ödemeler!$F6)),Ödemeler!$C6,0)) -> 1400 | G7: =IF(OR(Ödemeler!$A6="",Ödemeler!$G6="",Ödemeler!$E6=""),"",IF(AND(((Özet!$C$4*12+6)-(YEAR(Ödemeler!$E6)*12+MONTH(Ödemeler!$E6)))>=0,MOD(((Özet!$C$4*12+6)-(YEAR(Ödemeler!$E6)*12+MONTH(Ödemeler!$E6))),Ödemeler!$G6)=0,OR(Ödemeler!$F6="",DATE(Özet!$C$4,6,1)<=Ödemeler!$F6)),Ödemeler!$C6,0)) -> 1400 | H7: =IF(OR(Ödemeler!$A6="",Ödemeler!$G6="",Ödemeler!$E6=""),"",IF(AND(((Özet!$C$4*12+7)-(YEAR(Ödemeler!$E6)*12+MONTH(Ödemeler!$E6)))>=0,MOD(((Özet!$C$4*12+7)-(YEAR(Ödemeler!$E6)*12+MONTH(Ödemeler!$E6))),Ödemeler!$G6)=0,OR(Ödemeler!$F6="",DATE(Özet!$C$4,7,1)<=Ödemeler!$F6)),Ödemeler!$C6,0)) -> 1400 | I7: =IF(OR(Ödemeler!$A6="",Ödemeler!$G6="",Ödemeler!$E6=""),"",IF(AND(((Özet!$C$4*12+8)-(YEAR(Ödemeler!$E6)*12+MONTH(Ödemeler!$E6)))>=0,MOD(((Özet!$C$4*12+8)-(YEAR(Ödemeler!$E6)*12+MONTH(Ödemeler!$E6))),Ödemeler!$G6)=0,OR(Ödemeler!$F6="",DATE(Özet!$C$4,8,1)<=Ödemeler!$F6)),Ödemeler!$C6,0)) -> 1400 | J7: =IF(OR(Ödemeler!$A6="",Ödemeler!$G6="",Ödemeler!$E6=""),"",IF(AND(((Özet!$C$4*12+9)-(YEAR(Ödemeler!$E6)*12+MONTH(Ödemeler!$E6)))>=0,MOD(((Özet!$C$4*12+9)-(YEAR(Ödemeler!$E6)*12+MONTH(Ödemeler!$E6))),Ödemeler!$G6)=0,OR(Ödemeler!$F6="",DATE(Özet!$C$4,9,1)<=Ödemeler!$F6)),Ödemeler!$C6,0)) -> 1400 | K7: =IF(OR(Ödemeler!$A6="",Ödemeler!$G6="",Ödemeler!$E6=""),"",IF(AND(((Özet!$C$4*12+10)-(YEAR(Ödemeler!$E6)*12+MONTH(Ödemeler!$E6)))>=0,MOD(((Özet!$C$4*12+10)-(YEAR(Ödemeler!$E6)*12+MONTH(Ödemeler!$E6))),Ödemeler!$G6)=0,OR(Ödemeler!$F6="",DATE(Özet!$C$4,10,1)<=Ödemeler!$F6)),Ödemeler!$C6,0)) -> 1400 | L7: =IF(OR(Ödemeler!$A6="",Ödemeler!$G6="",Ödemeler!$E6=""),"",IF(AND(((Özet!$C$4*12+11)-(YEAR(Ödemeler!$E6)*12+MONTH(Ödemeler!$E6)))>=0,MOD(((Özet!$C$4*12+11)-(YEAR(Ödemeler!$E6)*12+MONTH(Ödemeler!$E6))),Ödemeler!$G6)=0,OR(Ödemeler!$F6="",DATE(Özet!$C$4,11,1)<=Ödemeler!$F6)),Ödemeler!$C6,0)) -> 1400 | M7: =IF(OR(Ödemeler!$A6="",Ödemeler!$G6="",Ödemeler!$E6=""),"",IF(AND(((Özet!$C$4*12+12)-(YEAR(Ödemeler!$E6)*12+MONTH(Ödemeler!$E6)))>=0,MOD(((Özet!$C$4*12+12)-(YEAR(Ödemeler!$E6)*12+MONTH(Ödemeler!$E6))),Ödemeler!$G6)=0,OR(Ödemeler!$F6="",DATE(Özet!$C$4,12,1)<=Ödemeler!$F6)),Ödemeler!$C6,0)) -> 1400 | N7: =IF(COUNT(B7:M7)=0,"",SUM(B7:M7)) -> 16800
A8: =IF(Ödemeler!A7="","",Ödemeler!A7) -> İnternet | B8: =IF(OR(Ödemeler!$A7="",Ödemeler!$G7="",Ödemeler!$E7=""),"",IF(AND(((Özet!$C$4*12+1)-(YEAR(Ödemeler!$E7)*12+MONTH(Ödemeler!$E7)))>=0,MOD(((Özet!$C$4*12+1)-(YEAR(Ödemeler!$E7)*12+MONTH(Ödemeler!$E7))),Ödemeler!$G7)=0,OR(Ödemeler!$F7="",DATE(Özet!$C$4,1,1)<=Ödemeler!$F7)),Ödemeler!$C7,0)) -> 0 | C8: =IF(OR(Ödemeler!$A7="",Ödemeler!$G7="",Ödemeler!$E7=""),"",IF(AND(((Özet!$C$4*12+2)-(YEAR(Ödemeler!$E7)*12+MONTH(Ödemeler!$E7)))>=0,MOD(((Özet!$C$4*12+2)-(YEAR(Ödemeler!$E7)*12+MONTH(Ödemeler!$E7))),Ödemeler!$G7)=0,OR(Ödemeler!$F7="",DATE(Özet!$C$4,2,1)<=Ödemeler!$F7)),Ödemeler!$C7,0)) -> 650 | D8: =IF(OR(Ödemeler!$A7="",Ödemeler!$G7="",Ödemeler!$E7=""),"",IF(AND(((Özet!$C$4*12+3)-(YEAR(Ödemeler!$E7)*12+MONTH(Ödemeler!$E7)))>=0,MOD(((Özet!$C$4*12+3)-(YEAR(Ödemeler!$E7)*12+MONTH(Ödemeler!$E7))),Ödemeler!$G7)=0,OR(Ödemeler!$F7="",DATE(Özet!$C$4,3,1)<=Ödemeler!$F7)),Ödemeler!$C7,0)) -> 650 | E8: =IF(OR(Ödemeler!$A7="",Ödemeler!$G7="",Ödemeler!$E7=""),"",IF(AND(((Özet!$C$4*12+4)-(YEAR(Ödemeler!$E7)*12+MONTH(Ödemeler!$E7)))>=0,MOD(((Özet!$C$4*12+4)-(YEAR(Ödemeler!$E7)*12+MONTH(Ödemeler!$E7))),Ödemeler!$G7)=0,OR(Ödemeler!$F7="",DATE(Özet!$C$4,4,1)<=Ödemeler!$F7)),Ödemeler!$C7,0)) -> 650 | F8: =IF(OR(Ödemeler!$A7="",Ödemeler!$G7="",Ödemeler!$E7=""),"",IF(AND(((Özet!$C$4*12+5)-(YEAR(Ödemeler!$E7)*12+MONTH(Ödemeler!$E7)))>=0,MOD(((Özet!$C$4*12+5)-(YEAR(Ödemeler!$E7)*12+MONTH(Ödemeler!$E7))),Ödemeler!$G7)=0,OR(Ödemeler!$F7="",DATE(Özet!$C$4,5,1)<=Ödemeler!$F7)),Ödemeler!$C7,0)) -> 650 | G8: =IF(OR(Ödemeler!$A7="",Ödemeler!$G7="",Ödemeler!$E7=""),"",IF(AND(((Özet!$C$4*12+6)-(YEAR(Ödemeler!$E7)*12+MONTH(Ödemeler!$E7)))>=0,MOD(((Özet!$C$4*12+6)-(YEAR(Ödemeler!$E7)*12+MONTH(Ödemeler!$E7))),Ödemeler!$G7)=0,OR(Ödemeler!$F7="",DATE(Özet!$C$4,6,1)<=Ödemeler!$F7)),Ödemeler!$C7,0)) -> 650 | H8: =IF(OR(Ödemeler!$A7="",Ödemeler!$G7="",Ödemeler!$E7=""),"",IF(AND(((Özet!$C$4*12+7)-(YEAR(Ödemeler!$E7)*12+MONTH(Ödemeler!$E7)))>=0,MOD(((Özet!$C$4*12+7)-(YEAR(Ödemeler!$E7)*12+MONTH(Ödemeler!$E7))),Ödemeler!$G7)=0,OR(Ödemeler!$F7="",DATE(Özet!$C$4,7,1)<=Ödemeler!$F7)),Ödemeler!$C7,0)) -> 650 | I8: =IF(OR(Ödemeler!$A7="",Ödemeler!$G7="",Ödemeler!$E7=""),"",IF(AND(((Özet!$C$4*12+8)-(YEAR(Ödemeler!$E7)*12+MONTH(Ödemeler!$E7)))>=0,MOD(((Özet!$C$4*12+8)-(YEAR(Ödemeler!$E7)*12+MONTH(Ödemeler!$E7))),Ödemeler!$G7)=0,OR(Ödemeler!$F7="",DATE(Özet!$C$4,8,1)<=Ödemeler!$F7)),Ödemeler!$C7,0)) -> 650 | J8: =IF(OR(Ödemeler!$A7="",Ödemeler!$G7="",Ödemeler!$E7=""),"",IF(AND(((Özet!$C$4*12+9)-(YEAR(Ödemeler!$E7)*12+MONTH(Ödemeler!$E7)))>=0,MOD(((Özet!$C$4*12+9)-(YEAR(Ödemeler!$E7)*12+MONTH(Ödemeler!$E7))),Ödemeler!$G7)=0,OR(Ödemeler!$F7="",DATE(Özet!$C$4,9,1)<=Ödemeler!$F7)),Ödemeler!$C7,0)) -> 650 | K8: =IF(OR(Ödemeler!$A7="",Ödemeler!$G7="",Ödemeler!$E7=""),"",IF(AND(((Özet!$C$4*12+10)-(YEAR(Ödemeler!$E7)*12+MONTH(Ödemeler!$E7)))>=0,MOD(((Özet!$C$4*12+10)-(YEAR(Ödemeler!$E7)*12+MONTH(Ödemeler!$E7))),Ödemeler!$G7)=0,OR(Ödemeler!$F7="",DATE(Özet!$C$4,10,1)<=Ödemeler!$F7)),Ödemeler!$C7,0)) -> 650 | L8: =IF(OR(Ödemeler!$A7="",Ödemeler!$G7="",Ödemeler!$E7=""),"",IF(AND(((Özet!$C$4*12+11)-(YEAR(Ödemeler!$E7)*12+MONTH(Ödemeler!$E7)))>=0,MOD(((Özet!$C$4*12+11)-(YEAR(Ödemeler!$E7)*12+MONTH(Ödemeler!$E7))),Ödemeler!$G7)=0,OR(Ödemeler!$F7="",DATE(Özet!$C$4,11,1)<=Ödemeler!$F7)),Ödemeler!$C7,0)) -> 650 | M8: =IF(OR(Ödemeler!$A7="",Ödemeler!$G7="",Ödemeler!$E7=""),"",IF(AND(((Özet!$C$4*12+12)-(YEAR(Ödemeler!$E7)*12+MONTH(Ödemeler!$E7)))>=0,MOD(((Özet!$C$4*12+12)-(YEAR(Ödemeler!$E7)*12+MONTH(Ödemeler!$E7))),Ödemeler!$G7)=0,OR(Ödemeler!$F7="",DATE(Özet!$C$4,12,1)<=Ödemeler!$F7)),Ödemeler!$C7,0)) -> 650 | N8: =IF(COUNT(B8:M8)=0,"",SUM(B8:M8)) -> 7150
A9: =IF(Ödemeler!A8="","",Ödemeler!A8) -> Film ve dizi aboneliği | B9: =IF(OR(Ödemeler!$A8="",Ödemeler!$G8="",Ödemeler!$E8=""),"",IF(AND(((Özet!$C$4*12+1)-(YEAR(Ödemeler!$E8)*12+MONTH(Ödemeler!$E8)))>=0,MOD(((Özet!$C$4*12+1)-(YEAR(Ödemeler!$E8)*12+MONTH(Ödemeler!$E8))),Ödemeler!$G8)=0,OR(Ödemeler!$F8="",DATE(Özet!$C$4,1,1)<=Ödemeler!$F8)),Ödemeler!$C8,0)) -> 230 | C9: =IF(OR(Ödemeler!$A8="",Ödemeler!$G8="",Ödemeler!$E8=""),"",IF(AND(((Özet!$C$4*12+2)-(YEAR(Ödemeler!$E8)*12+MONTH(Ödemeler!$E8)))>=0,MOD(((Özet!$C$4*12+2)-(YEAR(Ödemeler!$E8)*12+MONTH(Ödemeler!$E8))),Ödemeler!$G8)=0,OR(Ödemeler!$F8="",DATE(Özet!$C$4,2,1)<=Ödemeler!$F8)),Ödemeler!$C8,0)) -> 230 | D9: =IF(OR(Ödemeler!$A8="",Ödemeler!$G8="",Ödemeler!$E8=""),"",IF(AND(((Özet!$C$4*12+3)-(YEAR(Ödemeler!$E8)*12+MONTH(Ödemeler!$E8)))>=0,MOD(((Özet!$C$4*12+3)-(YEAR(Ödemeler!$E8)*12+MONTH(Ödemeler!$E8))),Ödemeler!$G8)=0,OR(Ödemeler!$F8="",DATE(Özet!$C$4,3,1)<=Ödemeler!$F8)),Ödemeler!$C8,0)) -> 230 | E9: =IF(OR(Ödemeler!$A8="",Ödemeler!$G8="",Ödemeler!$E8=""),"",IF(AND(((Özet!$C$4*12+4)-(YEAR(Ödemeler!$E8)*12+MONTH(Ödemeler!$E8)))>=0,MOD(((Özet!$C$4*12+4)-(YEAR(Ödemeler!$E8)*12+MONTH(Ödemeler!$E8))),Ödemeler!$G8)=0,OR(Ödemeler!$F8="",DATE(Özet!$C$4,4,1)<=Ödemeler!$F8)),Ödemeler!$C8,0)) -> 230 | F9: =IF(OR(Ödemeler!$A8="",Ödemeler!$G8="",Ödemeler!$E8=""),"",IF(AND(((Özet!$C$4*12+5)-(YEAR(Ödemeler!$E8)*12+MONTH(Ödemeler!$E8)))>=0,MOD(((Özet!$C$4*12+5)-(YEAR(Ödemeler!$E8)*12+MONTH(Ödemeler!$E8))),Ödemeler!$G8)=0,OR(Ödemeler!$F8="",DATE(Özet!$C$4,5,1)<=Ödemeler!$F8)),Ödemeler!$C8,0)) -> 230 | G9: =IF(OR(Ödemeler!$A8="",Ödemeler!$G8="",Ödemeler!$E8=""),"",IF(AND(((Özet!$C$4*12+6)-(YEAR(Ödemeler!$E8)*12+MONTH(Ödemeler!$E8)))>=0,MOD(((Özet!$C$4*12+6)-(YEAR(Ödemeler!$E8)*12+MONTH(Ödemeler!$E8))),Ödemeler!$G8)=0,OR(Ödemeler!$F8="",DATE(Özet!$C$4,6,1)<=Ödemeler!$F8)),Ödemeler!$C8,0)) -> 230 | H9: =IF(OR(Ödemeler!$A8="",Ödemeler!$G8="",Ödemeler!$E8=""),"",IF(AND(((Özet!$C$4*12+7)-(YEAR(Ödemeler!$E8)*12+MONTH(Ödemeler!$E8)))>=0,MOD(((Özet!$C$4*12+7)-(YEAR(Ödemeler!$E8)*12+MONTH(Ödemeler!$E8))),Ödemeler!$G8)=0,OR(Ödemeler!$F8="",DATE(Özet!$C$4,7,1)<=Ödemeler!$F8)),Ödemeler!$C8,0)) -> 230 | I9: =IF(OR(Ödemeler!$A8="",Ödemeler!$G8="",Ödemeler!$E8=""),"",IF(AND(((Özet!$C$4*12+8)-(YEAR(Ödemeler!$E8)*12+MONTH(Ödemeler!$E8)))>=0,MOD(((Özet!$C$4*12+8)-(YEAR(Ödemeler!$E8)*12+MONTH(Ödemeler!$E8))),Ödemeler!$G8)=0,OR(Ödemeler!$F8="",DATE(Özet!$C$4,8,1)<=Ödemeler!$F8)),Ödemeler!$C8,0)) -> 230 | J9: =IF(OR(Ödemeler!$A8="",Ödemeler!$G8="",Ödemeler!$E8=""),"",IF(AND(((Özet!$C$4*12+9)-(YEAR(Ödemeler!$E8)*12+MONTH(Ödemeler!$E8)))>=0,MOD(((Özet!$C$4*12+9)-(YEAR(Ödemeler!$E8)*12+MONTH(Ödemeler!$E8))),Ödemeler!$G8)=0,OR(Ödemeler!$F8="",DATE(Özet!$C$4,9,1)<=Ödemeler!$F8)),Ödemeler!$C8,0)) -> 230 | K9: =IF(OR(Ödemeler!$A8="",Ödemeler!$G8="",Ödemeler!$E8=""),"",IF(AND(((Özet!$C$4*12+10)-(YEAR(Ödemeler!$E8)*12+MONTH(Ödemeler!$E8)))>=0,MOD(((Özet!$C$4*12+10)-(YEAR(Ödemeler!$E8)*12+MONTH(Ödemeler!$E8))),Ödemeler!$G8)=0,OR(Ödemeler!$F8="",DATE(Özet!$C$4,10,1)<=Ödemeler!$F8)),Ödemeler!$C8,0)) -> 230 | L9: =IF(OR(Ödemeler!$A8="",Ödemeler!$G8="",Ödemeler!$E8=""),"",IF(AND(((Özet!$C$4*12+11)-(YEAR(Ödemeler!$E8)*12+MONTH(Ödemeler!$E8)))>=0,MOD(((Özet!$C$4*12+11)-(YEAR(Ödemeler!$E8)*12+MONTH(Ödemeler!$E8))),Ödemeler!$G8)=0,OR(Ödemeler!$F8="",DATE(Özet!$C$4,11,1)<=Ödemeler!$F8)),Ödemeler!$C8,0)) -> 230 | M9: =IF(OR(Ödemeler!$A8="",Ödemeler!$G8="",Ödemeler!$E8=""),"",IF(AND(((Özet!$C$4*12+12)-(YEAR(Ödemeler!$E8)*12+MONTH(Ödemeler!$E8)))>=0,MOD(((Özet!$C$4*12+12)-(YEAR(Ödemeler!$E8)*12+MONTH(Ödemeler!$E8))),Ödemeler!$G8)=0,OR(Ödemeler!$F8="",DATE(Özet!$C$4,12,1)<=Ödemeler!$F8)),Ödemeler!$C8,0)) -> 230 | N9: =IF(COUNT(B9:M9)=0,"",SUM(B9:M9)) -> 2760
A10: =IF(Ödemeler!A9="","",Ödemeler!A9) -> Bulut depolama | B10: =IF(OR(Ödemeler!$A9="",Ödemeler!$G9="",Ödemeler!$E9=""),"",IF(AND(((Özet!$C$4*12+1)-(YEAR(Ödemeler!$E9)*12+MONTH(Ödemeler!$E9)))>=0,MOD(((Özet!$C$4*12+1)-(YEAR(Ödemeler!$E9)*12+MONTH(Ödemeler!$E9))),Ödemeler!$G9)=0,OR(Ödemeler!$F9="",DATE(Özet!$C$4,1,1)<=Ödemeler!$F9)),Ödemeler!$C9,0)) -> 0 | C10: =IF(OR(Ödemeler!$A9="",Ödemeler!$G9="",Ödemeler!$E9=""),"",IF(AND(((Özet!$C$4*12+2)-(YEAR(Ödemeler!$E9)*12+MONTH(Ödemeler!$E9)))>=0,MOD(((Özet!$C$4*12+2)-(YEAR(Ödemeler!$E9)*12+MONTH(Ödemeler!$E9))),Ödemeler!$G9)=0,OR(Ödemeler!$F9="",DATE(Özet!$C$4,2,1)<=Ödemeler!$F9)),Ödemeler!$C9,0)) -> 0 | D10: =IF(OR(Ödemeler!$A9="",Ödemeler!$G9="",Ödemeler!$E9=""),"",IF(AND(((Özet!$C$4*12+3)-(YEAR(Ödemeler!$E9)*12+MONTH(Ödemeler!$E9)))>=0,MOD(((Özet!$C$4*12+3)-(YEAR(Ödemeler!$E9)*12+MONTH(Ödemeler!$E9))),Ödemeler!$G9)=0,OR(Ödemeler!$F9="",DATE(Özet!$C$4,3,1)<=Ödemeler!$F9)),Ödemeler!$C9,0)) -> 1200 | E10: =IF(OR(Ödemeler!$A9="",Ödemeler!$G9="",Ödemeler!$E9=""),"",IF(AND(((Özet!$C$4*12+4)-(YEAR(Ödemeler!$E9)*12+MONTH(Ödemeler!$E9)))>=0,MOD(((Özet!$C$4*12+4)-(YEAR(Ödemeler!$E9)*12+MONTH(Ödemeler!$E9))),Ödemeler!$G9)=0,OR(Ödemeler!$F9="",DATE(Özet!$C$4,4,1)<=Ödemeler!$F9)),Ödemeler!$C9,0)) -> 0 | F10: =IF(OR(Ödemeler!$A9="",Ödemeler!$G9="",Ödemeler!$E9=""),"",IF(AND(((Özet!$C$4*12+5)-(YEAR(Ödemeler!$E9)*12+MONTH(Ödemeler!$E9)))>=0,MOD(((Özet!$C$4*12+5)-(YEAR(Ödemeler!$E9)*12+MONTH(Ödemeler!$E9))),Ödemeler!$G9)=0,OR(Ödemeler!$F9="",DATE(Özet!$C$4,5,1)<=Ödemeler!$F9)),Ödemeler!$C9,0)) -> 0 | G10: =IF(OR(Ödemeler!$A9="",Ödemeler!$G9="",Ödemeler!$E9=""),"",IF(AND(((Özet!$C$4*12+6)-(YEAR(Ödemeler!$E9)*12+MONTH(Ödemeler!$E9)))>=0,MOD(((Özet!$C$4*12+6)-(YEAR(Ödemeler!$E9)*12+MONTH(Ödemeler!$E9))),Ödemeler!$G9)=0,OR(Ödemeler!$F9="",DATE(Özet!$C$4,6,1)<=Ödemeler!$F9)),Ödemeler!$C9,0)) -> 0 | H10: =IF(OR(Ödemeler!$A9="",Ödemeler!$G9="",Ödemeler!$E9=""),"",IF(AND(((Özet!$C$4*12+7)-(YEAR(Ödemeler!$E9)*12+MONTH(Ödemeler!$E9)))>=0,MOD(((Özet!$C$4*12+7)-(YEAR(Ödemeler!$E9)*12+MONTH(Ödemeler!$E9))),Ödemeler!$G9)=0,OR(Ödemeler!$F9="",DATE(Özet!$C$4,7,1)<=Ödemeler!$F9)),Ödemeler!$C9,0)) -> 0 | I10: =IF(OR(Ödemeler!$A9="",Ödemeler!$G9="",Ödemeler!$E9=""),"",IF(AND(((Özet!$C$4*12+8)-(YEAR(Ödemeler!$E9)*12+MONTH(Ödemeler!$E9)))>=0,MOD(((Özet!$C$4*12+8)-(YEAR(Ödemeler!$E9)*12+MONTH(Ödemeler!$E9))),Ödemeler!$G9)=0,OR(Ödemeler!$F9="",DATE(Özet!$C$4,8,1)<=Ödemeler!$F9)),Ödemeler!$C9,0)) -> 0 | J10: =IF(OR(Ödemeler!$A9="",Ödemeler!$G9="",Ödemeler!$E9=""),"",IF(AND(((Özet!$C$4*12+9)-(YEAR(Ödemeler!$E9)*12+MONTH(Ödemeler!$E9)))>=0,MOD(((Özet!$C$4*12+9)-(YEAR(Ödemeler!$E9)*12+MONTH(Ödemeler!$E9))),Ödemeler!$G9)=0,OR(Ödemeler!$F9="",DATE(Özet!$C$4,9,1)<=Ödemeler!$F9)),Ödemeler!$C9,0)) -> 0 | K10: =IF(OR(Ödemeler!$A9="",Ödemeler!$G9="",Ödemeler!$E9=""),"",IF(AND(((Özet!$C$4*12+10)-(YEAR(Ödemeler!$E9)*12+MONTH(Ödemeler!$E9)))>=0,MOD(((Özet!$C$4*12+10)-(YEAR(Ödemeler!$E9)*12+MONTH(Ödemeler!$E9))),Ödemeler!$G9)=0,OR(Ödemeler!$F9="",DATE(Özet!$C$4,10,1)<=Ödemeler!$F9)),Ödemeler!$C9,0)) -> 0 | L10: =IF(OR(Ödemeler!$A9="",Ödemeler!$G9="",Ödemeler!$E9=""),"",IF(AND(((Özet!$C$4*12+11)-(YEAR(Ödemeler!$E9)*12+MONTH(Ödemeler!$E9)))>=0,MOD(((Özet!$C$4*12+11)-(YEAR(Ödemeler!$E9)*12+MONTH(Ödemeler!$E9))),Ödemeler!$G9)=0,OR(Ödemeler!$F9="",DATE(Özet!$C$4,11,1)<=Ödemeler!$F9)),Ödemeler!$C9,0)) -> 0 | M10: =IF(OR(Ödemeler!$A9="",Ödemeler!$G9="",Ödemeler!$E9=""),"",IF(AND(((Özet!$C$4*12+12)-(YEAR(Ödemeler!$E9)*12+MONTH(Ödemeler!$E9)))>=0,MOD(((Özet!$C$4*12+12)-(YEAR(Ödemeler!$E9)*12+MONTH(Ödemeler!$E9))),Ödemeler!$G9)=0,OR(Ödemeler!$F9="",DATE(Özet!$C$4,12,1)<=Ödemeler!$F9)),Ödemeler!$C9,0)) -> 0 | N10: =IF(COUNT(B10:M10)=0,"",SUM(B10:M10)) -> 1200
A11: =IF(Ödemeler!A10="","",Ödemeler!A10) -> Telefon taksidi | B11: =IF(OR(Ödemeler!$A10="",Ödemeler!$G10="",Ödemeler!$E10=""),"",IF(AND(((Özet!$C$4*12+1)-(YEAR(Ödemeler!$E10)*12+MONTH(Ödemeler!$E10)))>=0,MOD(((Özet!$C$4*12+1)-(YEAR(Ödemeler!$E10)*12+MONTH(Ödemeler!$E10))),Ödemeler!$G10)=0,OR(Ödemeler!$F10="",DATE(Özet!$C$4,1,1)<=Ödemeler!$F10)),Ödemeler!$C10,0)) -> 0 | C11: =IF(OR(Ödemeler!$A10="",Ödemeler!$G10="",Ödemeler!$E10=""),"",IF(AND(((Özet!$C$4*12+2)-(YEAR(Ödemeler!$E10)*12+MONTH(Ödemeler!$E10)))>=0,MOD(((Özet!$C$4*12+2)-(YEAR(Ödemeler!$E10)*12+MONTH(Ödemeler!$E10))),Ödemeler!$G10)=0,OR(Ödemeler!$F10="",DATE(Özet!$C$4,2,1)<=Ödemeler!$F10)),Ödemeler!$C10,0)) -> 0 | D11: =IF(OR(Ödemeler!$A10="",Ödemeler!$G10="",Ödemeler!$E10=""),"",IF(AND(((Özet!$C$4*12+3)-(YEAR(Ödemeler!$E10)*12+MONTH(Ödemeler!$E10)))>=0,MOD(((Özet!$C$4*12+3)-(YEAR(Ödemeler!$E10)*12+MONTH(Ödemeler!$E10))),Ödemeler!$G10)=0,OR(Ödemeler!$F10="",DATE(Özet!$C$4,3,1)<=Ödemeler!$F10)),Ödemeler!$C10,0)) -> 0 | E11: =IF(OR(Ödemeler!$A10="",Ödemeler!$G10="",Ödemeler!$E10=""),"",IF(AND(((Özet!$C$4*12+4)-(YEAR(Ödemeler!$E10)*12+MONTH(Ödemeler!$E10)))>=0,MOD(((Özet!$C$4*12+4)-(YEAR(Ödemeler!$E10)*12+MONTH(Ödemeler!$E10))),Ödemeler!$G10)=0,OR(Ödemeler!$F10="",DATE(Özet!$C$4,4,1)<=Ödemeler!$F10)),Ödemeler!$C10,0)) -> 2500 | F11: =IF(OR(Ödemeler!$A10="",Ödemeler!$G10="",Ödemeler!$E10=""),"",IF(AND(((Özet!$C$4*12+5)-(YEAR(Ödemeler!$E10)*12+MONTH(Ödemeler!$E10)))>=0,MOD(((Özet!$C$4*12+5)-(YEAR(Ödemeler!$E10)*12+MONTH(Ödemeler!$E10))),Ödemeler!$G10)=0,OR(Ödemeler!$F10="",DATE(Özet!$C$4,5,1)<=Ödemeler!$F10)),Ödemeler!$C10,0)) -> 2500 | G11: =IF(OR(Ödemeler!$A10="",Ödemeler!$G10="",Ödemeler!$E10=""),"",IF(AND(((Özet!$C$4*12+6)-(YEAR(Ödemeler!$E10)*12+MONTH(Ödemeler!$E10)))>=0,MOD(((Özet!$C$4*12+6)-(YEAR(Ödemeler!$E10)*12+MONTH(Ödemeler!$E10))),Ödemeler!$G10)=0,OR(Ödemeler!$F10="",DATE(Özet!$C$4,6,1)<=Ödemeler!$F10)),Ödemeler!$C10,0)) -> 2500 | H11: =IF(OR(Ödemeler!$A10="",Ödemeler!$G10="",Ödemeler!$E10=""),"",IF(AND(((Özet!$C$4*12+7)-(YEAR(Ödemeler!$E10)*12+MONTH(Ödemeler!$E10)))>=0,MOD(((Özet!$C$4*12+7)-(YEAR(Ödemeler!$E10)*12+MONTH(Ödemeler!$E10))),Ödemeler!$G10)=0,OR(Ödemeler!$F10="",DATE(Özet!$C$4,7,1)<=Ödemeler!$F10)),Ödemeler!$C10,0)) -> 2500 | I11: =IF(OR(Ödemeler!$A10="",Ödemeler!$G10="",Ödemeler!$E10=""),"",IF(AND(((Özet!$C$4*12+8)-(YEAR(Ödemeler!$E10)*12+MONTH(Ödemeler!$E10)))>=0,MOD(((Özet!$C$4*12+8)-(YEAR(Ödemeler!$E10)*12+MONTH(Ödemeler!$E10))),Ödemeler!$G10)=0,OR(Ödemeler!$F10="",DATE(Özet!$C$4,8,1)<=Ödemeler!$F10)),Ödemeler!$C10,0)) -> 2500 | J11: =IF(OR(Ödemeler!$A10="",Ödemeler!$G10="",Ödemeler!$E10=""),"",IF(AND(((Özet!$C$4*12+9)-(YEAR(Ödemeler!$E10)*12+MONTH(Ödemeler!$E10)))>=0,MOD(((Özet!$C$4*12+9)-(YEAR(Ödemeler!$E10)*12+MONTH(Ödemeler!$E10))),Ödemeler!$G10)=0,OR(Ödemeler!$F10="",DATE(Özet!$C$4,9,1)<=Ödemeler!$F10)),Ödemeler!$C10,0)) -> 2500 | K11: =IF(OR(Ödemeler!$A10="",Ödemeler!$G10="",Ödemeler!$E10=""),"",IF(AND(((Özet!$C$4*12+10)-(YEAR(Ödemeler!$E10)*12+MONTH(Ödemeler!$E10)))>=0,MOD(((Özet!$C$4*12+10)-(YEAR(Ödemeler!$E10)*12+MONTH(Ödemeler!$E10))),Ödemeler!$G10)=0,OR(Ödemeler!$F10="",DATE(Özet!$C$4,10,1)<=Ödemeler!$F10)),Ödemeler!$C10,0)) -> 2500 | L11: =IF(OR(Ödemeler!$A10="",Ödemeler!$G10="",Ödemeler!$E10=""),"",IF(AND(((Özet!$C$4*12+11)-(YEAR(Ödemeler!$E10)*12+MONTH(Ödemeler!$E10)))>=0,MOD(((Özet!$C$4*12+11)-(YEAR(Ödemeler!$E10)*12+MONTH(Ödemeler!$E10))),Ödemeler!$G10)=0,OR(Ödemeler!$F10="",DATE(Özet!$C$4,11,1)<=Ödemeler!$F10)),Ödemeler!$C10,0)) -> 2500 | M11: =IF(OR(Ödemeler!$A10="",Ödemeler!$G10="",Ödemeler!$E10=""),"",IF(AND(((Özet!$C$4*12+12)-(YEAR(Ödemeler!$E10)*12+MONTH(Ödemeler!$E10)))>=0,MOD(((Özet!$C$4*12+12)-(YEAR(Ödemeler!$E10)*12+MONTH(Ödemeler!$E10))),Ödemeler!$G10)=0,OR(Ödemeler!$F10="",DATE(Özet!$C$4,12,1)<=Ödemeler!$F10)),Ödemeler!$C10,0)) -> 2500 | N11: =IF(COUNT(B11:M11)=0,"",SUM(B11:M11)) -> 22500
A12: =IF(Ödemeler!A11="","",Ödemeler!A11) -> Kasko | B12: =IF(OR(Ödemeler!$A11="",Ödemeler!$G11="",Ödemeler!$E11=""),"",IF(AND(((Özet!$C$4*12+1)-(YEAR(Ödemeler!$E11)*12+MONTH(Ödemeler!$E11)))>=0,MOD(((Özet!$C$4*12+1)-(YEAR(Ödemeler!$E11)*12+MONTH(Ödemeler!$E11))),Ödemeler!$G11)=0,OR(Ödemeler!$F11="",DATE(Özet!$C$4,1,1)<=Ödemeler!$F11)),Ödemeler!$C11,0)) -> 0 | C12: =IF(OR(Ödemeler!$A11="",Ödemeler!$G11="",Ödemeler!$E11=""),"",IF(AND(((Özet!$C$4*12+2)-(YEAR(Ödemeler!$E11)*12+MONTH(Ödemeler!$E11)))>=0,MOD(((Özet!$C$4*12+2)-(YEAR(Ödemeler!$E11)*12+MONTH(Ödemeler!$E11))),Ödemeler!$G11)=0,OR(Ödemeler!$F11="",DATE(Özet!$C$4,2,1)<=Ödemeler!$F11)),Ödemeler!$C11,0)) -> 0 | D12: =IF(OR(Ödemeler!$A11="",Ödemeler!$G11="",Ödemeler!$E11=""),"",IF(AND(((Özet!$C$4*12+3)-(YEAR(Ödemeler!$E11)*12+MONTH(Ödemeler!$E11)))>=0,MOD(((Özet!$C$4*12+3)-(YEAR(Ödemeler!$E11)*12+MONTH(Ödemeler!$E11))),Ödemeler!$G11)=0,OR(Ödemeler!$F11="",DATE(Özet!$C$4,3,1)<=Ödemeler!$F11)),Ödemeler!$C11,0)) -> 0 | E12: =IF(OR(Ödemeler!$A11="",Ödemeler!$G11="",Ödemeler!$E11=""),"",IF(AND(((Özet!$C$4*12+4)-(YEAR(Ödemeler!$E11)*12+MONTH(Ödemeler!$E11)))>=0,MOD(((Özet!$C$4*12+4)-(YEAR(Ödemeler!$E11)*12+MONTH(Ödemeler!$E11))),Ödemeler!$G11)=0,OR(Ödemeler!$F11="",DATE(Özet!$C$4,4,1)<=Ödemeler!$F11)),Ödemeler!$C11,0)) -> 0 | F12: =IF(OR(Ödemeler!$A11="",Ödemeler!$G11="",Ödemeler!$E11=""),"",IF(AND(((Özet!$C$4*12+5)-(YEAR(Ödemeler!$E11)*12+MONTH(Ödemeler!$E11)))>=0,MOD(((Özet!$C$4*12+5)-(YEAR(Ödemeler!$E11)*12+MONTH(Ödemeler!$E11))),Ödemeler!$G11)=0,OR(Ödemeler!$F11="",DATE(Özet!$C$4,5,1)<=Ödemeler!$F11)),Ödemeler!$C11,0)) -> 0 | G12: =IF(OR(Ödemeler!$A11="",Ödemeler!$G11="",Ödemeler!$E11=""),"",IF(AND(((Özet!$C$4*12+6)-(YEAR(Ödemeler!$E11)*12+MONTH(Ödemeler!$E11)))>=0,MOD(((Özet!$C$4*12+6)-(YEAR(Ödemeler!$E11)*12+MONTH(Ödemeler!$E11))),Ödemeler!$G11)=0,OR(Ödemeler!$F11="",DATE(Özet!$C$4,6,1)<=Ödemeler!$F11)),Ödemeler!$C11,0)) -> 9000 | H12: =IF(OR(Ödemeler!$A11="",Ödemeler!$G11="",Ödemeler!$E11=""),"",IF(AND(((Özet!$C$4*12+7)-(YEAR(Ödemeler!$E11)*12+MONTH(Ödemeler!$E11)))>=0,MOD(((Özet!$C$4*12+7)-(YEAR(Ödemeler!$E11)*12+MONTH(Ödemeler!$E11))),Ödemeler!$G11)=0,OR(Ödemeler!$F11="",DATE(Özet!$C$4,7,1)<=Ödemeler!$F11)),Ödemeler!$C11,0)) -> 0 | I12: =IF(OR(Ödemeler!$A11="",Ödemeler!$G11="",Ödemeler!$E11=""),"",IF(AND(((Özet!$C$4*12+8)-(YEAR(Ödemeler!$E11)*12+MONTH(Ödemeler!$E11)))>=0,MOD(((Özet!$C$4*12+8)-(YEAR(Ödemeler!$E11)*12+MONTH(Ödemeler!$E11))),Ödemeler!$G11)=0,OR(Ödemeler!$F11="",DATE(Özet!$C$4,8,1)<=Ödemeler!$F11)),Ödemeler!$C11,0)) -> 0 | J12: =IF(OR(Ödemeler!$A11="",Ödemeler!$G11="",Ödemeler!$E11=""),"",IF(AND(((Özet!$C$4*12+9)-(YEAR(Ödemeler!$E11)*12+MONTH(Ödemeler!$E11)))>=0,MOD(((Özet!$C$4*12+9)-(YEAR(Ödemeler!$E11)*12+MONTH(Ödemeler!$E11))),Ödemeler!$G11)=0,OR(Ödemeler!$F11="",DATE(Özet!$C$4,9,1)<=Ödemeler!$F11)),Ödemeler!$C11,0)) -> 0 | K12: =IF(OR(Ödemeler!$A11="",Ödemeler!$G11="",Ödemeler!$E11=""),"",IF(AND(((Özet!$C$4*12+10)-(YEAR(Ödemeler!$E11)*12+MONTH(Ödemeler!$E11)))>=0,MOD(((Özet!$C$4*12+10)-(YEAR(Ödemeler!$E11)*12+MONTH(Ödemeler!$E11))),Ödemeler!$G11)=0,OR(Ödemeler!$F11="",DATE(Özet!$C$4,10,1)<=Ödemeler!$F11)),Ödemeler!$C11,0)) -> 0 | L12: =IF(OR(Ödemeler!$A11="",Ödemeler!$G11="",Ödemeler!$E11=""),"",IF(AND(((Özet!$C$4*12+11)-(YEAR(Ödemeler!$E11)*12+MONTH(Ödemeler!$E11)))>=0,MOD(((Özet!$C$4*12+11)-(YEAR(Ödemeler!$E11)*12+MONTH(Ödemeler!$E11))),Ödemeler!$G11)=0,OR(Ödemeler!$F11="",DATE(Özet!$C$4,11,1)<=Ödemeler!$F11)),Ödemeler!$C11,0)) -> 0 | M12: =IF(OR(Ödemeler!$A11="",Ödemeler!$G11="",Ödemeler!$E11=""),"",IF(AND(((Özet!$C$4*12+12)-(YEAR(Ödemeler!$E11)*12+MONTH(Ödemeler!$E11)))>=0,MOD(((Özet!$C$4*12+12)-(YEAR(Ödemeler!$E11)*12+MONTH(Ödemeler!$E11))),Ödemeler!$G11)=0,OR(Ödemeler!$F11="",DATE(Özet!$C$4,12,1)<=Ödemeler!$F11)),Ödemeler!$C11,0)) -> 9000 | N12: =IF(COUNT(B12:M12)=0,"",SUM(B12:M12)) -> 18000
A13: =IF(Ödemeler!A12="","",Ödemeler!A12) -> Spor salonu | B13: =IF(OR(Ödemeler!$A12="",Ödemeler!$G12="",Ödemeler!$E12=""),"",IF(AND(((Özet!$C$4*12+1)-(YEAR(Ödemeler!$E12)*12+MONTH(Ödemeler!$E12)))>=0,MOD(((Özet!$C$4*12+1)-(YEAR(Ödemeler!$E12)*12+MONTH(Ödemeler!$E12))),Ödemeler!$G12)=0,OR(Ödemeler!$F12="",DATE(Özet!$C$4,1,1)<=Ödemeler!$F12)),Ödemeler!$C12,0)) -> 0 | C13: =IF(OR(Ödemeler!$A12="",Ödemeler!$G12="",Ödemeler!$E12=""),"",IF(AND(((Özet!$C$4*12+2)-(YEAR(Ödemeler!$E12)*12+MONTH(Ödemeler!$E12)))>=0,MOD(((Özet!$C$4*12+2)-(YEAR(Ödemeler!$E12)*12+MONTH(Ödemeler!$E12))),Ödemeler!$G12)=0,OR(Ödemeler!$F12="",DATE(Özet!$C$4,2,1)<=Ödemeler!$F12)),Ödemeler!$C12,0)) -> 0 | D13: =IF(OR(Ödemeler!$A12="",Ödemeler!$G12="",Ödemeler!$E12=""),"",IF(AND(((Özet!$C$4*12+3)-(YEAR(Ödemeler!$E12)*12+MONTH(Ödemeler!$E12)))>=0,MOD(((Özet!$C$4*12+3)-(YEAR(Ödemeler!$E12)*12+MONTH(Ödemeler!$E12))),Ödemeler!$G12)=0,OR(Ödemeler!$F12="",DATE(Özet!$C$4,3,1)<=Ödemeler!$F12)),Ödemeler!$C12,0)) -> 0 | E13: =IF(OR(Ödemeler!$A12="",Ödemeler!$G12="",Ödemeler!$E12=""),"",IF(AND(((Özet!$C$4*12+4)-(YEAR(Ödemeler!$E12)*12+MONTH(Ödemeler!$E12)))>=0,MOD(((Özet!$C$4*12+4)-(YEAR(Ödemeler!$E12)*12+MONTH(Ödemeler!$E12))),Ödemeler!$G12)=0,OR(Ödemeler!$F12="",DATE(Özet!$C$4,4,1)<=Ödemeler!$F12)),Ödemeler!$C12,0)) -> 0 | F13: =IF(OR(Ödemeler!$A12="",Ödemeler!$G12="",Ödemeler!$E12=""),"",IF(AND(((Özet!$C$4*12+5)-(YEAR(Ödemeler!$E12)*12+MONTH(Ödemeler!$E12)))>=0,MOD(((Özet!$C$4*12+5)-(YEAR(Ödemeler!$E12)*12+MONTH(Ödemeler!$E12))),Ödemeler!$G12)=0,OR(Ödemeler!$F12="",DATE(Özet!$C$4,5,1)<=Ödemeler!$F12)),Ödemeler!$C12,0)) -> 0 | G13: =IF(OR(Ödemeler!$A12="",Ödemeler!$G12="",Ödemeler!$E12=""),"",IF(AND(((Özet!$C$4*12+6)-(YEAR(Ödemeler!$E12)*12+MONTH(Ödemeler!$E12)))>=0,MOD(((Özet!$C$4*12+6)-(YEAR(Ödemeler!$E12)*12+MONTH(Ödemeler!$E12))),Ödemeler!$G12)=0,OR(Ödemeler!$F12="",DATE(Özet!$C$4,6,1)<=Ödemeler!$F12)),Ödemeler!$C12,0)) -> 0 | H13: =IF(OR(Ödemeler!$A12="",Ödemeler!$G12="",Ödemeler!$E12=""),"",IF(AND(((Özet!$C$4*12+7)-(YEAR(Ödemeler!$E12)*12+MONTH(Ödemeler!$E12)))>=0,MOD(((Özet!$C$4*12+7)-(YEAR(Ödemeler!$E12)*12+MONTH(Ödemeler!$E12))),Ödemeler!$G12)=0,OR(Ödemeler!$F12="",DATE(Özet!$C$4,7,1)<=Ödemeler!$F12)),Ödemeler!$C12,0)) -> 0 | I13: =IF(OR(Ödemeler!$A12="",Ödemeler!$G12="",Ödemeler!$E12=""),"",IF(AND(((Özet!$C$4*12+8)-(YEAR(Ödemeler!$E12)*12+MONTH(Ödemeler!$E12)))>=0,MOD(((Özet!$C$4*12+8)-(YEAR(Ödemeler!$E12)*12+MONTH(Ödemeler!$E12))),Ödemeler!$G12)=0,OR(Ödemeler!$F12="",DATE(Özet!$C$4,8,1)<=Ödemeler!$F12)),Ödemeler!$C12,0)) -> 4500 | J13: =IF(OR(Ödemeler!$A12="",Ödemeler!$G12="",Ödemeler!$E12=""),"",IF(AND(((Özet!$C$4*12+9)-(YEAR(Ödemeler!$E12)*12+MONTH(Ödemeler!$E12)))>=0,MOD(((Özet!$C$4*12+9)-(YEAR(Ödemeler!$E12)*12+MONTH(Ödemeler!$E12))),Ödemeler!$G12)=0,OR(Ödemeler!$F12="",DATE(Özet!$C$4,9,1)<=Ödemeler!$F12)),Ödemeler!$C12,0)) -> 0 | K13: =IF(OR(Ödemeler!$A12="",Ödemeler!$G12="",Ödemeler!$E12=""),"",IF(AND(((Özet!$C$4*12+10)-(YEAR(Ödemeler!$E12)*12+MONTH(Ödemeler!$E12)))>=0,MOD(((Özet!$C$4*12+10)-(YEAR(Ödemeler!$E12)*12+MONTH(Ödemeler!$E12))),Ödemeler!$G12)=0,OR(Ödemeler!$F12="",DATE(Özet!$C$4,10,1)<=Ödemeler!$F12)),Ödemeler!$C12,0)) -> 0 | L13: =IF(OR(Ödemeler!$A12="",Ödemeler!$G12="",Ödemeler!$E12=""),"",IF(AND(((Özet!$C$4*12+11)-(YEAR(Ödemeler!$E12)*12+MONTH(Ödemeler!$E12)))>=0,MOD(((Özet!$C$4*12+11)-(YEAR(Ödemeler!$E12)*12+MONTH(Ödemeler!$E12))),Ödemeler!$G12)=0,OR(Ödemeler!$F12="",DATE(Özet!$C$4,11,1)<=Ödemeler!$F12)),Ödemeler!$C12,0)) -> 4500 | M13: =IF(OR(Ödemeler!$A12="",Ödemeler!$G12="",Ödemeler!$E12=""),"",IF(AND(((Özet!$C$4*12+12)-(YEAR(Ödemeler!$E12)*12+MONTH(Ödemeler!$E12)))>=0,MOD(((Özet!$C$4*12+12)-(YEAR(Ödemeler!$E12)*12+MONTH(Ödemeler!$E12))),Ödemeler!$G12)=0,OR(Ödemeler!$F12="",DATE(Özet!$C$4,12,1)<=Ödemeler!$F12)),Ödemeler!$C12,0)) -> 0 | N13: =IF(COUNT(B13:M13)=0,"",SUM(B13:M13)) -> 9000
A14: =IF(Ödemeler!A13="","",Ödemeler!A13) -> Eski taksit | B14: =IF(OR(Ödemeler!$A13="",Ödemeler!$G13="",Ödemeler!$E13=""),"",IF(AND(((Özet!$C$4*12+1)-(YEAR(Ödemeler!$E13)*12+MONTH(Ödemeler!$E13)))>=0,MOD(((Özet!$C$4*12+1)-(YEAR(Ödemeler!$E13)*12+MONTH(Ödemeler!$E13))),Ödemeler!$G13)=0,OR(Ödemeler!$F13="",DATE(Özet!$C$4,1,1)<=Ödemeler!$F13)),Ödemeler!$C13,0)) -> 0 | C14: =IF(OR(Ödemeler!$A13="",Ödemeler!$G13="",Ödemeler!$E13=""),"",IF(AND(((Özet!$C$4*12+2)-(YEAR(Ödemeler!$E13)*12+MONTH(Ödemeler!$E13)))>=0,MOD(((Özet!$C$4*12+2)-(YEAR(Ödemeler!$E13)*12+MONTH(Ödemeler!$E13))),Ödemeler!$G13)=0,OR(Ödemeler!$F13="",DATE(Özet!$C$4,2,1)<=Ödemeler!$F13)),Ödemeler!$C13,0)) -> 0 | D14: =IF(OR(Ödemeler!$A13="",Ödemeler!$G13="",Ödemeler!$E13=""),"",IF(AND(((Özet!$C$4*12+3)-(YEAR(Ödemeler!$E13)*12+MONTH(Ödemeler!$E13)))>=0,MOD(((Özet!$C$4*12+3)-(YEAR(Ödemeler!$E13)*12+MONTH(Ödemeler!$E13))),Ödemeler!$G13)=0,OR(Ödemeler!$F13="",DATE(Özet!$C$4,3,1)<=Ödemeler!$F13)),Ödemeler!$C13,0)) -> 0 | E14: =IF(OR(Ödemeler!$A13="",Ödemeler!$G13="",Ödemeler!$E13=""),"",IF(AND(((Özet!$C$4*12+4)-(YEAR(Ödemeler!$E13)*12+MONTH(Ödemeler!$E13)))>=0,MOD(((Özet!$C$4*12+4)-(YEAR(Ödemeler!$E13)*12+MONTH(Ödemeler!$E13))),Ödemeler!$G13)=0,OR(Ödemeler!$F13="",DATE(Özet!$C$4,4,1)<=Ödemeler!$F13)),Ödemeler!$C13,0)) -> 0 | F14: =IF(OR(Ödemeler!$A13="",Ödemeler!$G13="",Ödemeler!$E13=""),"",IF(AND(((Özet!$C$4*12+5)-(YEAR(Ödemeler!$E13)*12+MONTH(Ödemeler!$E13)))>=0,MOD(((Özet!$C$4*12+5)-(YEAR(Ödemeler!$E13)*12+MONTH(Ödemeler!$E13))),Ödemeler!$G13)=0,OR(Ödemeler!$F13="",DATE(Özet!$C$4,5,1)<=Ödemeler!$F13)),Ödemeler!$C13,0)) -> 0 | G14: =IF(OR(Ödemeler!$A13="",Ödemeler!$G13="",Ödemeler!$E13=""),"",IF(AND(((Özet!$C$4*12+6)-(YEAR(Ödemeler!$E13)*12+MONTH(Ödemeler!$E13)))>=0,MOD(((Özet!$C$4*12+6)-(YEAR(Ödemeler!$E13)*12+MONTH(Ödemeler!$E13))),Ödemeler!$G13)=0,OR(Ödemeler!$F13="",DATE(Özet!$C$4,6,1)<=Ödemeler!$F13)),Ödemeler!$C13,0)) -> 0 | H14: =IF(OR(Ödemeler!$A13="",Ödemeler!$G13="",Ödemeler!$E13=""),"",IF(AND(((Özet!$C$4*12+7)-(YEAR(Ödemeler!$E13)*12+MONTH(Ödemeler!$E13)))>=0,MOD(((Özet!$C$4*12+7)-(YEAR(Ödemeler!$E13)*12+MONTH(Ödemeler!$E13))),Ödemeler!$G13)=0,OR(Ödemeler!$F13="",DATE(Özet!$C$4,7,1)<=Ödemeler!$F13)),Ödemeler!$C13,0)) -> 0 | I14: =IF(OR(Ödemeler!$A13="",Ödemeler!$G13="",Ödemeler!$E13=""),"",IF(AND(((Özet!$C$4*12+8)-(YEAR(Ödemeler!$E13)*12+MONTH(Ödemeler!$E13)))>=0,MOD(((Özet!$C$4*12+8)-(YEAR(Ödemeler!$E13)*12+MONTH(Ödemeler!$E13))),Ödemeler!$G13)=0,OR(Ödemeler!$F13="",DATE(Özet!$C$4,8,1)<=Ödemeler!$F13)),Ödemeler!$C13,0)) -> 0 | J14: =IF(OR(Ödemeler!$A13="",Ödemeler!$G13="",Ödemeler!$E13=""),"",IF(AND(((Özet!$C$4*12+9)-(YEAR(Ödemeler!$E13)*12+MONTH(Ödemeler!$E13)))>=0,MOD(((Özet!$C$4*12+9)-(YEAR(Ödemeler!$E13)*12+MONTH(Ödemeler!$E13))),Ödemeler!$G13)=0,OR(Ödemeler!$F13="",DATE(Özet!$C$4,9,1)<=Ödemeler!$F13)),Ödemeler!$C13,0)) -> 0 | K14: =IF(OR(Ödemeler!$A13="",Ödemeler!$G13="",Ödemeler!$E13=""),"",IF(AND(((Özet!$C$4*12+10)-(YEAR(Ödemeler!$E13)*12+MONTH(Ödemeler!$E13)))>=0,MOD(((Özet!$C$4*12+10)-(YEAR(Ödemeler!$E13)*12+MONTH(Ödemeler!$E13))),Ödemeler!$G13)=0,OR(Ödemeler!$F13="",DATE(Özet!$C$4,10,1)<=Ödemeler!$F13)),Ödemeler!$C13,0)) -> 0 | L14: =IF(OR(Ödemeler!$A13="",Ödemeler!$G13="",Ödemeler!$E13=""),"",IF(AND(((Özet!$C$4*12+11)-(YEAR(Ödemeler!$E13)*12+MONTH(Ödemeler!$E13)))>=0,MOD(((Özet!$C$4*12+11)-(YEAR(Ödemeler!$E13)*12+MONTH(Ödemeler!$E13))),Ödemeler!$G13)=0,OR(Ödemeler!$F13="",DATE(Özet!$C$4,11,1)<=Ödemeler!$F13)),Ödemeler!$C13,0)) -> 0 | M14: =IF(OR(Ödemeler!$A13="",Ödemeler!$G13="",Ödemeler!$E13=""),"",IF(AND(((Özet!$C$4*12+12)-(YEAR(Ödemeler!$E13)*12+MONTH(Ödemeler!$E13)))>=0,MOD(((Özet!$C$4*12+12)-(YEAR(Ödemeler!$E13)*12+MONTH(Ödemeler!$E13))),Ödemeler!$G13)=0,OR(Ödemeler!$F13="",DATE(Özet!$C$4,12,1)<=Ödemeler!$F13)),Ödemeler!$C13,0)) -> 0 | N14: =IF(COUNT(B14:M14)=0,"",SUM(B14:M14)) -> 0
