Workbook

Sheet Başla
B2: EXCEL KLİNİĞİ
B3: RİTİM | Alışkanlık takibi
B4: Her gün bir işaret koy; serini, haftalık hedefini ve aylık gidişini dosya saysın.
B6: NASIL KULLANILIR
B7: 1. Alışkanlıklar | C7: Yılı, takip edeceğin alışkanlıkları ve haftada kaç gün yapmayı hedeflediğini yaz.
B8: 2. Takip | C8: Her gün, yaptığın alışkanlığın hücresine 1 yaz. Bugünün satırı yeşil görünür.
B9: 3. Alışkanlıklar sayfasına dön | C9: Toplam gün, bu ay, bu hafta ile hedef, son 30 gün oranı, şimdiki seri ve en uzun seri hesaplanır.
B10: 4. Aylar | C10: Her alışkanlığı her ay kaç gün yaptığını gösterir.
B12: BİLMEN GEREKENLER
B13: Seri | C13: Art arda işaretlenen gün sayısıdır. Bugünü henüz işaretlemediysen dünkü seri gösterilir; dün de boşsa seri sıfırlanır.
B14: Hafta | C14: Hafta pazartesi başlar.
B15: Tek yıl | C15: Bir dosya bir yılı tutar. Yeni yıl için boş bir kopyayla başla.
B16: Kapasite | C16: 15 alışkanlık, bir yıl.
B18: RENKLER
B19: Sarı hücre | C19: Senin dolduracağın hücre. İçindeki örnekleri silip kendi bilgini yaz.
B20: Beyaz hücre, açık başlık | C20: Formül. Değiştirme, kendiliğinden hesaplanır.

Sheet Takip
A1: Takip
A2: Yaptığın günün hücresine 1 yaz. Bugünün satırı yeşil renklidir.
A4: Tarih | B4: Gün | C4: =IF(Alışkanlıklar!A5="","",Alışkanlıklar!A5) -> Yürüyüş (30 dk) | D4: =IF(Alışkanlıklar!A6="","",Alışkanlıklar!A6) -> Kitap okuma (20 sayfa) | E4: =IF(Alışkanlıklar!A7="","",Alışkanlıklar!A7) -> İngilizce çalışma | F4: =IF(Alışkanlıklar!A8="","",Alışkanlıklar!A8) -> Su (2 litre) | G4: =IF(Alışkanlıklar!A9="","",Alışkanlıklar!A9) | H4: =IF(Alışkanlıklar!A10="","",Alışkanlıklar!A10) | I4: =IF(Alışkanlıklar!A11="","",Alışkanlıklar!A11) | J4: =IF(Alışkanlıklar!A12="","",Alışkanlıklar!A12) | K4: =IF(Alışkanlıklar!A13="","",Alışkanlıklar!A13) | L4: =IF(Alışkanlıklar!A14="","",Alışkanlıklar!A14) | M4: =IF(Alışkanlıklar!A15="","",Alışkanlıklar!A15) | N4: =IF(Alışkanlıklar!A16="","",Alışkanlıklar!A16) | O4: =IF(Alışkanlıklar!A17="","",Alışkanlıklar!A17) | P4: =IF(Alışkanlıklar!A18="","",Alışkanlıklar!A18) | Q4: =IF(Alışkanlıklar!A19="","",Alışkanlıklar!A19) | R4: y | S4: y
A6: =DATE(Alışkanlıklar!$K$3,1,1) -> 46023 | B6: =IF(A6="","",CHOOSE(WEEKDAY(A6,2),"Pzt","Sal","Çar","Per","Cum","Cmt","Paz")) -> Per | R6: =IF(A6="",0,A6) -> 46023 | S6: =IF(A6="",0,MONTH(A6)) -> 1
A7: =A6+1 -> 46024 | B7: =IF(A7="","",CHOOSE(WEEKDAY(A7,2),"Pzt","Sal","Çar","Per","Cum","Cmt","Paz")) -> Cum | R7: =IF(A7="",0,A7) -> 46024 | S7: =IF(A7="",0,MONTH(A7)) -> 1
A8: =A7+1 -> 46025 | B8: =IF(A8="","",CHOOSE(WEEKDAY(A8,2),"Pzt","Sal","Çar","Per","Cum","Cmt","Paz")) -> Cmt | R8: =IF(A8="",0,A8) -> 46025 | S8: =IF(A8="",0,MONTH(A8)) -> 1
A9: =A8+1 -> 46026 | B9: =IF(A9="","",CHOOSE(WEEKDAY(A9,2),"Pzt","Sal","Çar","Per","Cum","Cmt","Paz")) -> Paz | R9: =IF(A9="",0,A9) -> 46026 | S9: =IF(A9="",0,MONTH(A9)) -> 1
A10: =A9+1 -> 46027 | B10: =IF(A10="","",CHOOSE(WEEKDAY(A10,2),"Pzt","Sal","Çar","Per","Cum","Cmt","Paz")) -> Pzt | R10: =IF(A10="",0,A10) -> 46027 | S10: =IF(A10="",0,MONTH(A10)) -> 1
A11: =A10+1 -> 46028 | B11: =IF(A11="","",CHOOSE(WEEKDAY(A11,2),"Pzt","Sal","Çar","Per","Cum","Cmt","Paz")) -> Sal | R11: =IF(A11="",0,A11) -> 46028 | S11: =IF(A11="",0,MONTH(A11)) -> 1
A12: =A11+1 -> 46029 | B12: =IF(A12="","",CHOOSE(WEEKDAY(A12,2),"Pzt","Sal","Çar","Per","Cum","Cmt","Paz")) -> Çar | R12: =IF(A12="",0,A12) -> 46029 | S12: =IF(A12="",0,MONTH(A12)) -> 1
A13: =A12+1 -> 46030 | B13: =IF(A13="","",CHOOSE(WEEKDAY(A13,2),"Pzt","Sal","Çar","Per","Cum","Cmt","Paz")) -> Per | R13: =IF(A13="",0,A13) -> 46030 | S13: =IF(A13="",0,MONTH(A13)) -> 1
A14: =A13+1 -> 46031 | B14: =IF(A14="","",CHOOSE(WEEKDAY(A14,2),"Pzt","Sal","Çar","Per","Cum","Cmt","Paz")) -> Cum | R14: =IF(A14="",0,A14) -> 46031 | S14: =IF(A14="",0,MONTH(A14)) -> 1
A15: =A14+1 -> 46032 | B15: =IF(A15="","",CHOOSE(WEEKDAY(A15,2),"Pzt","Sal","Çar","Per","Cum","Cmt","Paz")) -> Cmt | R15: =IF(A15="",0,A15) -> 46032 | S15: =IF(A15="",0,MONTH(A15)) -> 1
A16: =A15+1 -> 46033 | B16: =IF(A16="","",CHOOSE(WEEKDAY(A16,2),"Pzt","Sal","Çar","Per","Cum","Cmt","Paz")) -> Paz | R16: =IF(A16="",0,A16) -> 46033 | S16: =IF(A16="",0,MONTH(A16)) -> 1
A17: =A16+1 -> 46034 | B17: =IF(A17="","",CHOOSE(WEEKDAY(A17,2),"Pzt","Sal","Çar","Per","Cum","Cmt","Paz")) -> Pzt | R17: =IF(A17="",0,A17) -> 46034 | S17: =IF(A17="",0,MONTH(A17)) -> 1
A18: =A17+1 -> 46035 | B18: =IF(A18="","",CHOOSE(WEEKDAY(A18,2),"Pzt","Sal","Çar","Per","Cum","Cmt","Paz")) -> Sal | R18: =IF(A18="",0,A18) -> 46035 | S18: =IF(A18="",0,MONTH(A18)) -> 1
... A254: =A253+1 -> 46271 | B254: =IF(A254="","",CHOOSE(WEEKDAY(A254,2),"Pzt","Sal","Çar","Per","Cum","Cmt","Paz")) -> Paz | R254: =IF(A254="",0,A254) -> 46271 | S254: =IF(A254="",0,MONTH(A254)) -> 9
A255: =A254+1 -> 46272 | B255: =IF(A255="","",CHOOSE(WEEKDAY(A255,2),"Pzt","Sal","Çar","Per","Cum","Cmt","Paz")) -> Pzt | C255: 1 | D255: 1 | E255: 1 | R255: =IF(A255="",0,A255) -> 46272 | S255: =IF(A255="",0,MONTH(A255)) -> 9
A256: =A255+1 -> 46273 | B256: =IF(A256="","",CHOOSE(WEEKDAY(A256,2),"Pzt","Sal","Çar","Per","Cum","Cmt","Paz")) -> Sal | C256: 1 | D256: 1 | F256: 1 | R256: =IF(A256="",0,A256) -> 46273 | S256: =IF(A256="",0,MONTH(A256)) -> 9
A257: =A256+1 -> 46274 | B257: =IF(A257="","",CHOOSE(WEEKDAY(A257,2),"Pzt","Sal","Çar","Per","Cum","Cmt","Paz")) -> Çar | C257: 1 | D257: 1 | E257: 1 | F257: 1 | R257: =IF(A257="",0,A257) -> 46274 | S257: =IF(A257="",0,MONTH(A257)) -> 9
A258: =A257+1 -> 46275 | B258: =IF(A258="","",CHOOSE(WEEKDAY(A258,2),"Pzt","Sal","Çar","Per","Cum","Cmt","Paz")) -> Per | C258: 1 | D258: 1 | R258: =IF(A258="",0,A258) -> 46275 | S258: =IF(A258="",0,MONTH(A258)) -> 9
A259: =A258+1 -> 46276 | B259: =IF(A259="","",CHOOSE(WEEKDAY(A259,2),"Pzt","Sal","Çar","Per","Cum","Cmt","Paz")) -> Cum | C259: 1 | D259: 1 | E259: 1 | F259: 1 | R259: =IF(A259="",0,A259) -> 46276 | S259: =IF(A259="",0,MONTH(A259)) -> 9
A260: =A259+1 -> 46277 | B260: =IF(A260="","",CHOOSE(WEEKDAY(A260,2),"Pzt","Sal","Çar","Per","Cum","Cmt","Paz")) -> Cmt | D260: 1 | F260: 1 | R260: =IF(A260="",0,A260) -> 46277 | S260: =IF(A260="",0,MONTH(A260)) -> 9
A261: =A260+1 -> 46278 | B261: =IF(A261="","",CHOOSE(WEEKDAY(A261,2),"Pzt","Sal","Çar","Per","Cum","Cmt","Paz")) -> Paz | C261: 1 | D261: 1 | R261: =IF(A261="",0,A261) -> 46278 | S261: =IF(A261="",0,MONTH(A261)) -> 9
A262: =A261+1 -> 46279 | B262: =IF(A262="","",CHOOSE(WEEKDAY(A262,2),"Pzt","Sal","Çar","Per","Cum","Cmt","Paz")) -> Pzt | C262: 1 | D262: 1 | E262: 1 | F262: 1 | R262: =IF(A262="",0,A262) -> 46279 | S262: =IF(A262="",0,MONTH(A262)) -> 9
A263: =A262+1 -> 46280 | B263: =IF(A263="","",CHOOSE(WEEKDAY(A263,2),"Pzt","Sal","Çar","Per","Cum","Cmt","Paz")) -> Sal | C263: 1 | D263: 1 | F263: 1 | R263: =IF(A263="",0,A263) -> 46280 | S263: =IF(A263="",0,MONTH(A263)) -> 9
A264: =A263+1 -> 46281 | B264: =IF(A264="","",CHOOSE(WEEKDAY(A264,2),"Pzt","Sal","Çar","Per","Cum","Cmt","Paz")) -> Çar | C264: 1 | D264: 1 | E264: 1 | R264: =IF(A264="",0,A264) -> 46281 | S264: =IF(A264="",0,MONTH(A264)) -> 9
A265: =A264+1 -> 46282 | B265: =IF(A265="","",CHOOSE(WEEKDAY(A265,2),"Pzt","Sal","Çar","Per","Cum","Cmt","Paz")) -> Per | C265: 1 | D265: 1 | F265: 1 | R265: =IF(A265="",0,A265) -> 46282 | S265: =IF(A265="",0,MONTH(A265)) -> 9
A266: =A265+1 -> 46283 | B266: =IF(A266="","",CHOOSE(WEEKDAY(A266,2),"Pzt","Sal","Çar","Per","Cum","Cmt","Paz")) -> Cum | C266: 1 | D266: 1 | E266: 1 | F266: 1 | R266: =IF(A266="",0,A266) -> 46283 | S266: =IF(A266="",0,MONTH(A266)) -> 9
A267: =A266+1 -> 46284 | B267: =IF(A267="","",CHOOSE(WEEKDAY(A267,2),"Pzt","Sal","Çar","Per","Cum","Cmt","Paz")) -> Cmt | D267: 1 | R267: =IF(A267="",0,A267) -> 46284 | S267: =IF(A267="",0,MONTH(A267)) -> 9
A268: =A267+1 -> 46285 | B268: =IF(A268="","",CHOOSE(WEEKDAY(A268,2),"Pzt","Sal","Çar","Per","Cum","Cmt","Paz")) -> Paz | C268: 1 | D268: 1 | F268: 1 | R268: =IF(A268="",0,A268) -> 46285 | S268: =IF(A268="",0,MONTH(A268)) -> 9
A269: =A268+1 -> 46286 | B269: =IF(A269="","",CHOOSE(WEEKDAY(A269,2),"Pzt","Sal","Çar","Per","Cum","Cmt","Paz")) -> Pzt | C269: 1 | D269: 1 | E269: 1 | F269: 1 | R269: =IF(A269="",0,A269) -> 46286 | S269: =IF(A269="",0,MONTH(A269)) -> 9
A270: =A269+1 -> 46287 | B270: =IF(A270="","",CHOOSE(WEEKDAY(A270,2),"Pzt","Sal","Çar","Per","Cum","Cmt","Paz")) -> Sal | C270: 1 | D270: 1 | R270: =IF(A270="",0,A270) -> 46287 | S270: =IF(A270="",0,MONTH(A270)) -> 9
A271: =A270+1 -> 46288 | B271: =IF(A271="","",CHOOSE(WEEKDAY(A271,2),"Pzt","Sal","Çar","Per","Cum","Cmt","Paz")) -> Çar | C271: 1 | D271: 1 | E271: 1 | F271: 1 | R271: =IF(A271="",0,A271) -> 46288 | S271: =IF(A271="",0,MONTH(A271)) -> 9
A272: =A271+1 -> 46289 | B272: =IF(A272="","",CHOOSE(WEEKDAY(A272,2),"Pzt","Sal","Çar","Per","Cum","Cmt","Paz")) -> Per | C272: 1 | D272: 1 | F272: 1 | R272: =IF(A272="",0,A272) -> 46289 | S272: =IF(A272="",0,MONTH(A272)) -> 9
A273: =A272+1 -> 46290 | B273: =IF(A273="","",CHOOSE(WEEKDAY(A273,2),"Pzt","Sal","Çar","Per","Cum","Cmt","Paz")) -> Cum | C273: 1 | D273: 1 | E273: 1 | R273: =IF(A273="",0,A273) -> 46290 | S273: =IF(A273="",0,MONTH(A273)) -> 9
A274: =A273+1 -> 46291 | B274: =IF(A274="","",CHOOSE(WEEKDAY(A274,2),"Pzt","Sal","Çar","Per","Cum","Cmt","Paz")) -> Cmt | D274: 1 | F274: 1 | R274: =IF(A274="",0,A274) -> 46291 | S274: =IF(A274="",0,MONTH(A274)) -> 9
A275: =A274+1 -> 46292 | B275: =IF(A275="","",CHOOSE(WEEKDAY(A275,2),"Pzt","Sal","Çar","Per","Cum","Cmt","Paz")) -> Paz | C275: 1 | D275: 1 | F275: 1 | R275: =IF(A275="",0,A275) -> 46292 | S275: =IF(A275="",0,MONTH(A275)) -> 9
A276: =A275+1 -> 46293 | B276: =IF(A276="","",CHOOSE(WEEKDAY(A276,2),"Pzt","Sal","Çar","Per","Cum","Cmt","Paz")) -> Pzt | C276: 1 | D276: 1 | E276: 1 | R276: =IF(A276="",0,A276) -> 46293 | S276: =IF(A276="",0,MONTH(A276)) -> 9
A277: =A276+1 -> 46294 | B277: =IF(A277="","",CHOOSE(WEEKDAY(A277,2),"Pzt","Sal","Çar","Per","Cum","Cmt","Paz")) -> Sal | C277: 1 | D277: 1 | F277: 1 | R277: =IF(A277="",0,A277) -> 46294 | S277: =IF(A277="",0,MONTH(A277)) -> 9
...

Sheet Alışkanlıklar
A1: Alışkanlıklar
A2: Yılı ve takip edeceğin alışkanlıkları yaz. Gerisi Takip sayfasındaki işaretlerinden hesaplanır.
J3: Yıl | K3: 2026
A4: Alışkanlık | B4: Haftalık hedef (gün) | C4: Toplam gün | D4: Bu ay | E4: Bu hafta | F4: Son 30 gün | G4: Şimdiki seri | H4: En uzun seri
A5: Yürüyüş (30 dk) | B5: 5 | C5: =IF(A5="","",COUNT(Takip!$C$6:$C$371)) -> 24 | D5: =IF(A5="","",SUMPRODUCT((Takip!$S$6:$S$371=MONTH(TODAY()))*(Takip!$R$6:$R$371<=TODAY())*(Takip!$C$6:$C$371<>""))) -> 3 | E5: =IF(A5="","",SUMPRODUCT((Takip!$R$6:$R$371>=TODAY()-WEEKDAY(TODAY(),2)+1)*(Takip!$R$6:$R$371<=TODAY())*(Takip!$C$6:$C$371<>""))&" / "&B5) -> 6 / 5 | F5: =IF(A5="","",SUMPRODUCT((Takip!$R$6:$R$371>TODAY()-30)*(Takip!$R$6:$R$371<=TODAY())*(Takip!$C$6:$C$371<>""))/30) -> 0.8 | G5: =IF(A5="","",IFERROR(IF(INDEX(Takip!$C$6:$C$371,MATCH(TODAY(),Takip!$R$6:$R$371,0))<>"",INDEX(Seri!$C$6:$C$371,MATCH(TODAY(),Takip!$R$6:$R$371,0)),IF(MATCH(TODAY(),Takip!$R$6:$R$371,0)=1,0,INDEX(Seri!$C$6:$C$371,MATCH(TODAY(),Takip!$R$6:$R$371,0)-1))),0)) -> 1 | H5: =IF(A5="","",MAX(Seri!$C$6:$C$371)) -> 6
A6: Kitap okuma (20 sayfa) | B6: 7 | C6: =IF(A6="","",COUNT(Takip!$D$6:$D$371)) -> 28 | D6: =IF(A6="","",SUMPRODUCT((Takip!$S$6:$S$371=MONTH(TODAY()))*(Takip!$R$6:$R$371<=TODAY())*(Takip!$D$6:$D$371<>""))) -> 4 | E6: =IF(A6="","",SUMPRODUCT((Takip!$R$6:$R$371>=TODAY()-WEEKDAY(TODAY(),2)+1)*(Takip!$R$6:$R$371<=TODAY())*(Takip!$D$6:$D$371<>""))&" / "&B6) -> 7 / 7 | F6: =IF(A6="","",SUMPRODUCT((Takip!$R$6:$R$371>TODAY()-30)*(Takip!$R$6:$R$371<=TODAY())*(Takip!$D$6:$D$371<>""))/30) -> 0.93333333 | G6: =IF(A6="","",IFERROR(IF(INDEX(Takip!$D$6:$D$371,MATCH(TODAY(),Takip!$R$6:$R$371,0))<>"",INDEX(Seri!$D$6:$D$371,MATCH(TODAY(),Takip!$R$6:$R$371,0)),IF(MATCH(TODAY(),Takip!$R$6:$R$371,0)=1,0,INDEX(Seri!$D$6:$D$371,MATCH(TODAY(),Takip!$R$6:$R$371,0)-1))),0)) -> 28 | H6: =IF(A6="","",MAX(Seri!$D$6:$D$371)) -> 28
A7: İngilizce çalışma | B7: 4 | C7: =IF(A7="","",COUNT(Takip!$E$6:$E$371)) -> 12 | D7: =IF(A7="","",SUMPRODUCT((Takip!$S$6:$S$371=MONTH(TODAY()))*(Takip!$R$6:$R$371<=TODAY())*(Takip!$E$6:$E$371<>""))) -> 1 | E7: =IF(A7="","",SUMPRODUCT((Takip!$R$6:$R$371>=TODAY()-WEEKDAY(TODAY(),2)+1)*(Takip!$R$6:$R$371<=TODAY())*(Takip!$E$6:$E$371<>""))&" / "&B7) -> 3 / 4 | F7: =IF(A7="","",SUMPRODUCT((Takip!$R$6:$R$371>TODAY()-30)*(Takip!$R$6:$R$371<=TODAY())*(Takip!$E$6:$E$371<>""))/30) -> 0.4 | G7: =IF(A7="","",IFERROR(IF(INDEX(Takip!$E$6:$E$371,MATCH(TODAY(),Takip!$R$6:$R$371,0))<>"",INDEX(Seri!$E$6:$E$371,MATCH(TODAY(),Takip!$R$6:$R$371,0)),IF(MATCH(TODAY(),Takip!$R$6:$R$371,0)=1,0,INDEX(Seri!$E$6:$E$371,MATCH(TODAY(),Takip!$R$6:$R$371,0)-1))),0)) -> 0 | H7: =IF(A7="","",MAX(Seri!$E$6:$E$371)) -> 1
A8: Su (2 litre) | B8: 7 | C8: =IF(A8="","",COUNT(Takip!$F$6:$F$371)) -> 18 | D8: =IF(A8="","",SUMPRODUCT((Takip!$S$6:$S$371=MONTH(TODAY()))*(Takip!$R$6:$R$371<=TODAY())*(Takip!$F$6:$F$371<>""))) -> 2 | E8: =IF(A8="","",SUMPRODUCT((Takip!$R$6:$R$371>=TODAY()-WEEKDAY(TODAY(),2)+1)*(Takip!$R$6:$R$371<=TODAY())*(Takip!$F$6:$F$371<>""))&" / "&B8) -> 4 / 7 | F8: =IF(A8="","",SUMPRODUCT((Takip!$R$6:$R$371>TODAY()-30)*(Takip!$R$6:$R$371<=TODAY())*(Takip!$F$6:$F$371<>""))/30) -> 0.6 | G8: =IF(A8="","",IFERROR(IF(INDEX(Takip!$F$6:$F$371,MATCH(TODAY(),Takip!$R$6:$R$371,0))<>"",INDEX(Seri!$F$6:$F$371,MATCH(TODAY(),Takip!$R$6:$R$371,0)),IF(MATCH(TODAY(),Takip!$R$6:$R$371,0)=1,0,INDEX(Seri!$F$6:$F$371,MATCH(TODAY(),Takip!$R$6:$R$371,0)-1))),0)) -> 2 | H8: =IF(A8="","",MAX(Seri!$F$6:$F$371)) -> 2
C9: =IF(A9="","",COUNT(Takip!$G$6:$G$371)) | D9: =IF(A9="","",SUMPRODUCT((Takip!$S$6:$S$371=MONTH(TODAY()))*(Takip!$R$6:$R$371<=TODAY())*(Takip!$G$6:$G$371<>""))) | E9: =IF(A9="","",SUMPRODUCT((Takip!$R$6:$R$371>=TODAY()-WEEKDAY(TODAY(),2)+1)*(Takip!$R$6:$R$371<=TODAY())*(Takip!$G$6:$G$371<>""))&" / "&B9) | F9: =IF(A9="","",SUMPRODUCT((Takip!$R$6:$R$371>TODAY()-30)*(Takip!$R$6:$R$371<=TODAY())*(Takip!$G$6:$G$371<>""))/30) | G9: =IF(A9="","",IFERROR(IF(INDEX(Takip!$G$6:$G$371,MATCH(TODAY(),Takip!$R$6:$R$371,0))<>"",INDEX(Seri!$G$6:$G$371,MATCH(TODAY(),Takip!$R$6:$R$371,0)),IF(MATCH(TODAY(),Takip!$R$6:$R$371,0)=1,0,INDEX(Seri!$G$6:$G$371,MATCH(TODAY(),Takip!$R$6:$R$371,0)-1))),0)) | H9: =IF(A9="","",MAX(Seri!$G$6:$G$371))
C10: =IF(A10="","",COUNT(Takip!$H$6:$H$371)) | D10: =IF(A10="","",SUMPRODUCT((Takip!$S$6:$S$371=MONTH(TODAY()))*(Takip!$R$6:$R$371<=TODAY())*(Takip!$H$6:$H$371<>""))) | E10: =IF(A10="","",SUMPRODUCT((Takip!$R$6:$R$371>=TODAY()-WEEKDAY(TODAY(),2)+1)*(Takip!$R$6:$R$371<=TODAY())*(Takip!$H$6:$H$371<>""))&" / "&B10) | F10: =IF(A10="","",SUMPRODUCT((Takip!$R$6:$R$371>TODAY()-30)*(Takip!$R$6:$R$371<=TODAY())*(Takip!$H$6:$H$371<>""))/30) | G10: =IF(A10="","",IFERROR(IF(INDEX(Takip!$H$6:$H$371,MATCH(TODAY(),Takip!$R$6:$R$371,0))<>"",INDEX(Seri!$H$6:$H$371,MATCH(TODAY(),Takip!$R$6:$R$371,0)),IF(MATCH(TODAY(),Takip!$R$6:$R$371,0)=1,0,INDEX(Seri!$H$6:$H$371,MATCH(TODAY(),Takip!$R$6:$R$371,0)-1))),0)) | H10: =IF(A10="","",MAX(Seri!$H$6:$H$371))
C11: =IF(A11="","",COUNT(Takip!$I$6:$I$371)) | D11: =IF(A11="","",SUMPRODUCT((Takip!$S$6:$S$371=MONTH(TODAY()))*(Takip!$R$6:$R$371<=TODAY())*(Takip!$I$6:$I$371<>""))) | E11: =IF(A11="","",SUMPRODUCT((Takip!$R$6:$R$371>=TODAY()-WEEKDAY(TODAY(),2)+1)*(Takip!$R$6:$R$371<=TODAY())*(Takip!$I$6:$I$371<>""))&" / "&B11) | F11: =IF(A11="","",SUMPRODUCT((Takip!$R$6:$R$371>TODAY()-30)*(Takip!$R$6:$R$371<=TODAY())*(Takip!$I$6:$I$371<>""))/30) | G11: =IF(A11="","",IFERROR(IF(INDEX(Takip!$I$6:$I$371,MATCH(TODAY(),Takip!$R$6:$R$371,0))<>"",INDEX(Seri!$I$6:$I$371,MATCH(TODAY(),Takip!$R$6:$R$371,0)),IF(MATCH(TODAY(),Takip!$R$6:$R$371,0)=1,0,INDEX(Seri!$I$6:$I$371,MATCH(TODAY(),Takip!$R$6:$R$371,0)-1))),0)) | H11: =IF(A11="","",MAX(Seri!$I$6:$I$371))
C12: =IF(A12="","",COUNT(Takip!$J$6:$J$371)) | D12: =IF(A12="","",SUMPRODUCT((Takip!$S$6:$S$371=MONTH(TODAY()))*(Takip!$R$6:$R$371<=TODAY())*(Takip!$J$6:$J$371<>""))) | E12: =IF(A12="","",SUMPRODUCT((Takip!$R$6:$R$371>=TODAY()-WEEKDAY(TODAY(),2)+1)*(Takip!$R$6:$R$371<=TODAY())*(Takip!$J$6:$J$371<>""))&" / "&B12) | F12: =IF(A12="","",SUMPRODUCT((Takip!$R$6:$R$371>TODAY()-30)*(Takip!$R$6:$R$371<=TODAY())*(Takip!$J$6:$J$371<>""))/30) | G12: =IF(A12="","",IFERROR(IF(INDEX(Takip!$J$6:$J$371,MATCH(TODAY(),Takip!$R$6:$R$371,0))<>"",INDEX(Seri!$J$6:$J$371,MATCH(TODAY(),Takip!$R$6:$R$371,0)),IF(MATCH(TODAY(),Takip!$R$6:$R$371,0)=1,0,INDEX(Seri!$J$6:$J$371,MATCH(TODAY(),Takip!$R$6:$R$371,0)-1))),0)) | H12: =IF(A12="","",MAX(Seri!$J$6:$J$371))
C13: =IF(A13="","",COUNT(Takip!$K$6:$K$371)) | D13: =IF(A13="","",SUMPRODUCT((Takip!$S$6:$S$371=MONTH(TODAY()))*(Takip!$R$6:$R$371<=TODAY())*(Takip!$K$6:$K$371<>""))) | E13: =IF(A13="","",SUMPRODUCT((Takip!$R$6:$R$371>=TODAY()-WEEKDAY(TODAY(),2)+1)*(Takip!$R$6:$R$371<=TODAY())*(Takip!$K$6:$K$371<>""))&" / "&B13) | F13: =IF(A13="","",SUMPRODUCT((Takip!$R$6:$R$371>TODAY()-30)*(Takip!$R$6:$R$371<=TODAY())*(Takip!$K$6:$K$371<>""))/30) | G13: =IF(A13="","",IFERROR(IF(INDEX(Takip!$K$6:$K$371,MATCH(TODAY(),Takip!$R$6:$R$371,0))<>"",INDEX(Seri!$K$6:$K$371,MATCH(TODAY(),Takip!$R$6:$R$371,0)),IF(MATCH(TODAY(),Takip!$R$6:$R$371,0)=1,0,INDEX(Seri!$K$6:$K$371,MATCH(TODAY(),Takip!$R$6:$R$371,0)-1))),0)) | H13: =IF(A13="","",MAX(Seri!$K$6:$K$371))
C14: =IF(A14="","",COUNT(Takip!$L$6:$L$371)) | D14: =IF(A14="","",SUMPRODUCT((Takip!$S$6:$S$371=MONTH(TODAY()))*(Takip!$R$6:$R$371<=TODAY())*(Takip!$L$6:$L$371<>""))) | E14: =IF(A14="","",SUMPRODUCT((Takip!$R$6:$R$371>=TODAY()-WEEKDAY(TODAY(),2)+1)*(Takip!$R$6:$R$371<=TODAY())*(Takip!$L$6:$L$371<>""))&" / "&B14) | F14: =IF(A14="","",SUMPRODUCT((Takip!$R$6:$R$371>TODAY()-30)*(Takip!$R$6:$R$371<=TODAY())*(Takip!$L$6:$L$371<>""))/30) | G14: =IF(A14="","",IFERROR(IF(INDEX(Takip!$L$6:$L$371,MATCH(TODAY(),Takip!$R$6:$R$371,0))<>"",INDEX(Seri!$L$6:$L$371,MATCH(TODAY(),Takip!$R$6:$R$371,0)),IF(MATCH(TODAY(),Takip!$R$6:$R$371,0)=1,0,INDEX(Seri!$L$6:$L$371,MATCH(TODAY(),Takip!$R$6:$R$371,0)-1))),0)) | H14: =IF(A14="","",MAX(Seri!$L$6:$L$371))
C15: =IF(A15="","",COUNT(Takip!$M$6:$M$371)) | D15: =IF(A15="","",SUMPRODUCT((Takip!$S$6:$S$371=MONTH(TODAY()))*(Takip!$R$6:$R$371<=TODAY())*(Takip!$M$6:$M$371<>""))) | E15: =IF(A15="","",SUMPRODUCT((Takip!$R$6:$R$371>=TODAY()-WEEKDAY(TODAY(),2)+1)*(Takip!$R$6:$R$371<=TODAY())*(Takip!$M$6:$M$371<>""))&" / "&B15) | F15: =IF(A15="","",SUMPRODUCT((Takip!$R$6:$R$371>TODAY()-30)*(Takip!$R$6:$R$371<=TODAY())*(Takip!$M$6:$M$371<>""))/30) | G15: =IF(A15="","",IFERROR(IF(INDEX(Takip!$M$6:$M$371,MATCH(TODAY(),Takip!$R$6:$R$371,0))<>"",INDEX(Seri!$M$6:$M$371,MATCH(TODAY(),Takip!$R$6:$R$371,0)),IF(MATCH(TODAY(),Takip!$R$6:$R$371,0)=1,0,INDEX(Seri!$M$6:$M$371,MATCH(TODAY(),Takip!$R$6:$R$371,0)-1))),0)) | H15: =IF(A15="","",MAX(Seri!$M$6:$M$371))
C16: =IF(A16="","",COUNT(Takip!$N$6:$N$371)) | D16: =IF(A16="","",SUMPRODUCT((Takip!$S$6:$S$371=MONTH(TODAY()))*(Takip!$R$6:$R$371<=TODAY())*(Takip!$N$6:$N$371<>""))) | E16: =IF(A16="","",SUMPRODUCT((Takip!$R$6:$R$371>=TODAY()-WEEKDAY(TODAY(),2)+1)*(Takip!$R$6:$R$371<=TODAY())*(Takip!$N$6:$N$371<>""))&" / "&B16) | F16: =IF(A16="","",SUMPRODUCT((Takip!$R$6:$R$371>TODAY()-30)*(Takip!$R$6:$R$371<=TODAY())*(Takip!$N$6:$N$371<>""))/30) | G16: =IF(A16="","",IFERROR(IF(INDEX(Takip!$N$6:$N$371,MATCH(TODAY(),Takip!$R$6:$R$371,0))<>"",INDEX(Seri!$N$6:$N$371,MATCH(TODAY(),Takip!$R$6:$R$371,0)),IF(MATCH(TODAY(),Takip!$R$6:$R$371,0)=1,0,INDEX(Seri!$N$6:$N$371,MATCH(TODAY(),Takip!$R$6:$R$371,0)-1))),0)) | H16: =IF(A16="","",MAX(Seri!$N$6:$N$371))
C17: =IF(A17="","",COUNT(Takip!$O$6:$O$371)) | D17: =IF(A17="","",SUMPRODUCT((Takip!$S$6:$S$371=MONTH(TODAY()))*(Takip!$R$6:$R$371<=TODAY())*(Takip!$O$6:$O$371<>""))) | E17: =IF(A17="","",SUMPRODUCT((Takip!$R$6:$R$371>=TODAY()-WEEKDAY(TODAY(),2)+1)*(Takip!$R$6:$R$371<=TODAY())*(Takip!$O$6:$O$371<>""))&" / "&B17) | F17: =IF(A17="","",SUMPRODUCT((Takip!$R$6:$R$371>TODAY()-30)*(Takip!$R$6:$R$371<=TODAY())*(Takip!$O$6:$O$371<>""))/30) | G17: =IF(A17="","",IFERROR(IF(INDEX(Takip!$O$6:$O$371,MATCH(TODAY(),Takip!$R$6:$R$371,0))<>"",INDEX(Seri!$O$6:$O$371,MATCH(TODAY(),Takip!$R$6:$R$371,0)),IF(MATCH(TODAY(),Takip!$R$6:$R$371,0)=1,0,INDEX(Seri!$O$6:$O$371,MATCH(TODAY(),Takip!$R$6:$R$371,0)-1))),0)) | H17: =IF(A17="","",MAX(Seri!$O$6:$O$371))
C18: =IF(A18="","",COUNT(Takip!$P$6:$P$371)) | D18: =IF(A18="","",SUMPRODUCT((Takip!$S$6:$S$371=MONTH(TODAY()))*(Takip!$R$6:$R$371<=TODAY())*(Takip!$P$6:$P$371<>""))) | E18: =IF(A18="","",SUMPRODUCT((Takip!$R$6:$R$371>=TODAY()-WEEKDAY(TODAY(),2)+1)*(Takip!$R$6:$R$371<=TODAY())*(Takip!$P$6:$P$371<>""))&" / "&B18) | F18: =IF(A18="","",SUMPRODUCT((Takip!$R$6:$R$371>TODAY()-30)*(Takip!$R$6:$R$371<=TODAY())*(Takip!$P$6:$P$371<>""))/30) | G18: =IF(A18="","",IFERROR(IF(INDEX(Takip!$P$6:$P$371,MATCH(TODAY(),Takip!$R$6:$R$371,0))<>"",INDEX(Seri!$P$6:$P$371,MATCH(TODAY(),Takip!$R$6:$R$371,0)),IF(MATCH(TODAY(),Takip!$R$6:$R$371,0)=1,0,INDEX(Seri!$P$6:$P$371,MATCH(TODAY(),Takip!$R$6:$R$371,0)-1))),0)) | H18: =IF(A18="","",MAX(Seri!$P$6:$P$371))
C19: =IF(A19="","",COUNT(Takip!$Q$6:$Q$371)) | D19: =IF(A19="","",SUMPRODUCT((Takip!$S$6:$S$371=MONTH(TODAY()))*(Takip!$R$6:$R$371<=TODAY())*(Takip!$Q$6:$Q$371<>""))) | E19: =IF(A19="","",SUMPRODUCT((Takip!$R$6:$R$371>=TODAY()-WEEKDAY(TODAY(),2)+1)*(Takip!$R$6:$R$371<=TODAY())*(Takip!$Q$6:$Q$371<>""))&" / "&B19) | F19: =IF(A19="","",SUMPRODUCT((Takip!$R$6:$R$371>TODAY()-30)*(Takip!$R$6:$R$371<=TODAY())*(Takip!$Q$6:$Q$371<>""))/30) | G19: =IF(A19="","",IFERROR(IF(INDEX(Takip!$Q$6:$Q$371,MATCH(TODAY(),Takip!$R$6:$R$371,0))<>"",INDEX(Seri!$Q$6:$Q$371,MATCH(TODAY(),Takip!$R$6:$R$371,0)),IF(MATCH(TODAY(),Takip!$R$6:$R$371,0)=1,0,INDEX(Seri!$Q$6:$Q$371,MATCH(TODAY(),Takip!$R$6:$R$371,0)-1))),0)) | H19: =IF(A19="","",MAX(Seri!$Q$6:$Q$371))

Sheet Aylar
A1: Aylara Göre
A2: Her alışkanlığı her ay kaç gün yaptığın.
A4: Alışkanlık | B4: Oca | C4: Şub | D4: Mar | E4: Nis | F4: May | G4: Haz | H4: Tem | I4: Ağu | J4: Eyl | K4: Eki | L4: Kas | M4: Ara | N4: Toplam
A5: =IF(Alışkanlıklar!A5="","",Alışkanlıklar!A5) -> Yürüyüş (30 dk) | B5: =IF($A5="","",SUMPRODUCT((Takip!$S$6:$S$371=1)*(Takip!$C$6:$C$371<>""))) -> 0 | C5: =IF($A5="","",SUMPRODUCT((Takip!$S$6:$S$371=2)*(Takip!$C$6:$C$371<>""))) -> 0 | D5: =IF($A5="","",SUMPRODUCT((Takip!$S$6:$S$371=3)*(Takip!$C$6:$C$371<>""))) -> 0 | E5: =IF($A5="","",SUMPRODUCT((Takip!$S$6:$S$371=4)*(Takip!$C$6:$C$371<>""))) -> 0 | F5: =IF($A5="","",SUMPRODUCT((Takip!$S$6:$S$371=5)*(Takip!$C$6:$C$371<>""))) -> 0 | G5: =IF($A5="","",SUMPRODUCT((Takip!$S$6:$S$371=6)*(Takip!$C$6:$C$371<>""))) -> 0 | H5: =IF($A5="","",SUMPRODUCT((Takip!$S$6:$S$371=7)*(Takip!$C$6:$C$371<>""))) -> 0 | I5: =IF($A5="","",SUMPRODUCT((Takip!$S$6:$S$371=8)*(Takip!$C$6:$C$371<>""))) -> 0 | J5: =IF($A5="","",SUMPRODUCT((Takip!$S$6:$S$371=9)*(Takip!$C$6:$C$371<>""))) -> 21 | K5: =IF($A5="","",SUMPRODUCT((Takip!$S$6:$S$371=10)*(Takip!$C$6:$C$371<>""))) -> 3 | L5: =IF($A5="","",SUMPRODUCT((Takip!$S$6:$S$371=11)*(Takip!$C$6:$C$371<>""))) -> 0 | M5: =IF($A5="","",SUMPRODUCT((Takip!$S$6:$S$371=12)*(Takip!$C$6:$C$371<>""))) -> 0 | N5: =IF(A5="","",SUM(B5:M5)) -> 24
A6: =IF(Alışkanlıklar!A6="","",Alışkanlıklar!A6) -> Kitap okuma (20 sayfa) | B6: =IF($A6="","",SUMPRODUCT((Takip!$S$6:$S$371=1)*(Takip!$D$6:$D$371<>""))) -> 0 | C6: =IF($A6="","",SUMPRODUCT((Takip!$S$6:$S$371=2)*(Takip!$D$6:$D$371<>""))) -> 0 | D6: =IF($A6="","",SUMPRODUCT((Takip!$S$6:$S$371=3)*(Takip!$D$6:$D$371<>""))) -> 0 | E6: =IF($A6="","",SUMPRODUCT((Takip!$S$6:$S$371=4)*(Takip!$D$6:$D$371<>""))) -> 0 | F6: =IF($A6="","",SUMPRODUCT((Takip!$S$6:$S$371=5)*(Takip!$D$6:$D$371<>""))) -> 0 | G6: =IF($A6="","",SUMPRODUCT((Takip!$S$6:$S$371=6)*(Takip!$D$6:$D$371<>""))) -> 0 | H6: =IF($A6="","",SUMPRODUCT((Takip!$S$6:$S$371=7)*(Takip!$D$6:$D$371<>""))) -> 0 | I6: =IF($A6="","",SUMPRODUCT((Takip!$S$6:$S$371=8)*(Takip!$D$6:$D$371<>""))) -> 0 | J6: =IF($A6="","",SUMPRODUCT((Takip!$S$6:$S$371=9)*(Takip!$D$6:$D$371<>""))) -> 24 | K6: =IF($A6="","",SUMPRODUCT((Takip!$S$6:$S$371=10)*(Takip!$D$6:$D$371<>""))) -> 4 | L6: =IF($A6="","",SUMPRODUCT((Takip!$S$6:$S$371=11)*(Takip!$D$6:$D$371<>""))) -> 0 | M6: =IF($A6="","",SUMPRODUCT((Takip!$S$6:$S$371=12)*(Takip!$D$6:$D$371<>""))) -> 0 | N6: =IF(A6="","",SUM(B6:M6)) -> 28
A7: =IF(Alışkanlıklar!A7="","",Alışkanlıklar!A7) -> İngilizce çalışma | B7: =IF($A7="","",SUMPRODUCT((Takip!$S$6:$S$371=1)*(Takip!$E$6:$E$371<>""))) -> 0 | C7: =IF($A7="","",SUMPRODUCT((Takip!$S$6:$S$371=2)*(Takip!$E$6:$E$371<>""))) -> 0 | D7: =IF($A7="","",SUMPRODUCT((Takip!$S$6:$S$371=3)*(Takip!$E$6:$E$371<>""))) -> 0 | E7: =IF($A7="","",SUMPRODUCT((Takip!$S$6:$S$371=4)*(Takip!$E$6:$E$371<>""))) -> 0 | F7: =IF($A7="","",SUMPRODUCT((Takip!$S$6:$S$371=5)*(Takip!$E$6:$E$371<>""))) -> 0 | G7: =IF($A7="","",SUMPRODUCT((Takip!$S$6:$S$371=6)*(Takip!$E$6:$E$371<>""))) -> 0 | H7: =IF($A7="","",SUMPRODUCT((Takip!$S$6:$S$371=7)*(Takip!$E$6:$E$371<>""))) -> 0 | I7: =IF($A7="","",SUMPRODUCT((Takip!$S$6:$S$371=8)*(Takip!$E$6:$E$371<>""))) -> 0 | J7: =IF($A7="","",SUMPRODUCT((Takip!$S$6:$S$371=9)*(Takip!$E$6:$E$371<>""))) -> 11 | K7: =IF($A7="","",SUMPRODUCT((Takip!$S$6:$S$371=10)*(Takip!$E$6:$E$371<>""))) -> 1 | L7: =IF($A7="","",SUMPRODUCT((Takip!$S$6:$S$371=11)*(Takip!$E$6:$E$371<>""))) -> 0 | M7: =IF($A7="","",SUMPRODUCT((Takip!$S$6:$S$371=12)*(Takip!$E$6:$E$371<>""))) -> 0 | N7: =IF(A7="","",SUM(B7:M7)) -> 12
A8: =IF(Alışkanlıklar!A8="","",Alışkanlıklar!A8) -> Su (2 litre) | B8: =IF($A8="","",SUMPRODUCT((Takip!$S$6:$S$371=1)*(Takip!$F$6:$F$371<>""))) -> 0 | C8: =IF($A8="","",SUMPRODUCT((Takip!$S$6:$S$371=2)*(Takip!$F$6:$F$371<>""))) -> 0 | D8: =IF($A8="","",SUMPRODUCT((Takip!$S$6:$S$371=3)*(Takip!$F$6:$F$371<>""))) -> 0 | E8: =IF($A8="","",SUMPRODUCT((Takip!$S$6:$S$371=4)*(Takip!$F$6:$F$371<>""))) -> 0 | F8: =IF($A8="","",SUMPRODUCT((Takip!$S$6:$S$371=5)*(Takip!$F$6:$F$371<>""))) -> 0 | G8: =IF($A8="","",SUMPRODUCT((Takip!$S$6:$S$371=6)*(Takip!$F$6:$F$371<>""))) -> 0 | H8: =IF($A8="","",SUMPRODUCT((Takip!$S$6:$S$371=7)*(Takip!$F$6:$F$371<>""))) -> 0 | I8: =IF($A8="","",SUMPRODUCT((Takip!$S$6:$S$371=8)*(Takip!$F$6:$F$371<>""))) -> 0 | J8: =IF($A8="","",SUMPRODUCT((Takip!$S$6:$S$371=9)*(Takip!$F$6:$F$371<>""))) -> 16 | K8: =IF($A8="","",SUMPRODUCT((Takip!$S$6:$S$371=10)*(Takip!$F$6:$F$371<>""))) -> 2 | L8: =IF($A8="","",SUMPRODUCT((Takip!$S$6:$S$371=11)*(Takip!$F$6:$F$371<>""))) -> 0 | M8: =IF($A8="","",SUMPRODUCT((Takip!$S$6:$S$371=12)*(Takip!$F$6:$F$371<>""))) -> 0 | N8: =IF(A8="","",SUM(B8:M8)) -> 18
A9: =IF(Alışkanlıklar!A9="","",Alışkanlıklar!A9) | B9: =IF($A9="","",SUMPRODUCT((Takip!$S$6:$S$371=1)*(Takip!$G$6:$G$371<>""))) | C9: =IF($A9="","",SUMPRODUCT((Takip!$S$6:$S$371=2)*(Takip!$G$6:$G$371<>""))) | D9: =IF($A9="","",SUMPRODUCT((Takip!$S$6:$S$371=3)*(Takip!$G$6:$G$371<>""))) | E9: =IF($A9="","",SUMPRODUCT((Takip!$S$6:$S$371=4)*(Takip!$G$6:$G$371<>""))) | F9: =IF($A9="","",SUMPRODUCT((Takip!$S$6:$S$371=5)*(Takip!$G$6:$G$371<>""))) | G9: =IF($A9="","",SUMPRODUCT((Takip!$S$6:$S$371=6)*(Takip!$G$6:$G$371<>""))) | H9: =IF($A9="","",SUMPRODUCT((Takip!$S$6:$S$371=7)*(Takip!$G$6:$G$371<>""))) | I9: =IF($A9="","",SUMPRODUCT((Takip!$S$6:$S$371=8)*(Takip!$G$6:$G$371<>""))) | J9: =IF($A9="","",SUMPRODUCT((Takip!$S$6:$S$371=9)*(Takip!$G$6:$G$371<>""))) | K9: =IF($A9="","",SUMPRODUCT((Takip!$S$6:$S$371=10)*(Takip!$G$6:$G$371<>""))) | L9: =IF($A9="","",SUMPRODUCT((Takip!$S$6:$S$371=11)*(Takip!$G$6:$G$371<>""))) | M9: =IF($A9="","",SUMPRODUCT((Takip!$S$6:$S$371=12)*(Takip!$G$6:$G$371<>""))) | N9: =IF(A9="","",SUM(B9:M9))
A10: =IF(Alışkanlıklar!A10="","",Alışkanlıklar!A10) | B10: =IF($A10="","",SUMPRODUCT((Takip!$S$6:$S$371=1)*(Takip!$H$6:$H$371<>""))) | C10: =IF($A10="","",SUMPRODUCT((Takip!$S$6:$S$371=2)*(Takip!$H$6:$H$371<>""))) | D10: =IF($A10="","",SUMPRODUCT((Takip!$S$6:$S$371=3)*(Takip!$H$6:$H$371<>""))) | E10: =IF($A10="","",SUMPRODUCT((Takip!$S$6:$S$371=4)*(Takip!$H$6:$H$371<>""))) | F10: =IF($A10="","",SUMPRODUCT((Takip!$S$6:$S$371=5)*(Takip!$H$6:$H$371<>""))) | G10: =IF($A10="","",SUMPRODUCT((Takip!$S$6:$S$371=6)*(Takip!$H$6:$H$371<>""))) | H10: =IF($A10="","",SUMPRODUCT((Takip!$S$6:$S$371=7)*(Takip!$H$6:$H$371<>""))) | I10: =IF($A10="","",SUMPRODUCT((Takip!$S$6:$S$371=8)*(Takip!$H$6:$H$371<>""))) | J10: =IF($A10="","",SUMPRODUCT((Takip!$S$6:$S$371=9)*(Takip!$H$6:$H$371<>""))) | K10: =IF($A10="","",SUMPRODUCT((Takip!$S$6:$S$371=10)*(Takip!$H$6:$H$371<>""))) | L10: =IF($A10="","",SUMPRODUCT((Takip!$S$6:$S$371=11)*(Takip!$H$6:$H$371<>""))) | M10: =IF($A10="","",SUMPRODUCT((Takip!$S$6:$S$371=12)*(Takip!$H$6:$H$371<>""))) | N10: =IF(A10="","",SUM(B10:M10))
A11: =IF(Alışkanlıklar!A11="","",Alışkanlıklar!A11) | B11: =IF($A11="","",SUMPRODUCT((Takip!$S$6:$S$371=1)*(Takip!$I$6:$I$371<>""))) | C11: =IF($A11="","",SUMPRODUCT((Takip!$S$6:$S$371=2)*(Takip!$I$6:$I$371<>""))) | D11: =IF($A11="","",SUMPRODUCT((Takip!$S$6:$S$371=3)*(Takip!$I$6:$I$371<>""))) | E11: =IF($A11="","",SUMPRODUCT((Takip!$S$6:$S$371=4)*(Takip!$I$6:$I$371<>""))) | F11: =IF($A11="","",SUMPRODUCT((Takip!$S$6:$S$371=5)*(Takip!$I$6:$I$371<>""))) | G11: =IF($A11="","",SUMPRODUCT((Takip!$S$6:$S$371=6)*(Takip!$I$6:$I$371<>""))) | H11: =IF($A11="","",SUMPRODUCT((Takip!$S$6:$S$371=7)*(Takip!$I$6:$I$371<>""))) | I11: =IF($A11="","",SUMPRODUCT((Takip!$S$6:$S$371=8)*(Takip!$I$6:$I$371<>""))) | J11: =IF($A11="","",SUMPRODUCT((Takip!$S$6:$S$371=9)*(Takip!$I$6:$I$371<>""))) | K11: =IF($A11="","",SUMPRODUCT((Takip!$S$6:$S$371=10)*(Takip!$I$6:$I$371<>""))) | L11: =IF($A11="","",SUMPRODUCT((Takip!$S$6:$S$371=11)*(Takip!$I$6:$I$371<>""))) | M11: =IF($A11="","",SUMPRODUCT((Takip!$S$6:$S$371=12)*(Takip!$I$6:$I$371<>""))) | N11: =IF(A11="","",SUM(B11:M11))
A12: =IF(Alışkanlıklar!A12="","",Alışkanlıklar!A12) | B12: =IF($A12="","",SUMPRODUCT((Takip!$S$6:$S$371=1)*(Takip!$J$6:$J$371<>""))) | C12: =IF($A12="","",SUMPRODUCT((Takip!$S$6:$S$371=2)*(Takip!$J$6:$J$371<>""))) | D12: =IF($A12="","",SUMPRODUCT((Takip!$S$6:$S$371=3)*(Takip!$J$6:$J$371<>""))) | E12: =IF($A12="","",SUMPRODUCT((Takip!$S$6:$S$371=4)*(Takip!$J$6:$J$371<>""))) | F12: =IF($A12="","",SUMPRODUCT((Takip!$S$6:$S$371=5)*(Takip!$J$6:$J$371<>""))) | G12: =IF($A12="","",SUMPRODUCT((Takip!$S$6:$S$371=6)*(Takip!$J$6:$J$371<>""))) | H12: =IF($A12="","",SUMPRODUCT((Takip!$S$6:$S$371=7)*(Takip!$J$6:$J$371<>""))) | I12: =IF($A12="","",SUMPRODUCT((Takip!$S$6:$S$371=8)*(Takip!$J$6:$J$371<>""))) | J12: =IF($A12="","",SUMPRODUCT((Takip!$S$6:$S$371=9)*(Takip!$J$6:$J$371<>""))) | K12: =IF($A12="","",SUMPRODUCT((Takip!$S$6:$S$371=10)*(Takip!$J$6:$J$371<>""))) | L12: =IF($A12="","",SUMPRODUCT((Takip!$S$6:$S$371=11)*(Takip!$J$6:$J$371<>""))) | M12: =IF($A12="","",SUMPRODUCT((Takip!$S$6:$S$371=12)*(Takip!$J$6:$J$371<>""))) | N12: =IF(A12="","",SUM(B12:M12))
A13: =IF(Alışkanlıklar!A13="","",Alışkanlıklar!A13) | B13: =IF($A13="","",SUMPRODUCT((Takip!$S$6:$S$371=1)*(Takip!$K$6:$K$371<>""))) | C13: =IF($A13="","",SUMPRODUCT((Takip!$S$6:$S$371=2)*(Takip!$K$6:$K$371<>""))) | D13: =IF($A13="","",SUMPRODUCT((Takip!$S$6:$S$371=3)*(Takip!$K$6:$K$371<>""))) | E13: =IF($A13="","",SUMPRODUCT((Takip!$S$6:$S$371=4)*(Takip!$K$6:$K$371<>""))) | F13: =IF($A13="","",SUMPRODUCT((Takip!$S$6:$S$371=5)*(Takip!$K$6:$K$371<>""))) | G13: =IF($A13="","",SUMPRODUCT((Takip!$S$6:$S$371=6)*(Takip!$K$6:$K$371<>""))) | H13: =IF($A13="","",SUMPRODUCT((Takip!$S$6:$S$371=7)*(Takip!$K$6:$K$371<>""))) | I13: =IF($A13="","",SUMPRODUCT((Takip!$S$6:$S$371=8)*(Takip!$K$6:$K$371<>""))) | J13: =IF($A13="","",SUMPRODUCT((Takip!$S$6:$S$371=9)*(Takip!$K$6:$K$371<>""))) | K13: =IF($A13="","",SUMPRODUCT((Takip!$S$6:$S$371=10)*(Takip!$K$6:$K$371<>""))) | L13: =IF($A13="","",SUMPRODUCT((Takip!$S$6:$S$371=11)*(Takip!$K$6:$K$371<>""))) | M13: =IF($A13="","",SUMPRODUCT((Takip!$S$6:$S$371=12)*(Takip!$K$6:$K$371<>""))) | N13: =IF(A13="","",SUM(B13:M13))
A14: =IF(Alışkanlıklar!A14="","",Alışkanlıklar!A14) | B14: =IF($A14="","",SUMPRODUCT((Takip!$S$6:$S$371=1)*(Takip!$L$6:$L$371<>""))) | C14: =IF($A14="","",SUMPRODUCT((Takip!$S$6:$S$371=2)*(Takip!$L$6:$L$371<>""))) | D14: =IF($A14="","",SUMPRODUCT((Takip!$S$6:$S$371=3)*(Takip!$L$6:$L$371<>""))) | E14: =IF($A14="","",SUMPRODUCT((Takip!$S$6:$S$371=4)*(Takip!$L$6:$L$371<>""))) | F14: =IF($A14="","",SUMPRODUCT((Takip!$S$6:$S$371=5)*(Takip!$L$6:$L$371<>""))) | G14: =IF($A14="","",SUMPRODUCT((Takip!$S$6:$S$371=6)*(Takip!$L$6:$L$371<>""))) | H14: =IF($A14="","",SUMPRODUCT((Takip!$S$6:$S$371=7)*(Takip!$L$6:$L$371<>""))) | I14: =IF($A14="","",SUMPRODUCT((Takip!$S$6:$S$371=8)*(Takip!$L$6:$L$371<>""))) | J14: =IF($A14="","",SUMPRODUCT((Takip!$S$6:$S$371=9)*(Takip!$L$6:$L$371<>""))) | K14: =IF($A14="","",SUMPRODUCT((Takip!$S$6:$S$371=10)*(Takip!$L$6:$L$371<>""))) | L14: =IF($A14="","",SUMPRODUCT((Takip!$S$6:$S$371=11)*(Takip!$L$6:$L$371<>""))) | M14: =IF($A14="","",SUMPRODUCT((Takip!$S$6:$S$371=12)*(Takip!$L$6:$L$371<>""))) | N14: =IF(A14="","",SUM(B14:M14))
A15: =IF(Alışkanlıklar!A15="","",Alışkanlıklar!A15) | B15: =IF($A15="","",SUMPRODUCT((Takip!$S$6:$S$371=1)*(Takip!$M$6:$M$371<>""))) | C15: =IF($A15="","",SUMPRODUCT((Takip!$S$6:$S$371=2)*(Takip!$M$6:$M$371<>""))) | D15: =IF($A15="","",SUMPRODUCT((Takip!$S$6:$S$371=3)*(Takip!$M$6:$M$371<>""))) | E15: =IF($A15="","",SUMPRODUCT((Takip!$S$6:$S$371=4)*(Takip!$M$6:$M$371<>""))) | F15: =IF($A15="","",SUMPRODUCT((Takip!$S$6:$S$371=5)*(Takip!$M$6:$M$371<>""))) | G15: =IF($A15="","",SUMPRODUCT((Takip!$S$6:$S$371=6)*(Takip!$M$6:$M$371<>""))) | H15: =IF($A15="","",SUMPRODUCT((Takip!$S$6:$S$371=7)*(Takip!$M$6:$M$371<>""))) | I15: =IF($A15="","",SUMPRODUCT((Takip!$S$6:$S$371=8)*(Takip!$M$6:$M$371<>""))) | J15: =IF($A15="","",SUMPRODUCT((Takip!$S$6:$S$371=9)*(Takip!$M$6:$M$371<>""))) | K15: =IF($A15="","",SUMPRODUCT((Takip!$S$6:$S$371=10)*(Takip!$M$6:$M$371<>""))) | L15: =IF($A15="","",SUMPRODUCT((Takip!$S$6:$S$371=11)*(Takip!$M$6:$M$371<>""))) | M15: =IF($A15="","",SUMPRODUCT((Takip!$S$6:$S$371=12)*(Takip!$M$6:$M$371<>""))) | N15: =IF(A15="","",SUM(B15:M15))
A16: =IF(Alışkanlıklar!A16="","",Alışkanlıklar!A16) | B16: =IF($A16="","",SUMPRODUCT((Takip!$S$6:$S$371=1)*(Takip!$N$6:$N$371<>""))) | C16: =IF($A16="","",SUMPRODUCT((Takip!$S$6:$S$371=2)*(Takip!$N$6:$N$371<>""))) | D16: =IF($A16="","",SUMPRODUCT((Takip!$S$6:$S$371=3)*(Takip!$N$6:$N$371<>""))) | E16: =IF($A16="","",SUMPRODUCT((Takip!$S$6:$S$371=4)*(Takip!$N$6:$N$371<>""))) | F16: =IF($A16="","",SUMPRODUCT((Takip!$S$6:$S$371=5)*(Takip!$N$6:$N$371<>""))) | G16: =IF($A16="","",SUMPRODUCT((Takip!$S$6:$S$371=6)*(Takip!$N$6:$N$371<>""))) | H16: =IF($A16="","",SUMPRODUCT((Takip!$S$6:$S$371=7)*(Takip!$N$6:$N$371<>""))) | I16: =IF($A16="","",SUMPRODUCT((Takip!$S$6:$S$371=8)*(Takip!$N$6:$N$371<>""))) | J16: =IF($A16="","",SUMPRODUCT((Takip!$S$6:$S$371=9)*(Takip!$N$6:$N$371<>""))) | K16: =IF($A16="","",SUMPRODUCT((Takip!$S$6:$S$371=10)*(Takip!$N$6:$N$371<>""))) | L16: =IF($A16="","",SUMPRODUCT((Takip!$S$6:$S$371=11)*(Takip!$N$6:$N$371<>""))) | M16: =IF($A16="","",SUMPRODUCT((Takip!$S$6:$S$371=12)*(Takip!$N$6:$N$371<>""))) | N16: =IF(A16="","",SUM(B16:M16))
A17: =IF(Alışkanlıklar!A17="","",Alışkanlıklar!A17) | B17: =IF($A17="","",SUMPRODUCT((Takip!$S$6:$S$371=1)*(Takip!$O$6:$O$371<>""))) | C17: =IF($A17="","",SUMPRODUCT((Takip!$S$6:$S$371=2)*(Takip!$O$6:$O$371<>""))) | D17: =IF($A17="","",SUMPRODUCT((Takip!$S$6:$S$371=3)*(Takip!$O$6:$O$371<>""))) | E17: =IF($A17="","",SUMPRODUCT((Takip!$S$6:$S$371=4)*(Takip!$O$6:$O$371<>""))) | F17: =IF($A17="","",SUMPRODUCT((Takip!$S$6:$S$371=5)*(Takip!$O$6:$O$371<>""))) | G17: =IF($A17="","",SUMPRODUCT((Takip!$S$6:$S$371=6)*(Takip!$O$6:$O$371<>""))) | H17: =IF($A17="","",SUMPRODUCT((Takip!$S$6:$S$371=7)*(Takip!$O$6:$O$371<>""))) | I17: =IF($A17="","",SUMPRODUCT((Takip!$S$6:$S$371=8)*(Takip!$O$6:$O$371<>""))) | J17: =IF($A17="","",SUMPRODUCT((Takip!$S$6:$S$371=9)*(Takip!$O$6:$O$371<>""))) | K17: =IF($A17="","",SUMPRODUCT((Takip!$S$6:$S$371=10)*(Takip!$O$6:$O$371<>""))) | L17: =IF($A17="","",SUMPRODUCT((Takip!$S$6:$S$371=11)*(Takip!$O$6:$O$371<>""))) | M17: =IF($A17="","",SUMPRODUCT((Takip!$S$6:$S$371=12)*(Takip!$O$6:$O$371<>""))) | N17: =IF(A17="","",SUM(B17:M17))
A18: =IF(Alışkanlıklar!A18="","",Alışkanlıklar!A18) | B18: =IF($A18="","",SUMPRODUCT((Takip!$S$6:$S$371=1)*(Takip!$P$6:$P$371<>""))) | C18: =IF($A18="","",SUMPRODUCT((Takip!$S$6:$S$371=2)*(Takip!$P$6:$P$371<>""))) | D18: =IF($A18="","",SUMPRODUCT((Takip!$S$6:$S$371=3)*(Takip!$P$6:$P$371<>""))) | E18: =IF($A18="","",SUMPRODUCT((Takip!$S$6:$S$371=4)*(Takip!$P$6:$P$371<>""))) | F18: =IF($A18="","",SUMPRODUCT((Takip!$S$6:$S$371=5)*(Takip!$P$6:$P$371<>""))) | G18: =IF($A18="","",SUMPRODUCT((Takip!$S$6:$S$371=6)*(Takip!$P$6:$P$371<>""))) | H18: =IF($A18="","",SUMPRODUCT((Takip!$S$6:$S$371=7)*(Takip!$P$6:$P$371<>""))) | I18: =IF($A18="","",SUMPRODUCT((Takip!$S$6:$S$371=8)*(Takip!$P$6:$P$371<>""))) | J18: =IF($A18="","",SUMPRODUCT((Takip!$S$6:$S$371=9)*(Takip!$P$6:$P$371<>""))) | K18: =IF($A18="","",SUMPRODUCT((Takip!$S$6:$S$371=10)*(Takip!$P$6:$P$371<>""))) | L18: =IF($A18="","",SUMPRODUCT((Takip!$S$6:$S$371=11)*(Takip!$P$6:$P$371<>""))) | M18: =IF($A18="","",SUMPRODUCT((Takip!$S$6:$S$371=12)*(Takip!$P$6:$P$371<>""))) | N18: =IF(A18="","",SUM(B18:M18))
A19: =IF(Alışkanlıklar!A19="","",Alışkanlıklar!A19) | B19: =IF($A19="","",SUMPRODUCT((Takip!$S$6:$S$371=1)*(Takip!$Q$6:$Q$371<>""))) | C19: =IF($A19="","",SUMPRODUCT((Takip!$S$6:$S$371=2)*(Takip!$Q$6:$Q$371<>""))) | D19: =IF($A19="","",SUMPRODUCT((Takip!$S$6:$S$371=3)*(Takip!$Q$6:$Q$371<>""))) | E19: =IF($A19="","",SUMPRODUCT((Takip!$S$6:$S$371=4)*(Takip!$Q$6:$Q$371<>""))) | F19: =IF($A19="","",SUMPRODUCT((Takip!$S$6:$S$371=5)*(Takip!$Q$6:$Q$371<>""))) | G19: =IF($A19="","",SUMPRODUCT((Takip!$S$6:$S$371=6)*(Takip!$Q$6:$Q$371<>""))) | H19: =IF($A19="","",SUMPRODUCT((Takip!$S$6:$S$371=7)*(Takip!$Q$6:$Q$371<>""))) | I19: =IF($A19="","",SUMPRODUCT((Takip!$S$6:$S$371=8)*(Takip!$Q$6:$Q$371<>""))) | J19: =IF($A19="","",SUMPRODUCT((Takip!$S$6:$S$371=9)*(Takip!$Q$6:$Q$371<>""))) | K19: =IF($A19="","",SUMPRODUCT((Takip!$S$6:$S$371=10)*(Takip!$Q$6:$Q$371<>""))) | L19: =IF($A19="","",SUMPRODUCT((Takip!$S$6:$S$371=11)*(Takip!$Q$6:$Q$371<>""))) | M19: =IF($A19="","",SUMPRODUCT((Takip!$S$6:$S$371=12)*(Takip!$Q$6:$Q$371<>""))) | N19: =IF(A19="","",SUM(B19:M19))

Sheet Seri
A1: Seri (dokunma)
A2: Art arda gün sayısının ara hesabı. Bu sayfayı değiştirme.
A6: =Takip!R6 -> 46023 | C6: =IF(Takip!C6="",0,1) -> 0 | D6: =IF(Takip!D6="",0,1) -> 0 | E6: =IF(Takip!E6="",0,1) -> 0 | F6: =IF(Takip!F6="",0,1) -> 0 | G6: =IF(Takip!G6="",0,1) -> 0 | H6: =IF(Takip!H6="",0,1) -> 0 | I6: =IF(Takip!I6="",0,1) -> 0 | J6: =IF(Takip!J6="",0,1) -> 0 | ... Q6: =IF(Takip!Q6="",0,1) -> 0
A7: =Takip!R7 -> 46024 | C7: =IF(Takip!C7="",0,C6+1) -> 0 | D7: =IF(Takip!D7="",0,D6+1) -> 0 | E7: =IF(Takip!E7="",0,E6+1) -> 0 | F7: =IF(Takip!F7="",0,F6+1) -> 0 | G7: =IF(Takip!G7="",0,G6+1) -> 0 | H7: =IF(Takip!H7="",0,H6+1) -> 0 | I7: =IF(Takip!I7="",0,I6+1) -> 0 | J7: =IF(Takip!J7="",0,J6+1) -> 0 | ... Q7: =IF(Takip!Q7="",0,Q6+1) -> 0
A8: =Takip!R8 -> 46025 | C8: =IF(Takip!C8="",0,C7+1) -> 0 | D8: =IF(Takip!D8="",0,D7+1) -> 0 | E8: =IF(Takip!E8="",0,E7+1) -> 0 | F8: =IF(Takip!F8="",0,F7+1) -> 0 | G8: =IF(Takip!G8="",0,G7+1) -> 0 | H8: =IF(Takip!H8="",0,H7+1) -> 0 | I8: =IF(Takip!I8="",0,I7+1) -> 0 | J8: =IF(Takip!J8="",0,J7+1) -> 0 | ... Q8: =IF(Takip!Q8="",0,Q7+1) -> 0
A9: =Takip!R9 -> 46026 | C9: =IF(Takip!C9="",0,C8+1) -> 0 | D9: =IF(Takip!D9="",0,D8+1) -> 0 | E9: =IF(Takip!E9="",0,E8+1) -> 0 | F9: =IF(Takip!F9="",0,F8+1) -> 0 | G9: =IF(Takip!G9="",0,G8+1) -> 0 | H9: =IF(Takip!H9="",0,H8+1) -> 0 | I9: =IF(Takip!I9="",0,I8+1) -> 0 | J9: =IF(Takip!J9="",0,J8+1) -> 0 | ... Q9: =IF(Takip!Q9="",0,Q8+1) -> 0
A10: =Takip!R10 -> 46027 | C10: =IF(Takip!C10="",0,C9+1) -> 0 | D10: =IF(Takip!D10="",0,D9+1) -> 0 | E10: =IF(Takip!E10="",0,E9+1) -> 0 | F10: =IF(Takip!F10="",0,F9+1) -> 0 | G10: =IF(Takip!G10="",0,G9+1) -> 0 | H10: =IF(Takip!H10="",0,H9+1) -> 0 | I10: =IF(Takip!I10="",0,I9+1) -> 0 | J10: =IF(Takip!J10="",0,J9+1) -> 0 | ... Q10: =IF(Takip!Q10="",0,Q9+1) -> 0
A11: =Takip!R11 -> 46028 | C11: =IF(Takip!C11="",0,C10+1) -> 0 | D11: =IF(Takip!D11="",0,D10+1) -> 0 | E11: =IF(Takip!E11="",0,E10+1) -> 0 | F11: =IF(Takip!F11="",0,F10+1) -> 0 | G11: =IF(Takip!G11="",0,G10+1) -> 0 | H11: =IF(Takip!H11="",0,H10+1) -> 0 | I11: =IF(Takip!I11="",0,I10+1) -> 0 | J11: =IF(Takip!J11="",0,J10+1) -> 0 | ... Q11: =IF(Takip!Q11="",0,Q10+1) -> 0
A12: =Takip!R12 -> 46029 | C12: =IF(Takip!C12="",0,C11+1) -> 0 | D12: =IF(Takip!D12="",0,D11+1) -> 0 | E12: =IF(Takip!E12="",0,E11+1) -> 0 | F12: =IF(Takip!F12="",0,F11+1) -> 0 | G12: =IF(Takip!G12="",0,G11+1) -> 0 | H12: =IF(Takip!H12="",0,H11+1) -> 0 | I12: =IF(Takip!I12="",0,I11+1) -> 0 | J12: =IF(Takip!J12="",0,J11+1) -> 0 | ... Q12: =IF(Takip!Q12="",0,Q11+1) -> 0
A13: =Takip!R13 -> 46030 | C13: =IF(Takip!C13="",0,C12+1) -> 0 | D13: =IF(Takip!D13="",0,D12+1) -> 0 | E13: =IF(Takip!E13="",0,E12+1) -> 0 | F13: =IF(Takip!F13="",0,F12+1) -> 0 | G13: =IF(Takip!G13="",0,G12+1) -> 0 | H13: =IF(Takip!H13="",0,H12+1) -> 0 | I13: =IF(Takip!I13="",0,I12+1) -> 0 | J13: =IF(Takip!J13="",0,J12+1) -> 0 | ... Q13: =IF(Takip!Q13="",0,Q12+1) -> 0
A14: =Takip!R14 -> 46031 | C14: =IF(Takip!C14="",0,C13+1) -> 0 | D14: =IF(Takip!D14="",0,D13+1) -> 0 | E14: =IF(Takip!E14="",0,E13+1) -> 0 | F14: =IF(Takip!F14="",0,F13+1) -> 0 | G14: =IF(Takip!G14="",0,G13+1) -> 0 | H14: =IF(Takip!H14="",0,H13+1) -> 0 | I14: =IF(Takip!I14="",0,I13+1) -> 0 | J14: =IF(Takip!J14="",0,J13+1) -> 0 | ... Q14: =IF(Takip!Q14="",0,Q13+1) -> 0
A15: =Takip!R15 -> 46032 | C15: =IF(Takip!C15="",0,C14+1) -> 0 | D15: =IF(Takip!D15="",0,D14+1) -> 0 | E15: =IF(Takip!E15="",0,E14+1) -> 0 | F15: =IF(Takip!F15="",0,F14+1) -> 0 | G15: =IF(Takip!G15="",0,G14+1) -> 0 | H15: =IF(Takip!H15="",0,H14+1) -> 0 | I15: =IF(Takip!I15="",0,I14+1) -> 0 | J15: =IF(Takip!J15="",0,J14+1) -> 0 | ... Q15: =IF(Takip!Q15="",0,Q14+1) -> 0
A16: =Takip!R16 -> 46033 | C16: =IF(Takip!C16="",0,C15+1) -> 0 | D16: =IF(Takip!D16="",0,D15+1) -> 0 | E16: =IF(Takip!E16="",0,E15+1) -> 0 | F16: =IF(Takip!F16="",0,F15+1) -> 0 | G16: =IF(Takip!G16="",0,G15+1) -> 0 | H16: =IF(Takip!H16="",0,H15+1) -> 0 | I16: =IF(Takip!I16="",0,I15+1) -> 0 | J16: =IF(Takip!J16="",0,J15+1) -> 0 | ... Q16: =IF(Takip!Q16="",0,Q15+1) -> 0
A17: =Takip!R17 -> 46034 | C17: =IF(Takip!C17="",0,C16+1) -> 0 | D17: =IF(Takip!D17="",0,D16+1) -> 0 | E17: =IF(Takip!E17="",0,E16+1) -> 0 | F17: =IF(Takip!F17="",0,F16+1) -> 0 | G17: =IF(Takip!G17="",0,G16+1) -> 0 | H17: =IF(Takip!H17="",0,H16+1) -> 0 | I17: =IF(Takip!I17="",0,I16+1) -> 0 | J17: =IF(Takip!J17="",0,J16+1) -> 0 | ... Q17: =IF(Takip!Q17="",0,Q16+1) -> 0
A18: =Takip!R18 -> 46035 | C18: =IF(Takip!C18="",0,C17+1) -> 0 | D18: =IF(Takip!D18="",0,D17+1) -> 0 | E18: =IF(Takip!E18="",0,E17+1) -> 0 | F18: =IF(Takip!F18="",0,F17+1) -> 0 | G18: =IF(Takip!G18="",0,G17+1) -> 0 | H18: =IF(Takip!H18="",0,H17+1) -> 0 | I18: =IF(Takip!I18="",0,I17+1) -> 0 | J18: =IF(Takip!J18="",0,J17+1) -> 0 | ... Q18: =IF(Takip!Q18="",0,Q17+1) -> 0
... A371: =Takip!R371 -> 0 | C371: =IF(Takip!C371="",0,C370+1) -> 0 | D371: =IF(Takip!D371="",0,D370+1) -> 0 | E371: =IF(Takip!E371="",0,E370+1) -> 0 | F371: =IF(Takip!F371="",0,F370+1) -> 0 | G371: =IF(Takip!G371="",0,G370+1) -> 0 | H371: =IF(Takip!H371="",0,H370+1) -> 0 | I371: =IF(Takip!I371="",0,I370+1) -> 0 | J371: =IF(Takip!J371="",0,J370+1) -> 0 | ... Q371: =IF(Takip!Q371="",0,Q370+1) -> 0

Sheet AI Komutları
B1: Yapay Zeka Komutları
B2: İlgili sayfada başlık satırıyla birlikte kayıtlarını seç, kopyala, kullandığın yapay zeka asistanına yapıştır ve altına komutu ekle.
B3: Dikkat: Sağlıkla ilgili özel bilgileri paylaşmak zorunda değilsin; alışkanlık adlarını genel tutabilirsin. Yapay zekanın verdiği rakamları dosyadaki özet sayfasıyla karşılaştır.
B5: Ne için | C5: Komut (kopyala, yapıştır)
B6: Gidiş yorumu | C6: [Alışkanlıklar sayfası] Hedefime göre hangi alışkanlıkta iyiyim, hangisinde geride kalıyorum? Kısa ve dürüst yorumla.
B7: Kopma günleri | C7: [Takip sayfası] Serilerimin en çok hangi günlerde bozulduğunu bul. O günler için küçük bir önlem öner.
B8: Hedef ayarı | C8: [Alışkanlıklar sayfası] Son 30 gün oranıma bakarak haftalık hedeflerimi gerçekçi olacak şekilde yeniden öner.
B9: Küçük adım | C9: [Alışkanlık adı] alışkanlığını sürdüremiyorum. İki dakikada yapılabilecek daha küçük bir sürümünü öner.
B10: Aylık özet | C10: [Aylar sayfası] Aylara göre gidişimi üç cümleyle özetle ve gelecek ay için tek bir odak öner.
B11: Hatırlatma planı | C11: Bu alışkanlıklar için günün hangi saatine hangi hatırlatmayı koymalıyım? Sabah, öğle ve akşam olarak planla.
