Workbook

Sheet Başla
B2: EXCEL KLİNİĞİ
B3: TAHLİL | Satış analizi
B4: Satış kayıtlarını yapıştır; en çok kazandıran ürünler, en değerli müşteriler, aylık gidiş ve haftanın günleri kendiliğinden çıksın.
B6: NASIL KULLANILIR
B7: 1. Veri | C7: Satışlarını tarih, müşteri, ürün, adet ve tutar olarak yaz ya da başka bir dosyadan kopyalayıp yapıştır. Yapıştırırken yalnızca değerleri yapıştır.
B8: 2. Ürünler | C8: Ürünler cirosuna göre sıralanır; pay, birikimli pay ve A, B, C sınıfı hesaplanır.
B9: 3. Müşteriler | C9: Müşteriler cirosuna göre sıralanır; satış sayısı, ortalama ve son alışveriş tarihi görünür.
B10: 4. Özet | C10: Toplamlar, aylık gidiş, önceki aya göre değişim ve haftanın günlerine göre ciro.
B12: BİLMEN GEREKENLER
B13: A, B, C sınıfı | C13: Ürünler cirosuna göre dizilir. Cironun ilk yüzde 80'ini getirenler A, sonraki yüzde 15'i getirenler B, kalanlar C sınıfıdır. A sınıfı az sayıda üründür ama kazancın çoğunu onlar getirir.
B14: Yazım farkı | C14: Aynı ürünü ya da müşteriyi iki farklı yazarsan iki ayrı satır olarak sayılır. Adları tek biçimde yaz.
B15: Kâr değil ciro | C15: Dosya maliyet bilgisi istemez; bu yüzden kâr değil ciro analizi yapar.
B16: Kapasite | C16: 2000 satış satırı; analizde 200 ürün ve 200 müşteri. Dosya dolu veriyle birkaç saniye geç hesaplayabilir.
B18: RENKLER
B19: Sarı hücre | C19: Senin dolduracağın hücre. İçindeki örnekleri silip kendi bilgini yaz.
B20: Beyaz hücre, açık başlık | C20: Formül. Değiştirme, kendiliğinden hesaplanır.

Sheet Veri
A1: Veri
A2: Satışlarını buraya yaz ya da başka dosyadan yapıştır. Her satır bir satış kalemi.
A4: Tarih | B4: Müşteri | C4: Ürün | D4: Adet | E4: Tutar (₺) | F4: y1 | G4: y2 | H4: y3 | I4: y4
A5: 46204 | B5: Müşteri Epsilon | C5: Defter A4 | D5: 5 | E5: 300 | F5: =IF(C5="",0,IF(COUNTIF(C$5:C5,C5)=1,1,0)) -> 1 | G5: =SUM(F$5:F5) -> 1 | H5: =IF(B5="",0,IF(COUNTIF(B$5:B5,B5)=1,1,0)) -> 1 | I5: =SUM(H$5:H5) -> 1
A6: 46204 | B6: Müşteri Gama | C6: Klasör | D6: 20 | E6: 1500 | F6: =IF(C6="",0,IF(COUNTIF(C$5:C6,C6)=1,1,0)) -> 1 | G6: =SUM(F$5:F6) -> 2 | H6: =IF(B6="",0,IF(COUNTIF(B$5:B6,B6)=1,1,0)) -> 1 | I6: =SUM(H$5:H6) -> 2
A7: 46206 | B7: Müşteri Beta | C7: Klasör | D7: 5 | E7: 375 | F7: =IF(C7="",0,IF(COUNTIF(C$5:C7,C7)=1,1,0)) -> 0 | G7: =SUM(F$5:F7) -> 2 | H7: =IF(B7="",0,IF(COUNTIF(B$5:B7,B7)=1,1,0)) -> 1 | I7: =SUM(H$5:H7) -> 3
A8: 46206 | B8: Müşteri Epsilon | C8: Hesap makinesi | D8: 1 | E8: 350 | F8: =IF(C8="",0,IF(COUNTIF(C$5:C8,C8)=1,1,0)) -> 1 | G8: =SUM(F$5:F8) -> 3 | H8: =IF(B8="",0,IF(COUNTIF(B$5:B8,B8)=1,1,0)) -> 0 | I8: =SUM(H$5:H8) -> 3
A9: 46206 | B9: Müşteri Gama | C9: Fotokopi kâğıdı | D9: 20 | E9: 3800 | F9: =IF(C9="",0,IF(COUNTIF(C$5:C9,C9)=1,1,0)) -> 1 | G9: =SUM(F$5:F9) -> 4 | H9: =IF(B9="",0,IF(COUNTIF(B$5:B9,B9)=1,1,0)) -> 0 | I9: =SUM(H$5:H9) -> 3
A10: 46207 | B10: Müşteri Delta | C10: Fotokopi kâğıdı | D10: 5 | E10: 950 | F10: =IF(C10="",0,IF(COUNTIF(C$5:C10,C10)=1,1,0)) -> 0 | G10: =SUM(F$5:F10) -> 4 | H10: =IF(B10="",0,IF(COUNTIF(B$5:B10,B10)=1,1,0)) -> 1 | I10: =SUM(H$5:H10) -> 4
A11: 46207 | B11: Perakende | C11: Defter A4 | D11: 10 | E11: 600 | F11: =IF(C11="",0,IF(COUNTIF(C$5:C11,C11)=1,1,0)) -> 0 | G11: =SUM(F$5:F11) -> 4 | H11: =IF(B11="",0,IF(COUNTIF(B$5:B11,B11)=1,1,0)) -> 1 | I11: =SUM(H$5:H11) -> 5
A12: 46208 | B12: Müşteri Epsilon | C12: Hesap makinesi | D12: 1 | E12: 350 | F12: =IF(C12="",0,IF(COUNTIF(C$5:C12,C12)=1,1,0)) -> 0 | G12: =SUM(F$5:F12) -> 4 | H12: =IF(B12="",0,IF(COUNTIF(B$5:B12,B12)=1,1,0)) -> 0 | I12: =SUM(H$5:H12) -> 5
A13: 46209 | B13: Müşteri Gama | C13: Fotokopi kâğıdı | D13: 10 | E13: 1900 | F13: =IF(C13="",0,IF(COUNTIF(C$5:C13,C13)=1,1,0)) -> 0 | G13: =SUM(F$5:F13) -> 4 | H13: =IF(B13="",0,IF(COUNTIF(B$5:B13,B13)=1,1,0)) -> 0 | I13: =SUM(H$5:H13) -> 5
A14: 46211 | B14: Müşteri Delta | C14: Fotokopi kâğıdı | D14: 3 | E14: 570 | F14: =IF(C14="",0,IF(COUNTIF(C$5:C14,C14)=1,1,0)) -> 0 | G14: =SUM(F$5:F14) -> 4 | H14: =IF(B14="",0,IF(COUNTIF(B$5:B14,B14)=1,1,0)) -> 0 | I14: =SUM(H$5:H14) -> 5
A15: 46212 | B15: Müşteri Alfa | C15: Defter A4 | D15: 5 | E15: 300 | F15: =IF(C15="",0,IF(COUNTIF(C$5:C15,C15)=1,1,0)) -> 0 | G15: =SUM(F$5:F15) -> 4 | H15: =IF(B15="",0,IF(COUNTIF(B$5:B15,B15)=1,1,0)) -> 1 | I15: =SUM(H$5:H15) -> 6
A16: 46212 | B16: Müşteri Alfa | C16: Fotokopi kâğıdı | D16: 2 | E16: 380 | F16: =IF(C16="",0,IF(COUNTIF(C$5:C16,C16)=1,1,0)) -> 0 | G16: =SUM(F$5:F16) -> 4 | H16: =IF(B16="",0,IF(COUNTIF(B$5:B16,B16)=1,1,0)) -> 0 | I16: =SUM(H$5:H16) -> 6
... A84: 46298 | B84: Müşteri Gama | C84: Tükenmez kalem | D84: 40 | E84: 600 | F84: =IF(C84="",0,IF(COUNTIF(C$5:C84,C84)=1,1,0)) -> 0 | G84: =SUM(F$5:F84) -> 8 | H84: =IF(B84="",0,IF(COUNTIF(B$5:B84,B84)=1,1,0)) -> 0 | I84: =SUM(H$5:H84) -> 6
F85: =IF(C85="",0,IF(COUNTIF(C$5:C85,C85)=1,1,0)) -> 0 | G85: =SUM(F$5:F85) -> 8 | H85: =IF(B85="",0,IF(COUNTIF(B$5:B85,B85)=1,1,0)) -> 0 | I85: =SUM(H$5:H85) -> 6
F86: =IF(C86="",0,IF(COUNTIF(C$5:C86,C86)=1,1,0)) -> 0 | G86: =SUM(F$5:F86) -> 8 | H86: =IF(B86="",0,IF(COUNTIF(B$5:B86,B86)=1,1,0)) -> 0 | I86: =SUM(H$5:H86) -> 6
F87: =IF(C87="",0,IF(COUNTIF(C$5:C87,C87)=1,1,0)) -> 0 | G87: =SUM(F$5:F87) -> 8 | H87: =IF(B87="",0,IF(COUNTIF(B$5:B87,B87)=1,1,0)) -> 0 | I87: =SUM(H$5:H87) -> 6
F88: =IF(C88="",0,IF(COUNTIF(C$5:C88,C88)=1,1,0)) -> 0 | G88: =SUM(F$5:F88) -> 8 | H88: =IF(B88="",0,IF(COUNTIF(B$5:B88,B88)=1,1,0)) -> 0 | I88: =SUM(H$5:H88) -> 6
F89: =IF(C89="",0,IF(COUNTIF(C$5:C89,C89)=1,1,0)) -> 0 | G89: =SUM(F$5:F89) -> 8 | H89: =IF(B89="",0,IF(COUNTIF(B$5:B89,B89)=1,1,0)) -> 0 | I89: =SUM(H$5:H89) -> 6
F90: =IF(C90="",0,IF(COUNTIF(C$5:C90,C90)=1,1,0)) -> 0 | G90: =SUM(F$5:F90) -> 8 | H90: =IF(B90="",0,IF(COUNTIF(B$5:B90,B90)=1,1,0)) -> 0 | I90: =SUM(H$5:H90) -> 6
F91: =IF(C91="",0,IF(COUNTIF(C$5:C91,C91)=1,1,0)) -> 0 | G91: =SUM(F$5:F91) -> 8 | H91: =IF(B91="",0,IF(COUNTIF(B$5:B91,B91)=1,1,0)) -> 0 | I91: =SUM(H$5:H91) -> 6
F92: =IF(C92="",0,IF(COUNTIF(C$5:C92,C92)=1,1,0)) -> 0 | G92: =SUM(F$5:F92) -> 8 | H92: =IF(B92="",0,IF(COUNTIF(B$5:B92,B92)=1,1,0)) -> 0 | I92: =SUM(H$5:H92) -> 6
F93: =IF(C93="",0,IF(COUNTIF(C$5:C93,C93)=1,1,0)) -> 0 | G93: =SUM(F$5:F93) -> 8 | H93: =IF(B93="",0,IF(COUNTIF(B$5:B93,B93)=1,1,0)) -> 0 | I93: =SUM(H$5:H93) -> 6
F94: =IF(C94="",0,IF(COUNTIF(C$5:C94,C94)=1,1,0)) -> 0 | G94: =SUM(F$5:F94) -> 8 | H94: =IF(B94="",0,IF(COUNTIF(B$5:B94,B94)=1,1,0)) -> 0 | I94: =SUM(H$5:H94) -> 6
F95: =IF(C95="",0,IF(COUNTIF(C$5:C95,C95)=1,1,0)) -> 0 | G95: =SUM(F$5:F95) -> 8 | H95: =IF(B95="",0,IF(COUNTIF(B$5:B95,B95)=1,1,0)) -> 0 | I95: =SUM(H$5:H95) -> 6
F96: =IF(C96="",0,IF(COUNTIF(C$5:C96,C96)=1,1,0)) -> 0 | G96: =SUM(F$5:F96) -> 8 | H96: =IF(B96="",0,IF(COUNTIF(B$5:B96,B96)=1,1,0)) -> 0 | I96: =SUM(H$5:H96) -> 6
... F2004: =IF(C2004="",0,IF(COUNTIF(C$5:C2004,C2004)=1,1,0)) -> 0 | G2004: =SUM(F$5:F2004) -> 8 | H2004: =IF(B2004="",0,IF(COUNTIF(B$5:B2004,B2004)=1,1,0)) -> 0 | I2004: =SUM(H$5:H2004) -> 6

Sheet Özet
A1: Özet
A2: Bu sayfada yalnızca yılı değiştir.
B3: Yıl | C3: 2026
B5: Toplam ciro | C5: Satış satırı | D5: Satır başına ortalama | E5: Ürün çeşidi | F5: Müşteri | G5: A sınıfı ürün
B6: =SUM(Veri!$E$5:$E$2004) -> 115710 | C6: =COUNT(Veri!$E$5:$E$2004) -> 80 | D6: =IF(COUNT(Veri!$E$5:$E$2004)=0,0,SUM(Veri!$E$5:$E$2004)/COUNT(Veri!$E$5:$E$2004)) -> 1446.375 | E6: =MAX(Veri!$G$5:$G$2004) -> 8 | F6: =MAX(Veri!$I$5:$I$2004) -> 6 | G6: =COUNTIF(Ürünler!$G$5:$G$204,"A") -> 4
B8: ="A sınıfı ürünlerin cirodaki payı: "&TEXT(IF(SUM(Veri!$E$5:$E$2004)=0,0,SUMIFS(Ürünler!$D$5:$D$204,Ürünler!$G$5:$G$204,"A")/SUM(Veri!$E$5:$E$2004)),"0%") -> A sınıfı ürünlerin cirodaki payı: 87%
B10: Aylık gidiş | I10: Haftanın günleri
B11: Ay | C11: Ciro (₺) | D11: Adet | E11: Satış satırı | F11: Önceki aya göre | I11: Gün | J11: Ciro (₺)
B12: Ocak | C12: =SUMIFS(Veri!$E$5:$E$2004,Veri!$A$5:$A$2004,">="&DATE($C$3,1,1),Veri!$A$5:$A$2004,"<"&DATE($C$3,2,1)) -> 0 | D12: =SUMIFS(Veri!$D$5:$D$2004,Veri!$A$5:$A$2004,">="&DATE($C$3,1,1),Veri!$A$5:$A$2004,"<"&DATE($C$3,2,1)) -> 0 | E12: =COUNTIFS(Veri!$A$5:$A$2004,">="&DATE($C$3,1,1),Veri!$A$5:$A$2004,"<"&DATE($C$3,2,1)) -> 0 | F12: ="" | I12: Pazartesi | J12: =SUMPRODUCT((WEEKDAY(Veri!$A$5:$A$2004,2)=1)*(Veri!$A$5:$A$2004>0)*Veri!$E$5:$E$2004) -> 10260
B13: Şubat | C13: =SUMIFS(Veri!$E$5:$E$2004,Veri!$A$5:$A$2004,">="&DATE($C$3,2,1),Veri!$A$5:$A$2004,"<"&DATE($C$3,3,1)) -> 0 | D13: =SUMIFS(Veri!$D$5:$D$2004,Veri!$A$5:$A$2004,">="&DATE($C$3,2,1),Veri!$A$5:$A$2004,"<"&DATE($C$3,3,1)) -> 0 | E13: =COUNTIFS(Veri!$A$5:$A$2004,">="&DATE($C$3,2,1),Veri!$A$5:$A$2004,"<"&DATE($C$3,3,1)) -> 0 | F13: =IF(C12=0,"",C13/C12-1) | I13: Salı | J13: =SUMPRODUCT((WEEKDAY(Veri!$A$5:$A$2004,2)=2)*(Veri!$A$5:$A$2004>0)*Veri!$E$5:$E$2004) -> 7750
B14: Mart | C14: =SUMIFS(Veri!$E$5:$E$2004,Veri!$A$5:$A$2004,">="&DATE($C$3,3,1),Veri!$A$5:$A$2004,"<"&DATE($C$3,4,1)) -> 0 | D14: =SUMIFS(Veri!$D$5:$D$2004,Veri!$A$5:$A$2004,">="&DATE($C$3,3,1),Veri!$A$5:$A$2004,"<"&DATE($C$3,4,1)) -> 0 | E14: =COUNTIFS(Veri!$A$5:$A$2004,">="&DATE($C$3,3,1),Veri!$A$5:$A$2004,"<"&DATE($C$3,4,1)) -> 0 | F14: =IF(C13=0,"",C14/C13-1) | I14: Çarşamba | J14: =SUMPRODUCT((WEEKDAY(Veri!$A$5:$A$2004,2)=3)*(Veri!$A$5:$A$2004>0)*Veri!$E$5:$E$2004) -> 13045
B15: Nisan | C15: =SUMIFS(Veri!$E$5:$E$2004,Veri!$A$5:$A$2004,">="&DATE($C$3,4,1),Veri!$A$5:$A$2004,"<"&DATE($C$3,5,1)) -> 0 | D15: =SUMIFS(Veri!$D$5:$D$2004,Veri!$A$5:$A$2004,">="&DATE($C$3,4,1),Veri!$A$5:$A$2004,"<"&DATE($C$3,5,1)) -> 0 | E15: =COUNTIFS(Veri!$A$5:$A$2004,">="&DATE($C$3,4,1),Veri!$A$5:$A$2004,"<"&DATE($C$3,5,1)) -> 0 | F15: =IF(C14=0,"",C15/C14-1) | I15: Perşembe | J15: =SUMPRODUCT((WEEKDAY(Veri!$A$5:$A$2004,2)=4)*(Veri!$A$5:$A$2004>0)*Veri!$E$5:$E$2004) -> 6915
B16: Mayıs | C16: =SUMIFS(Veri!$E$5:$E$2004,Veri!$A$5:$A$2004,">="&DATE($C$3,5,1),Veri!$A$5:$A$2004,"<"&DATE($C$3,6,1)) -> 0 | D16: =SUMIFS(Veri!$D$5:$D$2004,Veri!$A$5:$A$2004,">="&DATE($C$3,5,1),Veri!$A$5:$A$2004,"<"&DATE($C$3,6,1)) -> 0 | E16: =COUNTIFS(Veri!$A$5:$A$2004,">="&DATE($C$3,5,1),Veri!$A$5:$A$2004,"<"&DATE($C$3,6,1)) -> 0 | F16: =IF(C15=0,"",C16/C15-1) | I16: Cuma | J16: =SUMPRODUCT((WEEKDAY(Veri!$A$5:$A$2004,2)=5)*(Veri!$A$5:$A$2004>0)*Veri!$E$5:$E$2004) -> 38375
B17: Haziran | C17: =SUMIFS(Veri!$E$5:$E$2004,Veri!$A$5:$A$2004,">="&DATE($C$3,6,1),Veri!$A$5:$A$2004,"<"&DATE($C$3,7,1)) -> 0 | D17: =SUMIFS(Veri!$D$5:$D$2004,Veri!$A$5:$A$2004,">="&DATE($C$3,6,1),Veri!$A$5:$A$2004,"<"&DATE($C$3,7,1)) -> 0 | E17: =COUNTIFS(Veri!$A$5:$A$2004,">="&DATE($C$3,6,1),Veri!$A$5:$A$2004,"<"&DATE($C$3,7,1)) -> 0 | F17: =IF(C16=0,"",C17/C16-1) | I17: Cumartesi | J17: =SUMPRODUCT((WEEKDAY(Veri!$A$5:$A$2004,2)=6)*(Veri!$A$5:$A$2004>0)*Veri!$E$5:$E$2004) -> 19595
B18: Temmuz | C18: =SUMIFS(Veri!$E$5:$E$2004,Veri!$A$5:$A$2004,">="&DATE($C$3,7,1),Veri!$A$5:$A$2004,"<"&DATE($C$3,8,1)) -> 53340 | D18: =SUMIFS(Veri!$D$5:$D$2004,Veri!$A$5:$A$2004,">="&DATE($C$3,7,1),Veri!$A$5:$A$2004,"<"&DATE($C$3,8,1)) -> 337 | E18: =COUNTIFS(Veri!$A$5:$A$2004,">="&DATE($C$3,7,1),Veri!$A$5:$A$2004,"<"&DATE($C$3,8,1)) -> 34 | F18: =IF(C17=0,"",C18/C17-1) | I18: Pazar | J18: =SUMPRODUCT((WEEKDAY(Veri!$A$5:$A$2004,2)=7)*(Veri!$A$5:$A$2004>0)*Veri!$E$5:$E$2004) -> 19770
B19: Ağustos | C19: =SUMIFS(Veri!$E$5:$E$2004,Veri!$A$5:$A$2004,">="&DATE($C$3,8,1),Veri!$A$5:$A$2004,"<"&DATE($C$3,9,1)) -> 27740 | D19: =SUMIFS(Veri!$D$5:$D$2004,Veri!$A$5:$A$2004,">="&DATE($C$3,8,1),Veri!$A$5:$A$2004,"<"&DATE($C$3,9,1)) -> 335 | E19: =COUNTIFS(Veri!$A$5:$A$2004,">="&DATE($C$3,8,1),Veri!$A$5:$A$2004,"<"&DATE($C$3,9,1)) -> 25 | F19: =IF(C18=0,"",C19/C18-1) -> -0.47994001
B20: Eylül | C20: =SUMIFS(Veri!$E$5:$E$2004,Veri!$A$5:$A$2004,">="&DATE($C$3,9,1),Veri!$A$5:$A$2004,"<"&DATE($C$3,10,1)) -> 26080 | D20: =SUMIFS(Veri!$D$5:$D$2004,Veri!$A$5:$A$2004,">="&DATE($C$3,9,1),Veri!$A$5:$A$2004,"<"&DATE($C$3,10,1)) -> 190 | E20: =COUNTIFS(Veri!$A$5:$A$2004,">="&DATE($C$3,9,1),Veri!$A$5:$A$2004,"<"&DATE($C$3,10,1)) -> 18 | F20: =IF(C19=0,"",C20/C19-1) -> -0.059841384
B21: Ekim | C21: =SUMIFS(Veri!$E$5:$E$2004,Veri!$A$5:$A$2004,">="&DATE($C$3,10,1),Veri!$A$5:$A$2004,"<"&DATE($C$3,11,1)) -> 8550 | D21: =SUMIFS(Veri!$D$5:$D$2004,Veri!$A$5:$A$2004,">="&DATE($C$3,10,1),Veri!$A$5:$A$2004,"<"&DATE($C$3,11,1)) -> 65 | E21: =COUNTIFS(Veri!$A$5:$A$2004,">="&DATE($C$3,10,1),Veri!$A$5:$A$2004,"<"&DATE($C$3,11,1)) -> 3 | F21: =IF(C20=0,"",C21/C20-1) -> -0.67216258
B22: Kasım | C22: =SUMIFS(Veri!$E$5:$E$2004,Veri!$A$5:$A$2004,">="&DATE($C$3,11,1),Veri!$A$5:$A$2004,"<"&DATE($C$3,12,1)) -> 0 | D22: =SUMIFS(Veri!$D$5:$D$2004,Veri!$A$5:$A$2004,">="&DATE($C$3,11,1),Veri!$A$5:$A$2004,"<"&DATE($C$3,12,1)) -> 0 | E22: =COUNTIFS(Veri!$A$5:$A$2004,">="&DATE($C$3,11,1),Veri!$A$5:$A$2004,"<"&DATE($C$3,12,1)) -> 0 | F22: =IF(C21=0,"",C22/C21-1) -> -1
B23: Aralık | C23: =SUMIFS(Veri!$E$5:$E$2004,Veri!$A$5:$A$2004,">="&DATE($C$3,12,1),Veri!$A$5:$A$2004,"<"&DATE($C$3,13,1)) -> 0 | D23: =SUMIFS(Veri!$D$5:$D$2004,Veri!$A$5:$A$2004,">="&DATE($C$3,12,1),Veri!$A$5:$A$2004,"<"&DATE($C$3,13,1)) -> 0 | E23: =COUNTIFS(Veri!$A$5:$A$2004,">="&DATE($C$3,12,1),Veri!$A$5:$A$2004,"<"&DATE($C$3,13,1)) -> 0 | F23: =IF(C22=0,"",C23/C22-1)

Sheet Ürünler
A1: Ürün Analizi
A2: Cirosu en yüksek üründen başlayarak sıralanır. A sınıfı: cironun ilk yüzde 80'ini getiren ürünler.
A4: Sıra | B4: Ürün | C4: Adet | D4: Ciro (₺) | E4: Pay | F4: Birikimli pay | G4: Sınıf | H4: Ortalama birim fiyat (₺) | I4: Son satış | K4: y | L4: y | M4: y | N4: y
A5: =IF(B5="","",1) -> 1 | B5: =IFERROR(INDEX($K$5:$K$204,MATCH(LARGE($M$5:$M$204,1),$M$5:$M$204,0)),"") -> Fotokopi kâğıdı | C5: =IF(B5="","",SUMIFS(Veri!$D$5:$D$2004,Veri!$C$5:$C$2004,B5)) -> 240 | D5: =IF(B5="","",SUMIFS(Veri!$E$5:$E$2004,Veri!$C$5:$C$2004,B5)) -> 45600 | E5: =IF(B5="","",IF(SUM(Veri!$E$5:$E$2004)=0,0,D5/SUM(Veri!$E$5:$E$2004))) -> 0.39408867 | F5: =IF(B5="","",SUM(E$5:E5)) -> 0.39408867 | G5: =IF(B5="","","A") -> A | H5: =IF(OR(B5="",C5=0),"",D5/C5) -> 190 | I5: =IF(B5="","",SUMPRODUCT(MAX((Veri!$C$5:$C$2004=B5)*Veri!$A$5:$A$2004))) -> 46298 | K5: =IF(1>MAX(Veri!$G$5:$G$2004),"",INDEX(Veri!$C$5:$C$2004,MATCH(1,Veri!$G$5:$G$2004,0))) -> Defter A4 | L5: =IF(K5="","",SUMIFS(Veri!$E$5:$E$2004,Veri!$C$5:$C$2004,K5)) -> 9660 | M5: =IF(K5="","",L5+ROW()/1000000000) -> 9660
A6: =IF(B6="","",2) -> 2 | B6: =IFERROR(INDEX($K$5:$K$204,MATCH(LARGE($M$5:$M$204,2),$M$5:$M$204,0)),"") -> Boya kalemi seti | C6: =IF(B6="","",SUMIFS(Veri!$D$5:$D$2004,Veri!$C$5:$C$2004,B6)) -> 149 | D6: =IF(B6="","",SUMIFS(Veri!$E$5:$E$2004,Veri!$C$5:$C$2004,B6)) -> 22350 | E6: =IF(B6="","",IF(SUM(Veri!$E$5:$E$2004)=0,0,D6/SUM(Veri!$E$5:$E$2004))) -> 0.1931553 | F6: =IF(B6="","",SUM(E$5:E6)) -> 0.58724397 | G6: =IF(B6="","",IF(F5<0.8,"A",IF(F5<0.95,"B","C"))) -> A | H6: =IF(OR(B6="",C6=0),"",D6/C6) -> 150 | I6: =IF(B6="","",SUMPRODUCT(MAX((Veri!$C$5:$C$2004=B6)*Veri!$A$5:$A$2004))) -> 46295 | K6: =IF(2>MAX(Veri!$G$5:$G$2004),"",INDEX(Veri!$C$5:$C$2004,MATCH(2,Veri!$G$5:$G$2004,0))) -> Klasör | L6: =IF(K6="","",SUMIFS(Veri!$E$5:$E$2004,Veri!$C$5:$C$2004,K6)) -> 11325 | M6: =IF(K6="","",L6+ROW()/1000000000) -> 11325
A7: =IF(B7="","",3) -> 3 | B7: =IFERROR(INDEX($K$5:$K$204,MATCH(LARGE($M$5:$M$204,3),$M$5:$M$204,0)),"") -> Hesap makinesi | C7: =IF(B7="","",SUMIFS(Veri!$D$5:$D$2004,Veri!$C$5:$C$2004,B7)) -> 62 | D7: =IF(B7="","",SUMIFS(Veri!$E$5:$E$2004,Veri!$C$5:$C$2004,B7)) -> 21700 | E7: =IF(B7="","",IF(SUM(Veri!$E$5:$E$2004)=0,0,D7/SUM(Veri!$E$5:$E$2004))) -> 0.18753781 | F7: =IF(B7="","",SUM(E$5:E7)) -> 0.77478178 | G7: =IF(B7="","",IF(F6<0.8,"A",IF(F6<0.95,"B","C"))) -> A | H7: =IF(OR(B7="",C7=0),"",D7/C7) -> 350 | I7: =IF(B7="","",SUMPRODUCT(MAX((Veri!$C$5:$C$2004=B7)*Veri!$A$5:$A$2004))) -> 46297 | K7: =IF(3>MAX(Veri!$G$5:$G$2004),"",INDEX(Veri!$C$5:$C$2004,MATCH(3,Veri!$G$5:$G$2004,0))) -> Hesap makinesi | L7: =IF(K7="","",SUMIFS(Veri!$E$5:$E$2004,Veri!$C$5:$C$2004,K7)) -> 21700 | M7: =IF(K7="","",L7+ROW()/1000000000) -> 21700
A8: =IF(B8="","",4) -> 4 | B8: =IFERROR(INDEX($K$5:$K$204,MATCH(LARGE($M$5:$M$204,4),$M$5:$M$204,0)),"") -> Klasör | C8: =IF(B8="","",SUMIFS(Veri!$D$5:$D$2004,Veri!$C$5:$C$2004,B8)) -> 151 | D8: =IF(B8="","",SUMIFS(Veri!$E$5:$E$2004,Veri!$C$5:$C$2004,B8)) -> 11325 | E8: =IF(B8="","",IF(SUM(Veri!$E$5:$E$2004)=0,0,D8/SUM(Veri!$E$5:$E$2004))) -> 0.097873995 | F8: =IF(B8="","",SUM(E$5:E8)) -> 0.87265578 | G8: =IF(B8="","",IF(F7<0.8,"A",IF(F7<0.95,"B","C"))) -> A | H8: =IF(OR(B8="",C8=0),"",D8/C8) -> 75 | I8: =IF(B8="","",SUMPRODUCT(MAX((Veri!$C$5:$C$2004=B8)*Veri!$A$5:$A$2004))) -> 46282 | K8: =IF(4>MAX(Veri!$G$5:$G$2004),"",INDEX(Veri!$C$5:$C$2004,MATCH(4,Veri!$G$5:$G$2004,0))) -> Fotokopi kâğıdı | L8: =IF(K8="","",SUMIFS(Veri!$E$5:$E$2004,Veri!$C$5:$C$2004,K8)) -> 45600 | M8: =IF(K8="","",L8+ROW()/1000000000) -> 45600
A9: =IF(B9="","",5) -> 5 | B9: =IFERROR(INDEX($K$5:$K$204,MATCH(LARGE($M$5:$M$204,5),$M$5:$M$204,0)),"") -> Defter A4 | C9: =IF(B9="","",SUMIFS(Veri!$D$5:$D$2004,Veri!$C$5:$C$2004,B9)) -> 161 | D9: =IF(B9="","",SUMIFS(Veri!$E$5:$E$2004,Veri!$C$5:$C$2004,B9)) -> 9660 | E9: =IF(B9="","",IF(SUM(Veri!$E$5:$E$2004)=0,0,D9/SUM(Veri!$E$5:$E$2004))) -> 0.083484574 | F9: =IF(B9="","",SUM(E$5:E9)) -> 0.95614035 | G9: =IF(B9="","",IF(F8<0.8,"A",IF(F8<0.95,"B","C"))) -> B | H9: =IF(OR(B9="",C9=0),"",D9/C9) -> 60 | I9: =IF(B9="","",SUMPRODUCT(MAX((Veri!$C$5:$C$2004=B9)*Veri!$A$5:$A$2004))) -> 46294 | K9: =IF(5>MAX(Veri!$G$5:$G$2004),"",INDEX(Veri!$C$5:$C$2004,MATCH(5,Veri!$G$5:$G$2004,0))) -> Tükenmez kalem | L9: =IF(K9="","",SUMIFS(Veri!$E$5:$E$2004,Veri!$C$5:$C$2004,K9)) -> 2055 | M9: =IF(K9="","",L9+ROW()/1000000000) -> 2055
A10: =IF(B10="","",6) -> 6 | B10: =IFERROR(INDEX($K$5:$K$204,MATCH(LARGE($M$5:$M$204,6),$M$5:$M$204,0)),"") -> Zımba | C10: =IF(B10="","",SUMIFS(Veri!$D$5:$D$2004,Veri!$C$5:$C$2004,B10)) -> 25 | D10: =IF(B10="","",SUMIFS(Veri!$E$5:$E$2004,Veri!$C$5:$C$2004,B10)) -> 3000 | E10: =IF(B10="","",IF(SUM(Veri!$E$5:$E$2004)=0,0,D10/SUM(Veri!$E$5:$E$2004))) -> 0.025926886 | F10: =IF(B10="","",SUM(E$5:E10)) -> 0.98206724 | G10: =IF(B10="","",IF(F9<0.8,"A",IF(F9<0.95,"B","C"))) -> C | H10: =IF(OR(B10="",C10=0),"",D10/C10) -> 120 | I10: =IF(B10="","",SUMPRODUCT(MAX((Veri!$C$5:$C$2004=B10)*Veri!$A$5:$A$2004))) -> 46280 | K10: =IF(6>MAX(Veri!$G$5:$G$2004),"",INDEX(Veri!$C$5:$C$2004,MATCH(6,Veri!$G$5:$G$2004,0))) -> Boya kalemi seti | L10: =IF(K10="","",SUMIFS(Veri!$E$5:$E$2004,Veri!$C$5:$C$2004,K10)) -> 22350 | M10: =IF(K10="","",L10+ROW()/1000000000) -> 22350
A11: =IF(B11="","",7) -> 7 | B11: =IFERROR(INDEX($K$5:$K$204,MATCH(LARGE($M$5:$M$204,7),$M$5:$M$204,0)),"") -> Tükenmez kalem | C11: =IF(B11="","",SUMIFS(Veri!$D$5:$D$2004,Veri!$C$5:$C$2004,B11)) -> 137 | D11: =IF(B11="","",SUMIFS(Veri!$E$5:$E$2004,Veri!$C$5:$C$2004,B11)) -> 2055 | E11: =IF(B11="","",IF(SUM(Veri!$E$5:$E$2004)=0,0,D11/SUM(Veri!$E$5:$E$2004))) -> 0.017759917 | F11: =IF(B11="","",SUM(E$5:E11)) -> 0.99982715 | G11: =IF(B11="","",IF(F10<0.8,"A",IF(F10<0.95,"B","C"))) -> C | H11: =IF(OR(B11="",C11=0),"",D11/C11) -> 15 | I11: =IF(B11="","",SUMPRODUCT(MAX((Veri!$C$5:$C$2004=B11)*Veri!$A$5:$A$2004))) -> 46298 | K11: =IF(7>MAX(Veri!$G$5:$G$2004),"",INDEX(Veri!$C$5:$C$2004,MATCH(7,Veri!$G$5:$G$2004,0))) -> Silgi | L11: =IF(K11="","",SUMIFS(Veri!$E$5:$E$2004,Veri!$C$5:$C$2004,K11)) -> 20 | M11: =IF(K11="","",L11+ROW()/1000000000) -> 20
A12: =IF(B12="","",8) -> 8 | B12: =IFERROR(INDEX($K$5:$K$204,MATCH(LARGE($M$5:$M$204,8),$M$5:$M$204,0)),"") -> Silgi | C12: =IF(B12="","",SUMIFS(Veri!$D$5:$D$2004,Veri!$C$5:$C$2004,B12)) -> 2 | D12: =IF(B12="","",SUMIFS(Veri!$E$5:$E$2004,Veri!$C$5:$C$2004,B12)) -> 20 | E12: =IF(B12="","",IF(SUM(Veri!$E$5:$E$2004)=0,0,D12/SUM(Veri!$E$5:$E$2004))) -> 0.00017284591 | F12: =IF(B12="","",SUM(E$5:E12)) -> 1 | G12: =IF(B12="","",IF(F11<0.8,"A",IF(F11<0.95,"B","C"))) -> C | H12: =IF(OR(B12="",C12=0),"",D12/C12) -> 10 | I12: =IF(B12="","",SUMPRODUCT(MAX((Veri!$C$5:$C$2004=B12)*Veri!$A$5:$A$2004))) -> 46256 | K12: =IF(8>MAX(Veri!$G$5:$G$2004),"",INDEX(Veri!$C$5:$C$2004,MATCH(8,Veri!$G$5:$G$2004,0))) -> Zımba | L12: =IF(K12="","",SUMIFS(Veri!$E$5:$E$2004,Veri!$C$5:$C$2004,K12)) -> 3000 | M12: =IF(K12="","",L12+ROW()/1000000000) -> 3000
A13: =IF(B13="","",9) | B13: =IFERROR(INDEX($K$5:$K$204,MATCH(LARGE($M$5:$M$204,9),$M$5:$M$204,0)),"") | C13: =IF(B13="","",SUMIFS(Veri!$D$5:$D$2004,Veri!$C$5:$C$2004,B13)) | D13: =IF(B13="","",SUMIFS(Veri!$E$5:$E$2004,Veri!$C$5:$C$2004,B13)) | E13: =IF(B13="","",IF(SUM(Veri!$E$5:$E$2004)=0,0,D13/SUM(Veri!$E$5:$E$2004))) | F13: =IF(B13="","",SUM(E$5:E13)) | G13: =IF(B13="","",IF(F12<0.8,"A",IF(F12<0.95,"B","C"))) | H13: =IF(OR(B13="",C13=0),"",D13/C13) | I13: =IF(B13="","",SUMPRODUCT(MAX((Veri!$C$5:$C$2004=B13)*Veri!$A$5:$A$2004))) | K13: =IF(9>MAX(Veri!$G$5:$G$2004),"",INDEX(Veri!$C$5:$C$2004,MATCH(9,Veri!$G$5:$G$2004,0))) | L13: =IF(K13="","",SUMIFS(Veri!$E$5:$E$2004,Veri!$C$5:$C$2004,K13)) | M13: =IF(K13="","",L13+ROW()/1000000000)
A14: =IF(B14="","",10) | B14: =IFERROR(INDEX($K$5:$K$204,MATCH(LARGE($M$5:$M$204,10),$M$5:$M$204,0)),"") | C14: =IF(B14="","",SUMIFS(Veri!$D$5:$D$2004,Veri!$C$5:$C$2004,B14)) | D14: =IF(B14="","",SUMIFS(Veri!$E$5:$E$2004,Veri!$C$5:$C$2004,B14)) | E14: =IF(B14="","",IF(SUM(Veri!$E$5:$E$2004)=0,0,D14/SUM(Veri!$E$5:$E$2004))) | F14: =IF(B14="","",SUM(E$5:E14)) | G14: =IF(B14="","",IF(F13<0.8,"A",IF(F13<0.95,"B","C"))) | H14: =IF(OR(B14="",C14=0),"",D14/C14) | I14: =IF(B14="","",SUMPRODUCT(MAX((Veri!$C$5:$C$2004=B14)*Veri!$A$5:$A$2004))) | K14: =IF(10>MAX(Veri!$G$5:$G$2004),"",INDEX(Veri!$C$5:$C$2004,MATCH(10,Veri!$G$5:$G$2004,0))) | L14: =IF(K14="","",SUMIFS(Veri!$E$5:$E$2004,Veri!$C$5:$C$2004,K14)) | M14: =IF(K14="","",L14+ROW()/1000000000)
A15: =IF(B15="","",11) | B15: =IFERROR(INDEX($K$5:$K$204,MATCH(LARGE($M$5:$M$204,11),$M$5:$M$204,0)),"") | C15: =IF(B15="","",SUMIFS(Veri!$D$5:$D$2004,Veri!$C$5:$C$2004,B15)) | D15: =IF(B15="","",SUMIFS(Veri!$E$5:$E$2004,Veri!$C$5:$C$2004,B15)) | E15: =IF(B15="","",IF(SUM(Veri!$E$5:$E$2004)=0,0,D15/SUM(Veri!$E$5:$E$2004))) | F15: =IF(B15="","",SUM(E$5:E15)) | G15: =IF(B15="","",IF(F14<0.8,"A",IF(F14<0.95,"B","C"))) | H15: =IF(OR(B15="",C15=0),"",D15/C15) | I15: =IF(B15="","",SUMPRODUCT(MAX((Veri!$C$5:$C$2004=B15)*Veri!$A$5:$A$2004))) | K15: =IF(11>MAX(Veri!$G$5:$G$2004),"",INDEX(Veri!$C$5:$C$2004,MATCH(11,Veri!$G$5:$G$2004,0))) | L15: =IF(K15="","",SUMIFS(Veri!$E$5:$E$2004,Veri!$C$5:$C$2004,K15)) | M15: =IF(K15="","",L15+ROW()/1000000000)
A16: =IF(B16="","",12) | B16: =IFERROR(INDEX($K$5:$K$204,MATCH(LARGE($M$5:$M$204,12),$M$5:$M$204,0)),"") | C16: =IF(B16="","",SUMIFS(Veri!$D$5:$D$2004,Veri!$C$5:$C$2004,B16)) | D16: =IF(B16="","",SUMIFS(Veri!$E$5:$E$2004,Veri!$C$5:$C$2004,B16)) | E16: =IF(B16="","",IF(SUM(Veri!$E$5:$E$2004)=0,0,D16/SUM(Veri!$E$5:$E$2004))) | F16: =IF(B16="","",SUM(E$5:E16)) | G16: =IF(B16="","",IF(F15<0.8,"A",IF(F15<0.95,"B","C"))) | H16: =IF(OR(B16="",C16=0),"",D16/C16) | I16: =IF(B16="","",SUMPRODUCT(MAX((Veri!$C$5:$C$2004=B16)*Veri!$A$5:$A$2004))) | K16: =IF(12>MAX(Veri!$G$5:$G$2004),"",INDEX(Veri!$C$5:$C$2004,MATCH(12,Veri!$G$5:$G$2004,0))) | L16: =IF(K16="","",SUMIFS(Veri!$E$5:$E$2004,Veri!$C$5:$C$2004,K16)) | M16: =IF(K16="","",L16+ROW()/1000000000)
A17: =IF(B17="","",13) | B17: =IFERROR(INDEX($K$5:$K$204,MATCH(LARGE($M$5:$M$204,13),$M$5:$M$204,0)),"") | C17: =IF(B17="","",SUMIFS(Veri!$D$5:$D$2004,Veri!$C$5:$C$2004,B17)) | D17: =IF(B17="","",SUMIFS(Veri!$E$5:$E$2004,Veri!$C$5:$C$2004,B17)) | E17: =IF(B17="","",IF(SUM(Veri!$E$5:$E$2004)=0,0,D17/SUM(Veri!$E$5:$E$2004))) | F17: =IF(B17="","",SUM(E$5:E17)) | G17: =IF(B17="","",IF(F16<0.8,"A",IF(F16<0.95,"B","C"))) | H17: =IF(OR(B17="",C17=0),"",D17/C17) | I17: =IF(B17="","",SUMPRODUCT(MAX((Veri!$C$5:$C$2004=B17)*Veri!$A$5:$A$2004))) | K17: =IF(13>MAX(Veri!$G$5:$G$2004),"",INDEX(Veri!$C$5:$C$2004,MATCH(13,Veri!$G$5:$G$2004,0))) | L17: =IF(K17="","",SUMIFS(Veri!$E$5:$E$2004,Veri!$C$5:$C$2004,K17)) | M17: =IF(K17="","",L17+ROW()/1000000000)
A18: =IF(B18="","",14) | B18: =IFERROR(INDEX($K$5:$K$204,MATCH(LARGE($M$5:$M$204,14),$M$5:$M$204,0)),"") | C18: =IF(B18="","",SUMIFS(Veri!$D$5:$D$2004,Veri!$C$5:$C$2004,B18)) | D18: =IF(B18="","",SUMIFS(Veri!$E$5:$E$2004,Veri!$C$5:$C$2004,B18)) | E18: =IF(B18="","",IF(SUM(Veri!$E$5:$E$2004)=0,0,D18/SUM(Veri!$E$5:$E$2004))) | F18: =IF(B18="","",SUM(E$5:E18)) | G18: =IF(B18="","",IF(F17<0.8,"A",IF(F17<0.95,"B","C"))) | H18: =IF(OR(B18="",C18=0),"",D18/C18) | I18: =IF(B18="","",SUMPRODUCT(MAX((Veri!$C$5:$C$2004=B18)*Veri!$A$5:$A$2004))) | K18: =IF(14>MAX(Veri!$G$5:$G$2004),"",INDEX(Veri!$C$5:$C$2004,MATCH(14,Veri!$G$5:$G$2004,0))) | L18: =IF(K18="","",SUMIFS(Veri!$E$5:$E$2004,Veri!$C$5:$C$2004,K18)) | M18: =IF(K18="","",L18+ROW()/1000000000)
A19: =IF(B19="","",15) | B19: =IFERROR(INDEX($K$5:$K$204,MATCH(LARGE($M$5:$M$204,15),$M$5:$M$204,0)),"") | C19: =IF(B19="","",SUMIFS(Veri!$D$5:$D$2004,Veri!$C$5:$C$2004,B19)) | D19: =IF(B19="","",SUMIFS(Veri!$E$5:$E$2004,Veri!$C$5:$C$2004,B19)) | E19: =IF(B19="","",IF(SUM(Veri!$E$5:$E$2004)=0,0,D19/SUM(Veri!$E$5:$E$2004))) | F19: =IF(B19="","",SUM(E$5:E19)) | G19: =IF(B19="","",IF(F18<0.8,"A",IF(F18<0.95,"B","C"))) | H19: =IF(OR(B19="",C19=0),"",D19/C19) | I19: =IF(B19="","",SUMPRODUCT(MAX((Veri!$C$5:$C$2004=B19)*Veri!$A$5:$A$2004))) | K19: =IF(15>MAX(Veri!$G$5:$G$2004),"",INDEX(Veri!$C$5:$C$2004,MATCH(15,Veri!$G$5:$G$2004,0))) | L19: =IF(K19="","",SUMIFS(Veri!$E$5:$E$2004,Veri!$C$5:$C$2004,K19)) | M19: =IF(K19="","",L19+ROW()/1000000000)
A20: =IF(B20="","",16) | B20: =IFERROR(INDEX($K$5:$K$204,MATCH(LARGE($M$5:$M$204,16),$M$5:$M$204,0)),"") | C20: =IF(B20="","",SUMIFS(Veri!$D$5:$D$2004,Veri!$C$5:$C$2004,B20)) | D20: =IF(B20="","",SUMIFS(Veri!$E$5:$E$2004,Veri!$C$5:$C$2004,B20)) | E20: =IF(B20="","",IF(SUM(Veri!$E$5:$E$2004)=0,0,D20/SUM(Veri!$E$5:$E$2004))) | F20: =IF(B20="","",SUM(E$5:E20)) | G20: =IF(B20="","",IF(F19<0.8,"A",IF(F19<0.95,"B","C"))) | H20: =IF(OR(B20="",C20=0),"",D20/C20) | I20: =IF(B20="","",SUMPRODUCT(MAX((Veri!$C$5:$C$2004=B20)*Veri!$A$5:$A$2004))) | K20: =IF(16>MAX(Veri!$G$5:$G$2004),"",INDEX(Veri!$C$5:$C$2004,MATCH(16,Veri!$G$5:$G$2004,0))) | L20: =IF(K20="","",SUMIFS(Veri!$E$5:$E$2004,Veri!$C$5:$C$2004,K20)) | M20: =IF(K20="","",L20+ROW()/1000000000)
A21: =IF(B21="","",17) | B21: =IFERROR(INDEX($K$5:$K$204,MATCH(LARGE($M$5:$M$204,17),$M$5:$M$204,0)),"") | C21: =IF(B21="","",SUMIFS(Veri!$D$5:$D$2004,Veri!$C$5:$C$2004,B21)) | D21: =IF(B21="","",SUMIFS(Veri!$E$5:$E$2004,Veri!$C$5:$C$2004,B21)) | E21: =IF(B21="","",IF(SUM(Veri!$E$5:$E$2004)=0,0,D21/SUM(Veri!$E$5:$E$2004))) | F21: =IF(B21="","",SUM(E$5:E21)) | G21: =IF(B21="","",IF(F20<0.8,"A",IF(F20<0.95,"B","C"))) | H21: =IF(OR(B21="",C21=0),"",D21/C21) | I21: =IF(B21="","",SUMPRODUCT(MAX((Veri!$C$5:$C$2004=B21)*Veri!$A$5:$A$2004))) | K21: =IF(17>MAX(Veri!$G$5:$G$2004),"",INDEX(Veri!$C$5:$C$2004,MATCH(17,Veri!$G$5:$G$2004,0))) | L21: =IF(K21="","",SUMIFS(Veri!$E$5:$E$2004,Veri!$C$5:$C$2004,K21)) | M21: =IF(K21="","",L21+ROW()/1000000000)
A22: =IF(B22="","",18) | B22: =IFERROR(INDEX($K$5:$K$204,MATCH(LARGE($M$5:$M$204,18),$M$5:$M$204,0)),"") | C22: =IF(B22="","",SUMIFS(Veri!$D$5:$D$2004,Veri!$C$5:$C$2004,B22)) | D22: =IF(B22="","",SUMIFS(Veri!$E$5:$E$2004,Veri!$C$5:$C$2004,B22)) | E22: =IF(B22="","",IF(SUM(Veri!$E$5:$E$2004)=0,0,D22/SUM(Veri!$E$5:$E$2004))) | F22: =IF(B22="","",SUM(E$5:E22)) | G22: =IF(B22="","",IF(F21<0.8,"A",IF(F21<0.95,"B","C"))) | H22: =IF(OR(B22="",C22=0),"",D22/C22) | I22: =IF(B22="","",SUMPRODUCT(MAX((Veri!$C$5:$C$2004=B22)*Veri!$A$5:$A$2004))) | K22: =IF(18>MAX(Veri!$G$5:$G$2004),"",INDEX(Veri!$C$5:$C$2004,MATCH(18,Veri!$G$5:$G$2004,0))) | L22: =IF(K22="","",SUMIFS(Veri!$E$5:$E$2004,Veri!$C$5:$C$2004,K22)) | M22: =IF(K22="","",L22+ROW()/1000000000)
A23: =IF(B23="","",19) | B23: =IFERROR(INDEX($K$5:$K$204,MATCH(LARGE($M$5:$M$204,19),$M$5:$M$204,0)),"") | C23: =IF(B23="","",SUMIFS(Veri!$D$5:$D$2004,Veri!$C$5:$C$2004,B23)) | D23: =IF(B23="","",SUMIFS(Veri!$E$5:$E$2004,Veri!$C$5:$C$2004,B23)) | E23: =IF(B23="","",IF(SUM(Veri!$E$5:$E$2004)=0,0,D23/SUM(Veri!$E$5:$E$2004))) | F23: =IF(B23="","",SUM(E$5:E23)) | G23: =IF(B23="","",IF(F22<0.8,"A",IF(F22<0.95,"B","C"))) | H23: =IF(OR(B23="",C23=0),"",D23/C23) | I23: =IF(B23="","",SUMPRODUCT(MAX((Veri!$C$5:$C$2004=B23)*Veri!$A$5:$A$2004))) | K23: =IF(19>MAX(Veri!$G$5:$G$2004),"",INDEX(Veri!$C$5:$C$2004,MATCH(19,Veri!$G$5:$G$2004,0))) | L23: =IF(K23="","",SUMIFS(Veri!$E$5:$E$2004,Veri!$C$5:$C$2004,K23)) | M23: =IF(K23="","",L23+ROW()/1000000000)
A24: =IF(B24="","",20) | B24: =IFERROR(INDEX($K$5:$K$204,MATCH(LARGE($M$5:$M$204,20),$M$5:$M$204,0)),"") | C24: =IF(B24="","",SUMIFS(Veri!$D$5:$D$2004,Veri!$C$5:$C$2004,B24)) | D24: =IF(B24="","",SUMIFS(Veri!$E$5:$E$2004,Veri!$C$5:$C$2004,B24)) | E24: =IF(B24="","",IF(SUM(Veri!$E$5:$E$2004)=0,0,D24/SUM(Veri!$E$5:$E$2004))) | F24: =IF(B24="","",SUM(E$5:E24)) | G24: =IF(B24="","",IF(F23<0.8,"A",IF(F23<0.95,"B","C"))) | H24: =IF(OR(B24="",C24=0),"",D24/C24) | I24: =IF(B24="","",SUMPRODUCT(MAX((Veri!$C$5:$C$2004=B24)*Veri!$A$5:$A$2004))) | K24: =IF(20>MAX(Veri!$G$5:$G$2004),"",INDEX(Veri!$C$5:$C$2004,MATCH(20,Veri!$G$5:$G$2004,0))) | L24: =IF(K24="","",SUMIFS(Veri!$E$5:$E$2004,Veri!$C$5:$C$2004,K24)) | M24: =IF(K24="","",L24+ROW()/1000000000)
A25: =IF(B25="","",21) | B25: =IFERROR(INDEX($K$5:$K$204,MATCH(LARGE($M$5:$M$204,21),$M$5:$M$204,0)),"") | C25: =IF(B25="","",SUMIFS(Veri!$D$5:$D$2004,Veri!$C$5:$C$2004,B25)) | D25: =IF(B25="","",SUMIFS(Veri!$E$5:$E$2004,Veri!$C$5:$C$2004,B25)) | E25: =IF(B25="","",IF(SUM(Veri!$E$5:$E$2004)=0,0,D25/SUM(Veri!$E$5:$E$2004))) | F25: =IF(B25="","",SUM(E$5:E25)) | G25: =IF(B25="","",IF(F24<0.8,"A",IF(F24<0.95,"B","C"))) | H25: =IF(OR(B25="",C25=0),"",D25/C25) | I25: =IF(B25="","",SUMPRODUCT(MAX((Veri!$C$5:$C$2004=B25)*Veri!$A$5:$A$2004))) | K25: =IF(21>MAX(Veri!$G$5:$G$2004),"",INDEX(Veri!$C$5:$C$2004,MATCH(21,Veri!$G$5:$G$2004,0))) | L25: =IF(K25="","",SUMIFS(Veri!$E$5:$E$2004,Veri!$C$5:$C$2004,K25)) | M25: =IF(K25="","",L25+ROW()/1000000000)
A26: =IF(B26="","",22) | B26: =IFERROR(INDEX($K$5:$K$204,MATCH(LARGE($M$5:$M$204,22),$M$5:$M$204,0)),"") | C26: =IF(B26="","",SUMIFS(Veri!$D$5:$D$2004,Veri!$C$5:$C$2004,B26)) | D26: =IF(B26="","",SUMIFS(Veri!$E$5:$E$2004,Veri!$C$5:$C$2004,B26)) | E26: =IF(B26="","",IF(SUM(Veri!$E$5:$E$2004)=0,0,D26/SUM(Veri!$E$5:$E$2004))) | F26: =IF(B26="","",SUM(E$5:E26)) | G26: =IF(B26="","",IF(F25<0.8,"A",IF(F25<0.95,"B","C"))) | H26: =IF(OR(B26="",C26=0),"",D26/C26) | I26: =IF(B26="","",SUMPRODUCT(MAX((Veri!$C$5:$C$2004=B26)*Veri!$A$5:$A$2004))) | K26: =IF(22>MAX(Veri!$G$5:$G$2004),"",INDEX(Veri!$C$5:$C$2004,MATCH(22,Veri!$G$5:$G$2004,0))) | L26: =IF(K26="","",SUMIFS(Veri!$E$5:$E$2004,Veri!$C$5:$C$2004,K26)) | M26: =IF(K26="","",L26+ROW()/1000000000)
A27: =IF(B27="","",23) | B27: =IFERROR(INDEX($K$5:$K$204,MATCH(LARGE($M$5:$M$204,23),$M$5:$M$204,0)),"") | C27: =IF(B27="","",SUMIFS(Veri!$D$5:$D$2004,Veri!$C$5:$C$2004,B27)) | D27: =IF(B27="","",SUMIFS(Veri!$E$5:$E$2004,Veri!$C$5:$C$2004,B27)) | E27: =IF(B27="","",IF(SUM(Veri!$E$5:$E$2004)=0,0,D27/SUM(Veri!$E$5:$E$2004))) | F27: =IF(B27="","",SUM(E$5:E27)) | G27: =IF(B27="","",IF(F26<0.8,"A",IF(F26<0.95,"B","C"))) | H27: =IF(OR(B27="",C27=0),"",D27/C27) | I27: =IF(B27="","",SUMPRODUCT(MAX((Veri!$C$5:$C$2004=B27)*Veri!$A$5:$A$2004))) | K27: =IF(23>MAX(Veri!$G$5:$G$2004),"",INDEX(Veri!$C$5:$C$2004,MATCH(23,Veri!$G$5:$G$2004,0))) | L27: =IF(K27="","",SUMIFS(Veri!$E$5:$E$2004,Veri!$C$5:$C$2004,K27)) | M27: =IF(K27="","",L27+ROW()/1000000000)
A28: =IF(B28="","",24) | B28: =IFERROR(INDEX($K$5:$K$204,MATCH(LARGE($M$5:$M$204,24),$M$5:$M$204,0)),"") | C28: =IF(B28="","",SUMIFS(Veri!$D$5:$D$2004,Veri!$C$5:$C$2004,B28)) | D28: =IF(B28="","",SUMIFS(Veri!$E$5:$E$2004,Veri!$C$5:$C$2004,B28)) | E28: =IF(B28="","",IF(SUM(Veri!$E$5:$E$2004)=0,0,D28/SUM(Veri!$E$5:$E$2004))) | F28: =IF(B28="","",SUM(E$5:E28)) | G28: =IF(B28="","",IF(F27<0.8,"A",IF(F27<0.95,"B","C"))) | H28: =IF(OR(B28="",C28=0),"",D28/C28) | I28: =IF(B28="","",SUMPRODUCT(MAX((Veri!$C$5:$C$2004=B28)*Veri!$A$5:$A$2004))) | K28: =IF(24>MAX(Veri!$G$5:$G$2004),"",INDEX(Veri!$C$5:$C$2004,MATCH(24,Veri!$G$5:$G$2004,0))) | L28: =IF(K28="","",SUMIFS(Veri!$E$5:$E$2004,Veri!$C$5:$C$2004,K28)) | M28: =IF(K28="","",L28+ROW()/1000000000)
A29: =IF(B29="","",25) | B29: =IFERROR(INDEX($K$5:$K$204,MATCH(LARGE($M$5:$M$204,25),$M$5:$M$204,0)),"") | C29: =IF(B29="","",SUMIFS(Veri!$D$5:$D$2004,Veri!$C$5:$C$2004,B29)) | D29: =IF(B29="","",SUMIFS(Veri!$E$5:$E$2004,Veri!$C$5:$C$2004,B29)) | E29: =IF(B29="","",IF(SUM(Veri!$E$5:$E$2004)=0,0,D29/SUM(Veri!$E$5:$E$2004))) | F29: =IF(B29="","",SUM(E$5:E29)) | G29: =IF(B29="","",IF(F28<0.8,"A",IF(F28<0.95,"B","C"))) | H29: =IF(OR(B29="",C29=0),"",D29/C29) | I29: =IF(B29="","",SUMPRODUCT(MAX((Veri!$C$5:$C$2004=B29)*Veri!$A$5:$A$2004))) | K29: =IF(25>MAX(Veri!$G$5:$G$2004),"",INDEX(Veri!$C$5:$C$2004,MATCH(25,Veri!$G$5:$G$2004,0))) | L29: =IF(K29="","",SUMIFS(Veri!$E$5:$E$2004,Veri!$C$5:$C$2004,K29)) | M29: =IF(K29="","",L29+ROW()/1000000000)
A30: =IF(B30="","",26) | B30: =IFERROR(INDEX($K$5:$K$204,MATCH(LARGE($M$5:$M$204,26),$M$5:$M$204,0)),"") | C30: =IF(B30="","",SUMIFS(Veri!$D$5:$D$2004,Veri!$C$5:$C$2004,B30)) | D30: =IF(B30="","",SUMIFS(Veri!$E$5:$E$2004,Veri!$C$5:$C$2004,B30)) | E30: =IF(B30="","",IF(SUM(Veri!$E$5:$E$2004)=0,0,D30/SUM(Veri!$E$5:$E$2004))) | F30: =IF(B30="","",SUM(E$5:E30)) | G30: =IF(B30="","",IF(F29<0.8,"A",IF(F29<0.95,"B","C"))) | H30: =IF(OR(B30="",C30=0),"",D30/C30) | I30: =IF(B30="","",SUMPRODUCT(MAX((Veri!$C$5:$C$2004=B30)*Veri!$A$5:$A$2004))) | K30: =IF(26>MAX(Veri!$G$5:$G$2004),"",INDEX(Veri!$C$5:$C$2004,MATCH(26,Veri!$G$5:$G$2004,0))) | L30: =IF(K30="","",SUMIFS(Veri!$E$5:$E$2004,Veri!$C$5:$C$2004,K30)) | M30: =IF(K30="","",L30+ROW()/1000000000)
A31: =IF(B31="","",27) | B31: =IFERROR(INDEX($K$5:$K$204,MATCH(LARGE($M$5:$M$204,27),$M$5:$M$204,0)),"") | C31: =IF(B31="","",SUMIFS(Veri!$D$5:$D$2004,Veri!$C$5:$C$2004,B31)) | D31: =IF(B31="","",SUMIFS(Veri!$E$5:$E$2004,Veri!$C$5:$C$2004,B31)) | E31: =IF(B31="","",IF(SUM(Veri!$E$5:$E$2004)=0,0,D31/SUM(Veri!$E$5:$E$2004))) | F31: =IF(B31="","",SUM(E$5:E31)) | G31: =IF(B31="","",IF(F30<0.8,"A",IF(F30<0.95,"B","C"))) | H31: =IF(OR(B31="",C31=0),"",D31/C31) | I31: =IF(B31="","",SUMPRODUCT(MAX((Veri!$C$5:$C$2004=B31)*Veri!$A$5:$A$2004))) | K31: =IF(27>MAX(Veri!$G$5:$G$2004),"",INDEX(Veri!$C$5:$C$2004,MATCH(27,Veri!$G$5:$G$2004,0))) | L31: =IF(K31="","",SUMIFS(Veri!$E$5:$E$2004,Veri!$C$5:$C$2004,K31)) | M31: =IF(K31="","",L31+ROW()/1000000000)
A32: =IF(B32="","",28) | B32: =IFERROR(INDEX($K$5:$K$204,MATCH(LARGE($M$5:$M$204,28),$M$5:$M$204,0)),"") | C32: =IF(B32="","",SUMIFS(Veri!$D$5:$D$2004,Veri!$C$5:$C$2004,B32)) | D32: =IF(B32="","",SUMIFS(Veri!$E$5:$E$2004,Veri!$C$5:$C$2004,B32)) | E32: =IF(B32="","",IF(SUM(Veri!$E$5:$E$2004)=0,0,D32/SUM(Veri!$E$5:$E$2004))) | F32: =IF(B32="","",SUM(E$5:E32)) | G32: =IF(B32="","",IF(F31<0.8,"A",IF(F31<0.95,"B","C"))) | H32: =IF(OR(B32="",C32=0),"",D32/C32) | I32: =IF(B32="","",SUMPRODUCT(MAX((Veri!$C$5:$C$2004=B32)*Veri!$A$5:$A$2004))) | K32: =IF(28>MAX(Veri!$G$5:$G$2004),"",INDEX(Veri!$C$5:$C$2004,MATCH(28,Veri!$G$5:$G$2004,0))) | L32: =IF(K32="","",SUMIFS(Veri!$E$5:$E$2004,Veri!$C$5:$C$2004,K32)) | M32: =IF(K32="","",L32+ROW()/1000000000)
A33: =IF(B33="","",29) | B33: =IFERROR(INDEX($K$5:$K$204,MATCH(LARGE($M$5:$M$204,29),$M$5:$M$204,0)),"") | C33: =IF(B33="","",SUMIFS(Veri!$D$5:$D$2004,Veri!$C$5:$C$2004,B33)) | D33: =IF(B33="","",SUMIFS(Veri!$E$5:$E$2004,Veri!$C$5:$C$2004,B33)) | E33: =IF(B33="","",IF(SUM(Veri!$E$5:$E$2004)=0,0,D33/SUM(Veri!$E$5:$E$2004))) | F33: =IF(B33="","",SUM(E$5:E33)) | G33: =IF(B33="","",IF(F32<0.8,"A",IF(F32<0.95,"B","C"))) | H33: =IF(OR(B33="",C33=0),"",D33/C33) | I33: =IF(B33="","",SUMPRODUCT(MAX((Veri!$C$5:$C$2004=B33)*Veri!$A$5:$A$2004))) | K33: =IF(29>MAX(Veri!$G$5:$G$2004),"",INDEX(Veri!$C$5:$C$2004,MATCH(29,Veri!$G$5:$G$2004,0))) | L33: =IF(K33="","",SUMIFS(Veri!$E$5:$E$2004,Veri!$C$5:$C$2004,K33)) | M33: =IF(K33="","",L33+ROW()/1000000000)
A34: =IF(B34="","",30) | B34: =IFERROR(INDEX($K$5:$K$204,MATCH(LARGE($M$5:$M$204,30),$M$5:$M$204,0)),"") | C34: =IF(B34="","",SUMIFS(Veri!$D$5:$D$2004,Veri!$C$5:$C$2004,B34)) | D34: =IF(B34="","",SUMIFS(Veri!$E$5:$E$2004,Veri!$C$5:$C$2004,B34)) | E34: =IF(B34="","",IF(SUM(Veri!$E$5:$E$2004)=0,0,D34/SUM(Veri!$E$5:$E$2004))) | F34: =IF(B34="","",SUM(E$5:E34)) | G34: =IF(B34="","",IF(F33<0.8,"A",IF(F33<0.95,"B","C"))) | H34: =IF(OR(B34="",C34=0),"",D34/C34) | I34: =IF(B34="","",SUMPRODUCT(MAX((Veri!$C$5:$C$2004=B34)*Veri!$A$5:$A$2004))) | K34: =IF(30>MAX(Veri!$G$5:$G$2004),"",INDEX(Veri!$C$5:$C$2004,MATCH(30,Veri!$G$5:$G$2004,0))) | L34: =IF(K34="","",SUMIFS(Veri!$E$5:$E$2004,Veri!$C$5:$C$2004,K34)) | M34: =IF(K34="","",L34+ROW()/1000000000)
A35: =IF(B35="","",31) | B35: =IFERROR(INDEX($K$5:$K$204,MATCH(LARGE($M$5:$M$204,31),$M$5:$M$204,0)),"") | C35: =IF(B35="","",SUMIFS(Veri!$D$5:$D$2004,Veri!$C$5:$C$2004,B35)) | D35: =IF(B35="","",SUMIFS(Veri!$E$5:$E$2004,Veri!$C$5:$C$2004,B35)) | E35: =IF(B35="","",IF(SUM(Veri!$E$5:$E$2004)=0,0,D35/SUM(Veri!$E$5:$E$2004))) | F35: =IF(B35="","",SUM(E$5:E35)) | G35: =IF(B35="","",IF(F34<0.8,"A",IF(F34<0.95,"B","C"))) | H35: =IF(OR(B35="",C35=0),"",D35/C35) | I35: =IF(B35="","",SUMPRODUCT(MAX((Veri!$C$5:$C$2004=B35)*Veri!$A$5:$A$2004))) | K35: =IF(31>MAX(Veri!$G$5:$G$2004),"",INDEX(Veri!$C$5:$C$2004,MATCH(31,Veri!$G$5:$G$2004,0))) | L35: =IF(K35="","",SUMIFS(Veri!$E$5:$E$2004,Veri!$C$5:$C$2004,K35)) | M35: =IF(K35="","",L35+ROW()/1000000000)
A36: =IF(B36="","",32) | B36: =IFERROR(INDEX($K$5:$K$204,MATCH(LARGE($M$5:$M$204,32),$M$5:$M$204,0)),"") | C36: =IF(B36="","",SUMIFS(Veri!$D$5:$D$2004,Veri!$C$5:$C$2004,B36)) | D36: =IF(B36="","",SUMIFS(Veri!$E$5:$E$2004,Veri!$C$5:$C$2004,B36)) | E36: =IF(B36="","",IF(SUM(Veri!$E$5:$E$2004)=0,0,D36/SUM(Veri!$E$5:$E$2004))) | F36: =IF(B36="","",SUM(E$5:E36)) | G36: =IF(B36="","",IF(F35<0.8,"A",IF(F35<0.95,"B","C"))) | H36: =IF(OR(B36="",C36=0),"",D36/C36) | I36: =IF(B36="","",SUMPRODUCT(MAX((Veri!$C$5:$C$2004=B36)*Veri!$A$5:$A$2004))) | K36: =IF(32>MAX(Veri!$G$5:$G$2004),"",INDEX(Veri!$C$5:$C$2004,MATCH(32,Veri!$G$5:$G$2004,0))) | L36: =IF(K36="","",SUMIFS(Veri!$E$5:$E$2004,Veri!$C$5:$C$2004,K36)) | M36: =IF(K36="","",L36+ROW()/1000000000)
A37: =IF(B37="","",33) | B37: =IFERROR(INDEX($K$5:$K$204,MATCH(LARGE($M$5:$M$204,33),$M$5:$M$204,0)),"") | C37: =IF(B37="","",SUMIFS(Veri!$D$5:$D$2004,Veri!$C$5:$C$2004,B37)) | D37: =IF(B37="","",SUMIFS(Veri!$E$5:$E$2004,Veri!$C$5:$C$2004,B37)) | E37: =IF(B37="","",IF(SUM(Veri!$E$5:$E$2004)=0,0,D37/SUM(Veri!$E$5:$E$2004))) | F37: =IF(B37="","",SUM(E$5:E37)) | G37: =IF(B37="","",IF(F36<0.8,"A",IF(F36<0.95,"B","C"))) | H37: =IF(OR(B37="",C37=0),"",D37/C37) | I37: =IF(B37="","",SUMPRODUCT(MAX((Veri!$C$5:$C$2004=B37)*Veri!$A$5:$A$2004))) | K37: =IF(33>MAX(Veri!$G$5:$G$2004),"",INDEX(Veri!$C$5:$C$2004,MATCH(33,Veri!$G$5:$G$2004,0))) | L37: =IF(K37="","",SUMIFS(Veri!$E$5:$E$2004,Veri!$C$5:$C$2004,K37)) | M37: =IF(K37="","",L37+ROW()/1000000000)
A38: =IF(B38="","",34) | B38: =IFERROR(INDEX($K$5:$K$204,MATCH(LARGE($M$5:$M$204,34),$M$5:$M$204,0)),"") | C38: =IF(B38="","",SUMIFS(Veri!$D$5:$D$2004,Veri!$C$5:$C$2004,B38)) | D38: =IF(B38="","",SUMIFS(Veri!$E$5:$E$2004,Veri!$C$5:$C$2004,B38)) | E38: =IF(B38="","",IF(SUM(Veri!$E$5:$E$2004)=0,0,D38/SUM(Veri!$E$5:$E$2004))) | F38: =IF(B38="","",SUM(E$5:E38)) | G38: =IF(B38="","",IF(F37<0.8,"A",IF(F37<0.95,"B","C"))) | H38: =IF(OR(B38="",C38=0),"",D38/C38) | I38: =IF(B38="","",SUMPRODUCT(MAX((Veri!$C$5:$C$2004=B38)*Veri!$A$5:$A$2004))) | K38: =IF(34>MAX(Veri!$G$5:$G$2004),"",INDEX(Veri!$C$5:$C$2004,MATCH(34,Veri!$G$5:$G$2004,0))) | L38: =IF(K38="","",SUMIFS(Veri!$E$5:$E$2004,Veri!$C$5:$C$2004,K38)) | M38: =IF(K38="","",L38+ROW()/1000000000)
A39: =IF(B39="","",35) | B39: =IFERROR(INDEX($K$5:$K$204,MATCH(LARGE($M$5:$M$204,35),$M$5:$M$204,0)),"") | C39: =IF(B39="","",SUMIFS(Veri!$D$5:$D$2004,Veri!$C$5:$C$2004,B39)) | D39: =IF(B39="","",SUMIFS(Veri!$E$5:$E$2004,Veri!$C$5:$C$2004,B39)) | E39: =IF(B39="","",IF(SUM(Veri!$E$5:$E$2004)=0,0,D39/SUM(Veri!$E$5:$E$2004))) | F39: =IF(B39="","",SUM(E$5:E39)) | G39: =IF(B39="","",IF(F38<0.8,"A",IF(F38<0.95,"B","C"))) | H39: =IF(OR(B39="",C39=0),"",D39/C39) | I39: =IF(B39="","",SUMPRODUCT(MAX((Veri!$C$5:$C$2004=B39)*Veri!$A$5:$A$2004))) | K39: =IF(35>MAX(Veri!$G$5:$G$2004),"",INDEX(Veri!$C$5:$C$2004,MATCH(35,Veri!$G$5:$G$2004,0))) | L39: =IF(K39="","",SUMIFS(Veri!$E$5:$E$2004,Veri!$C$5:$C$2004,K39)) | M39: =IF(K39="","",L39+ROW()/1000000000)
A40: =IF(B40="","",36) | B40: =IFERROR(INDEX($K$5:$K$204,MATCH(LARGE($M$5:$M$204,36),$M$5:$M$204,0)),"") | C40: =IF(B40="","",SUMIFS(Veri!$D$5:$D$2004,Veri!$C$5:$C$2004,B40)) | D40: =IF(B40="","",SUMIFS(Veri!$E$5:$E$2004,Veri!$C$5:$C$2004,B40)) | E40: =IF(B40="","",IF(SUM(Veri!$E$5:$E$2004)=0,0,D40/SUM(Veri!$E$5:$E$2004))) | F40: =IF(B40="","",SUM(E$5:E40)) | G40: =IF(B40="","",IF(F39<0.8,"A",IF(F39<0.95,"B","C"))) | H40: =IF(OR(B40="",C40=0),"",D40/C40) | I40: =IF(B40="","",SUMPRODUCT(MAX((Veri!$C$5:$C$2004=B40)*Veri!$A$5:$A$2004))) | K40: =IF(36>MAX(Veri!$G$5:$G$2004),"",INDEX(Veri!$C$5:$C$2004,MATCH(36,Veri!$G$5:$G$2004,0))) | L40: =IF(K40="","",SUMIFS(Veri!$E$5:$E$2004,Veri!$C$5:$C$2004,K40)) | M40: =IF(K40="","",L40+ROW()/1000000000)
A41: =IF(B41="","",37) | B41: =IFERROR(INDEX($K$5:$K$204,MATCH(LARGE($M$5:$M$204,37),$M$5:$M$204,0)),"") | C41: =IF(B41="","",SUMIFS(Veri!$D$5:$D$2004,Veri!$C$5:$C$2004,B41)) | D41: =IF(B41="","",SUMIFS(Veri!$E$5:$E$2004,Veri!$C$5:$C$2004,B41)) | E41: =IF(B41="","",IF(SUM(Veri!$E$5:$E$2004)=0,0,D41/SUM(Veri!$E$5:$E$2004))) | F41: =IF(B41="","",SUM(E$5:E41)) | G41: =IF(B41="","",IF(F40<0.8,"A",IF(F40<0.95,"B","C"))) | H41: =IF(OR(B41="",C41=0),"",D41/C41) | I41: =IF(B41="","",SUMPRODUCT(MAX((Veri!$C$5:$C$2004=B41)*Veri!$A$5:$A$2004))) | K41: =IF(37>MAX(Veri!$G$5:$G$2004),"",INDEX(Veri!$C$5:$C$2004,MATCH(37,Veri!$G$5:$G$2004,0))) | L41: =IF(K41="","",SUMIFS(Veri!$E$5:$E$2004,Veri!$C$5:$C$2004,K41)) | M41: =IF(K41="","",L41+ROW()/1000000000)
...

Sheet Müşteriler
A1: Müşteri Analizi
A2: Cirosu en yüksek müşteriden başlayarak sıralanır.
A4: Sıra | B4: Müşteri | C4: Satış satırı | D4: Ciro (₺) | E4: Pay | F4: Birikimli pay | G4: Sınıf | H4: Satır başına ortalama (₺) | I4: Son alışveriş | K4: y | L4: y | M4: y | N4: y
A5: =IF(B5="","",1) -> 1 | B5: =IFERROR(INDEX($K$5:$K$204,MATCH(LARGE($M$5:$M$204,1),$M$5:$M$204,0)),"") -> Müşteri Alfa | C5: =IF(B5="","",COUNTIF(Veri!$B$5:$B$2004,B5)) -> 17 | D5: =IF(B5="","",SUMIFS(Veri!$E$5:$E$2004,Veri!$B$5:$B$2004,B5)) -> 28610 | E5: =IF(B5="","",IF(SUM(Veri!$E$5:$E$2004)=0,0,D5/SUM(Veri!$E$5:$E$2004))) -> 0.24725607 | F5: =IF(B5="","",SUM(E$5:E5)) -> 0.24725607 | G5: =IF(B5="","","A") -> A | H5: =IF(OR(B5="",C5=0),"",D5/C5) -> 1682.9412 | I5: =IF(B5="","",SUMPRODUCT(MAX((Veri!$B$5:$B$2004=B5)*Veri!$A$5:$A$2004))) -> 46282 | K5: =IF(1>MAX(Veri!$I$5:$I$2004),"",INDEX(Veri!$B$5:$B$2004,MATCH(1,Veri!$I$5:$I$2004,0))) -> Müşteri Epsilon | L5: =IF(K5="","",SUMIFS(Veri!$E$5:$E$2004,Veri!$B$5:$B$2004,K5)) -> 9535 | M5: =IF(K5="","",L5+ROW()/1000000000) -> 9535
A6: =IF(B6="","",2) -> 2 | B6: =IFERROR(INDEX($K$5:$K$204,MATCH(LARGE($M$5:$M$204,2),$M$5:$M$204,0)),"") -> Müşteri Delta | C6: =IF(B6="","",COUNTIF(Veri!$B$5:$B$2004,B6)) -> 16 | D6: =IF(B6="","",SUMIFS(Veri!$E$5:$E$2004,Veri!$B$5:$B$2004,B6)) -> 26970 | E6: =IF(B6="","",IF(SUM(Veri!$E$5:$E$2004)=0,0,D6/SUM(Veri!$E$5:$E$2004))) -> 0.23308271 | F6: =IF(B6="","",SUM(E$5:E6)) -> 0.48033878 | G6: =IF(B6="","",IF(F5<0.8,"A",IF(F5<0.95,"B","C"))) -> A | H6: =IF(OR(B6="",C6=0),"",D6/C6) -> 1685.625 | I6: =IF(B6="","",SUMPRODUCT(MAX((Veri!$B$5:$B$2004=B6)*Veri!$A$5:$A$2004))) -> 46298 | K6: =IF(2>MAX(Veri!$I$5:$I$2004),"",INDEX(Veri!$B$5:$B$2004,MATCH(2,Veri!$I$5:$I$2004,0))) -> Müşteri Gama | L6: =IF(K6="","",SUMIFS(Veri!$E$5:$E$2004,Veri!$B$5:$B$2004,K6)) -> 17595 | M6: =IF(K6="","",L6+ROW()/1000000000) -> 17595
A7: =IF(B7="","",3) -> 3 | B7: =IFERROR(INDEX($K$5:$K$204,MATCH(LARGE($M$5:$M$204,3),$M$5:$M$204,0)),"") -> Müşteri Beta | C7: =IF(B7="","",COUNTIF(Veri!$B$5:$B$2004,B7)) -> 10 | D7: =IF(B7="","",SUMIFS(Veri!$E$5:$E$2004,Veri!$B$5:$B$2004,B7)) -> 21020 | E7: =IF(B7="","",IF(SUM(Veri!$E$5:$E$2004)=0,0,D7/SUM(Veri!$E$5:$E$2004))) -> 0.18166105 | F7: =IF(B7="","",SUM(E$5:E7)) -> 0.66199983 | G7: =IF(B7="","",IF(F6<0.8,"A",IF(F6<0.95,"B","C"))) -> A | H7: =IF(OR(B7="",C7=0),"",D7/C7) -> 2102 | I7: =IF(B7="","",SUMPRODUCT(MAX((Veri!$B$5:$B$2004=B7)*Veri!$A$5:$A$2004))) -> 46295 | K7: =IF(3>MAX(Veri!$I$5:$I$2004),"",INDEX(Veri!$B$5:$B$2004,MATCH(3,Veri!$I$5:$I$2004,0))) -> Müşteri Beta | L7: =IF(K7="","",SUMIFS(Veri!$E$5:$E$2004,Veri!$B$5:$B$2004,K7)) -> 21020 | M7: =IF(K7="","",L7+ROW()/1000000000) -> 21020
A8: =IF(B8="","",4) -> 4 | B8: =IFERROR(INDEX($K$5:$K$204,MATCH(LARGE($M$5:$M$204,4),$M$5:$M$204,0)),"") -> Müşteri Gama | C8: =IF(B8="","",COUNTIF(Veri!$B$5:$B$2004,B8)) -> 13 | D8: =IF(B8="","",SUMIFS(Veri!$E$5:$E$2004,Veri!$B$5:$B$2004,B8)) -> 17595 | E8: =IF(B8="","",IF(SUM(Veri!$E$5:$E$2004)=0,0,D8/SUM(Veri!$E$5:$E$2004))) -> 0.15206119 | F8: =IF(B8="","",SUM(E$5:E8)) -> 0.81406101 | G8: =IF(B8="","",IF(F7<0.8,"A",IF(F7<0.95,"B","C"))) -> A | H8: =IF(OR(B8="",C8=0),"",D8/C8) -> 1353.4615 | I8: =IF(B8="","",SUMPRODUCT(MAX((Veri!$B$5:$B$2004=B8)*Veri!$A$5:$A$2004))) -> 46298 | K8: =IF(4>MAX(Veri!$I$5:$I$2004),"",INDEX(Veri!$B$5:$B$2004,MATCH(4,Veri!$I$5:$I$2004,0))) -> Müşteri Delta | L8: =IF(K8="","",SUMIFS(Veri!$E$5:$E$2004,Veri!$B$5:$B$2004,K8)) -> 26970 | M8: =IF(K8="","",L8+ROW()/1000000000) -> 26970
A9: =IF(B9="","",5) -> 5 | B9: =IFERROR(INDEX($K$5:$K$204,MATCH(LARGE($M$5:$M$204,5),$M$5:$M$204,0)),"") -> Perakende | C9: =IF(B9="","",COUNTIF(Veri!$B$5:$B$2004,B9)) -> 10 | D9: =IF(B9="","",SUMIFS(Veri!$E$5:$E$2004,Veri!$B$5:$B$2004,B9)) -> 11980 | E9: =IF(B9="","",IF(SUM(Veri!$E$5:$E$2004)=0,0,D9/SUM(Veri!$E$5:$E$2004))) -> 0.1035347 | F9: =IF(B9="","",SUM(E$5:E9)) -> 0.91759571 | G9: =IF(B9="","",IF(F8<0.8,"A",IF(F8<0.95,"B","C"))) -> B | H9: =IF(OR(B9="",C9=0),"",D9/C9) -> 1198 | I9: =IF(B9="","",SUMPRODUCT(MAX((Veri!$B$5:$B$2004=B9)*Veri!$A$5:$A$2004))) -> 46294 | K9: =IF(5>MAX(Veri!$I$5:$I$2004),"",INDEX(Veri!$B$5:$B$2004,MATCH(5,Veri!$I$5:$I$2004,0))) -> Perakende | L9: =IF(K9="","",SUMIFS(Veri!$E$5:$E$2004,Veri!$B$5:$B$2004,K9)) -> 11980 | M9: =IF(K9="","",L9+ROW()/1000000000) -> 11980
A10: =IF(B10="","",6) -> 6 | B10: =IFERROR(INDEX($K$5:$K$204,MATCH(LARGE($M$5:$M$204,6),$M$5:$M$204,0)),"") -> Müşteri Epsilon | C10: =IF(B10="","",COUNTIF(Veri!$B$5:$B$2004,B10)) -> 14 | D10: =IF(B10="","",SUMIFS(Veri!$E$5:$E$2004,Veri!$B$5:$B$2004,B10)) -> 9535 | E10: =IF(B10="","",IF(SUM(Veri!$E$5:$E$2004)=0,0,D10/SUM(Veri!$E$5:$E$2004))) -> 0.082404287 | F10: =IF(B10="","",SUM(E$5:E10)) -> 1 | G10: =IF(B10="","",IF(F9<0.8,"A",IF(F9<0.95,"B","C"))) -> B | H10: =IF(OR(B10="",C10=0),"",D10/C10) -> 681.07143 | I10: =IF(B10="","",SUMPRODUCT(MAX((Veri!$B$5:$B$2004=B10)*Veri!$A$5:$A$2004))) -> 46270 | K10: =IF(6>MAX(Veri!$I$5:$I$2004),"",INDEX(Veri!$B$5:$B$2004,MATCH(6,Veri!$I$5:$I$2004,0))) -> Müşteri Alfa | L10: =IF(K10="","",SUMIFS(Veri!$E$5:$E$2004,Veri!$B$5:$B$2004,K10)) -> 28610 | M10: =IF(K10="","",L10+ROW()/1000000000) -> 28610
A11: =IF(B11="","",7) | B11: =IFERROR(INDEX($K$5:$K$204,MATCH(LARGE($M$5:$M$204,7),$M$5:$M$204,0)),"") | C11: =IF(B11="","",COUNTIF(Veri!$B$5:$B$2004,B11)) | D11: =IF(B11="","",SUMIFS(Veri!$E$5:$E$2004,Veri!$B$5:$B$2004,B11)) | E11: =IF(B11="","",IF(SUM(Veri!$E$5:$E$2004)=0,0,D11/SUM(Veri!$E$5:$E$2004))) | F11: =IF(B11="","",SUM(E$5:E11)) | G11: =IF(B11="","",IF(F10<0.8,"A",IF(F10<0.95,"B","C"))) | H11: =IF(OR(B11="",C11=0),"",D11/C11) | I11: =IF(B11="","",SUMPRODUCT(MAX((Veri!$B$5:$B$2004=B11)*Veri!$A$5:$A$2004))) | K11: =IF(7>MAX(Veri!$I$5:$I$2004),"",INDEX(Veri!$B$5:$B$2004,MATCH(7,Veri!$I$5:$I$2004,0))) | L11: =IF(K11="","",SUMIFS(Veri!$E$5:$E$2004,Veri!$B$5:$B$2004,K11)) | M11: =IF(K11="","",L11+ROW()/1000000000)
A12: =IF(B12="","",8) | B12: =IFERROR(INDEX($K$5:$K$204,MATCH(LARGE($M$5:$M$204,8),$M$5:$M$204,0)),"") | C12: =IF(B12="","",COUNTIF(Veri!$B$5:$B$2004,B12)) | D12: =IF(B12="","",SUMIFS(Veri!$E$5:$E$2004,Veri!$B$5:$B$2004,B12)) | E12: =IF(B12="","",IF(SUM(Veri!$E$5:$E$2004)=0,0,D12/SUM(Veri!$E$5:$E$2004))) | F12: =IF(B12="","",SUM(E$5:E12)) | G12: =IF(B12="","",IF(F11<0.8,"A",IF(F11<0.95,"B","C"))) | H12: =IF(OR(B12="",C12=0),"",D12/C12) | I12: =IF(B12="","",SUMPRODUCT(MAX((Veri!$B$5:$B$2004=B12)*Veri!$A$5:$A$2004))) | K12: =IF(8>MAX(Veri!$I$5:$I$2004),"",INDEX(Veri!$B$5:$B$2004,MATCH(8,Veri!$I$5:$I$2004,0))) | L12: =IF(K12="","",SUMIFS(Veri!$E$5:$E$2004,Veri!$B$5:$B$2004,K12)) | M12: =IF(K12="","",L12+ROW()/1000000000)
A13: =IF(B13="","",9) | B13: =IFERROR(INDEX($K$5:$K$204,MATCH(LARGE($M$5:$M$204,9),$M$5:$M$204,0)),"") | C13: =IF(B13="","",COUNTIF(Veri!$B$5:$B$2004,B13)) | D13: =IF(B13="","",SUMIFS(Veri!$E$5:$E$2004,Veri!$B$5:$B$2004,B13)) | E13: =IF(B13="","",IF(SUM(Veri!$E$5:$E$2004)=0,0,D13/SUM(Veri!$E$5:$E$2004))) | F13: =IF(B13="","",SUM(E$5:E13)) | G13: =IF(B13="","",IF(F12<0.8,"A",IF(F12<0.95,"B","C"))) | H13: =IF(OR(B13="",C13=0),"",D13/C13) | I13: =IF(B13="","",SUMPRODUCT(MAX((Veri!$B$5:$B$2004=B13)*Veri!$A$5:$A$2004))) | K13: =IF(9>MAX(Veri!$I$5:$I$2004),"",INDEX(Veri!$B$5:$B$2004,MATCH(9,Veri!$I$5:$I$2004,0))) | L13: =IF(K13="","",SUMIFS(Veri!$E$5:$E$2004,Veri!$B$5:$B$2004,K13)) | M13: =IF(K13="","",L13+ROW()/1000000000)
A14: =IF(B14="","",10) | B14: =IFERROR(INDEX($K$5:$K$204,MATCH(LARGE($M$5:$M$204,10),$M$5:$M$204,0)),"") | C14: =IF(B14="","",COUNTIF(Veri!$B$5:$B$2004,B14)) | D14: =IF(B14="","",SUMIFS(Veri!$E$5:$E$2004,Veri!$B$5:$B$2004,B14)) | E14: =IF(B14="","",IF(SUM(Veri!$E$5:$E$2004)=0,0,D14/SUM(Veri!$E$5:$E$2004))) | F14: =IF(B14="","",SUM(E$5:E14)) | G14: =IF(B14="","",IF(F13<0.8,"A",IF(F13<0.95,"B","C"))) | H14: =IF(OR(B14="",C14=0),"",D14/C14) | I14: =IF(B14="","",SUMPRODUCT(MAX((Veri!$B$5:$B$2004=B14)*Veri!$A$5:$A$2004))) | K14: =IF(10>MAX(Veri!$I$5:$I$2004),"",INDEX(Veri!$B$5:$B$2004,MATCH(10,Veri!$I$5:$I$2004,0))) | L14: =IF(K14="","",SUMIFS(Veri!$E$5:$E$2004,Veri!$B$5:$B$2004,K14)) | M14: =IF(K14="","",L14+ROW()/1000000000)
A15: =IF(B15="","",11) | B15: =IFERROR(INDEX($K$5:$K$204,MATCH(LARGE($M$5:$M$204,11),$M$5:$M$204,0)),"") | C15: =IF(B15="","",COUNTIF(Veri!$B$5:$B$2004,B15)) | D15: =IF(B15="","",SUMIFS(Veri!$E$5:$E$2004,Veri!$B$5:$B$2004,B15)) | E15: =IF(B15="","",IF(SUM(Veri!$E$5:$E$2004)=0,0,D15/SUM(Veri!$E$5:$E$2004))) | F15: =IF(B15="","",SUM(E$5:E15)) | G15: =IF(B15="","",IF(F14<0.8,"A",IF(F14<0.95,"B","C"))) | H15: =IF(OR(B15="",C15=0),"",D15/C15) | I15: =IF(B15="","",SUMPRODUCT(MAX((Veri!$B$5:$B$2004=B15)*Veri!$A$5:$A$2004))) | K15: =IF(11>MAX(Veri!$I$5:$I$2004),"",INDEX(Veri!$B$5:$B$2004,MATCH(11,Veri!$I$5:$I$2004,0))) | L15: =IF(K15="","",SUMIFS(Veri!$E$5:$E$2004,Veri!$B$5:$B$2004,K15)) | M15: =IF(K15="","",L15+ROW()/1000000000)
A16: =IF(B16="","",12) | B16: =IFERROR(INDEX($K$5:$K$204,MATCH(LARGE($M$5:$M$204,12),$M$5:$M$204,0)),"") | C16: =IF(B16="","",COUNTIF(Veri!$B$5:$B$2004,B16)) | D16: =IF(B16="","",SUMIFS(Veri!$E$5:$E$2004,Veri!$B$5:$B$2004,B16)) | E16: =IF(B16="","",IF(SUM(Veri!$E$5:$E$2004)=0,0,D16/SUM(Veri!$E$5:$E$2004))) | F16: =IF(B16="","",SUM(E$5:E16)) | G16: =IF(B16="","",IF(F15<0.8,"A",IF(F15<0.95,"B","C"))) | H16: =IF(OR(B16="",C16=0),"",D16/C16) | I16: =IF(B16="","",SUMPRODUCT(MAX((Veri!$B$5:$B$2004=B16)*Veri!$A$5:$A$2004))) | K16: =IF(12>MAX(Veri!$I$5:$I$2004),"",INDEX(Veri!$B$5:$B$2004,MATCH(12,Veri!$I$5:$I$2004,0))) | L16: =IF(K16="","",SUMIFS(Veri!$E$5:$E$2004,Veri!$B$5:$B$2004,K16)) | M16: =IF(K16="","",L16+ROW()/1000000000)
A17: =IF(B17="","",13) | B17: =IFERROR(INDEX($K$5:$K$204,MATCH(LARGE($M$5:$M$204,13),$M$5:$M$204,0)),"") | C17: =IF(B17="","",COUNTIF(Veri!$B$5:$B$2004,B17)) | D17: =IF(B17="","",SUMIFS(Veri!$E$5:$E$2004,Veri!$B$5:$B$2004,B17)) | E17: =IF(B17="","",IF(SUM(Veri!$E$5:$E$2004)=0,0,D17/SUM(Veri!$E$5:$E$2004))) | F17: =IF(B17="","",SUM(E$5:E17)) | G17: =IF(B17="","",IF(F16<0.8,"A",IF(F16<0.95,"B","C"))) | H17: =IF(OR(B17="",C17=0),"",D17/C17) | I17: =IF(B17="","",SUMPRODUCT(MAX((Veri!$B$5:$B$2004=B17)*Veri!$A$5:$A$2004))) | K17: =IF(13>MAX(Veri!$I$5:$I$2004),"",INDEX(Veri!$B$5:$B$2004,MATCH(13,Veri!$I$5:$I$2004,0))) | L17: =IF(K17="","",SUMIFS(Veri!$E$5:$E$2004,Veri!$B$5:$B$2004,K17)) | M17: =IF(K17="","",L17+ROW()/1000000000)
A18: =IF(B18="","",14) | B18: =IFERROR(INDEX($K$5:$K$204,MATCH(LARGE($M$5:$M$204,14),$M$5:$M$204,0)),"") | C18: =IF(B18="","",COUNTIF(Veri!$B$5:$B$2004,B18)) | D18: =IF(B18="","",SUMIFS(Veri!$E$5:$E$2004,Veri!$B$5:$B$2004,B18)) | E18: =IF(B18="","",IF(SUM(Veri!$E$5:$E$2004)=0,0,D18/SUM(Veri!$E$5:$E$2004))) | F18: =IF(B18="","",SUM(E$5:E18)) | G18: =IF(B18="","",IF(F17<0.8,"A",IF(F17<0.95,"B","C"))) | H18: =IF(OR(B18="",C18=0),"",D18/C18) | I18: =IF(B18="","",SUMPRODUCT(MAX((Veri!$B$5:$B$2004=B18)*Veri!$A$5:$A$2004))) | K18: =IF(14>MAX(Veri!$I$5:$I$2004),"",INDEX(Veri!$B$5:$B$2004,MATCH(14,Veri!$I$5:$I$2004,0))) | L18: =IF(K18="","",SUMIFS(Veri!$E$5:$E$2004,Veri!$B$5:$B$2004,K18)) | M18: =IF(K18="","",L18+ROW()/1000000000)
A19: =IF(B19="","",15) | B19: =IFERROR(INDEX($K$5:$K$204,MATCH(LARGE($M$5:$M$204,15),$M$5:$M$204,0)),"") | C19: =IF(B19="","",COUNTIF(Veri!$B$5:$B$2004,B19)) | D19: =IF(B19="","",SUMIFS(Veri!$E$5:$E$2004,Veri!$B$5:$B$2004,B19)) | E19: =IF(B19="","",IF(SUM(Veri!$E$5:$E$2004)=0,0,D19/SUM(Veri!$E$5:$E$2004))) | F19: =IF(B19="","",SUM(E$5:E19)) | G19: =IF(B19="","",IF(F18<0.8,"A",IF(F18<0.95,"B","C"))) | H19: =IF(OR(B19="",C19=0),"",D19/C19) | I19: =IF(B19="","",SUMPRODUCT(MAX((Veri!$B$5:$B$2004=B19)*Veri!$A$5:$A$2004))) | K19: =IF(15>MAX(Veri!$I$5:$I$2004),"",INDEX(Veri!$B$5:$B$2004,MATCH(15,Veri!$I$5:$I$2004,0))) | L19: =IF(K19="","",SUMIFS(Veri!$E$5:$E$2004,Veri!$B$5:$B$2004,K19)) | M19: =IF(K19="","",L19+ROW()/1000000000)
A20: =IF(B20="","",16) | B20: =IFERROR(INDEX($K$5:$K$204,MATCH(LARGE($M$5:$M$204,16),$M$5:$M$204,0)),"") | C20: =IF(B20="","",COUNTIF(Veri!$B$5:$B$2004,B20)) | D20: =IF(B20="","",SUMIFS(Veri!$E$5:$E$2004,Veri!$B$5:$B$2004,B20)) | E20: =IF(B20="","",IF(SUM(Veri!$E$5:$E$2004)=0,0,D20/SUM(Veri!$E$5:$E$2004))) | F20: =IF(B20="","",SUM(E$5:E20)) | G20: =IF(B20="","",IF(F19<0.8,"A",IF(F19<0.95,"B","C"))) | H20: =IF(OR(B20="",C20=0),"",D20/C20) | I20: =IF(B20="","",SUMPRODUCT(MAX((Veri!$B$5:$B$2004=B20)*Veri!$A$5:$A$2004))) | K20: =IF(16>MAX(Veri!$I$5:$I$2004),"",INDEX(Veri!$B$5:$B$2004,MATCH(16,Veri!$I$5:$I$2004,0))) | L20: =IF(K20="","",SUMIFS(Veri!$E$5:$E$2004,Veri!$B$5:$B$2004,K20)) | M20: =IF(K20="","",L20+ROW()/1000000000)
A21: =IF(B21="","",17) | B21: =IFERROR(INDEX($K$5:$K$204,MATCH(LARGE($M$5:$M$204,17),$M$5:$M$204,0)),"") | C21: =IF(B21="","",COUNTIF(Veri!$B$5:$B$2004,B21)) | D21: =IF(B21="","",SUMIFS(Veri!$E$5:$E$2004,Veri!$B$5:$B$2004,B21)) | E21: =IF(B21="","",IF(SUM(Veri!$E$5:$E$2004)=0,0,D21/SUM(Veri!$E$5:$E$2004))) | F21: =IF(B21="","",SUM(E$5:E21)) | G21: =IF(B21="","",IF(F20<0.8,"A",IF(F20<0.95,"B","C"))) | H21: =IF(OR(B21="",C21=0),"",D21/C21) | I21: =IF(B21="","",SUMPRODUCT(MAX((Veri!$B$5:$B$2004=B21)*Veri!$A$5:$A$2004))) | K21: =IF(17>MAX(Veri!$I$5:$I$2004),"",INDEX(Veri!$B$5:$B$2004,MATCH(17,Veri!$I$5:$I$2004,0))) | L21: =IF(K21="","",SUMIFS(Veri!$E$5:$E$2004,Veri!$B$5:$B$2004,K21)) | M21: =IF(K21="","",L21+ROW()/1000000000)
A22: =IF(B22="","",18) | B22: =IFERROR(INDEX($K$5:$K$204,MATCH(LARGE($M$5:$M$204,18),$M$5:$M$204,0)),"") | C22: =IF(B22="","",COUNTIF(Veri!$B$5:$B$2004,B22)) | D22: =IF(B22="","",SUMIFS(Veri!$E$5:$E$2004,Veri!$B$5:$B$2004,B22)) | E22: =IF(B22="","",IF(SUM(Veri!$E$5:$E$2004)=0,0,D22/SUM(Veri!$E$5:$E$2004))) | F22: =IF(B22="","",SUM(E$5:E22)) | G22: =IF(B22="","",IF(F21<0.8,"A",IF(F21<0.95,"B","C"))) | H22: =IF(OR(B22="",C22=0),"",D22/C22) | I22: =IF(B22="","",SUMPRODUCT(MAX((Veri!$B$5:$B$2004=B22)*Veri!$A$5:$A$2004))) | K22: =IF(18>MAX(Veri!$I$5:$I$2004),"",INDEX(Veri!$B$5:$B$2004,MATCH(18,Veri!$I$5:$I$2004,0))) | L22: =IF(K22="","",SUMIFS(Veri!$E$5:$E$2004,Veri!$B$5:$B$2004,K22)) | M22: =IF(K22="","",L22+ROW()/1000000000)
A23: =IF(B23="","",19) | B23: =IFERROR(INDEX($K$5:$K$204,MATCH(LARGE($M$5:$M$204,19),$M$5:$M$204,0)),"") | C23: =IF(B23="","",COUNTIF(Veri!$B$5:$B$2004,B23)) | D23: =IF(B23="","",SUMIFS(Veri!$E$5:$E$2004,Veri!$B$5:$B$2004,B23)) | E23: =IF(B23="","",IF(SUM(Veri!$E$5:$E$2004)=0,0,D23/SUM(Veri!$E$5:$E$2004))) | F23: =IF(B23="","",SUM(E$5:E23)) | G23: =IF(B23="","",IF(F22<0.8,"A",IF(F22<0.95,"B","C"))) | H23: =IF(OR(B23="",C23=0),"",D23/C23) | I23: =IF(B23="","",SUMPRODUCT(MAX((Veri!$B$5:$B$2004=B23)*Veri!$A$5:$A$2004))) | K23: =IF(19>MAX(Veri!$I$5:$I$2004),"",INDEX(Veri!$B$5:$B$2004,MATCH(19,Veri!$I$5:$I$2004,0))) | L23: =IF(K23="","",SUMIFS(Veri!$E$5:$E$2004,Veri!$B$5:$B$2004,K23)) | M23: =IF(K23="","",L23+ROW()/1000000000)
A24: =IF(B24="","",20) | B24: =IFERROR(INDEX($K$5:$K$204,MATCH(LARGE($M$5:$M$204,20),$M$5:$M$204,0)),"") | C24: =IF(B24="","",COUNTIF(Veri!$B$5:$B$2004,B24)) | D24: =IF(B24="","",SUMIFS(Veri!$E$5:$E$2004,Veri!$B$5:$B$2004,B24)) | E24: =IF(B24="","",IF(SUM(Veri!$E$5:$E$2004)=0,0,D24/SUM(Veri!$E$5:$E$2004))) | F24: =IF(B24="","",SUM(E$5:E24)) | G24: =IF(B24="","",IF(F23<0.8,"A",IF(F23<0.95,"B","C"))) | H24: =IF(OR(B24="",C24=0),"",D24/C24) | I24: =IF(B24="","",SUMPRODUCT(MAX((Veri!$B$5:$B$2004=B24)*Veri!$A$5:$A$2004))) | K24: =IF(20>MAX(Veri!$I$5:$I$2004),"",INDEX(Veri!$B$5:$B$2004,MATCH(20,Veri!$I$5:$I$2004,0))) | L24: =IF(K24="","",SUMIFS(Veri!$E$5:$E$2004,Veri!$B$5:$B$2004,K24)) | M24: =IF(K24="","",L24+ROW()/1000000000)
A25: =IF(B25="","",21) | B25: =IFERROR(INDEX($K$5:$K$204,MATCH(LARGE($M$5:$M$204,21),$M$5:$M$204,0)),"") | C25: =IF(B25="","",COUNTIF(Veri!$B$5:$B$2004,B25)) | D25: =IF(B25="","",SUMIFS(Veri!$E$5:$E$2004,Veri!$B$5:$B$2004,B25)) | E25: =IF(B25="","",IF(SUM(Veri!$E$5:$E$2004)=0,0,D25/SUM(Veri!$E$5:$E$2004))) | F25: =IF(B25="","",SUM(E$5:E25)) | G25: =IF(B25="","",IF(F24<0.8,"A",IF(F24<0.95,"B","C"))) | H25: =IF(OR(B25="",C25=0),"",D25/C25) | I25: =IF(B25="","",SUMPRODUCT(MAX((Veri!$B$5:$B$2004=B25)*Veri!$A$5:$A$2004))) | K25: =IF(21>MAX(Veri!$I$5:$I$2004),"",INDEX(Veri!$B$5:$B$2004,MATCH(21,Veri!$I$5:$I$2004,0))) | L25: =IF(K25="","",SUMIFS(Veri!$E$5:$E$2004,Veri!$B$5:$B$2004,K25)) | M25: =IF(K25="","",L25+ROW()/1000000000)
A26: =IF(B26="","",22) | B26: =IFERROR(INDEX($K$5:$K$204,MATCH(LARGE($M$5:$M$204,22),$M$5:$M$204,0)),"") | C26: =IF(B26="","",COUNTIF(Veri!$B$5:$B$2004,B26)) | D26: =IF(B26="","",SUMIFS(Veri!$E$5:$E$2004,Veri!$B$5:$B$2004,B26)) | E26: =IF(B26="","",IF(SUM(Veri!$E$5:$E$2004)=0,0,D26/SUM(Veri!$E$5:$E$2004))) | F26: =IF(B26="","",SUM(E$5:E26)) | G26: =IF(B26="","",IF(F25<0.8,"A",IF(F25<0.95,"B","C"))) | H26: =IF(OR(B26="",C26=0),"",D26/C26) | I26: =IF(B26="","",SUMPRODUCT(MAX((Veri!$B$5:$B$2004=B26)*Veri!$A$5:$A$2004))) | K26: =IF(22>MAX(Veri!$I$5:$I$2004),"",INDEX(Veri!$B$5:$B$2004,MATCH(22,Veri!$I$5:$I$2004,0))) | L26: =IF(K26="","",SUMIFS(Veri!$E$5:$E$2004,Veri!$B$5:$B$2004,K26)) | M26: =IF(K26="","",L26+ROW()/1000000000)
A27: =IF(B27="","",23) | B27: =IFERROR(INDEX($K$5:$K$204,MATCH(LARGE($M$5:$M$204,23),$M$5:$M$204,0)),"") | C27: =IF(B27="","",COUNTIF(Veri!$B$5:$B$2004,B27)) | D27: =IF(B27="","",SUMIFS(Veri!$E$5:$E$2004,Veri!$B$5:$B$2004,B27)) | E27: =IF(B27="","",IF(SUM(Veri!$E$5:$E$2004)=0,0,D27/SUM(Veri!$E$5:$E$2004))) | F27: =IF(B27="","",SUM(E$5:E27)) | G27: =IF(B27="","",IF(F26<0.8,"A",IF(F26<0.95,"B","C"))) | H27: =IF(OR(B27="",C27=0),"",D27/C27) | I27: =IF(B27="","",SUMPRODUCT(MAX((Veri!$B$5:$B$2004=B27)*Veri!$A$5:$A$2004))) | K27: =IF(23>MAX(Veri!$I$5:$I$2004),"",INDEX(Veri!$B$5:$B$2004,MATCH(23,Veri!$I$5:$I$2004,0))) | L27: =IF(K27="","",SUMIFS(Veri!$E$5:$E$2004,Veri!$B$5:$B$2004,K27)) | M27: =IF(K27="","",L27+ROW()/1000000000)
