Workbook

Sheet Başla
B2: EXCEL KLİNİĞİ
B3: VİZİTE | Personel izin ve mesai takibi
B4: Kim ne zaman izinli, kimin kaç gün izni kaldı, kim ne kadar mesai yaptı.
B6: NASIL KULLANILIR
B7: 1. Ayarlar | C7: Yılı yaz. Ramazan ve Kurban Bayramı günlerini resmî tatil listesine ekle.
B8: 2. Personel | C8: Çalışanları, işe giriş tarihini ve o yılki yıllık izin hakkını yaz.
B9: 3. İzinler | C9: Her izni ya da raporu başlangıç ve bitiş tarihiyle gir. Gün sayısı kendiliğinden hesaplanır.
B10: 4. Mesai | C10: Fazla çalışmayı kişi, tarih ve saat olarak yaz.
B11: 5. Ay ve Özet | C11: Ay çizelgesinde kimin hangi gün izinli olduğunu, Özet'te toplamları gör.
B13: BİLMEN GEREKENLER
B14: Yıllık izin günü | C14: Başlangıç ve bitiş arasındaki günlerden pazarlar ve listedeki resmî tatiller düşülür. Ayarlar'da cumartesiyi de düşecek şekilde değiştirebilirsin. Rapor ve diğer izinler takvim günü olarak sayılır.
B15: İzin hakkı | C15: Yıllık izin hakkını sen yazarsın; dosya kıdeme göre hak hesaplamaz ve önceki yıldan devreden izni kendiliğinden eklemez.
B16: Yıl geçişi | C16: Bir izin iki yıla yayılıyorsa başladığı yıla yazılır; iki ayrı satır olarak girmen daha doğru olur.
B17: Resmî belge değil | C17: Bordro ve puantaj programı yerine geçmez; kendi takibin içindir.
B18: Kapasite | C18: 50 personel, 500 izin kaydı, 500 mesai kaydı.
B20: RENKLER
B21: Sarı hücre | C21: Senin dolduracağın hücre. İçindeki örnekleri silip kendi bilgini yaz.
B22: Beyaz hücre, açık başlık | C22: Formül. Değiştirme, kendiliğinden hesaplanır.

Sheet İzinler
A1: İzinler
A2: Her izin ya da rapor bir satır. Gün sayısı kendiliğinden hesaplanır.
A4: Personel | B4: Tür | C4: Başlangıç | D4: Bitiş (dahil) | E4: Not | F4: Gün | G4: Kontrol
A5: Personel Alfa | B5: Yıllık izin | C5: 46216 | D5: 46228 | F5: =IF(OR(C5="",D5="",D5<C5),"",IF(B5="Yıllık izin",D5-C5+1-INT((WEEKDAY(C5-1)+D5-C5)/7)-IF(Ayarlar!$C$5=1,0,INT((WEEKDAY(C5-7)+D5-C5)/7))-SUMPRODUCT((Ayarlar!$E$5:$E$24>=C5)*(Ayarlar!$E$5:$E$24<=D5)*(WEEKDAY(Ayarlar!$E$5:$E$24,2)<IF(Ayarlar!$C$5=1,7,6))),D5-C5+1)) -> 11 | G5: =IF(A5="","",IF(OR(B5="",C5="",D5=""),"Eksik bilgi",IF(D5<C5,"Bitiş başlangıçtan önce","OK"))) -> OK
A6: Personel Beta | B6: Yıllık izin | C6: 46258 | D6: 46267 | F6: =IF(OR(C6="",D6="",D6<C6),"",IF(B6="Yıllık izin",D6-C6+1-INT((WEEKDAY(C6-1)+D6-C6)/7)-IF(Ayarlar!$C$5=1,0,INT((WEEKDAY(C6-7)+D6-C6)/7))-SUMPRODUCT((Ayarlar!$E$5:$E$24>=C6)*(Ayarlar!$E$5:$E$24<=D6)*(WEEKDAY(Ayarlar!$E$5:$E$24,2)<IF(Ayarlar!$C$5=1,7,6))),D6-C6+1)) -> 9 | G6: =IF(A6="","",IF(OR(B6="",C6="",D6=""),"Eksik bilgi",IF(D6<C6,"Bitiş başlangıçtan önce","OK"))) -> OK
A7: Personel Gama | B7: Rapor | C7: 46279 | D7: 46281 | F7: =IF(OR(C7="",D7="",D7<C7),"",IF(B7="Yıllık izin",D7-C7+1-INT((WEEKDAY(C7-1)+D7-C7)/7)-IF(Ayarlar!$C$5=1,0,INT((WEEKDAY(C7-7)+D7-C7)/7))-SUMPRODUCT((Ayarlar!$E$5:$E$24>=C7)*(Ayarlar!$E$5:$E$24<=D7)*(WEEKDAY(Ayarlar!$E$5:$E$24,2)<IF(Ayarlar!$C$5=1,7,6))),D7-C7+1)) -> 3 | G7: =IF(A7="","",IF(OR(B7="",C7="",D7=""),"Eksik bilgi",IF(D7<C7,"Bitiş başlangıçtan önce","OK"))) -> OK
A8: Personel Alfa | B8: Yıllık izin | C8: 46321 | D8: 46326 | F8: =IF(OR(C8="",D8="",D8<C8),"",IF(B8="Yıllık izin",D8-C8+1-INT((WEEKDAY(C8-1)+D8-C8)/7)-IF(Ayarlar!$C$5=1,0,INT((WEEKDAY(C8-7)+D8-C8)/7))-SUMPRODUCT((Ayarlar!$E$5:$E$24>=C8)*(Ayarlar!$E$5:$E$24<=D8)*(WEEKDAY(Ayarlar!$E$5:$E$24,2)<IF(Ayarlar!$C$5=1,7,6))),D8-C8+1)) -> 5 | G8: =IF(A8="","",IF(OR(B8="",C8="",D8=""),"Eksik bilgi",IF(D8<C8,"Bitiş başlangıçtan önce","OK"))) -> OK
A9: Personel Beta | B9: Ücretsiz izin | C9: 46300 | D9: 46301 | F9: =IF(OR(C9="",D9="",D9<C9),"",IF(B9="Yıllık izin",D9-C9+1-INT((WEEKDAY(C9-1)+D9-C9)/7)-IF(Ayarlar!$C$5=1,0,INT((WEEKDAY(C9-7)+D9-C9)/7))-SUMPRODUCT((Ayarlar!$E$5:$E$24>=C9)*(Ayarlar!$E$5:$E$24<=D9)*(WEEKDAY(Ayarlar!$E$5:$E$24,2)<IF(Ayarlar!$C$5=1,7,6))),D9-C9+1)) -> 2 | G9: =IF(A9="","",IF(OR(B9="",C9="",D9=""),"Eksik bilgi",IF(D9<C9,"Bitiş başlangıçtan önce","OK"))) -> OK
A10: Personel Gama | B10: Mazeret izni | C10: 46299 | D10: 46299 | F10: =IF(OR(C10="",D10="",D10<C10),"",IF(B10="Yıllık izin",D10-C10+1-INT((WEEKDAY(C10-1)+D10-C10)/7)-IF(Ayarlar!$C$5=1,0,INT((WEEKDAY(C10-7)+D10-C10)/7))-SUMPRODUCT((Ayarlar!$E$5:$E$24>=C10)*(Ayarlar!$E$5:$E$24<=D10)*(WEEKDAY(Ayarlar!$E$5:$E$24,2)<IF(Ayarlar!$C$5=1,7,6))),D10-C10+1)) -> 1 | G10: =IF(A10="","",IF(OR(B10="",C10="",D10=""),"Eksik bilgi",IF(D10<C10,"Bitiş başlangıçtan önce","OK"))) -> OK
F11: =IF(OR(C11="",D11="",D11<C11),"",IF(B11="Yıllık izin",D11-C11+1-INT((WEEKDAY(C11-1)+D11-C11)/7)-IF(Ayarlar!$C$5=1,0,INT((WEEKDAY(C11-7)+D11-C11)/7))-SUMPRODUCT((Ayarlar!$E$5:$E$24>=C11)*(Ayarlar!$E$5:$E$24<=D11)*(WEEKDAY(Ayarlar!$E$5:$E$24,2)<IF(Ayarlar!$C$5=1,7,6))),D11-C11+1)) | G11: =IF(A11="","",IF(OR(B11="",C11="",D11=""),"Eksik bilgi",IF(D11<C11,"Bitiş başlangıçtan önce","OK")))
F12: =IF(OR(C12="",D12="",D12<C12),"",IF(B12="Yıllık izin",D12-C12+1-INT((WEEKDAY(C12-1)+D12-C12)/7)-IF(Ayarlar!$C$5=1,0,INT((WEEKDAY(C12-7)+D12-C12)/7))-SUMPRODUCT((Ayarlar!$E$5:$E$24>=C12)*(Ayarlar!$E$5:$E$24<=D12)*(WEEKDAY(Ayarlar!$E$5:$E$24,2)<IF(Ayarlar!$C$5=1,7,6))),D12-C12+1)) | G12: =IF(A12="","",IF(OR(B12="",C12="",D12=""),"Eksik bilgi",IF(D12<C12,"Bitiş başlangıçtan önce","OK")))
F13: =IF(OR(C13="",D13="",D13<C13),"",IF(B13="Yıllık izin",D13-C13+1-INT((WEEKDAY(C13-1)+D13-C13)/7)-IF(Ayarlar!$C$5=1,0,INT((WEEKDAY(C13-7)+D13-C13)/7))-SUMPRODUCT((Ayarlar!$E$5:$E$24>=C13)*(Ayarlar!$E$5:$E$24<=D13)*(WEEKDAY(Ayarlar!$E$5:$E$24,2)<IF(Ayarlar!$C$5=1,7,6))),D13-C13+1)) | G13: =IF(A13="","",IF(OR(B13="",C13="",D13=""),"Eksik bilgi",IF(D13<C13,"Bitiş başlangıçtan önce","OK")))
F14: =IF(OR(C14="",D14="",D14<C14),"",IF(B14="Yıllık izin",D14-C14+1-INT((WEEKDAY(C14-1)+D14-C14)/7)-IF(Ayarlar!$C$5=1,0,INT((WEEKDAY(C14-7)+D14-C14)/7))-SUMPRODUCT((Ayarlar!$E$5:$E$24>=C14)*(Ayarlar!$E$5:$E$24<=D14)*(WEEKDAY(Ayarlar!$E$5:$E$24,2)<IF(Ayarlar!$C$5=1,7,6))),D14-C14+1)) | G14: =IF(A14="","",IF(OR(B14="",C14="",D14=""),"Eksik bilgi",IF(D14<C14,"Bitiş başlangıçtan önce","OK")))
F15: =IF(OR(C15="",D15="",D15<C15),"",IF(B15="Yıllık izin",D15-C15+1-INT((WEEKDAY(C15-1)+D15-C15)/7)-IF(Ayarlar!$C$5=1,0,INT((WEEKDAY(C15-7)+D15-C15)/7))-SUMPRODUCT((Ayarlar!$E$5:$E$24>=C15)*(Ayarlar!$E$5:$E$24<=D15)*(WEEKDAY(Ayarlar!$E$5:$E$24,2)<IF(Ayarlar!$C$5=1,7,6))),D15-C15+1)) | G15: =IF(A15="","",IF(OR(B15="",C15="",D15=""),"Eksik bilgi",IF(D15<C15,"Bitiş başlangıçtan önce","OK")))
F16: =IF(OR(C16="",D16="",D16<C16),"",IF(B16="Yıllık izin",D16-C16+1-INT((WEEKDAY(C16-1)+D16-C16)/7)-IF(Ayarlar!$C$5=1,0,INT((WEEKDAY(C16-7)+D16-C16)/7))-SUMPRODUCT((Ayarlar!$E$5:$E$24>=C16)*(Ayarlar!$E$5:$E$24<=D16)*(WEEKDAY(Ayarlar!$E$5:$E$24,2)<IF(Ayarlar!$C$5=1,7,6))),D16-C16+1)) | G16: =IF(A16="","",IF(OR(B16="",C16="",D16=""),"Eksik bilgi",IF(D16<C16,"Bitiş başlangıçtan önce","OK")))
F17: =IF(OR(C17="",D17="",D17<C17),"",IF(B17="Yıllık izin",D17-C17+1-INT((WEEKDAY(C17-1)+D17-C17)/7)-IF(Ayarlar!$C$5=1,0,INT((WEEKDAY(C17-7)+D17-C17)/7))-SUMPRODUCT((Ayarlar!$E$5:$E$24>=C17)*(Ayarlar!$E$5:$E$24<=D17)*(WEEKDAY(Ayarlar!$E$5:$E$24,2)<IF(Ayarlar!$C$5=1,7,6))),D17-C17+1)) | G17: =IF(A17="","",IF(OR(B17="",C17="",D17=""),"Eksik bilgi",IF(D17<C17,"Bitiş başlangıçtan önce","OK")))
F18: =IF(OR(C18="",D18="",D18<C18),"",IF(B18="Yıllık izin",D18-C18+1-INT((WEEKDAY(C18-1)+D18-C18)/7)-IF(Ayarlar!$C$5=1,0,INT((WEEKDAY(C18-7)+D18-C18)/7))-SUMPRODUCT((Ayarlar!$E$5:$E$24>=C18)*(Ayarlar!$E$5:$E$24<=D18)*(WEEKDAY(Ayarlar!$E$5:$E$24,2)<IF(Ayarlar!$C$5=1,7,6))),D18-C18+1)) | G18: =IF(A18="","",IF(OR(B18="",C18="",D18=""),"Eksik bilgi",IF(D18<C18,"Bitiş başlangıçtan önce","OK")))
F19: =IF(OR(C19="",D19="",D19<C19),"",IF(B19="Yıllık izin",D19-C19+1-INT((WEEKDAY(C19-1)+D19-C19)/7)-IF(Ayarlar!$C$5=1,0,INT((WEEKDAY(C19-7)+D19-C19)/7))-SUMPRODUCT((Ayarlar!$E$5:$E$24>=C19)*(Ayarlar!$E$5:$E$24<=D19)*(WEEKDAY(Ayarlar!$E$5:$E$24,2)<IF(Ayarlar!$C$5=1,7,6))),D19-C19+1)) | G19: =IF(A19="","",IF(OR(B19="",C19="",D19=""),"Eksik bilgi",IF(D19<C19,"Bitiş başlangıçtan önce","OK")))
F20: =IF(OR(C20="",D20="",D20<C20),"",IF(B20="Yıllık izin",D20-C20+1-INT((WEEKDAY(C20-1)+D20-C20)/7)-IF(Ayarlar!$C$5=1,0,INT((WEEKDAY(C20-7)+D20-C20)/7))-SUMPRODUCT((Ayarlar!$E$5:$E$24>=C20)*(Ayarlar!$E$5:$E$24<=D20)*(WEEKDAY(Ayarlar!$E$5:$E$24,2)<IF(Ayarlar!$C$5=1,7,6))),D20-C20+1)) | G20: =IF(A20="","",IF(OR(B20="",C20="",D20=""),"Eksik bilgi",IF(D20<C20,"Bitiş başlangıçtan önce","OK")))
F21: =IF(OR(C21="",D21="",D21<C21),"",IF(B21="Yıllık izin",D21-C21+1-INT((WEEKDAY(C21-1)+D21-C21)/7)-IF(Ayarlar!$C$5=1,0,INT((WEEKDAY(C21-7)+D21-C21)/7))-SUMPRODUCT((Ayarlar!$E$5:$E$24>=C21)*(Ayarlar!$E$5:$E$24<=D21)*(WEEKDAY(Ayarlar!$E$5:$E$24,2)<IF(Ayarlar!$C$5=1,7,6))),D21-C21+1)) | G21: =IF(A21="","",IF(OR(B21="",C21="",D21=""),"Eksik bilgi",IF(D21<C21,"Bitiş başlangıçtan önce","OK")))
F22: =IF(OR(C22="",D22="",D22<C22),"",IF(B22="Yıllık izin",D22-C22+1-INT((WEEKDAY(C22-1)+D22-C22)/7)-IF(Ayarlar!$C$5=1,0,INT((WEEKDAY(C22-7)+D22-C22)/7))-SUMPRODUCT((Ayarlar!$E$5:$E$24>=C22)*(Ayarlar!$E$5:$E$24<=D22)*(WEEKDAY(Ayarlar!$E$5:$E$24,2)<IF(Ayarlar!$C$5=1,7,6))),D22-C22+1)) | G22: =IF(A22="","",IF(OR(B22="",C22="",D22=""),"Eksik bilgi",IF(D22<C22,"Bitiş başlangıçtan önce","OK")))
... F504: =IF(OR(C504="",D504="",D504<C504),"",IF(B504="Yıllık izin",D504-C504+1-INT((WEEKDAY(C504-1)+D504-C504)/7)-IF(Ayarlar!$C$5=1,0,INT((WEEKDAY(C504-7)+D504-C504)/7))-SUMPRODUCT((Ayarlar!$E$5:$E$24>=C504)*(Ayarlar!$E$5:$E$24<=D504)*(WEEKDAY(Ayarlar!$E$5:$E$24,2)<IF(Ayarlar!$C$5=1,7,6))),D504-C504+1)) | G504: =IF(A504="","",IF(OR(B504="",C504="",D504=""),"Eksik bilgi",IF(D504<C504,"Bitiş başlangıçtan önce","OK")))

Sheet Mesai
A1: Mesai
A2: Fazla çalışmayı kişi, tarih ve saat olarak yaz.
A4: Personel | B4: Tarih | C4: Saat | D4: Açıklama
A5: Personel Alfa | B5: 46277 | C5: 3 | D5: Örnek
A6: Personel Gama | B6: 46284 | C6: 4.5 | D6: Örnek
A7: Personel Alfa | B7: 46298 | C7: 2 | D7: Örnek

Sheet Ay
A1: Ay Çizelgesi
A2: Ayı yaz. İ yıllık izin, R rapor, Ü ücretsiz izin, M mazeret izni. Gri sütunlar pazar günleridir.
B3: Ay (1-12) | C3: 10
B5: Personel | C5: =IF(DAY(DATE(Ayarlar!$C$4,$C$3,1))=1,DATE(Ayarlar!$C$4,$C$3,1),"") -> 46296 | D5: =IF(DAY(DATE(Ayarlar!$C$4,$C$3,2))=2,DATE(Ayarlar!$C$4,$C$3,2),"") -> 46297 | E5: =IF(DAY(DATE(Ayarlar!$C$4,$C$3,3))=3,DATE(Ayarlar!$C$4,$C$3,3),"") -> 46298 | F5: =IF(DAY(DATE(Ayarlar!$C$4,$C$3,4))=4,DATE(Ayarlar!$C$4,$C$3,4),"") -> 46299 | G5: =IF(DAY(DATE(Ayarlar!$C$4,$C$3,5))=5,DATE(Ayarlar!$C$4,$C$3,5),"") -> 46300 | H5: =IF(DAY(DATE(Ayarlar!$C$4,$C$3,6))=6,DATE(Ayarlar!$C$4,$C$3,6),"") -> 46301 | I5: =IF(DAY(DATE(Ayarlar!$C$4,$C$3,7))=7,DATE(Ayarlar!$C$4,$C$3,7),"") -> 46302 | J5: =IF(DAY(DATE(Ayarlar!$C$4,$C$3,8))=8,DATE(Ayarlar!$C$4,$C$3,8),"") -> 46303 | K5: =IF(DAY(DATE(Ayarlar!$C$4,$C$3,9))=9,DATE(Ayarlar!$C$4,$C$3,9),"") -> 46304 | L5: =IF(DAY(DATE(Ayarlar!$C$4,$C$3,10))=10,DATE(Ayarlar!$C$4,$C$3,10),"") -> 46305 | M5: =IF(DAY(DATE(Ayarlar!$C$4,$C$3,11))=11,DATE(Ayarlar!$C$4,$C$3,11),"") -> 46306 | N5: =IF(DAY(DATE(Ayarlar!$C$4,$C$3,12))=12,DATE(Ayarlar!$C$4,$C$3,12),"") -> 46307 | O5: =IF(DAY(DATE(Ayarlar!$C$4,$C$3,13))=13,DATE(Ayarlar!$C$4,$C$3,13),"") -> 46308 | P5: =IF(DAY(DATE(Ayarlar!$C$4,$C$3,14))=14,DATE(Ayarlar!$C$4,$C$3,14),"") -> 46309 | Q5: =IF(DAY(DATE(Ayarlar!$C$4,$C$3,15))=15,DATE(Ayarlar!$C$4,$C$3,15),"") -> 46310 | R5: =IF(DAY(DATE(Ayarlar!$C$4,$C$3,16))=16,DATE(Ayarlar!$C$4,$C$3,16),"") -> 46311 | S5: =IF(DAY(DATE(Ayarlar!$C$4,$C$3,17))=17,DATE(Ayarlar!$C$4,$C$3,17),"") -> 46312 | T5: =IF(DAY(DATE(Ayarlar!$C$4,$C$3,18))=18,DATE(Ayarlar!$C$4,$C$3,18),"") -> 46313 | U5: =IF(DAY(DATE(Ayarlar!$C$4,$C$3,19))=19,DATE(Ayarlar!$C$4,$C$3,19),"") -> 46314 | V5: =IF(DAY(DATE(Ayarlar!$C$4,$C$3,20))=20,DATE(Ayarlar!$C$4,$C$3,20),"") -> 46315 | W5: =IF(DAY(DATE(Ayarlar!$C$4,$C$3,21))=21,DATE(Ayarlar!$C$4,$C$3,21),"") -> 46316 | X5: =IF(DAY(DATE(Ayarlar!$C$4,$C$3,22))=22,DATE(Ayarlar!$C$4,$C$3,22),"") -> 46317 | Y5: =IF(DAY(DATE(Ayarlar!$C$4,$C$3,23))=23,DATE(Ayarlar!$C$4,$C$3,23),"") -> 46318 | Z5: =IF(DAY(DATE(Ayarlar!$C$4,$C$3,24))=24,DATE(Ayarlar!$C$4,$C$3,24),"") -> 46319 | AA5: =IF(DAY(DATE(Ayarlar!$C$4,$C$3,25))=25,DATE(Ayarlar!$C$4,$C$3,25),"") -> 46320 | AB5: =IF(DAY(DATE(Ayarlar!$C$4,$C$3,26))=26,DATE(Ayarlar!$C$4,$C$3,26),"") -> 46321 | AC5: =IF(DAY(DATE(Ayarlar!$C$4,$C$3,27))=27,DATE(Ayarlar!$C$4,$C$3,27),"") -> 46322 | AD5: =IF(DAY(DATE(Ayarlar!$C$4,$C$3,28))=28,DATE(Ayarlar!$C$4,$C$3,28),"") -> 46323 | AE5: =IF(DAY(DATE(Ayarlar!$C$4,$C$3,29))=29,DATE(Ayarlar!$C$4,$C$3,29),"") -> 46324 | AF5: =IF(DAY(DATE(Ayarlar!$C$4,$C$3,30))=30,DATE(Ayarlar!$C$4,$C$3,30),"") -> 46325 | AG5: =IF(DAY(DATE(Ayarlar!$C$4,$C$3,31))=31,DATE(Ayarlar!$C$4,$C$3,31),"") -> 46326 | AH5: İzinli gün
B6: =IF(Personel!A5="","",Personel!A5) -> Personel Alfa | C6: =IF(OR($B6="",C$5=""),"",IF(SUMPRODUCT(MAX((İzinler!$A$5:$A$504=$B6)*(İzinler!$C$5:$C$504<=C$5)*(İzinler!$D$5:$D$504>=C$5)*ROW(İzinler!$A$5:$A$504)))=0,"",LEFT(SUBSTITUTE(SUBSTITUTE(INDEX(İzinler!$B$1:$B$504,SUMPRODUCT(MAX((İzinler!$A$5:$A$504=$B6)*(İzinler!$C$5:$C$504<=C$5)*(İzinler!$D$5:$D$504>=C$5)*ROW(İzinler!$A$5:$A$504)))),"Yıllık izin","İ"),"Ücretsiz izin","Ü"),1))) | D6: =IF(OR($B6="",D$5=""),"",IF(SUMPRODUCT(MAX((İzinler!$A$5:$A$504=$B6)*(İzinler!$C$5:$C$504<=D$5)*(İzinler!$D$5:$D$504>=D$5)*ROW(İzinler!$A$5:$A$504)))=0,"",LEFT(SUBSTITUTE(SUBSTITUTE(INDEX(İzinler!$B$1:$B$504,SUMPRODUCT(MAX((İzinler!$A$5:$A$504=$B6)*(İzinler!$C$5:$C$504<=D$5)*(İzinler!$D$5:$D$504>=D$5)*ROW(İzinler!$A$5:$A$504)))),"Yıllık izin","İ"),"Ücretsiz izin","Ü"),1))) | E6: =IF(OR($B6="",E$5=""),"",IF(SUMPRODUCT(MAX((İzinler!$A$5:$A$504=$B6)*(İzinler!$C$5:$C$504<=E$5)*(İzinler!$D$5:$D$504>=E$5)*ROW(İzinler!$A$5:$A$504)))=0,"",LEFT(SUBSTITUTE(SUBSTITUTE(INDEX(İzinler!$B$1:$B$504,SUMPRODUCT(MAX((İzinler!$A$5:$A$504=$B6)*(İzinler!$C$5:$C$504<=E$5)*(İzinler!$D$5:$D$504>=E$5)*ROW(İzinler!$A$5:$A$504)))),"Yıllık izin","İ"),"Ücretsiz izin","Ü"),1))) | F6: =IF(OR($B6="",F$5=""),"",IF(SUMPRODUCT(MAX((İzinler!$A$5:$A$504=$B6)*(İzinler!$C$5:$C$504<=F$5)*(İzinler!$D$5:$D$504>=F$5)*ROW(İzinler!$A$5:$A$504)))=0,"",LEFT(SUBSTITUTE(SUBSTITUTE(INDEX(İzinler!$B$1:$B$504,SUMPRODUCT(MAX((İzinler!$A$5:$A$504=$B6)*(İzinler!$C$5:$C$504<=F$5)*(İzinler!$D$5:$D$504>=F$5)*ROW(İzinler!$A$5:$A$504)))),"Yıllık izin","İ"),"Ücretsiz izin","Ü"),1))) | G6: =IF(OR($B6="",G$5=""),"",IF(SUMPRODUCT(MAX((İzinler!$A$5:$A$504=$B6)*(İzinler!$C$5:$C$504<=G$5)*(İzinler!$D$5:$D$504>=G$5)*ROW(İzinler!$A$5:$A$504)))=0,"",LEFT(SUBSTITUTE(SUBSTITUTE(INDEX(İzinler!$B$1:$B$504,SUMPRODUCT(MAX((İzinler!$A$5:$A$504=$B6)*(İzinler!$C$5:$C$504<=G$5)*(İzinler!$D$5:$D$504>=G$5)*ROW(İzinler!$A$5:$A$504)))),"Yıllık izin","İ"),"Ücretsiz izin","Ü"),1))) | H6: =IF(OR($B6="",H$5=""),"",IF(SUMPRODUCT(MAX((İzinler!$A$5:$A$504=$B6)*(İzinler!$C$5:$C$504<=H$5)*(İzinler!$D$5:$D$504>=H$5)*ROW(İzinler!$A$5:$A$504)))=0,"",LEFT(SUBSTITUTE(SUBSTITUTE(INDEX(İzinler!$B$1:$B$504,SUMPRODUCT(MAX((İzinler!$A$5:$A$504=$B6)*(İzinler!$C$5:$C$504<=H$5)*(İzinler!$D$5:$D$504>=H$5)*ROW(İzinler!$A$5:$A$504)))),"Yıllık izin","İ"),"Ücretsiz izin","Ü"),1))) | I6: =IF(OR($B6="",I$5=""),"",IF(SUMPRODUCT(MAX((İzinler!$A$5:$A$504=$B6)*(İzinler!$C$5:$C$504<=I$5)*(İzinler!$D$5:$D$504>=I$5)*ROW(İzinler!$A$5:$A$504)))=0,"",LEFT(SUBSTITUTE(SUBSTITUTE(INDEX(İzinler!$B$1:$B$504,SUMPRODUCT(MAX((İzinler!$A$5:$A$504=$B6)*(İzinler!$C$5:$C$504<=I$5)*(İzinler!$D$5:$D$504>=I$5)*ROW(İzinler!$A$5:$A$504)))),"Yıllık izin","İ"),"Ücretsiz izin","Ü"),1))) | J6: =IF(OR($B6="",J$5=""),"",IF(SUMPRODUCT(MAX((İzinler!$A$5:$A$504=$B6)*(İzinler!$C$5:$C$504<=J$5)*(İzinler!$D$5:$D$504>=J$5)*ROW(İzinler!$A$5:$A$504)))=0,"",LEFT(SUBSTITUTE(SUBSTITUTE(INDEX(İzinler!$B$1:$B$504,SUMPRODUCT(MAX((İzinler!$A$5:$A$504=$B6)*(İzinler!$C$5:$C$504<=J$5)*(İzinler!$D$5:$D$504>=J$5)*ROW(İzinler!$A$5:$A$504)))),"Yıllık izin","İ"),"Ücretsiz izin","Ü"),1))) | ... AG6: =IF(OR($B6="",AG$5=""),"",IF(SUMPRODUCT(MAX((İzinler!$A$5:$A$504=$B6)*(İzinler!$C$5:$C$504<=AG$5)*(İzinler!$D$5:$D$504>=AG$5)*ROW(İzinler!$A$5:$A$504)))=0,"",LEFT(SUBSTITUTE(SUBSTITUTE(INDEX(İzinler!$B$1:$B$504,SUMPRODUCT(MAX((İzinler!$A$5:$A$504=$B6)*(İzinler!$C$5:$C$504<=AG$5)*(İzinler!$D$5:$D$504>=AG$5)*ROW(İzinler!$A$5:$A$504)))),"Yıllık izin","İ"),"Ücretsiz izin","Ü"),1))) -> İ | AH6: =IF(B6="","",COUNTIF(C6:AG6,"?")) -> 6
B7: =IF(Personel!A6="","",Personel!A6) -> Personel Beta | C7: =IF(OR($B7="",C$5=""),"",IF(SUMPRODUCT(MAX((İzinler!$A$5:$A$504=$B7)*(İzinler!$C$5:$C$504<=C$5)*(İzinler!$D$5:$D$504>=C$5)*ROW(İzinler!$A$5:$A$504)))=0,"",LEFT(SUBSTITUTE(SUBSTITUTE(INDEX(İzinler!$B$1:$B$504,SUMPRODUCT(MAX((İzinler!$A$5:$A$504=$B7)*(İzinler!$C$5:$C$504<=C$5)*(İzinler!$D$5:$D$504>=C$5)*ROW(İzinler!$A$5:$A$504)))),"Yıllık izin","İ"),"Ücretsiz izin","Ü"),1))) | D7: =IF(OR($B7="",D$5=""),"",IF(SUMPRODUCT(MAX((İzinler!$A$5:$A$504=$B7)*(İzinler!$C$5:$C$504<=D$5)*(İzinler!$D$5:$D$504>=D$5)*ROW(İzinler!$A$5:$A$504)))=0,"",LEFT(SUBSTITUTE(SUBSTITUTE(INDEX(İzinler!$B$1:$B$504,SUMPRODUCT(MAX((İzinler!$A$5:$A$504=$B7)*(İzinler!$C$5:$C$504<=D$5)*(İzinler!$D$5:$D$504>=D$5)*ROW(İzinler!$A$5:$A$504)))),"Yıllık izin","İ"),"Ücretsiz izin","Ü"),1))) | E7: =IF(OR($B7="",E$5=""),"",IF(SUMPRODUCT(MAX((İzinler!$A$5:$A$504=$B7)*(İzinler!$C$5:$C$504<=E$5)*(İzinler!$D$5:$D$504>=E$5)*ROW(İzinler!$A$5:$A$504)))=0,"",LEFT(SUBSTITUTE(SUBSTITUTE(INDEX(İzinler!$B$1:$B$504,SUMPRODUCT(MAX((İzinler!$A$5:$A$504=$B7)*(İzinler!$C$5:$C$504<=E$5)*(İzinler!$D$5:$D$504>=E$5)*ROW(İzinler!$A$5:$A$504)))),"Yıllık izin","İ"),"Ücretsiz izin","Ü"),1))) | F7: =IF(OR($B7="",F$5=""),"",IF(SUMPRODUCT(MAX((İzinler!$A$5:$A$504=$B7)*(İzinler!$C$5:$C$504<=F$5)*(İzinler!$D$5:$D$504>=F$5)*ROW(İzinler!$A$5:$A$504)))=0,"",LEFT(SUBSTITUTE(SUBSTITUTE(INDEX(İzinler!$B$1:$B$504,SUMPRODUCT(MAX((İzinler!$A$5:$A$504=$B7)*(İzinler!$C$5:$C$504<=F$5)*(İzinler!$D$5:$D$504>=F$5)*ROW(İzinler!$A$5:$A$504)))),"Yıllık izin","İ"),"Ücretsiz izin","Ü"),1))) | G7: =IF(OR($B7="",G$5=""),"",IF(SUMPRODUCT(MAX((İzinler!$A$5:$A$504=$B7)*(İzinler!$C$5:$C$504<=G$5)*(İzinler!$D$5:$D$504>=G$5)*ROW(İzinler!$A$5:$A$504)))=0,"",LEFT(SUBSTITUTE(SUBSTITUTE(INDEX(İzinler!$B$1:$B$504,SUMPRODUCT(MAX((İzinler!$A$5:$A$504=$B7)*(İzinler!$C$5:$C$504<=G$5)*(İzinler!$D$5:$D$504>=G$5)*ROW(İzinler!$A$5:$A$504)))),"Yıllık izin","İ"),"Ücretsiz izin","Ü"),1))) -> Ü | H7: =IF(OR($B7="",H$5=""),"",IF(SUMPRODUCT(MAX((İzinler!$A$5:$A$504=$B7)*(İzinler!$C$5:$C$504<=H$5)*(İzinler!$D$5:$D$504>=H$5)*ROW(İzinler!$A$5:$A$504)))=0,"",LEFT(SUBSTITUTE(SUBSTITUTE(INDEX(İzinler!$B$1:$B$504,SUMPRODUCT(MAX((İzinler!$A$5:$A$504=$B7)*(İzinler!$C$5:$C$504<=H$5)*(İzinler!$D$5:$D$504>=H$5)*ROW(İzinler!$A$5:$A$504)))),"Yıllık izin","İ"),"Ücretsiz izin","Ü"),1))) -> Ü | I7: =IF(OR($B7="",I$5=""),"",IF(SUMPRODUCT(MAX((İzinler!$A$5:$A$504=$B7)*(İzinler!$C$5:$C$504<=I$5)*(İzinler!$D$5:$D$504>=I$5)*ROW(İzinler!$A$5:$A$504)))=0,"",LEFT(SUBSTITUTE(SUBSTITUTE(INDEX(İzinler!$B$1:$B$504,SUMPRODUCT(MAX((İzinler!$A$5:$A$504=$B7)*(İzinler!$C$5:$C$504<=I$5)*(İzinler!$D$5:$D$504>=I$5)*ROW(İzinler!$A$5:$A$504)))),"Yıllık izin","İ"),"Ücretsiz izin","Ü"),1))) | J7: =IF(OR($B7="",J$5=""),"",IF(SUMPRODUCT(MAX((İzinler!$A$5:$A$504=$B7)*(İzinler!$C$5:$C$504<=J$5)*(İzinler!$D$5:$D$504>=J$5)*ROW(İzinler!$A$5:$A$504)))=0,"",LEFT(SUBSTITUTE(SUBSTITUTE(INDEX(İzinler!$B$1:$B$504,SUMPRODUCT(MAX((İzinler!$A$5:$A$504=$B7)*(İzinler!$C$5:$C$504<=J$5)*(İzinler!$D$5:$D$504>=J$5)*ROW(İzinler!$A$5:$A$504)))),"Yıllık izin","İ"),"Ücretsiz izin","Ü"),1))) | ... AG7: =IF(OR($B7="",AG$5=""),"",IF(SUMPRODUCT(MAX((İzinler!$A$5:$A$504=$B7)*(İzinler!$C$5:$C$504<=AG$5)*(İzinler!$D$5:$D$504>=AG$5)*ROW(İzinler!$A$5:$A$504)))=0,"",LEFT(SUBSTITUTE(SUBSTITUTE(INDEX(İzinler!$B$1:$B$504,SUMPRODUCT(MAX((İzinler!$A$5:$A$504=$B7)*(İzinler!$C$5:$C$504<=AG$5)*(İzinler!$D$5:$D$504>=AG$5)*ROW(İzinler!$A$5:$A$504)))),"Yıllık izin","İ"),"Ücretsiz izin","Ü"),1))) | AH7: =IF(B7="","",COUNTIF(C7:AG7,"?")) -> 2
B8: =IF(Personel!A7="","",Personel!A7) -> Personel Gama | C8: =IF(OR($B8="",C$5=""),"",IF(SUMPRODUCT(MAX((İzinler!$A$5:$A$504=$B8)*(İzinler!$C$5:$C$504<=C$5)*(İzinler!$D$5:$D$504>=C$5)*ROW(İzinler!$A$5:$A$504)))=0,"",LEFT(SUBSTITUTE(SUBSTITUTE(INDEX(İzinler!$B$1:$B$504,SUMPRODUCT(MAX((İzinler!$A$5:$A$504=$B8)*(İzinler!$C$5:$C$504<=C$5)*(İzinler!$D$5:$D$504>=C$5)*ROW(İzinler!$A$5:$A$504)))),"Yıllık izin","İ"),"Ücretsiz izin","Ü"),1))) | D8: =IF(OR($B8="",D$5=""),"",IF(SUMPRODUCT(MAX((İzinler!$A$5:$A$504=$B8)*(İzinler!$C$5:$C$504<=D$5)*(İzinler!$D$5:$D$504>=D$5)*ROW(İzinler!$A$5:$A$504)))=0,"",LEFT(SUBSTITUTE(SUBSTITUTE(INDEX(İzinler!$B$1:$B$504,SUMPRODUCT(MAX((İzinler!$A$5:$A$504=$B8)*(İzinler!$C$5:$C$504<=D$5)*(İzinler!$D$5:$D$504>=D$5)*ROW(İzinler!$A$5:$A$504)))),"Yıllık izin","İ"),"Ücretsiz izin","Ü"),1))) | E8: =IF(OR($B8="",E$5=""),"",IF(SUMPRODUCT(MAX((İzinler!$A$5:$A$504=$B8)*(İzinler!$C$5:$C$504<=E$5)*(İzinler!$D$5:$D$504>=E$5)*ROW(İzinler!$A$5:$A$504)))=0,"",LEFT(SUBSTITUTE(SUBSTITUTE(INDEX(İzinler!$B$1:$B$504,SUMPRODUCT(MAX((İzinler!$A$5:$A$504=$B8)*(İzinler!$C$5:$C$504<=E$5)*(İzinler!$D$5:$D$504>=E$5)*ROW(İzinler!$A$5:$A$504)))),"Yıllık izin","İ"),"Ücretsiz izin","Ü"),1))) | F8: =IF(OR($B8="",F$5=""),"",IF(SUMPRODUCT(MAX((İzinler!$A$5:$A$504=$B8)*(İzinler!$C$5:$C$504<=F$5)*(İzinler!$D$5:$D$504>=F$5)*ROW(İzinler!$A$5:$A$504)))=0,"",LEFT(SUBSTITUTE(SUBSTITUTE(INDEX(İzinler!$B$1:$B$504,SUMPRODUCT(MAX((İzinler!$A$5:$A$504=$B8)*(İzinler!$C$5:$C$504<=F$5)*(İzinler!$D$5:$D$504>=F$5)*ROW(İzinler!$A$5:$A$504)))),"Yıllık izin","İ"),"Ücretsiz izin","Ü"),1))) -> M | G8: =IF(OR($B8="",G$5=""),"",IF(SUMPRODUCT(MAX((İzinler!$A$5:$A$504=$B8)*(İzinler!$C$5:$C$504<=G$5)*(İzinler!$D$5:$D$504>=G$5)*ROW(İzinler!$A$5:$A$504)))=0,"",LEFT(SUBSTITUTE(SUBSTITUTE(INDEX(İzinler!$B$1:$B$504,SUMPRODUCT(MAX((İzinler!$A$5:$A$504=$B8)*(İzinler!$C$5:$C$504<=G$5)*(İzinler!$D$5:$D$504>=G$5)*ROW(İzinler!$A$5:$A$504)))),"Yıllık izin","İ"),"Ücretsiz izin","Ü"),1))) | H8: =IF(OR($B8="",H$5=""),"",IF(SUMPRODUCT(MAX((İzinler!$A$5:$A$504=$B8)*(İzinler!$C$5:$C$504<=H$5)*(İzinler!$D$5:$D$504>=H$5)*ROW(İzinler!$A$5:$A$504)))=0,"",LEFT(SUBSTITUTE(SUBSTITUTE(INDEX(İzinler!$B$1:$B$504,SUMPRODUCT(MAX((İzinler!$A$5:$A$504=$B8)*(İzinler!$C$5:$C$504<=H$5)*(İzinler!$D$5:$D$504>=H$5)*ROW(İzinler!$A$5:$A$504)))),"Yıllık izin","İ"),"Ücretsiz izin","Ü"),1))) | I8: =IF(OR($B8="",I$5=""),"",IF(SUMPRODUCT(MAX((İzinler!$A$5:$A$504=$B8)*(İzinler!$C$5:$C$504<=I$5)*(İzinler!$D$5:$D$504>=I$5)*ROW(İzinler!$A$5:$A$504)))=0,"",LEFT(SUBSTITUTE(SUBSTITUTE(INDEX(İzinler!$B$1:$B$504,SUMPRODUCT(MAX((İzinler!$A$5:$A$504=$B8)*(İzinler!$C$5:$C$504<=I$5)*(İzinler!$D$5:$D$504>=I$5)*ROW(İzinler!$A$5:$A$504)))),"Yıllık izin","İ"),"Ücretsiz izin","Ü"),1))) | J8: =IF(OR($B8="",J$5=""),"",IF(SUMPRODUCT(MAX((İzinler!$A$5:$A$504=$B8)*(İzinler!$C$5:$C$504<=J$5)*(İzinler!$D$5:$D$504>=J$5)*ROW(İzinler!$A$5:$A$504)))=0,"",LEFT(SUBSTITUTE(SUBSTITUTE(INDEX(İzinler!$B$1:$B$504,SUMPRODUCT(MAX((İzinler!$A$5:$A$504=$B8)*(İzinler!$C$5:$C$504<=J$5)*(İzinler!$D$5:$D$504>=J$5)*ROW(İzinler!$A$5:$A$504)))),"Yıllık izin","İ"),"Ücretsiz izin","Ü"),1))) | ... AG8: =IF(OR($B8="",AG$5=""),"",IF(SUMPRODUCT(MAX((İzinler!$A$5:$A$504=$B8)*(İzinler!$C$5:$C$504<=AG$5)*(İzinler!$D$5:$D$504>=AG$5)*ROW(İzinler!$A$5:$A$504)))=0,"",LEFT(SUBSTITUTE(SUBSTITUTE(INDEX(İzinler!$B$1:$B$504,SUMPRODUCT(MAX((İzinler!$A$5:$A$504=$B8)*(İzinler!$C$5:$C$504<=AG$5)*(İzinler!$D$5:$D$504>=AG$5)*ROW(İzinler!$A$5:$A$504)))),"Yıllık izin","İ"),"Ücretsiz izin","Ü"),1))) | AH8: =IF(B8="","",COUNTIF(C8:AG8,"?")) -> 1
B9: =IF(Personel!A8="","",Personel!A8) | C9: =IF(OR($B9="",C$5=""),"",IF(SUMPRODUCT(MAX((İzinler!$A$5:$A$504=$B9)*(İzinler!$C$5:$C$504<=C$5)*(İzinler!$D$5:$D$504>=C$5)*ROW(İzinler!$A$5:$A$504)))=0,"",LEFT(SUBSTITUTE(SUBSTITUTE(INDEX(İzinler!$B$1:$B$504,SUMPRODUCT(MAX((İzinler!$A$5:$A$504=$B9)*(İzinler!$C$5:$C$504<=C$5)*(İzinler!$D$5:$D$504>=C$5)*ROW(İzinler!$A$5:$A$504)))),"Yıllık izin","İ"),"Ücretsiz izin","Ü"),1))) | D9: =IF(OR($B9="",D$5=""),"",IF(SUMPRODUCT(MAX((İzinler!$A$5:$A$504=$B9)*(İzinler!$C$5:$C$504<=D$5)*(İzinler!$D$5:$D$504>=D$5)*ROW(İzinler!$A$5:$A$504)))=0,"",LEFT(SUBSTITUTE(SUBSTITUTE(INDEX(İzinler!$B$1:$B$504,SUMPRODUCT(MAX((İzinler!$A$5:$A$504=$B9)*(İzinler!$C$5:$C$504<=D$5)*(İzinler!$D$5:$D$504>=D$5)*ROW(İzinler!$A$5:$A$504)))),"Yıllık izin","İ"),"Ücretsiz izin","Ü"),1))) | E9: =IF(OR($B9="",E$5=""),"",IF(SUMPRODUCT(MAX((İzinler!$A$5:$A$504=$B9)*(İzinler!$C$5:$C$504<=E$5)*(İzinler!$D$5:$D$504>=E$5)*ROW(İzinler!$A$5:$A$504)))=0,"",LEFT(SUBSTITUTE(SUBSTITUTE(INDEX(İzinler!$B$1:$B$504,SUMPRODUCT(MAX((İzinler!$A$5:$A$504=$B9)*(İzinler!$C$5:$C$504<=E$5)*(İzinler!$D$5:$D$504>=E$5)*ROW(İzinler!$A$5:$A$504)))),"Yıllık izin","İ"),"Ücretsiz izin","Ü"),1))) | F9: =IF(OR($B9="",F$5=""),"",IF(SUMPRODUCT(MAX((İzinler!$A$5:$A$504=$B9)*(İzinler!$C$5:$C$504<=F$5)*(İzinler!$D$5:$D$504>=F$5)*ROW(İzinler!$A$5:$A$504)))=0,"",LEFT(SUBSTITUTE(SUBSTITUTE(INDEX(İzinler!$B$1:$B$504,SUMPRODUCT(MAX((İzinler!$A$5:$A$504=$B9)*(İzinler!$C$5:$C$504<=F$5)*(İzinler!$D$5:$D$504>=F$5)*ROW(İzinler!$A$5:$A$504)))),"Yıllık izin","İ"),"Ücretsiz izin","Ü"),1))) | G9: =IF(OR($B9="",G$5=""),"",IF(SUMPRODUCT(MAX((İzinler!$A$5:$A$504=$B9)*(İzinler!$C$5:$C$504<=G$5)*(İzinler!$D$5:$D$504>=G$5)*ROW(İzinler!$A$5:$A$504)))=0,"",LEFT(SUBSTITUTE(SUBSTITUTE(INDEX(İzinler!$B$1:$B$504,SUMPRODUCT(MAX((İzinler!$A$5:$A$504=$B9)*(İzinler!$C$5:$C$504<=G$5)*(İzinler!$D$5:$D$504>=G$5)*ROW(İzinler!$A$5:$A$504)))),"Yıllık izin","İ"),"Ücretsiz izin","Ü"),1))) | H9: =IF(OR($B9="",H$5=""),"",IF(SUMPRODUCT(MAX((İzinler!$A$5:$A$504=$B9)*(İzinler!$C$5:$C$504<=H$5)*(İzinler!$D$5:$D$504>=H$5)*ROW(İzinler!$A$5:$A$504)))=0,"",LEFT(SUBSTITUTE(SUBSTITUTE(INDEX(İzinler!$B$1:$B$504,SUMPRODUCT(MAX((İzinler!$A$5:$A$504=$B9)*(İzinler!$C$5:$C$504<=H$5)*(İzinler!$D$5:$D$504>=H$5)*ROW(İzinler!$A$5:$A$504)))),"Yıllık izin","İ"),"Ücretsiz izin","Ü"),1))) | I9: =IF(OR($B9="",I$5=""),"",IF(SUMPRODUCT(MAX((İzinler!$A$5:$A$504=$B9)*(İzinler!$C$5:$C$504<=I$5)*(İzinler!$D$5:$D$504>=I$5)*ROW(İzinler!$A$5:$A$504)))=0,"",LEFT(SUBSTITUTE(SUBSTITUTE(INDEX(İzinler!$B$1:$B$504,SUMPRODUCT(MAX((İzinler!$A$5:$A$504=$B9)*(İzinler!$C$5:$C$504<=I$5)*(İzinler!$D$5:$D$504>=I$5)*ROW(İzinler!$A$5:$A$504)))),"Yıllık izin","İ"),"Ücretsiz izin","Ü"),1))) | J9: =IF(OR($B9="",J$5=""),"",IF(SUMPRODUCT(MAX((İzinler!$A$5:$A$504=$B9)*(İzinler!$C$5:$C$504<=J$5)*(İzinler!$D$5:$D$504>=J$5)*ROW(İzinler!$A$5:$A$504)))=0,"",LEFT(SUBSTITUTE(SUBSTITUTE(INDEX(İzinler!$B$1:$B$504,SUMPRODUCT(MAX((İzinler!$A$5:$A$504=$B9)*(İzinler!$C$5:$C$504<=J$5)*(İzinler!$D$5:$D$504>=J$5)*ROW(İzinler!$A$5:$A$504)))),"Yıllık izin","İ"),"Ücretsiz izin","Ü"),1))) | ... AG9: =IF(OR($B9="",AG$5=""),"",IF(SUMPRODUCT(MAX((İzinler!$A$5:$A$504=$B9)*(İzinler!$C$5:$C$504<=AG$5)*(İzinler!$D$5:$D$504>=AG$5)*ROW(İzinler!$A$5:$A$504)))=0,"",LEFT(SUBSTITUTE(SUBSTITUTE(INDEX(İzinler!$B$1:$B$504,SUMPRODUCT(MAX((İzinler!$A$5:$A$504=$B9)*(İzinler!$C$5:$C$504<=AG$5)*(İzinler!$D$5:$D$504>=AG$5)*ROW(İzinler!$A$5:$A$504)))),"Yıllık izin","İ"),"Ücretsiz izin","Ü"),1))) | AH9: =IF(B9="","",COUNTIF(C9:AG9,"?"))
B10: =IF(Personel!A9="","",Personel!A9) | C10: =IF(OR($B10="",C$5=""),"",IF(SUMPRODUCT(MAX((İzinler!$A$5:$A$504=$B10)*(İzinler!$C$5:$C$504<=C$5)*(İzinler!$D$5:$D$504>=C$5)*ROW(İzinler!$A$5:$A$504)))=0,"",LEFT(SUBSTITUTE(SUBSTITUTE(INDEX(İzinler!$B$1:$B$504,SUMPRODUCT(MAX((İzinler!$A$5:$A$504=$B10)*(İzinler!$C$5:$C$504<=C$5)*(İzinler!$D$5:$D$504>=C$5)*ROW(İzinler!$A$5:$A$504)))),"Yıllık izin","İ"),"Ücretsiz izin","Ü"),1))) | D10: =IF(OR($B10="",D$5=""),"",IF(SUMPRODUCT(MAX((İzinler!$A$5:$A$504=$B10)*(İzinler!$C$5:$C$504<=D$5)*(İzinler!$D$5:$D$504>=D$5)*ROW(İzinler!$A$5:$A$504)))=0,"",LEFT(SUBSTITUTE(SUBSTITUTE(INDEX(İzinler!$B$1:$B$504,SUMPRODUCT(MAX((İzinler!$A$5:$A$504=$B10)*(İzinler!$C$5:$C$504<=D$5)*(İzinler!$D$5:$D$504>=D$5)*ROW(İzinler!$A$5:$A$504)))),"Yıllık izin","İ"),"Ücretsiz izin","Ü"),1))) | E10: =IF(OR($B10="",E$5=""),"",IF(SUMPRODUCT(MAX((İzinler!$A$5:$A$504=$B10)*(İzinler!$C$5:$C$504<=E$5)*(İzinler!$D$5:$D$504>=E$5)*ROW(İzinler!$A$5:$A$504)))=0,"",LEFT(SUBSTITUTE(SUBSTITUTE(INDEX(İzinler!$B$1:$B$504,SUMPRODUCT(MAX((İzinler!$A$5:$A$504=$B10)*(İzinler!$C$5:$C$504<=E$5)*(İzinler!$D$5:$D$504>=E$5)*ROW(İzinler!$A$5:$A$504)))),"Yıllık izin","İ"),"Ücretsiz izin","Ü"),1))) | F10: =IF(OR($B10="",F$5=""),"",IF(SUMPRODUCT(MAX((İzinler!$A$5:$A$504=$B10)*(İzinler!$C$5:$C$504<=F$5)*(İzinler!$D$5:$D$504>=F$5)*ROW(İzinler!$A$5:$A$504)))=0,"",LEFT(SUBSTITUTE(SUBSTITUTE(INDEX(İzinler!$B$1:$B$504,SUMPRODUCT(MAX((İzinler!$A$5:$A$504=$B10)*(İzinler!$C$5:$C$504<=F$5)*(İzinler!$D$5:$D$504>=F$5)*ROW(İzinler!$A$5:$A$504)))),"Yıllık izin","İ"),"Ücretsiz izin","Ü"),1))) | G10: =IF(OR($B10="",G$5=""),"",IF(SUMPRODUCT(MAX((İzinler!$A$5:$A$504=$B10)*(İzinler!$C$5:$C$504<=G$5)*(İzinler!$D$5:$D$504>=G$5)*ROW(İzinler!$A$5:$A$504)))=0,"",LEFT(SUBSTITUTE(SUBSTITUTE(INDEX(İzinler!$B$1:$B$504,SUMPRODUCT(MAX((İzinler!$A$5:$A$504=$B10)*(İzinler!$C$5:$C$504<=G$5)*(İzinler!$D$5:$D$504>=G$5)*ROW(İzinler!$A$5:$A$504)))),"Yıllık izin","İ"),"Ücretsiz izin","Ü"),1))) | H10: =IF(OR($B10="",H$5=""),"",IF(SUMPRODUCT(MAX((İzinler!$A$5:$A$504=$B10)*(İzinler!$C$5:$C$504<=H$5)*(İzinler!$D$5:$D$504>=H$5)*ROW(İzinler!$A$5:$A$504)))=0,"",LEFT(SUBSTITUTE(SUBSTITUTE(INDEX(İzinler!$B$1:$B$504,SUMPRODUCT(MAX((İzinler!$A$5:$A$504=$B10)*(İzinler!$C$5:$C$504<=H$5)*(İzinler!$D$5:$D$504>=H$5)*ROW(İzinler!$A$5:$A$504)))),"Yıllık izin","İ"),"Ücretsiz izin","Ü"),1))) | I10: =IF(OR($B10="",I$5=""),"",IF(SUMPRODUCT(MAX((İzinler!$A$5:$A$504=$B10)*(İzinler!$C$5:$C$504<=I$5)*(İzinler!$D$5:$D$504>=I$5)*ROW(İzinler!$A$5:$A$504)))=0,"",LEFT(SUBSTITUTE(SUBSTITUTE(INDEX(İzinler!$B$1:$B$504,SUMPRODUCT(MAX((İzinler!$A$5:$A$504=$B10)*(İzinler!$C$5:$C$504<=I$5)*(İzinler!$D$5:$D$504>=I$5)*ROW(İzinler!$A$5:$A$504)))),"Yıllık izin","İ"),"Ücretsiz izin","Ü"),1))) | J10: =IF(OR($B10="",J$5=""),"",IF(SUMPRODUCT(MAX((İzinler!$A$5:$A$504=$B10)*(İzinler!$C$5:$C$504<=J$5)*(İzinler!$D$5:$D$504>=J$5)*ROW(İzinler!$A$5:$A$504)))=0,"",LEFT(SUBSTITUTE(SUBSTITUTE(INDEX(İzinler!$B$1:$B$504,SUMPRODUCT(MAX((İzinler!$A$5:$A$504=$B10)*(İzinler!$C$5:$C$504<=J$5)*(İzinler!$D$5:$D$504>=J$5)*ROW(İzinler!$A$5:$A$504)))),"Yıllık izin","İ"),"Ücretsiz izin","Ü"),1))) | ... AG10: =IF(OR($B10="",AG$5=""),"",IF(SUMPRODUCT(MAX((İzinler!$A$5:$A$504=$B10)*(İzinler!$C$5:$C$504<=AG$5)*(İzinler!$D$5:$D$504>=AG$5)*ROW(İzinler!$A$5:$A$504)))=0,"",LEFT(SUBSTITUTE(SUBSTITUTE(INDEX(İzinler!$B$1:$B$504,SUMPRODUCT(MAX((İzinler!$A$5:$A$504=$B10)*(İzinler!$C$5:$C$504<=AG$5)*(İzinler!$D$5:$D$504>=AG$5)*ROW(İzinler!$A$5:$A$504)))),"Yıllık izin","İ"),"Ücretsiz izin","Ü"),1))) | AH10: =IF(B10="","",COUNTIF(C10:AG10,"?"))
B11: =IF(Personel!A10="","",Personel!A10) | C11: =IF(OR($B11="",C$5=""),"",IF(SUMPRODUCT(MAX((İzinler!$A$5:$A$504=$B11)*(İzinler!$C$5:$C$504<=C$5)*(İzinler!$D$5:$D$504>=C$5)*ROW(İzinler!$A$5:$A$504)))=0,"",LEFT(SUBSTITUTE(SUBSTITUTE(INDEX(İzinler!$B$1:$B$504,SUMPRODUCT(MAX((İzinler!$A$5:$A$504=$B11)*(İzinler!$C$5:$C$504<=C$5)*(İzinler!$D$5:$D$504>=C$5)*ROW(İzinler!$A$5:$A$504)))),"Yıllık izin","İ"),"Ücretsiz izin","Ü"),1))) | D11: =IF(OR($B11="",D$5=""),"",IF(SUMPRODUCT(MAX((İzinler!$A$5:$A$504=$B11)*(İzinler!$C$5:$C$504<=D$5)*(İzinler!$D$5:$D$504>=D$5)*ROW(İzinler!$A$5:$A$504)))=0,"",LEFT(SUBSTITUTE(SUBSTITUTE(INDEX(İzinler!$B$1:$B$504,SUMPRODUCT(MAX((İzinler!$A$5:$A$504=$B11)*(İzinler!$C$5:$C$504<=D$5)*(İzinler!$D$5:$D$504>=D$5)*ROW(İzinler!$A$5:$A$504)))),"Yıllık izin","İ"),"Ücretsiz izin","Ü"),1))) | E11: =IF(OR($B11="",E$5=""),"",IF(SUMPRODUCT(MAX((İzinler!$A$5:$A$504=$B11)*(İzinler!$C$5:$C$504<=E$5)*(İzinler!$D$5:$D$504>=E$5)*ROW(İzinler!$A$5:$A$504)))=0,"",LEFT(SUBSTITUTE(SUBSTITUTE(INDEX(İzinler!$B$1:$B$504,SUMPRODUCT(MAX((İzinler!$A$5:$A$504=$B11)*(İzinler!$C$5:$C$504<=E$5)*(İzinler!$D$5:$D$504>=E$5)*ROW(İzinler!$A$5:$A$504)))),"Yıllık izin","İ"),"Ücretsiz izin","Ü"),1))) | F11: =IF(OR($B11="",F$5=""),"",IF(SUMPRODUCT(MAX((İzinler!$A$5:$A$504=$B11)*(İzinler!$C$5:$C$504<=F$5)*(İzinler!$D$5:$D$504>=F$5)*ROW(İzinler!$A$5:$A$504)))=0,"",LEFT(SUBSTITUTE(SUBSTITUTE(INDEX(İzinler!$B$1:$B$504,SUMPRODUCT(MAX((İzinler!$A$5:$A$504=$B11)*(İzinler!$C$5:$C$504<=F$5)*(İzinler!$D$5:$D$504>=F$5)*ROW(İzinler!$A$5:$A$504)))),"Yıllık izin","İ"),"Ücretsiz izin","Ü"),1))) | G11: =IF(OR($B11="",G$5=""),"",IF(SUMPRODUCT(MAX((İzinler!$A$5:$A$504=$B11)*(İzinler!$C$5:$C$504<=G$5)*(İzinler!$D$5:$D$504>=G$5)*ROW(İzinler!$A$5:$A$504)))=0,"",LEFT(SUBSTITUTE(SUBSTITUTE(INDEX(İzinler!$B$1:$B$504,SUMPRODUCT(MAX((İzinler!$A$5:$A$504=$B11)*(İzinler!$C$5:$C$504<=G$5)*(İzinler!$D$5:$D$504>=G$5)*ROW(İzinler!$A$5:$A$504)))),"Yıllık izin","İ"),"Ücretsiz izin","Ü"),1))) | H11: =IF(OR($B11="",H$5=""),"",IF(SUMPRODUCT(MAX((İzinler!$A$5:$A$504=$B11)*(İzinler!$C$5:$C$504<=H$5)*(İzinler!$D$5:$D$504>=H$5)*ROW(İzinler!$A$5:$A$504)))=0,"",LEFT(SUBSTITUTE(SUBSTITUTE(INDEX(İzinler!$B$1:$B$504,SUMPRODUCT(MAX((İzinler!$A$5:$A$504=$B11)*(İzinler!$C$5:$C$504<=H$5)*(İzinler!$D$5:$D$504>=H$5)*ROW(İzinler!$A$5:$A$504)))),"Yıllık izin","İ"),"Ücretsiz izin","Ü"),1))) | I11: =IF(OR($B11="",I$5=""),"",IF(SUMPRODUCT(MAX((İzinler!$A$5:$A$504=$B11)*(İzinler!$C$5:$C$504<=I$5)*(İzinler!$D$5:$D$504>=I$5)*ROW(İzinler!$A$5:$A$504)))=0,"",LEFT(SUBSTITUTE(SUBSTITUTE(INDEX(İzinler!$B$1:$B$504,SUMPRODUCT(MAX((İzinler!$A$5:$A$504=$B11)*(İzinler!$C$5:$C$504<=I$5)*(İzinler!$D$5:$D$504>=I$5)*ROW(İzinler!$A$5:$A$504)))),"Yıllık izin","İ"),"Ücretsiz izin","Ü"),1))) | J11: =IF(OR($B11="",J$5=""),"",IF(SUMPRODUCT(MAX((İzinler!$A$5:$A$504=$B11)*(İzinler!$C$5:$C$504<=J$5)*(İzinler!$D$5:$D$504>=J$5)*ROW(İzinler!$A$5:$A$504)))=0,"",LEFT(SUBSTITUTE(SUBSTITUTE(INDEX(İzinler!$B$1:$B$504,SUMPRODUCT(MAX((İzinler!$A$5:$A$504=$B11)*(İzinler!$C$5:$C$504<=J$5)*(İzinler!$D$5:$D$504>=J$5)*ROW(İzinler!$A$5:$A$504)))),"Yıllık izin","İ"),"Ücretsiz izin","Ü"),1))) | ... AG11: =IF(OR($B11="",AG$5=""),"",IF(SUMPRODUCT(MAX((İzinler!$A$5:$A$504=$B11)*(İzinler!$C$5:$C$504<=AG$5)*(İzinler!$D$5:$D$504>=AG$5)*ROW(İzinler!$A$5:$A$504)))=0,"",LEFT(SUBSTITUTE(SUBSTITUTE(INDEX(İzinler!$B$1:$B$504,SUMPRODUCT(MAX((İzinler!$A$5:$A$504=$B11)*(İzinler!$C$5:$C$504<=AG$5)*(İzinler!$D$5:$D$504>=AG$5)*ROW(İzinler!$A$5:$A$504)))),"Yıllık izin","İ"),"Ücretsiz izin","Ü"),1))) | AH11: =IF(B11="","",COUNTIF(C11:AG11,"?"))
B12: =IF(Personel!A11="","",Personel!A11) | C12: =IF(OR($B12="",C$5=""),"",IF(SUMPRODUCT(MAX((İzinler!$A$5:$A$504=$B12)*(İzinler!$C$5:$C$504<=C$5)*(İzinler!$D$5:$D$504>=C$5)*ROW(İzinler!$A$5:$A$504)))=0,"",LEFT(SUBSTITUTE(SUBSTITUTE(INDEX(İzinler!$B$1:$B$504,SUMPRODUCT(MAX((İzinler!$A$5:$A$504=$B12)*(İzinler!$C$5:$C$504<=C$5)*(İzinler!$D$5:$D$504>=C$5)*ROW(İzinler!$A$5:$A$504)))),"Yıllık izin","İ"),"Ücretsiz izin","Ü"),1))) | D12: =IF(OR($B12="",D$5=""),"",IF(SUMPRODUCT(MAX((İzinler!$A$5:$A$504=$B12)*(İzinler!$C$5:$C$504<=D$5)*(İzinler!$D$5:$D$504>=D$5)*ROW(İzinler!$A$5:$A$504)))=0,"",LEFT(SUBSTITUTE(SUBSTITUTE(INDEX(İzinler!$B$1:$B$504,SUMPRODUCT(MAX((İzinler!$A$5:$A$504=$B12)*(İzinler!$C$5:$C$504<=D$5)*(İzinler!$D$5:$D$504>=D$5)*ROW(İzinler!$A$5:$A$504)))),"Yıllık izin","İ"),"Ücretsiz izin","Ü"),1))) | E12: =IF(OR($B12="",E$5=""),"",IF(SUMPRODUCT(MAX((İzinler!$A$5:$A$504=$B12)*(İzinler!$C$5:$C$504<=E$5)*(İzinler!$D$5:$D$504>=E$5)*ROW(İzinler!$A$5:$A$504)))=0,"",LEFT(SUBSTITUTE(SUBSTITUTE(INDEX(İzinler!$B$1:$B$504,SUMPRODUCT(MAX((İzinler!$A$5:$A$504=$B12)*(İzinler!$C$5:$C$504<=E$5)*(İzinler!$D$5:$D$504>=E$5)*ROW(İzinler!$A$5:$A$504)))),"Yıllık izin","İ"),"Ücretsiz izin","Ü"),1))) | F12: =IF(OR($B12="",F$5=""),"",IF(SUMPRODUCT(MAX((İzinler!$A$5:$A$504=$B12)*(İzinler!$C$5:$C$504<=F$5)*(İzinler!$D$5:$D$504>=F$5)*ROW(İzinler!$A$5:$A$504)))=0,"",LEFT(SUBSTITUTE(SUBSTITUTE(INDEX(İzinler!$B$1:$B$504,SUMPRODUCT(MAX((İzinler!$A$5:$A$504=$B12)*(İzinler!$C$5:$C$504<=F$5)*(İzinler!$D$5:$D$504>=F$5)*ROW(İzinler!$A$5:$A$504)))),"Yıllık izin","İ"),"Ücretsiz izin","Ü"),1))) | G12: =IF(OR($B12="",G$5=""),"",IF(SUMPRODUCT(MAX((İzinler!$A$5:$A$504=$B12)*(İzinler!$C$5:$C$504<=G$5)*(İzinler!$D$5:$D$504>=G$5)*ROW(İzinler!$A$5:$A$504)))=0,"",LEFT(SUBSTITUTE(SUBSTITUTE(INDEX(İzinler!$B$1:$B$504,SUMPRODUCT(MAX((İzinler!$A$5:$A$504=$B12)*(İzinler!$C$5:$C$504<=G$5)*(İzinler!$D$5:$D$504>=G$5)*ROW(İzinler!$A$5:$A$504)))),"Yıllık izin","İ"),"Ücretsiz izin","Ü"),1))) | H12: =IF(OR($B12="",H$5=""),"",IF(SUMPRODUCT(MAX((İzinler!$A$5:$A$504=$B12)*(İzinler!$C$5:$C$504<=H$5)*(İzinler!$D$5:$D$504>=H$5)*ROW(İzinler!$A$5:$A$504)))=0,"",LEFT(SUBSTITUTE(SUBSTITUTE(INDEX(İzinler!$B$1:$B$504,SUMPRODUCT(MAX((İzinler!$A$5:$A$504=$B12)*(İzinler!$C$5:$C$504<=H$5)*(İzinler!$D$5:$D$504>=H$5)*ROW(İzinler!$A$5:$A$504)))),"Yıllık izin","İ"),"Ücretsiz izin","Ü"),1))) | I12: =IF(OR($B12="",I$5=""),"",IF(SUMPRODUCT(MAX((İzinler!$A$5:$A$504=$B12)*(İzinler!$C$5:$C$504<=I$5)*(İzinler!$D$5:$D$504>=I$5)*ROW(İzinler!$A$5:$A$504)))=0,"",LEFT(SUBSTITUTE(SUBSTITUTE(INDEX(İzinler!$B$1:$B$504,SUMPRODUCT(MAX((İzinler!$A$5:$A$504=$B12)*(İzinler!$C$5:$C$504<=I$5)*(İzinler!$D$5:$D$504>=I$5)*ROW(İzinler!$A$5:$A$504)))),"Yıllık izin","İ"),"Ücretsiz izin","Ü"),1))) | J12: =IF(OR($B12="",J$5=""),"",IF(SUMPRODUCT(MAX((İzinler!$A$5:$A$504=$B12)*(İzinler!$C$5:$C$504<=J$5)*(İzinler!$D$5:$D$504>=J$5)*ROW(İzinler!$A$5:$A$504)))=0,"",LEFT(SUBSTITUTE(SUBSTITUTE(INDEX(İzinler!$B$1:$B$504,SUMPRODUCT(MAX((İzinler!$A$5:$A$504=$B12)*(İzinler!$C$5:$C$504<=J$5)*(İzinler!$D$5:$D$504>=J$5)*ROW(İzinler!$A$5:$A$504)))),"Yıllık izin","İ"),"Ücretsiz izin","Ü"),1))) | ... AG12: =IF(OR($B12="",AG$5=""),"",IF(SUMPRODUCT(MAX((İzinler!$A$5:$A$504=$B12)*(İzinler!$C$5:$C$504<=AG$5)*(İzinler!$D$5:$D$504>=AG$5)*ROW(İzinler!$A$5:$A$504)))=0,"",LEFT(SUBSTITUTE(SUBSTITUTE(INDEX(İzinler!$B$1:$B$504,SUMPRODUCT(MAX((İzinler!$A$5:$A$504=$B12)*(İzinler!$C$5:$C$504<=AG$5)*(İzinler!$D$5:$D$504>=AG$5)*ROW(İzinler!$A$5:$A$504)))),"Yıllık izin","İ"),"Ücretsiz izin","Ü"),1))) | AH12: =IF(B12="","",COUNTIF(C12:AG12,"?"))
B13: =IF(Personel!A12="","",Personel!A12) | C13: =IF(OR($B13="",C$5=""),"",IF(SUMPRODUCT(MAX((İzinler!$A$5:$A$504=$B13)*(İzinler!$C$5:$C$504<=C$5)*(İzinler!$D$5:$D$504>=C$5)*ROW(İzinler!$A$5:$A$504)))=0,"",LEFT(SUBSTITUTE(SUBSTITUTE(INDEX(İzinler!$B$1:$B$504,SUMPRODUCT(MAX((İzinler!$A$5:$A$504=$B13)*(İzinler!$C$5:$C$504<=C$5)*(İzinler!$D$5:$D$504>=C$5)*ROW(İzinler!$A$5:$A$504)))),"Yıllık izin","İ"),"Ücretsiz izin","Ü"),1))) | D13: =IF(OR($B13="",D$5=""),"",IF(SUMPRODUCT(MAX((İzinler!$A$5:$A$504=$B13)*(İzinler!$C$5:$C$504<=D$5)*(İzinler!$D$5:$D$504>=D$5)*ROW(İzinler!$A$5:$A$504)))=0,"",LEFT(SUBSTITUTE(SUBSTITUTE(INDEX(İzinler!$B$1:$B$504,SUMPRODUCT(MAX((İzinler!$A$5:$A$504=$B13)*(İzinler!$C$5:$C$504<=D$5)*(İzinler!$D$5:$D$504>=D$5)*ROW(İzinler!$A$5:$A$504)))),"Yıllık izin","İ"),"Ücretsiz izin","Ü"),1))) | E13: =IF(OR($B13="",E$5=""),"",IF(SUMPRODUCT(MAX((İzinler!$A$5:$A$504=$B13)*(İzinler!$C$5:$C$504<=E$5)*(İzinler!$D$5:$D$504>=E$5)*ROW(İzinler!$A$5:$A$504)))=0,"",LEFT(SUBSTITUTE(SUBSTITUTE(INDEX(İzinler!$B$1:$B$504,SUMPRODUCT(MAX((İzinler!$A$5:$A$504=$B13)*(İzinler!$C$5:$C$504<=E$5)*(İzinler!$D$5:$D$504>=E$5)*ROW(İzinler!$A$5:$A$504)))),"Yıllık izin","İ"),"Ücretsiz izin","Ü"),1))) | F13: =IF(OR($B13="",F$5=""),"",IF(SUMPRODUCT(MAX((İzinler!$A$5:$A$504=$B13)*(İzinler!$C$5:$C$504<=F$5)*(İzinler!$D$5:$D$504>=F$5)*ROW(İzinler!$A$5:$A$504)))=0,"",LEFT(SUBSTITUTE(SUBSTITUTE(INDEX(İzinler!$B$1:$B$504,SUMPRODUCT(MAX((İzinler!$A$5:$A$504=$B13)*(İzinler!$C$5:$C$504<=F$5)*(İzinler!$D$5:$D$504>=F$5)*ROW(İzinler!$A$5:$A$504)))),"Yıllık izin","İ"),"Ücretsiz izin","Ü"),1))) | G13: =IF(OR($B13="",G$5=""),"",IF(SUMPRODUCT(MAX((İzinler!$A$5:$A$504=$B13)*(İzinler!$C$5:$C$504<=G$5)*(İzinler!$D$5:$D$504>=G$5)*ROW(İzinler!$A$5:$A$504)))=0,"",LEFT(SUBSTITUTE(SUBSTITUTE(INDEX(İzinler!$B$1:$B$504,SUMPRODUCT(MAX((İzinler!$A$5:$A$504=$B13)*(İzinler!$C$5:$C$504<=G$5)*(İzinler!$D$5:$D$504>=G$5)*ROW(İzinler!$A$5:$A$504)))),"Yıllık izin","İ"),"Ücretsiz izin","Ü"),1))) | H13: =IF(OR($B13="",H$5=""),"",IF(SUMPRODUCT(MAX((İzinler!$A$5:$A$504=$B13)*(İzinler!$C$5:$C$504<=H$5)*(İzinler!$D$5:$D$504>=H$5)*ROW(İzinler!$A$5:$A$504)))=0,"",LEFT(SUBSTITUTE(SUBSTITUTE(INDEX(İzinler!$B$1:$B$504,SUMPRODUCT(MAX((İzinler!$A$5:$A$504=$B13)*(İzinler!$C$5:$C$504<=H$5)*(İzinler!$D$5:$D$504>=H$5)*ROW(İzinler!$A$5:$A$504)))),"Yıllık izin","İ"),"Ücretsiz izin","Ü"),1))) | I13: =IF(OR($B13="",I$5=""),"",IF(SUMPRODUCT(MAX((İzinler!$A$5:$A$504=$B13)*(İzinler!$C$5:$C$504<=I$5)*(İzinler!$D$5:$D$504>=I$5)*ROW(İzinler!$A$5:$A$504)))=0,"",LEFT(SUBSTITUTE(SUBSTITUTE(INDEX(İzinler!$B$1:$B$504,SUMPRODUCT(MAX((İzinler!$A$5:$A$504=$B13)*(İzinler!$C$5:$C$504<=I$5)*(İzinler!$D$5:$D$504>=I$5)*ROW(İzinler!$A$5:$A$504)))),"Yıllık izin","İ"),"Ücretsiz izin","Ü"),1))) | J13: =IF(OR($B13="",J$5=""),"",IF(SUMPRODUCT(MAX((İzinler!$A$5:$A$504=$B13)*(İzinler!$C$5:$C$504<=J$5)*(İzinler!$D$5:$D$504>=J$5)*ROW(İzinler!$A$5:$A$504)))=0,"",LEFT(SUBSTITUTE(SUBSTITUTE(INDEX(İzinler!$B$1:$B$504,SUMPRODUCT(MAX((İzinler!$A$5:$A$504=$B13)*(İzinler!$C$5:$C$504<=J$5)*(İzinler!$D$5:$D$504>=J$5)*ROW(İzinler!$A$5:$A$504)))),"Yıllık izin","İ"),"Ücretsiz izin","Ü"),1))) | ... AG13: =IF(OR($B13="",AG$5=""),"",IF(SUMPRODUCT(MAX((İzinler!$A$5:$A$504=$B13)*(İzinler!$C$5:$C$504<=AG$5)*(İzinler!$D$5:$D$504>=AG$5)*ROW(İzinler!$A$5:$A$504)))=0,"",LEFT(SUBSTITUTE(SUBSTITUTE(INDEX(İzinler!$B$1:$B$504,SUMPRODUCT(MAX((İzinler!$A$5:$A$504=$B13)*(İzinler!$C$5:$C$504<=AG$5)*(İzinler!$D$5:$D$504>=AG$5)*ROW(İzinler!$A$5:$A$504)))),"Yıllık izin","İ"),"Ücretsiz izin","Ü"),1))) | AH13: =IF(B13="","",COUNTIF(C13:AG13,"?"))
B14: =IF(Personel!A13="","",Personel!A13) | C14: =IF(OR($B14="",C$5=""),"",IF(SUMPRODUCT(MAX((İzinler!$A$5:$A$504=$B14)*(İzinler!$C$5:$C$504<=C$5)*(İzinler!$D$5:$D$504>=C$5)*ROW(İzinler!$A$5:$A$504)))=0,"",LEFT(SUBSTITUTE(SUBSTITUTE(INDEX(İzinler!$B$1:$B$504,SUMPRODUCT(MAX((İzinler!$A$5:$A$504=$B14)*(İzinler!$C$5:$C$504<=C$5)*(İzinler!$D$5:$D$504>=C$5)*ROW(İzinler!$A$5:$A$504)))),"Yıllık izin","İ"),"Ücretsiz izin","Ü"),1))) | D14: =IF(OR($B14="",D$5=""),"",IF(SUMPRODUCT(MAX((İzinler!$A$5:$A$504=$B14)*(İzinler!$C$5:$C$504<=D$5)*(İzinler!$D$5:$D$504>=D$5)*ROW(İzinler!$A$5:$A$504)))=0,"",LEFT(SUBSTITUTE(SUBSTITUTE(INDEX(İzinler!$B$1:$B$504,SUMPRODUCT(MAX((İzinler!$A$5:$A$504=$B14)*(İzinler!$C$5:$C$504<=D$5)*(İzinler!$D$5:$D$504>=D$5)*ROW(İzinler!$A$5:$A$504)))),"Yıllık izin","İ"),"Ücretsiz izin","Ü"),1))) | E14: =IF(OR($B14="",E$5=""),"",IF(SUMPRODUCT(MAX((İzinler!$A$5:$A$504=$B14)*(İzinler!$C$5:$C$504<=E$5)*(İzinler!$D$5:$D$504>=E$5)*ROW(İzinler!$A$5:$A$504)))=0,"",LEFT(SUBSTITUTE(SUBSTITUTE(INDEX(İzinler!$B$1:$B$504,SUMPRODUCT(MAX((İzinler!$A$5:$A$504=$B14)*(İzinler!$C$5:$C$504<=E$5)*(İzinler!$D$5:$D$504>=E$5)*ROW(İzinler!$A$5:$A$504)))),"Yıllık izin","İ"),"Ücretsiz izin","Ü"),1))) | F14: =IF(OR($B14="",F$5=""),"",IF(SUMPRODUCT(MAX((İzinler!$A$5:$A$504=$B14)*(İzinler!$C$5:$C$504<=F$5)*(İzinler!$D$5:$D$504>=F$5)*ROW(İzinler!$A$5:$A$504)))=0,"",LEFT(SUBSTITUTE(SUBSTITUTE(INDEX(İzinler!$B$1:$B$504,SUMPRODUCT(MAX((İzinler!$A$5:$A$504=$B14)*(İzinler!$C$5:$C$504<=F$5)*(İzinler!$D$5:$D$504>=F$5)*ROW(İzinler!$A$5:$A$504)))),"Yıllık izin","İ"),"Ücretsiz izin","Ü"),1))) | G14: =IF(OR($B14="",G$5=""),"",IF(SUMPRODUCT(MAX((İzinler!$A$5:$A$504=$B14)*(İzinler!$C$5:$C$504<=G$5)*(İzinler!$D$5:$D$504>=G$5)*ROW(İzinler!$A$5:$A$504)))=0,"",LEFT(SUBSTITUTE(SUBSTITUTE(INDEX(İzinler!$B$1:$B$504,SUMPRODUCT(MAX((İzinler!$A$5:$A$504=$B14)*(İzinler!$C$5:$C$504<=G$5)*(İzinler!$D$5:$D$504>=G$5)*ROW(İzinler!$A$5:$A$504)))),"Yıllık izin","İ"),"Ücretsiz izin","Ü"),1))) | H14: =IF(OR($B14="",H$5=""),"",IF(SUMPRODUCT(MAX((İzinler!$A$5:$A$504=$B14)*(İzinler!$C$5:$C$504<=H$5)*(İzinler!$D$5:$D$504>=H$5)*ROW(İzinler!$A$5:$A$504)))=0,"",LEFT(SUBSTITUTE(SUBSTITUTE(INDEX(İzinler!$B$1:$B$504,SUMPRODUCT(MAX((İzinler!$A$5:$A$504=$B14)*(İzinler!$C$5:$C$504<=H$5)*(İzinler!$D$5:$D$504>=H$5)*ROW(İzinler!$A$5:$A$504)))),"Yıllık izin","İ"),"Ücretsiz izin","Ü"),1))) | I14: =IF(OR($B14="",I$5=""),"",IF(SUMPRODUCT(MAX((İzinler!$A$5:$A$504=$B14)*(İzinler!$C$5:$C$504<=I$5)*(İzinler!$D$5:$D$504>=I$5)*ROW(İzinler!$A$5:$A$504)))=0,"",LEFT(SUBSTITUTE(SUBSTITUTE(INDEX(İzinler!$B$1:$B$504,SUMPRODUCT(MAX((İzinler!$A$5:$A$504=$B14)*(İzinler!$C$5:$C$504<=I$5)*(İzinler!$D$5:$D$504>=I$5)*ROW(İzinler!$A$5:$A$504)))),"Yıllık izin","İ"),"Ücretsiz izin","Ü"),1))) | J14: =IF(OR($B14="",J$5=""),"",IF(SUMPRODUCT(MAX((İzinler!$A$5:$A$504=$B14)*(İzinler!$C$5:$C$504<=J$5)*(İzinler!$D$5:$D$504>=J$5)*ROW(İzinler!$A$5:$A$504)))=0,"",LEFT(SUBSTITUTE(SUBSTITUTE(INDEX(İzinler!$B$1:$B$504,SUMPRODUCT(MAX((İzinler!$A$5:$A$504=$B14)*(İzinler!$C$5:$C$504<=J$5)*(İzinler!$D$5:$D$504>=J$5)*ROW(İzinler!$A$5:$A$504)))),"Yıllık izin","İ"),"Ücretsiz izin","Ü"),1))) | ... AG14: =IF(OR($B14="",AG$5=""),"",IF(SUMPRODUCT(MAX((İzinler!$A$5:$A$504=$B14)*(İzinler!$C$5:$C$504<=AG$5)*(İzinler!$D$5:$D$504>=AG$5)*ROW(İzinler!$A$5:$A$504)))=0,"",LEFT(SUBSTITUTE(SUBSTITUTE(INDEX(İzinler!$B$1:$B$504,SUMPRODUCT(MAX((İzinler!$A$5:$A$504=$B14)*(İzinler!$C$5:$C$504<=AG$5)*(İzinler!$D$5:$D$504>=AG$5)*ROW(İzinler!$A$5:$A$504)))),"Yıllık izin","İ"),"Ücretsiz izin","Ü"),1))) | AH14: =IF(B14="","",COUNTIF(C14:AG14,"?"))
B15: =IF(Personel!A14="","",Personel!A14) | C15: =IF(OR($B15="",C$5=""),"",IF(SUMPRODUCT(MAX((İzinler!$A$5:$A$504=$B15)*(İzinler!$C$5:$C$504<=C$5)*(İzinler!$D$5:$D$504>=C$5)*ROW(İzinler!$A$5:$A$504)))=0,"",LEFT(SUBSTITUTE(SUBSTITUTE(INDEX(İzinler!$B$1:$B$504,SUMPRODUCT(MAX((İzinler!$A$5:$A$504=$B15)*(İzinler!$C$5:$C$504<=C$5)*(İzinler!$D$5:$D$504>=C$5)*ROW(İzinler!$A$5:$A$504)))),"Yıllık izin","İ"),"Ücretsiz izin","Ü"),1))) | D15: =IF(OR($B15="",D$5=""),"",IF(SUMPRODUCT(MAX((İzinler!$A$5:$A$504=$B15)*(İzinler!$C$5:$C$504<=D$5)*(İzinler!$D$5:$D$504>=D$5)*ROW(İzinler!$A$5:$A$504)))=0,"",LEFT(SUBSTITUTE(SUBSTITUTE(INDEX(İzinler!$B$1:$B$504,SUMPRODUCT(MAX((İzinler!$A$5:$A$504=$B15)*(İzinler!$C$5:$C$504<=D$5)*(İzinler!$D$5:$D$504>=D$5)*ROW(İzinler!$A$5:$A$504)))),"Yıllık izin","İ"),"Ücretsiz izin","Ü"),1))) | E15: =IF(OR($B15="",E$5=""),"",IF(SUMPRODUCT(MAX((İzinler!$A$5:$A$504=$B15)*(İzinler!$C$5:$C$504<=E$5)*(İzinler!$D$5:$D$504>=E$5)*ROW(İzinler!$A$5:$A$504)))=0,"",LEFT(SUBSTITUTE(SUBSTITUTE(INDEX(İzinler!$B$1:$B$504,SUMPRODUCT(MAX((İzinler!$A$5:$A$504=$B15)*(İzinler!$C$5:$C$504<=E$5)*(İzinler!$D$5:$D$504>=E$5)*ROW(İzinler!$A$5:$A$504)))),"Yıllık izin","İ"),"Ücretsiz izin","Ü"),1))) | F15: =IF(OR($B15="",F$5=""),"",IF(SUMPRODUCT(MAX((İzinler!$A$5:$A$504=$B15)*(İzinler!$C$5:$C$504<=F$5)*(İzinler!$D$5:$D$504>=F$5)*ROW(İzinler!$A$5:$A$504)))=0,"",LEFT(SUBSTITUTE(SUBSTITUTE(INDEX(İzinler!$B$1:$B$504,SUMPRODUCT(MAX((İzinler!$A$5:$A$504=$B15)*(İzinler!$C$5:$C$504<=F$5)*(İzinler!$D$5:$D$504>=F$5)*ROW(İzinler!$A$5:$A$504)))),"Yıllık izin","İ"),"Ücretsiz izin","Ü"),1))) | G15: =IF(OR($B15="",G$5=""),"",IF(SUMPRODUCT(MAX((İzinler!$A$5:$A$504=$B15)*(İzinler!$C$5:$C$504<=G$5)*(İzinler!$D$5:$D$504>=G$5)*ROW(İzinler!$A$5:$A$504)))=0,"",LEFT(SUBSTITUTE(SUBSTITUTE(INDEX(İzinler!$B$1:$B$504,SUMPRODUCT(MAX((İzinler!$A$5:$A$504=$B15)*(İzinler!$C$5:$C$504<=G$5)*(İzinler!$D$5:$D$504>=G$5)*ROW(İzinler!$A$5:$A$504)))),"Yıllık izin","İ"),"Ücretsiz izin","Ü"),1))) | H15: =IF(OR($B15="",H$5=""),"",IF(SUMPRODUCT(MAX((İzinler!$A$5:$A$504=$B15)*(İzinler!$C$5:$C$504<=H$5)*(İzinler!$D$5:$D$504>=H$5)*ROW(İzinler!$A$5:$A$504)))=0,"",LEFT(SUBSTITUTE(SUBSTITUTE(INDEX(İzinler!$B$1:$B$504,SUMPRODUCT(MAX((İzinler!$A$5:$A$504=$B15)*(İzinler!$C$5:$C$504<=H$5)*(İzinler!$D$5:$D$504>=H$5)*ROW(İzinler!$A$5:$A$504)))),"Yıllık izin","İ"),"Ücretsiz izin","Ü"),1))) | I15: =IF(OR($B15="",I$5=""),"",IF(SUMPRODUCT(MAX((İzinler!$A$5:$A$504=$B15)*(İzinler!$C$5:$C$504<=I$5)*(İzinler!$D$5:$D$504>=I$5)*ROW(İzinler!$A$5:$A$504)))=0,"",LEFT(SUBSTITUTE(SUBSTITUTE(INDEX(İzinler!$B$1:$B$504,SUMPRODUCT(MAX((İzinler!$A$5:$A$504=$B15)*(İzinler!$C$5:$C$504<=I$5)*(İzinler!$D$5:$D$504>=I$5)*ROW(İzinler!$A$5:$A$504)))),"Yıllık izin","İ"),"Ücretsiz izin","Ü"),1))) | J15: =IF(OR($B15="",J$5=""),"",IF(SUMPRODUCT(MAX((İzinler!$A$5:$A$504=$B15)*(İzinler!$C$5:$C$504<=J$5)*(İzinler!$D$5:$D$504>=J$5)*ROW(İzinler!$A$5:$A$504)))=0,"",LEFT(SUBSTITUTE(SUBSTITUTE(INDEX(İzinler!$B$1:$B$504,SUMPRODUCT(MAX((İzinler!$A$5:$A$504=$B15)*(İzinler!$C$5:$C$504<=J$5)*(İzinler!$D$5:$D$504>=J$5)*ROW(İzinler!$A$5:$A$504)))),"Yıllık izin","İ"),"Ücretsiz izin","Ü"),1))) | ... AG15: =IF(OR($B15="",AG$5=""),"",IF(SUMPRODUCT(MAX((İzinler!$A$5:$A$504=$B15)*(İzinler!$C$5:$C$504<=AG$5)*(İzinler!$D$5:$D$504>=AG$5)*ROW(İzinler!$A$5:$A$504)))=0,"",LEFT(SUBSTITUTE(SUBSTITUTE(INDEX(İzinler!$B$1:$B$504,SUMPRODUCT(MAX((İzinler!$A$5:$A$504=$B15)*(İzinler!$C$5:$C$504<=AG$5)*(İzinler!$D$5:$D$504>=AG$5)*ROW(İzinler!$A$5:$A$504)))),"Yıllık izin","İ"),"Ücretsiz izin","Ü"),1))) | AH15: =IF(B15="","",COUNTIF(C15:AG15,"?"))
B16: =IF(Personel!A15="","",Personel!A15) | C16: =IF(OR($B16="",C$5=""),"",IF(SUMPRODUCT(MAX((İzinler!$A$5:$A$504=$B16)*(İzinler!$C$5:$C$504<=C$5)*(İzinler!$D$5:$D$504>=C$5)*ROW(İzinler!$A$5:$A$504)))=0,"",LEFT(SUBSTITUTE(SUBSTITUTE(INDEX(İzinler!$B$1:$B$504,SUMPRODUCT(MAX((İzinler!$A$5:$A$504=$B16)*(İzinler!$C$5:$C$504<=C$5)*(İzinler!$D$5:$D$504>=C$5)*ROW(İzinler!$A$5:$A$504)))),"Yıllık izin","İ"),"Ücretsiz izin","Ü"),1))) | D16: =IF(OR($B16="",D$5=""),"",IF(SUMPRODUCT(MAX((İzinler!$A$5:$A$504=$B16)*(İzinler!$C$5:$C$504<=D$5)*(İzinler!$D$5:$D$504>=D$5)*ROW(İzinler!$A$5:$A$504)))=0,"",LEFT(SUBSTITUTE(SUBSTITUTE(INDEX(İzinler!$B$1:$B$504,SUMPRODUCT(MAX((İzinler!$A$5:$A$504=$B16)*(İzinler!$C$5:$C$504<=D$5)*(İzinler!$D$5:$D$504>=D$5)*ROW(İzinler!$A$5:$A$504)))),"Yıllık izin","İ"),"Ücretsiz izin","Ü"),1))) | E16: =IF(OR($B16="",E$5=""),"",IF(SUMPRODUCT(MAX((İzinler!$A$5:$A$504=$B16)*(İzinler!$C$5:$C$504<=E$5)*(İzinler!$D$5:$D$504>=E$5)*ROW(İzinler!$A$5:$A$504)))=0,"",LEFT(SUBSTITUTE(SUBSTITUTE(INDEX(İzinler!$B$1:$B$504,SUMPRODUCT(MAX((İzinler!$A$5:$A$504=$B16)*(İzinler!$C$5:$C$504<=E$5)*(İzinler!$D$5:$D$504>=E$5)*ROW(İzinler!$A$5:$A$504)))),"Yıllık izin","İ"),"Ücretsiz izin","Ü"),1))) | F16: =IF(OR($B16="",F$5=""),"",IF(SUMPRODUCT(MAX((İzinler!$A$5:$A$504=$B16)*(İzinler!$C$5:$C$504<=F$5)*(İzinler!$D$5:$D$504>=F$5)*ROW(İzinler!$A$5:$A$504)))=0,"",LEFT(SUBSTITUTE(SUBSTITUTE(INDEX(İzinler!$B$1:$B$504,SUMPRODUCT(MAX((İzinler!$A$5:$A$504=$B16)*(İzinler!$C$5:$C$504<=F$5)*(İzinler!$D$5:$D$504>=F$5)*ROW(İzinler!$A$5:$A$504)))),"Yıllık izin","İ"),"Ücretsiz izin","Ü"),1))) | G16: =IF(OR($B16="",G$5=""),"",IF(SUMPRODUCT(MAX((İzinler!$A$5:$A$504=$B16)*(İzinler!$C$5:$C$504<=G$5)*(İzinler!$D$5:$D$504>=G$5)*ROW(İzinler!$A$5:$A$504)))=0,"",LEFT(SUBSTITUTE(SUBSTITUTE(INDEX(İzinler!$B$1:$B$504,SUMPRODUCT(MAX((İzinler!$A$5:$A$504=$B16)*(İzinler!$C$5:$C$504<=G$5)*(İzinler!$D$5:$D$504>=G$5)*ROW(İzinler!$A$5:$A$504)))),"Yıllık izin","İ"),"Ücretsiz izin","Ü"),1))) | H16: =IF(OR($B16="",H$5=""),"",IF(SUMPRODUCT(MAX((İzinler!$A$5:$A$504=$B16)*(İzinler!$C$5:$C$504<=H$5)*(İzinler!$D$5:$D$504>=H$5)*ROW(İzinler!$A$5:$A$504)))=0,"",LEFT(SUBSTITUTE(SUBSTITUTE(INDEX(İzinler!$B$1:$B$504,SUMPRODUCT(MAX((İzinler!$A$5:$A$504=$B16)*(İzinler!$C$5:$C$504<=H$5)*(İzinler!$D$5:$D$504>=H$5)*ROW(İzinler!$A$5:$A$504)))),"Yıllık izin","İ"),"Ücretsiz izin","Ü"),1))) | I16: =IF(OR($B16="",I$5=""),"",IF(SUMPRODUCT(MAX((İzinler!$A$5:$A$504=$B16)*(İzinler!$C$5:$C$504<=I$5)*(İzinler!$D$5:$D$504>=I$5)*ROW(İzinler!$A$5:$A$504)))=0,"",LEFT(SUBSTITUTE(SUBSTITUTE(INDEX(İzinler!$B$1:$B$504,SUMPRODUCT(MAX((İzinler!$A$5:$A$504=$B16)*(İzinler!$C$5:$C$504<=I$5)*(İzinler!$D$5:$D$504>=I$5)*ROW(İzinler!$A$5:$A$504)))),"Yıllık izin","İ"),"Ücretsiz izin","Ü"),1))) | J16: =IF(OR($B16="",J$5=""),"",IF(SUMPRODUCT(MAX((İzinler!$A$5:$A$504=$B16)*(İzinler!$C$5:$C$504<=J$5)*(İzinler!$D$5:$D$504>=J$5)*ROW(İzinler!$A$5:$A$504)))=0,"",LEFT(SUBSTITUTE(SUBSTITUTE(INDEX(İzinler!$B$1:$B$504,SUMPRODUCT(MAX((İzinler!$A$5:$A$504=$B16)*(İzinler!$C$5:$C$504<=J$5)*(İzinler!$D$5:$D$504>=J$5)*ROW(İzinler!$A$5:$A$504)))),"Yıllık izin","İ"),"Ücretsiz izin","Ü"),1))) | ... AG16: =IF(OR($B16="",AG$5=""),"",IF(SUMPRODUCT(MAX((İzinler!$A$5:$A$504=$B16)*(İzinler!$C$5:$C$504<=AG$5)*(İzinler!$D$5:$D$504>=AG$5)*ROW(İzinler!$A$5:$A$504)))=0,"",LEFT(SUBSTITUTE(SUBSTITUTE(INDEX(İzinler!$B$1:$B$504,SUMPRODUCT(MAX((İzinler!$A$5:$A$504=$B16)*(İzinler!$C$5:$C$504<=AG$5)*(İzinler!$D$5:$D$504>=AG$5)*ROW(İzinler!$A$5:$A$504)))),"Yıllık izin","İ"),"Ücretsiz izin","Ü"),1))) | AH16: =IF(B16="","",COUNTIF(C16:AG16,"?"))
B17: =IF(Personel!A16="","",Personel!A16) | C17: =IF(OR($B17="",C$5=""),"",IF(SUMPRODUCT(MAX((İzinler!$A$5:$A$504=$B17)*(İzinler!$C$5:$C$504<=C$5)*(İzinler!$D$5:$D$504>=C$5)*ROW(İzinler!$A$5:$A$504)))=0,"",LEFT(SUBSTITUTE(SUBSTITUTE(INDEX(İzinler!$B$1:$B$504,SUMPRODUCT(MAX((İzinler!$A$5:$A$504=$B17)*(İzinler!$C$5:$C$504<=C$5)*(İzinler!$D$5:$D$504>=C$5)*ROW(İzinler!$A$5:$A$504)))),"Yıllık izin","İ"),"Ücretsiz izin","Ü"),1))) | D17: =IF(OR($B17="",D$5=""),"",IF(SUMPRODUCT(MAX((İzinler!$A$5:$A$504=$B17)*(İzinler!$C$5:$C$504<=D$5)*(İzinler!$D$5:$D$504>=D$5)*ROW(İzinler!$A$5:$A$504)))=0,"",LEFT(SUBSTITUTE(SUBSTITUTE(INDEX(İzinler!$B$1:$B$504,SUMPRODUCT(MAX((İzinler!$A$5:$A$504=$B17)*(İzinler!$C$5:$C$504<=D$5)*(İzinler!$D$5:$D$504>=D$5)*ROW(İzinler!$A$5:$A$504)))),"Yıllık izin","İ"),"Ücretsiz izin","Ü"),1))) | E17: =IF(OR($B17="",E$5=""),"",IF(SUMPRODUCT(MAX((İzinler!$A$5:$A$504=$B17)*(İzinler!$C$5:$C$504<=E$5)*(İzinler!$D$5:$D$504>=E$5)*ROW(İzinler!$A$5:$A$504)))=0,"",LEFT(SUBSTITUTE(SUBSTITUTE(INDEX(İzinler!$B$1:$B$504,SUMPRODUCT(MAX((İzinler!$A$5:$A$504=$B17)*(İzinler!$C$5:$C$504<=E$5)*(İzinler!$D$5:$D$504>=E$5)*ROW(İzinler!$A$5:$A$504)))),"Yıllık izin","İ"),"Ücretsiz izin","Ü"),1))) | F17: =IF(OR($B17="",F$5=""),"",IF(SUMPRODUCT(MAX((İzinler!$A$5:$A$504=$B17)*(İzinler!$C$5:$C$504<=F$5)*(İzinler!$D$5:$D$504>=F$5)*ROW(İzinler!$A$5:$A$504)))=0,"",LEFT(SUBSTITUTE(SUBSTITUTE(INDEX(İzinler!$B$1:$B$504,SUMPRODUCT(MAX((İzinler!$A$5:$A$504=$B17)*(İzinler!$C$5:$C$504<=F$5)*(İzinler!$D$5:$D$504>=F$5)*ROW(İzinler!$A$5:$A$504)))),"Yıllık izin","İ"),"Ücretsiz izin","Ü"),1))) | G17: =IF(OR($B17="",G$5=""),"",IF(SUMPRODUCT(MAX((İzinler!$A$5:$A$504=$B17)*(İzinler!$C$5:$C$504<=G$5)*(İzinler!$D$5:$D$504>=G$5)*ROW(İzinler!$A$5:$A$504)))=0,"",LEFT(SUBSTITUTE(SUBSTITUTE(INDEX(İzinler!$B$1:$B$504,SUMPRODUCT(MAX((İzinler!$A$5:$A$504=$B17)*(İzinler!$C$5:$C$504<=G$5)*(İzinler!$D$5:$D$504>=G$5)*ROW(İzinler!$A$5:$A$504)))),"Yıllık izin","İ"),"Ücretsiz izin","Ü"),1))) | H17: =IF(OR($B17="",H$5=""),"",IF(SUMPRODUCT(MAX((İzinler!$A$5:$A$504=$B17)*(İzinler!$C$5:$C$504<=H$5)*(İzinler!$D$5:$D$504>=H$5)*ROW(İzinler!$A$5:$A$504)))=0,"",LEFT(SUBSTITUTE(SUBSTITUTE(INDEX(İzinler!$B$1:$B$504,SUMPRODUCT(MAX((İzinler!$A$5:$A$504=$B17)*(İzinler!$C$5:$C$504<=H$5)*(İzinler!$D$5:$D$504>=H$5)*ROW(İzinler!$A$5:$A$504)))),"Yıllık izin","İ"),"Ücretsiz izin","Ü"),1))) | I17: =IF(OR($B17="",I$5=""),"",IF(SUMPRODUCT(MAX((İzinler!$A$5:$A$504=$B17)*(İzinler!$C$5:$C$504<=I$5)*(İzinler!$D$5:$D$504>=I$5)*ROW(İzinler!$A$5:$A$504)))=0,"",LEFT(SUBSTITUTE(SUBSTITUTE(INDEX(İzinler!$B$1:$B$504,SUMPRODUCT(MAX((İzinler!$A$5:$A$504=$B17)*(İzinler!$C$5:$C$504<=I$5)*(İzinler!$D$5:$D$504>=I$5)*ROW(İzinler!$A$5:$A$504)))),"Yıllık izin","İ"),"Ücretsiz izin","Ü"),1))) | J17: =IF(OR($B17="",J$5=""),"",IF(SUMPRODUCT(MAX((İzinler!$A$5:$A$504=$B17)*(İzinler!$C$5:$C$504<=J$5)*(İzinler!$D$5:$D$504>=J$5)*ROW(İzinler!$A$5:$A$504)))=0,"",LEFT(SUBSTITUTE(SUBSTITUTE(INDEX(İzinler!$B$1:$B$504,SUMPRODUCT(MAX((İzinler!$A$5:$A$504=$B17)*(İzinler!$C$5:$C$504<=J$5)*(İzinler!$D$5:$D$504>=J$5)*ROW(İzinler!$A$5:$A$504)))),"Yıllık izin","İ"),"Ücretsiz izin","Ü"),1))) | ... AG17: =IF(OR($B17="",AG$5=""),"",IF(SUMPRODUCT(MAX((İzinler!$A$5:$A$504=$B17)*(İzinler!$C$5:$C$504<=AG$5)*(İzinler!$D$5:$D$504>=AG$5)*ROW(İzinler!$A$5:$A$504)))=0,"",LEFT(SUBSTITUTE(SUBSTITUTE(INDEX(İzinler!$B$1:$B$504,SUMPRODUCT(MAX((İzinler!$A$5:$A$504=$B17)*(İzinler!$C$5:$C$504<=AG$5)*(İzinler!$D$5:$D$504>=AG$5)*ROW(İzinler!$A$5:$A$504)))),"Yıllık izin","İ"),"Ücretsiz izin","Ü"),1))) | AH17: =IF(B17="","",COUNTIF(C17:AG17,"?"))
... B55: =IF(Personel!A54="","",Personel!A54) | C55: =IF(OR($B55="",C$5=""),"",IF(SUMPRODUCT(MAX((İzinler!$A$5:$A$504=$B55)*(İzinler!$C$5:$C$504<=C$5)*(İzinler!$D$5:$D$504>=C$5)*ROW(İzinler!$A$5:$A$504)))=0,"",LEFT(SUBSTITUTE(SUBSTITUTE(INDEX(İzinler!$B$1:$B$504,SUMPRODUCT(MAX((İzinler!$A$5:$A$504=$B55)*(İzinler!$C$5:$C$504<=C$5)*(İzinler!$D$5:$D$504>=C$5)*ROW(İzinler!$A$5:$A$504)))),"Yıllık izin","İ"),"Ücretsiz izin","Ü"),1))) | D55: =IF(OR($B55="",D$5=""),"",IF(SUMPRODUCT(MAX((İzinler!$A$5:$A$504=$B55)*(İzinler!$C$5:$C$504<=D$5)*(İzinler!$D$5:$D$504>=D$5)*ROW(İzinler!$A$5:$A$504)))=0,"",LEFT(SUBSTITUTE(SUBSTITUTE(INDEX(İzinler!$B$1:$B$504,SUMPRODUCT(MAX((İzinler!$A$5:$A$504=$B55)*(İzinler!$C$5:$C$504<=D$5)*(İzinler!$D$5:$D$504>=D$5)*ROW(İzinler!$A$5:$A$504)))),"Yıllık izin","İ"),"Ücretsiz izin","Ü"),1))) | E55: =IF(OR($B55="",E$5=""),"",IF(SUMPRODUCT(MAX((İzinler!$A$5:$A$504=$B55)*(İzinler!$C$5:$C$504<=E$5)*(İzinler!$D$5:$D$504>=E$5)*ROW(İzinler!$A$5:$A$504)))=0,"",LEFT(SUBSTITUTE(SUBSTITUTE(INDEX(İzinler!$B$1:$B$504,SUMPRODUCT(MAX((İzinler!$A$5:$A$504=$B55)*(İzinler!$C$5:$C$504<=E$5)*(İzinler!$D$5:$D$504>=E$5)*ROW(İzinler!$A$5:$A$504)))),"Yıllık izin","İ"),"Ücretsiz izin","Ü"),1))) | F55: =IF(OR($B55="",F$5=""),"",IF(SUMPRODUCT(MAX((İzinler!$A$5:$A$504=$B55)*(İzinler!$C$5:$C$504<=F$5)*(İzinler!$D$5:$D$504>=F$5)*ROW(İzinler!$A$5:$A$504)))=0,"",LEFT(SUBSTITUTE(SUBSTITUTE(INDEX(İzinler!$B$1:$B$504,SUMPRODUCT(MAX((İzinler!$A$5:$A$504=$B55)*(İzinler!$C$5:$C$504<=F$5)*(İzinler!$D$5:$D$504>=F$5)*ROW(İzinler!$A$5:$A$504)))),"Yıllık izin","İ"),"Ücretsiz izin","Ü"),1))) | G55: =IF(OR($B55="",G$5=""),"",IF(SUMPRODUCT(MAX((İzinler!$A$5:$A$504=$B55)*(İzinler!$C$5:$C$504<=G$5)*(İzinler!$D$5:$D$504>=G$5)*ROW(İzinler!$A$5:$A$504)))=0,"",LEFT(SUBSTITUTE(SUBSTITUTE(INDEX(İzinler!$B$1:$B$504,SUMPRODUCT(MAX((İzinler!$A$5:$A$504=$B55)*(İzinler!$C$5:$C$504<=G$5)*(İzinler!$D$5:$D$504>=G$5)*ROW(İzinler!$A$5:$A$504)))),"Yıllık izin","İ"),"Ücretsiz izin","Ü"),1))) | H55: =IF(OR($B55="",H$5=""),"",IF(SUMPRODUCT(MAX((İzinler!$A$5:$A$504=$B55)*(İzinler!$C$5:$C$504<=H$5)*(İzinler!$D$5:$D$504>=H$5)*ROW(İzinler!$A$5:$A$504)))=0,"",LEFT(SUBSTITUTE(SUBSTITUTE(INDEX(İzinler!$B$1:$B$504,SUMPRODUCT(MAX((İzinler!$A$5:$A$504=$B55)*(İzinler!$C$5:$C$504<=H$5)*(İzinler!$D$5:$D$504>=H$5)*ROW(İzinler!$A$5:$A$504)))),"Yıllık izin","İ"),"Ücretsiz izin","Ü"),1))) | I55: =IF(OR($B55="",I$5=""),"",IF(SUMPRODUCT(MAX((İzinler!$A$5:$A$504=$B55)*(İzinler!$C$5:$C$504<=I$5)*(İzinler!$D$5:$D$504>=I$5)*ROW(İzinler!$A$5:$A$504)))=0,"",LEFT(SUBSTITUTE(SUBSTITUTE(INDEX(İzinler!$B$1:$B$504,SUMPRODUCT(MAX((İzinler!$A$5:$A$504=$B55)*(İzinler!$C$5:$C$504<=I$5)*(İzinler!$D$5:$D$504>=I$5)*ROW(İzinler!$A$5:$A$504)))),"Yıllık izin","İ"),"Ücretsiz izin","Ü"),1))) | J55: =IF(OR($B55="",J$5=""),"",IF(SUMPRODUCT(MAX((İzinler!$A$5:$A$504=$B55)*(İzinler!$C$5:$C$504<=J$5)*(İzinler!$D$5:$D$504>=J$5)*ROW(İzinler!$A$5:$A$504)))=0,"",LEFT(SUBSTITUTE(SUBSTITUTE(INDEX(İzinler!$B$1:$B$504,SUMPRODUCT(MAX((İzinler!$A$5:$A$504=$B55)*(İzinler!$C$5:$C$504<=J$5)*(İzinler!$D$5:$D$504>=J$5)*ROW(İzinler!$A$5:$A$504)))),"Yıllık izin","İ"),"Ücretsiz izin","Ü"),1))) | ... AG55: =IF(OR($B55="",AG$5=""),"",IF(SUMPRODUCT(MAX((İzinler!$A$5:$A$504=$B55)*(İzinler!$C$5:$C$504<=AG$5)*(İzinler!$D$5:$D$504>=AG$5)*ROW(İzinler!$A$5:$A$504)))=0,"",LEFT(SUBSTITUTE(SUBSTITUTE(INDEX(İzinler!$B$1:$B$504,SUMPRODUCT(MAX((İzinler!$A$5:$A$504=$B55)*(İzinler!$C$5:$C$504<=AG$5)*(İzinler!$D$5:$D$504>=AG$5)*ROW(İzinler!$A$5:$A$504)))),"Yıllık izin","İ"),"Ücretsiz izin","Ü"),1))) | AH55: =IF(B55="","",COUNTIF(C55:AG55,"?"))

Sheet Özet
A1: Özet
A2: Bu sayfaya yazma. Yılı Ayarlar sayfasından değiştir.
B4: Personel | C4: Bugün izinde | D4: Kullanılan yıllık izin (gün) | E4: Kalan yıllık izin (gün) | F4: Mesai (saat)
B5: =COUNTA(Personel!$A$5:$A$54) -> 3 | C5: =SUMPRODUCT((İzinler!$A$5:$A$504<>"")*(İzinler!$C$5:$C$504<=TODAY())*(İzinler!$D$5:$D$504>=TODAY())) -> 1 | D5: =SUM(Personel!$E$5:$E$54) -> 25 | E5: =SUM(Personel!$F$5:$F$54) -> 23 | F5: =SUM(Personel!$I$5:$I$54) -> 9.5
B8: Aylara göre izin ve mesai
B9: Ay | C9: Yıllık izin (gün) | D9: Rapor (gün) | E9: Mesai (saat)
B10: Ocak | C10: =SUMIFS(İzinler!$F$5:$F$504,İzinler!$C$5:$C$504,">="&DATE(Ayarlar!$C$4,1,1),İzinler!$C$5:$C$504,"<"&DATE(Ayarlar!$C$4,2,1),İzinler!$B$5:$B$504,"Yıllık izin") -> 0 | D10: =SUMIFS(İzinler!$F$5:$F$504,İzinler!$C$5:$C$504,">="&DATE(Ayarlar!$C$4,1,1),İzinler!$C$5:$C$504,"<"&DATE(Ayarlar!$C$4,2,1),İzinler!$B$5:$B$504,"Rapor") -> 0 | E10: =SUMIFS(Mesai!$C$5:$C$504,Mesai!$B$5:$B$504,">="&DATE(Ayarlar!$C$4,1,1),Mesai!$B$5:$B$504,"<"&DATE(Ayarlar!$C$4,2,1)) -> 0
