Workbook

Sheet Başla
B2: EXCEL KLİNİĞİ
B3: KREDİ | Kredi taksit ve teklif karşılaştırma
B4: Taksit ne kadar, toplamda ne ödeyeceksin, erken ödeme yaparsan ne kazanırsın, hangi banka teklifi gerçekten daha ucuz.
B6: NASIL KULLANILIR
B7: 1. Kredi | C7: Tutarı, aylık faizi, vergi oranını, vadeyi ve ilk taksit tarihini yaz. Taksit ve ödeme planı çıkar.
B8: 2. Erken ödeme | C8: Bir taksitte fazladan ödeme yapmayı düşünüyorsan taksit numarasını ve tutarı yaz; kazancını ve kısalan vadeyi gör.
B9: 3. Teklifler | C9: Farklı bankaların tekliflerini yan yana yaz; toplam maliyete göre sıralanır.
B11: BİLMEN GEREKENLER
B12: Vergili oran | C12: Faiz oranı, yazdığın vergi ve fon oranıyla büyütülür. Varsayılan yüzde 30 bir kullanıcı girişidir; kredi türüne göre değişir.
B13: Erken ödeme | C13: Fazladan ödenen tutar anaparadan düşer, taksit aynı kalır, vade kısalır. Bankalar erken ödeme ücreti alabilir; dosya bunu hesaba katmaz.
B14: Banka tablosuyla fark | C14: Bankanın ödeme planı gün hesabı ve yuvarlama nedeniyle birkaç lira farklı olabilir. Bağlayıcı olan bankanın verdiği plandır.
B15: Finansal tavsiye değildir | C15: Dosya hesap yapar; kredi kullanıp kullanmama kararını vermez.
B16: Kapasite | C16: Teklifler: 10 satır; 120 aya kadar vade.
B18: RENKLER
B19: Sarı hücre | C19: Senin dolduracağın hücre. İçindeki örnekleri silip kendi bilgini yaz.
B20: Beyaz hücre, açık başlık | C20: Formül. Değiştirme, kendiliğinden hesaplanır.

Sheet Kredi
A1: Kredi Hesabı
A2: Sarı hücreleri doldur. Ödeme planı aşağıda kendiliğinden çıkar.
B3: Kredi tutarı (₺) | C3: 200000
B4: Aylık faiz oranı (vergiler hariç) | C4: 0.035
B5: Faiz üzerinden vergi ve fon oranı | C5: 0.3 | D5: Kullanıcı girişi. Kredi türüne göre değişir; bankandan doğrula.
B6: Vade (ay) | C6: 24
B7: İlk taksit tarihi | C7: 46331
B8: Tek seferlik masraflar (₺) | C8: 2000
B9: Erken ödeme yapılacak taksit no (istersen) | C9: 6
B10: Erken ödeme tutarı (₺) | C10: 40000
B12: Vergili aylık oran | C12: =C4*(1+C5) -> 0.0455
B13: Aylık taksit (₺) | C13: =IF(OR(C3="",C6="",C6=0),0,IF(C12=0,C3/C6,-PMT(C12,C6,C3))) -> 13866.339
B15: Aylık taksit | C15: Toplam geri ödeme | D15: Toplam faiz ve vergi | E15: Son taksit | F15: Taksit sayısı
B16: =C13 -> 13866.339 | C16: =SUM(D23:D142)+C8 -> 294918.53 | D16: =SUM(E23:E142) -> 92918.55 | E16: =IF(COUNT(B23:B142)=0,"",INDEX(C23:C142,COUNT(B23:B142))) -> 46878 | F16: =COUNT(B23:B142) -> 19
B18: Erken ödeme yapmasaydın toplam faiz ve vergi (₺) | E18: =C13*C6-C3 -> 132792.13
B19: Erken ödemenin kazandırdığı (₺) | E19: =E18-D16 -> 39873.584
B20: Kısalan vade (ay) | E20: =C6-F16 -> 5
B22: Taksit no | C22: Tarih | D22: Ödeme (₺) | E22: Faiz ve vergi (₺) | F22: Anapara (₺) | G22: Kalan borç (₺)
B23: =IF(OR(1>$C$6,$C$3<=0.005),"",1) -> 1 | C23: =IF(B23="","",EDATE($C$7,0)) -> 46331 | D23: =IF(B23="","",MIN($C$3+E23,$C$13+IF(1=$C$9,$C$10,0))) -> 13866.339 | E23: =IF(B23="","",ROUND($C$3*$C$12,2)) -> 9100 | F23: =IF(B23="","",D23-E23) -> 4766.3389 | G23: =IF(B23="",0,ROUND($C$3-F23,2)) -> 195233.66
B24: =IF(OR(2>$C$6,G23<=0.005),"",2) -> 2 | C24: =IF(B24="","",EDATE($C$7,1)) -> 46361 | D24: =IF(B24="","",MIN(G23+E24,$C$13+IF(2=$C$9,$C$10,0))) -> 13866.339 | E24: =IF(B24="","",ROUND(G23*$C$12,2)) -> 8883.13 | F24: =IF(B24="","",D24-E24) -> 4983.2089 | G24: =IF(B24="",0,ROUND(G23-F24,2)) -> 190250.45
B25: =IF(OR(3>$C$6,G24<=0.005),"",3) -> 3 | C25: =IF(B25="","",EDATE($C$7,2)) -> 46392 | D25: =IF(B25="","",MIN(G24+E25,$C$13+IF(3=$C$9,$C$10,0))) -> 13866.339 | E25: =IF(B25="","",ROUND(G24*$C$12,2)) -> 8656.4 | F25: =IF(B25="","",D25-E25) -> 5209.9389 | G25: =IF(B25="",0,ROUND(G24-F25,2)) -> 185040.51
B26: =IF(OR(4>$C$6,G25<=0.005),"",4) -> 4 | C26: =IF(B26="","",EDATE($C$7,3)) -> 46423 | D26: =IF(B26="","",MIN(G25+E26,$C$13+IF(4=$C$9,$C$10,0))) -> 13866.339 | E26: =IF(B26="","",ROUND(G25*$C$12,2)) -> 8419.34 | F26: =IF(B26="","",D26-E26) -> 5446.9989 | G26: =IF(B26="",0,ROUND(G25-F26,2)) -> 179593.51
B27: =IF(OR(5>$C$6,G26<=0.005),"",5) -> 5 | C27: =IF(B27="","",EDATE($C$7,4)) -> 46451 | D27: =IF(B27="","",MIN(G26+E27,$C$13+IF(5=$C$9,$C$10,0))) -> 13866.339 | E27: =IF(B27="","",ROUND(G26*$C$12,2)) -> 8171.5 | F27: =IF(B27="","",D27-E27) -> 5694.8389 | G27: =IF(B27="",0,ROUND(G26-F27,2)) -> 173898.67
B28: =IF(OR(6>$C$6,G27<=0.005),"",6) -> 6 | C28: =IF(B28="","",EDATE($C$7,5)) -> 46482 | D28: =IF(B28="","",MIN(G27+E28,$C$13+IF(6=$C$9,$C$10,0))) -> 53866.339 | E28: =IF(B28="","",ROUND(G27*$C$12,2)) -> 7912.39 | F28: =IF(B28="","",D28-E28) -> 45953.949 | G28: =IF(B28="",0,ROUND(G27-F28,2)) -> 127944.72
B29: =IF(OR(7>$C$6,G28<=0.005),"",7) -> 7 | C29: =IF(B29="","",EDATE($C$7,6)) -> 46512 | D29: =IF(B29="","",MIN(G28+E29,$C$13+IF(7=$C$9,$C$10,0))) -> 13866.339 | E29: =IF(B29="","",ROUND(G28*$C$12,2)) -> 5821.48 | F29: =IF(B29="","",D29-E29) -> 8044.8589 | G29: =IF(B29="",0,ROUND(G28-F29,2)) -> 119899.86
B30: =IF(OR(8>$C$6,G29<=0.005),"",8) -> 8 | C30: =IF(B30="","",EDATE($C$7,7)) -> 46543 | D30: =IF(B30="","",MIN(G29+E30,$C$13+IF(8=$C$9,$C$10,0))) -> 13866.339 | E30: =IF(B30="","",ROUND(G29*$C$12,2)) -> 5455.44 | F30: =IF(B30="","",D30-E30) -> 8410.8989 | G30: =IF(B30="",0,ROUND(G29-F30,2)) -> 111488.96
B31: =IF(OR(9>$C$6,G30<=0.005),"",9) -> 9 | C31: =IF(B31="","",EDATE($C$7,8)) -> 46573 | D31: =IF(B31="","",MIN(G30+E31,$C$13+IF(9=$C$9,$C$10,0))) -> 13866.339 | E31: =IF(B31="","",ROUND(G30*$C$12,2)) -> 5072.75 | F31: =IF(B31="","",D31-E31) -> 8793.5889 | G31: =IF(B31="",0,ROUND(G30-F31,2)) -> 102695.37
B32: =IF(OR(10>$C$6,G31<=0.005),"",10) -> 10 | C32: =IF(B32="","",EDATE($C$7,9)) -> 46604 | D32: =IF(B32="","",MIN(G31+E32,$C$13+IF(10=$C$9,$C$10,0))) -> 13866.339 | E32: =IF(B32="","",ROUND(G31*$C$12,2)) -> 4672.64 | F32: =IF(B32="","",D32-E32) -> 9193.6989 | G32: =IF(B32="",0,ROUND(G31-F32,2)) -> 93501.67
B33: =IF(OR(11>$C$6,G32<=0.005),"",11) -> 11 | C33: =IF(B33="","",EDATE($C$7,10)) -> 46635 | D33: =IF(B33="","",MIN(G32+E33,$C$13+IF(11=$C$9,$C$10,0))) -> 13866.339 | E33: =IF(B33="","",ROUND(G32*$C$12,2)) -> 4254.33 | F33: =IF(B33="","",D33-E33) -> 9612.0089 | G33: =IF(B33="",0,ROUND(G32-F33,2)) -> 83889.66
B34: =IF(OR(12>$C$6,G33<=0.005),"",12) -> 12 | C34: =IF(B34="","",EDATE($C$7,11)) -> 46665 | D34: =IF(B34="","",MIN(G33+E34,$C$13+IF(12=$C$9,$C$10,0))) -> 13866.339 | E34: =IF(B34="","",ROUND(G33*$C$12,2)) -> 3816.98 | F34: =IF(B34="","",D34-E34) -> 10049.359 | G34: =IF(B34="",0,ROUND(G33-F34,2)) -> 73840.3
B35: =IF(OR(13>$C$6,G34<=0.005),"",13) -> 13 | C35: =IF(B35="","",EDATE($C$7,12)) -> 46696 | D35: =IF(B35="","",MIN(G34+E35,$C$13+IF(13=$C$9,$C$10,0))) -> 13866.339 | E35: =IF(B35="","",ROUND(G34*$C$12,2)) -> 3359.73 | F35: =IF(B35="","",D35-E35) -> 10506.609 | G35: =IF(B35="",0,ROUND(G34-F35,2)) -> 63333.69
B36: =IF(OR(14>$C$6,G35<=0.005),"",14) -> 14 | C36: =IF(B36="","",EDATE($C$7,13)) -> 46726 | D36: =IF(B36="","",MIN(G35+E36,$C$13+IF(14=$C$9,$C$10,0))) -> 13866.339 | E36: =IF(B36="","",ROUND(G35*$C$12,2)) -> 2881.68 | F36: =IF(B36="","",D36-E36) -> 10984.659 | G36: =IF(B36="",0,ROUND(G35-F36,2)) -> 52349.03
B37: =IF(OR(15>$C$6,G36<=0.005),"",15) -> 15 | C37: =IF(B37="","",EDATE($C$7,14)) -> 46757 | D37: =IF(B37="","",MIN(G36+E37,$C$13+IF(15=$C$9,$C$10,0))) -> 13866.339 | E37: =IF(B37="","",ROUND(G36*$C$12,2)) -> 2381.88 | F37: =IF(B37="","",D37-E37) -> 11484.459 | G37: =IF(B37="",0,ROUND(G36-F37,2)) -> 40864.57
B38: =IF(OR(16>$C$6,G37<=0.005),"",16) -> 16 | C38: =IF(B38="","",EDATE($C$7,15)) -> 46788 | D38: =IF(B38="","",MIN(G37+E38,$C$13+IF(16=$C$9,$C$10,0))) -> 13866.339 | E38: =IF(B38="","",ROUND(G37*$C$12,2)) -> 1859.34 | F38: =IF(B38="","",D38-E38) -> 12006.999 | G38: =IF(B38="",0,ROUND(G37-F38,2)) -> 28857.57
B39: =IF(OR(17>$C$6,G38<=0.005),"",17) -> 17 | C39: =IF(B39="","",EDATE($C$7,16)) -> 46817 | D39: =IF(B39="","",MIN(G38+E39,$C$13+IF(17=$C$9,$C$10,0))) -> 13866.339 | E39: =IF(B39="","",ROUND(G38*$C$12,2)) -> 1313.02 | F39: =IF(B39="","",D39-E39) -> 12553.319 | G39: =IF(B39="",0,ROUND(G38-F39,2)) -> 16304.25
B40: =IF(OR(18>$C$6,G39<=0.005),"",18) -> 18 | C40: =IF(B40="","",EDATE($C$7,17)) -> 46848 | D40: =IF(B40="","",MIN(G39+E40,$C$13+IF(18=$C$9,$C$10,0))) -> 13866.339 | E40: =IF(B40="","",ROUND(G39*$C$12,2)) -> 741.84 | F40: =IF(B40="","",D40-E40) -> 13124.499 | G40: =IF(B40="",0,ROUND(G39-F40,2)) -> 3179.75
B41: =IF(OR(19>$C$6,G40<=0.005),"",19) -> 19 | C41: =IF(B41="","",EDATE($C$7,18)) -> 46878 | D41: =IF(B41="","",MIN(G40+E41,$C$13+IF(19=$C$9,$C$10,0))) -> 3324.43 | E41: =IF(B41="","",ROUND(G40*$C$12,2)) -> 144.68 | F41: =IF(B41="","",D41-E41) -> 3179.75 | G41: =IF(B41="",0,ROUND(G40-F41,2)) -> 0
B42: =IF(OR(20>$C$6,G41<=0.005),"",20) | C42: =IF(B42="","",EDATE($C$7,19)) | D42: =IF(B42="","",MIN(G41+E42,$C$13+IF(20=$C$9,$C$10,0))) | E42: =IF(B42="","",ROUND(G41*$C$12,2)) | F42: =IF(B42="","",D42-E42) | G42: =IF(B42="",0,ROUND(G41-F42,2)) -> 0
B43: =IF(OR(21>$C$6,G42<=0.005),"",21) | C43: =IF(B43="","",EDATE($C$7,20)) | D43: =IF(B43="","",MIN(G42+E43,$C$13+IF(21=$C$9,$C$10,0))) | E43: =IF(B43="","",ROUND(G42*$C$12,2)) | F43: =IF(B43="","",D43-E43) | G43: =IF(B43="",0,ROUND(G42-F43,2)) -> 0
B44: =IF(OR(22>$C$6,G43<=0.005),"",22) | C44: =IF(B44="","",EDATE($C$7,21)) | D44: =IF(B44="","",MIN(G43+E44,$C$13+IF(22=$C$9,$C$10,0))) | E44: =IF(B44="","",ROUND(G43*$C$12,2)) | F44: =IF(B44="","",D44-E44) | G44: =IF(B44="",0,ROUND(G43-F44,2)) -> 0
...

Sheet Teklifler
A1: Teklif Karşılaştırma
A2: Farklı bankaların tekliflerini yaz; en ucuzu toplam maliyete göre sıralanır.
A4: Banka | B4: Tutar (₺) | C4: Aylık faiz oranı | D4: Vade (ay) | E4: Masraf (₺) | F4: Aylık taksit (₺) | G4: Toplam geri ödeme (₺) | H4: Toplam maliyet (₺) | I4: Sıra
A5: Banka Alfa | B5: 200000 | C5: 0.035 | D5: 24 | E5: 2000 | F5: =IF(OR(A5="",B5="",D5="",D5=0),"",IF(C5*(1+Kredi!$C$5)=0,B5/D5,-PMT(C5*(1+Kredi!$C$5),D5,B5))) -> 13866.339 | G5: =IF(F5="","",F5*D5+E5) -> 334792.13 | H5: =IF(G5="","",G5-B5) -> 134792.13 | I5: =IF(H5="","",RANK(H5,$H$5:$H$14,1)) -> 3
A6: Banka Beta | B6: 200000 | C6: 0.033 | D6: 24 | E6: 6000 | F6: =IF(OR(A6="",B6="",D6="",D6=0),"",IF(C6*(1+Kredi!$C$5)=0,B6/D6,-PMT(C6*(1+Kredi!$C$5),D6,B6))) -> 13509.721 | G6: =IF(F6="","",F6*D6+E6) -> 330233.31 | H6: =IF(G6="","",G6-B6) -> 130233.31 | I6: =IF(H6="","",RANK(H6,$H$5:$H$14,1)) -> 2
A7: Banka Gama | B7: 200000 | C7: 0.036 | D7: 18 | E7: 0 | F7: =IF(OR(A7="",B7="",D7="",D7=0),"",IF(C7*(1+Kredi!$C$5)=0,B7/D7,-PMT(C7*(1+Kredi!$C$5),D7,B7))) -> 16684.15 | G7: =IF(F7="","",F7*D7+E7) -> 300314.7 | H7: =IF(G7="","",G7-B7) -> 100314.7 | I7: =IF(H7="","",RANK(H7,$H$5:$H$14,1)) -> 1
F8: =IF(OR(A8="",B8="",D8="",D8=0),"",IF(C8*(1+Kredi!$C$5)=0,B8/D8,-PMT(C8*(1+Kredi!$C$5),D8,B8))) | G8: =IF(F8="","",F8*D8+E8) | H8: =IF(G8="","",G8-B8) | I8: =IF(H8="","",RANK(H8,$H$5:$H$14,1))
F9: =IF(OR(A9="",B9="",D9="",D9=0),"",IF(C9*(1+Kredi!$C$5)=0,B9/D9,-PMT(C9*(1+Kredi!$C$5),D9,B9))) | G9: =IF(F9="","",F9*D9+E9) | H9: =IF(G9="","",G9-B9) | I9: =IF(H9="","",RANK(H9,$H$5:$H$14,1))
F10: =IF(OR(A10="",B10="",D10="",D10=0),"",IF(C10*(1+Kredi!$C$5)=0,B10/D10,-PMT(C10*(1+Kredi!$C$5),D10,B10))) | G10: =IF(F10="","",F10*D10+E10) | H10: =IF(G10="","",G10-B10) | I10: =IF(H10="","",RANK(H10,$H$5:$H$14,1))
F11: =IF(OR(A11="",B11="",D11="",D11=0),"",IF(C11*(1+Kredi!$C$5)=0,B11/D11,-PMT(C11*(1+Kredi!$C$5),D11,B11))) | G11: =IF(F11="","",F11*D11+E11) | H11: =IF(G11="","",G11-B11) | I11: =IF(H11="","",RANK(H11,$H$5:$H$14,1))
F12: =IF(OR(A12="",B12="",D12="",D12=0),"",IF(C12*(1+Kredi!$C$5)=0,B12/D12,-PMT(C12*(1+Kredi!$C$5),D12,B12))) | G12: =IF(F12="","",F12*D12+E12) | H12: =IF(G12="","",G12-B12) | I12: =IF(H12="","",RANK(H12,$H$5:$H$14,1))
F13: =IF(OR(A13="",B13="",D13="",D13=0),"",IF(C13*(1+Kredi!$C$5)=0,B13/D13,-PMT(C13*(1+Kredi!$C$5),D13,B13))) | G13: =IF(F13="","",F13*D13+E13) | H13: =IF(G13="","",G13-B13) | I13: =IF(H13="","",RANK(H13,$H$5:$H$14,1))
F14: =IF(OR(A14="",B14="",D14="",D14=0),"",IF(C14*(1+Kredi!$C$5)=0,B14/D14,-PMT(C14*(1+Kredi!$C$5),D14,B14))) | G14: =IF(F14="","",F14*D14+E14) | H14: =IF(G14="","",G14-B14) | I14: =IF(H14="","",RANK(H14,$H$5:$H$14,1))

Sheet AI Komutları
B1: Yapay Zeka Komutları
B2: İlgili sayfada başlık satırıyla birlikte kayıtlarını seç, kopyala, kullandığın yapay zeka asistanına yapıştır ve altına komutu ekle.
B3: Dikkat: Banka adı dışında kişisel bilgi yazma; kimlik ve hesap numarası paylaşma. Yapay zekanın verdiği rakamları dosyadaki özet sayfasıyla karşılaştır.
B5: Ne için | C5: Komut (kopyala, yapıştır)
B6: Teklif yorumu | C6: [Teklifler sayfası] Tekliflerin farkını taksit, toplam maliyet ve vade açısından yorumla.
B7: Bütçe uyumu | C7: Aylık gelirim [tutar], sabit giderim [tutar]. Bu taksit bütçeme ne kadar yük getirir?
B8: Sorular | C8: Bankaya kredi öncesinde sormam gereken soruları listele: masraflar, sigorta, erken ödeme.
B9: Erken ödeme zamanı | C9: Elimde [tutar] var. Erken ödemeyi şimdi mi yapmalıyım, yoksa acil durum için mi tutmalıyım? Artı ve eksileri yaz.
