Workbook

Sheet Başla
B2: EXCEL KLİNİĞİ
B3: ACİL | Borç kapatma planı
B4: Borçlarını yaz, her ay ayırabileceğin tutarı gir; hangi borcu önce kapatacağını, ne zaman borçsuz kalacağını ve ne kadar faiz ödeyeceğini gör.
B6: NASIL KULLANILIR
B7: 1. Borçlar | C7: Her borcun kalan tutarını, aylık faiz oranını ve asgari aylık ödemesini yaz. Faizsiz borçta oranı 0 gir.
B8: 2. Ödeme gücü | C8: Asgari ödemelerin üstüne her ay ne kadar ayırabileceğini ve yöntemi (Çığ ya da Kartopu) seç.
B9: 3. Özet | C9: Ne zaman borçsuz kalacağını, toplam faizi ve yalnız asgari ödeseydin ne olacağını gör.
B10: 4. Borçlar sayfasına dön | C10: Her borcun öncelik sırası, kapanış ayı ve ödenecek faizi yazılır.
B12: NASIL HESAPLANIR
B13: Aylık akış | C13: Her ay önce bütün borçların faizi işler ve asgari ödemeleri yapılır. Kalan tutar öncelik sırasındaki ilk borca gider; o kapanınca sıradakine geçer. Kapanan borcun asgari ödemesi de sıradaki borca eklenir.
B14: Faiz oranı | C14: Aylık oranı vergiler dahil gir. Yıllık oran biliyorsan kabaca 12'ye böl; bankanın kendi hesabı küçük farklarla çıkabilir.
B16: BİLMEN GEREKENLER
B17: Banka hesabıyla birebir tutmaz | C17: Gecikme faizi, dönem içi harcama, vergi ve masraf ayrıntıları hesaba katılmaz. Plan bir yol haritasıdır, ödeme tablosu değildir.
B18: Yeni borç yok varsayımı | C18: Plan, kartla yeni harcama yapmadığını ve her ay aynı tutarı ödediğini varsayar.
B19: Finansal tavsiye değildir | C19: Yapılandırma, borç birleştirme gibi kararlar için bankanla ya da bir uzmanla görüş.
B20: Kapasite | C20: 10 borç, 120 ay.
B22: RENKLER
B23: Sarı hücre | C23: Senin dolduracağın hücre. İçindeki örnekleri silip kendi bilgini yaz.
B24: Beyaz hücre, açık başlık | C24: Formül. Değiştirme, kendiliğinden hesaplanır.

Sheet Borçlar
A1: Borçlar
A2: Her borcun kalan tutarını, aylık faiz oranını ve asgari aylık ödemesini yaz.
A4: Borç | B4: Kalan borç (₺) | C4: Aylık faiz oranı | D4: Asgari aylık ödeme (₺) | E4: Öncelik | F4: Kapanış ayı | G4: Ödenecek faiz (₺) | H4: Kontrol | L4: y
A5: Kredi kartı | B5: 60000 | C5: 0.045 | D5: 3000 | E5: =IF(L5>8000000000000000,"",SUMPRODUCT(--($L$5:$L$14<L5))+1) -> 2 | F5: =IF(E5="","",INDEX(Plan!$D$4:$M$4,E5)) -> 46631 | G5: =IF(E5="","",INDEX(Plan!$D$5:$M$5,E5)) -> 23289.407 | H5: =IF(E5="","",IF(D5<=B5*C5,"Asgari ödeme faizi karşılamıyor",IF(F5="Bitmiyor","120 ayda kapanmıyor","OK"))) -> OK | J5: Asgarilerin üstüne ayırabileceğin aylık tutar (₺) | K5: 5000 | L5: =IF(OR(A5="",B5="",B5=0),9000000000000000,IF($K$6="Kartopu",B5,-C5*1000000)+ROW()/1000) -> -44999.995
A6: İhtiyaç kredisi | B6: 120000 | C6: 0.035 | D6: 7500 | E6: =IF(L6>8000000000000000,"",SUMPRODUCT(--($L$5:$L$14<L6))+1) -> 3 | F6: =IF(E6="","",INDEX(Plan!$D$4:$M$4,E6)) -> 46784 | G6: =IF(E6="","",INDEX(Plan!$D$5:$M$5,E6)) -> 48713.332 | H6: =IF(E6="","",IF(D6<=B6*C6,"Asgari ödeme faizi karşılamıyor",IF(F6="Bitmiyor","120 ayda kapanmıyor","OK"))) -> OK | J6: Yöntem | K6: Çığ | L6: =IF(OR(A6="",B6="",B6=0),9000000000000000,IF($K$6="Kartopu",B6,-C6*1000000)+ROW()/1000) -> -34999.994
A7: Kredili hesap | B7: 25000 | C7: 0.05 | D7: 1500 | E7: =IF(L7>8000000000000000,"",SUMPRODUCT(--($L$5:$L$14<L7))+1) -> 1 | F7: =IF(E7="","",INDEX(Plan!$D$4:$M$4,E7)) -> 46419 | G7: =IF(E7="","",INDEX(Plan!$D$5:$M$5,E7)) -> 3490.4365 | H7: =IF(E7="","",IF(D7<=B7*C7,"Asgari ödeme faizi karşılamıyor",IF(F7="Bitmiyor","120 ayda kapanmıyor","OK"))) -> OK | J7: Planın başladığı ay | K7: 46296 | L7: =IF(OR(A7="",B7="",B7=0),9000000000000000,IF($K$6="Kartopu",B7,-C7*1000000)+ROW()/1000) -> -49999.993
A8: Aileden borç | B8: 40000 | C8: 0 | D8: 2000 | E8: =IF(L8>8000000000000000,"",SUMPRODUCT(--($L$5:$L$14<L8))+1) -> 4 | F8: =IF(E8="","",INDEX(Plan!$D$4:$M$4,E8)) -> 46784 | G8: =IF(E8="","",INDEX(Plan!$D$5:$M$5,E8)) -> 0 | H8: =IF(E8="","",IF(D8<=B8*C8,"Asgari ödeme faizi karşılamıyor",IF(F8="Bitmiyor","120 ayda kapanmıyor","OK"))) -> OK | J8: Toplam aylık ödeme gücün (₺) | K8: =SUM(D5:D14)+K5 -> 19000 | L8: =IF(OR(A8="",B8="",B8=0),9000000000000000,IF($K$6="Kartopu",B8,-C8*1000000)+ROW()/1000) -> 0.008
E9: =IF(L9>8000000000000000,"",SUMPRODUCT(--($L$5:$L$14<L9))+1) | F9: =IF(E9="","",INDEX(Plan!$D$4:$M$4,E9)) | G9: =IF(E9="","",INDEX(Plan!$D$5:$M$5,E9)) | H9: =IF(E9="","",IF(D9<=B9*C9,"Asgari ödeme faizi karşılamıyor",IF(F9="Bitmiyor","120 ayda kapanmıyor","OK"))) | L9: =IF(OR(A9="",B9="",B9=0),9000000000000000,IF($K$6="Kartopu",B9,-C9*1000000)+ROW()/1000) -> 9e+15
E10: =IF(L10>8000000000000000,"",SUMPRODUCT(--($L$5:$L$14<L10))+1) | F10: =IF(E10="","",INDEX(Plan!$D$4:$M$4,E10)) | G10: =IF(E10="","",INDEX(Plan!$D$5:$M$5,E10)) | H10: =IF(E10="","",IF(D10<=B10*C10,"Asgari ödeme faizi karşılamıyor",IF(F10="Bitmiyor","120 ayda kapanmıyor","OK"))) | J10: Çığ: faizi en yüksek borca yüklenir, toplamda en az faizi ödetir. | L10: =IF(OR(A10="",B10="",B10=0),9000000000000000,IF($K$6="Kartopu",B10,-C10*1000000)+ROW()/1000) -> 9e+15
E11: =IF(L11>8000000000000000,"",SUMPRODUCT(--($L$5:$L$14<L11))+1) | F11: =IF(E11="","",INDEX(Plan!$D$4:$M$4,E11)) | G11: =IF(E11="","",INDEX(Plan!$D$5:$M$5,E11)) | H11: =IF(E11="","",IF(D11<=B11*C11,"Asgari ödeme faizi karşılamıyor",IF(F11="Bitmiyor","120 ayda kapanmıyor","OK"))) | J11: Kartopu: en küçük borca yüklenir, ilk borç daha çabuk kapanır. | L11: =IF(OR(A11="",B11="",B11=0),9000000000000000,IF($K$6="Kartopu",B11,-C11*1000000)+ROW()/1000) -> 9e+15
E12: =IF(L12>8000000000000000,"",SUMPRODUCT(--($L$5:$L$14<L12))+1) | F12: =IF(E12="","",INDEX(Plan!$D$4:$M$4,E12)) | G12: =IF(E12="","",INDEX(Plan!$D$5:$M$5,E12)) | H12: =IF(E12="","",IF(D12<=B12*C12,"Asgari ödeme faizi karşılamıyor",IF(F12="Bitmiyor","120 ayda kapanmıyor","OK"))) | L12: =IF(OR(A12="",B12="",B12=0),9000000000000000,IF($K$6="Kartopu",B12,-C12*1000000)+ROW()/1000) -> 9e+15
E13: =IF(L13>8000000000000000,"",SUMPRODUCT(--($L$5:$L$14<L13))+1) | F13: =IF(E13="","",INDEX(Plan!$D$4:$M$4,E13)) | G13: =IF(E13="","",INDEX(Plan!$D$5:$M$5,E13)) | H13: =IF(E13="","",IF(D13<=B13*C13,"Asgari ödeme faizi karşılamıyor",IF(F13="Bitmiyor","120 ayda kapanmıyor","OK"))) | L13: =IF(OR(A13="",B13="",B13=0),9000000000000000,IF($K$6="Kartopu",B13,-C13*1000000)+ROW()/1000) -> 9e+15
E14: =IF(L14>8000000000000000,"",SUMPRODUCT(--($L$5:$L$14<L14))+1) | F14: =IF(E14="","",INDEX(Plan!$D$4:$M$4,E14)) | G14: =IF(E14="","",INDEX(Plan!$D$5:$M$5,E14)) | H14: =IF(E14="","",IF(D14<=B14*C14,"Asgari ödeme faizi karşılamıyor",IF(F14="Bitmiyor","120 ayda kapanmıyor","OK"))) | L14: =IF(OR(A14="",B14="",B14=0),9000000000000000,IF($K$6="Kartopu",B14,-C14*1000000)+ROW()/1000) -> 9e+15

Sheet Özet
A1: Özet
A2: Bu sayfaya yazma. Rakamları Borçlar sayfasından değiştir.
B4: Toplam borç | C4: Aylık ödeme gücü | D4: Borçsuz kalacağın ay | E4: Ödeyeceğin toplam faiz
B5: =SUM(Borçlar!$B$5:$B$14) -> 245000 | C5: =Borçlar!K8 -> 19000 | D5: =IF(SUM(Borçlar!$B$5:$B$14)=0,"",IFERROR(INDEX(Plan!$B$11:$B$130,MATCH(0,Plan!$F$11:$F$130,0)),"120 ayda bitmiyor")) -> 46784 | E5: =SUM(Plan!$E$11:$E$130) -> 75493.176
B8: Ek ödeme yapmasaydın
C9: Ek ödemeyle | D9: Yalnız asgari ödemeyle | E9: Fark
B10: Kapanış süresi (ay) | C10: =IFERROR(MATCH(0,Plan!$F$11:$F$130,0),"") -> 17 | D10: =IFERROR(MATCH(0,'Yalnız Asgari'!$F$11:$F$130,0),"") -> 29 | E10: =IF(OR(C10="",D10=""),"",D10-C10) -> 12
B11: Borçsuz kalınan ay | C11: =IF(SUM(Borçlar!$B$5:$B$14)=0,"",IFERROR(INDEX(Plan!$B$11:$B$130,MATCH(0,Plan!$F$11:$F$130,0)),"120 ayda bitmiyor")) -> 46784 | D11: =IF(SUM(Borçlar!$B$5:$B$14)=0,"",IFERROR(INDEX('Yalnız Asgari'!$B$11:$B$130,MATCH(0,'Yalnız Asgari'!$F$11:$F$130,0)),"120 ayda bitmiyor")) -> 47150 | E11: =""
B12: Toplam faiz (₺) | C12: =SUM(Plan!$E$11:$E$130) -> 75493.176 | D12: =SUM('Yalnız Asgari'!$E$11:$E$130) -> 148922.85 | E12: =D12-C12 -> 73429.67
B14: Asgari ödemeyle bile kapanan borçlardan boşalan tutar sıradaki borca aktarılır; iki sütunda da bu varsayılır.
B15: Yalnız asgari ödeme 120 ayda borcu bitirmiyorsa o sütundaki faiz, 120 ayın faizidir; gerçekte daha fazladır.

Sheet Plan
A1: Plan (ek ödemeyle)
B2: Borç | D2: =IFERROR(INDEX(Borçlar!$A$5:$A$14,MATCH(1,Borçlar!$E$5:$E$14,0))&"","") -> Kredili hesap | E2: =IFERROR(INDEX(Borçlar!$A$5:$A$14,MATCH(2,Borçlar!$E$5:$E$14,0))&"","") -> Kredi kartı | F2: =IFERROR(INDEX(Borçlar!$A$5:$A$14,MATCH(3,Borçlar!$E$5:$E$14,0))&"","") -> İhtiyaç kredisi | G2: =IFERROR(INDEX(Borçlar!$A$5:$A$14,MATCH(4,Borçlar!$E$5:$E$14,0))&"","") -> Aileden borç | H2: =IFERROR(INDEX(Borçlar!$A$5:$A$14,MATCH(5,Borçlar!$E$5:$E$14,0))&"","") | I2: =IFERROR(INDEX(Borçlar!$A$5:$A$14,MATCH(6,Borçlar!$E$5:$E$14,0))&"","") | J2: =IFERROR(INDEX(Borçlar!$A$5:$A$14,MATCH(7,Borçlar!$E$5:$E$14,0))&"","") | K2: =IFERROR(INDEX(Borçlar!$A$5:$A$14,MATCH(8,Borçlar!$E$5:$E$14,0))&"","") | L2: =IFERROR(INDEX(Borçlar!$A$5:$A$14,MATCH(9,Borçlar!$E$5:$E$14,0))&"","") | M2: =IFERROR(INDEX(Borçlar!$A$5:$A$14,MATCH(10,Borçlar!$E$5:$E$14,0))&"","")
C3: Öncelik | D3: 1 | E3: 2 | F3: 3 | G3: 4 | H3: 5 | I3: 6 | J3: 7 | K3: 8 | L3: 9 | M3: 10
B4: Kapanış ayı | D4: =IF(D6=0,"",IFERROR(INDEX($B$11:$B$130,MATCH(0,Q11:Q130,0)),"Bitmiyor")) -> 46419 | E4: =IF(E6=0,"",IFERROR(INDEX($B$11:$B$130,MATCH(0,U11:U130,0)),"Bitmiyor")) -> 46631 | F4: =IF(F6=0,"",IFERROR(INDEX($B$11:$B$130,MATCH(0,Y11:Y130,0)),"Bitmiyor")) -> 46784 | G4: =IF(G6=0,"",IFERROR(INDEX($B$11:$B$130,MATCH(0,AC11:AC130,0)),"Bitmiyor")) -> 46784 | H4: =IF(H6=0,"",IFERROR(INDEX($B$11:$B$130,MATCH(0,AG11:AG130,0)),"Bitmiyor")) | I4: =IF(I6=0,"",IFERROR(INDEX($B$11:$B$130,MATCH(0,AK11:AK130,0)),"Bitmiyor")) | J4: =IF(J6=0,"",IFERROR(INDEX($B$11:$B$130,MATCH(0,AO11:AO130,0)),"Bitmiyor")) | K4: =IF(K6=0,"",IFERROR(INDEX($B$11:$B$130,MATCH(0,AS11:AS130,0)),"Bitmiyor")) | L4: =IF(L6=0,"",IFERROR(INDEX($B$11:$B$130,MATCH(0,AW11:AW130,0)),"Bitmiyor")) | M4: =IF(M6=0,"",IFERROR(INDEX($B$11:$B$130,MATCH(0,BA11:BA130,0)),"Bitmiyor"))
B5: Toplam faiz (₺) | D5: =IF(D6=0,0,SUM(N11:N130)-D6-(SUM(Q11:Q130)-Q130)) -> 3490.4365 | E5: =IF(E6=0,0,SUM(R11:R130)-E6-(SUM(U11:U130)-U130)) -> 23289.407 | F5: =IF(F6=0,0,SUM(V11:V130)-F6-(SUM(Y11:Y130)-Y130)) -> 48713.332 | G5: =IF(G6=0,0,SUM(Z11:Z130)-G6-(SUM(AC11:AC130)-AC130)) -> 0 | H5: =IF(H6=0,0,SUM(AD11:AD130)-H6-(SUM(AG11:AG130)-AG130)) -> 0 | I5: =IF(I6=0,0,SUM(AH11:AH130)-I6-(SUM(AK11:AK130)-AK130)) -> 0 | J5: =IF(J6=0,0,SUM(AL11:AL130)-J6-(SUM(AO11:AO130)-AO130)) -> 0 | K5: =IF(K6=0,0,SUM(AP11:AP130)-K6-(SUM(AS11:AS130)-AS130)) -> 0 | L5: =IF(L6=0,0,SUM(AT11:AT130)-L6-(SUM(AW11:AW130)-AW130)) -> 0 | M5: =IF(M6=0,0,SUM(AX11:AX130)-M6-(SUM(BA11:BA130)-BA130)) -> 0
B6: Açılış bakiyesi | D6: =IFERROR(INDEX(Borçlar!$B$5:$B$14,MATCH(1,Borçlar!$E$5:$E$14,0)),0) -> 25000 | E6: =IFERROR(INDEX(Borçlar!$B$5:$B$14,MATCH(2,Borçlar!$E$5:$E$14,0)),0) -> 60000 | F6: =IFERROR(INDEX(Borçlar!$B$5:$B$14,MATCH(3,Borçlar!$E$5:$E$14,0)),0) -> 120000 | G6: =IFERROR(INDEX(Borçlar!$B$5:$B$14,MATCH(4,Borçlar!$E$5:$E$14,0)),0) -> 40000 | H6: =IFERROR(INDEX(Borçlar!$B$5:$B$14,MATCH(5,Borçlar!$E$5:$E$14,0)),0) -> 0 | I6: =IFERROR(INDEX(Borçlar!$B$5:$B$14,MATCH(6,Borçlar!$E$5:$E$14,0)),0) -> 0 | J6: =IFERROR(INDEX(Borçlar!$B$5:$B$14,MATCH(7,Borçlar!$E$5:$E$14,0)),0) -> 0 | K6: =IFERROR(INDEX(Borçlar!$B$5:$B$14,MATCH(8,Borçlar!$E$5:$E$14,0)),0) -> 0 | L6: =IFERROR(INDEX(Borçlar!$B$5:$B$14,MATCH(9,Borçlar!$E$5:$E$14,0)),0) -> 0 | M6: =IFERROR(INDEX(Borçlar!$B$5:$B$14,MATCH(10,Borçlar!$E$5:$E$14,0)),0) -> 0
B7: Aylık faiz | D7: =IFERROR(INDEX(Borçlar!$C$5:$C$14,MATCH(1,Borçlar!$E$5:$E$14,0)),0) -> 0.05 | E7: =IFERROR(INDEX(Borçlar!$C$5:$C$14,MATCH(2,Borçlar!$E$5:$E$14,0)),0) -> 0.045 | F7: =IFERROR(INDEX(Borçlar!$C$5:$C$14,MATCH(3,Borçlar!$E$5:$E$14,0)),0) -> 0.035 | G7: =IFERROR(INDEX(Borçlar!$C$5:$C$14,MATCH(4,Borçlar!$E$5:$E$14,0)),0) -> 0 | H7: =IFERROR(INDEX(Borçlar!$C$5:$C$14,MATCH(5,Borçlar!$E$5:$E$14,0)),0) -> 0 | I7: =IFERROR(INDEX(Borçlar!$C$5:$C$14,MATCH(6,Borçlar!$E$5:$E$14,0)),0) -> 0 | J7: =IFERROR(INDEX(Borçlar!$C$5:$C$14,MATCH(7,Borçlar!$E$5:$E$14,0)),0) -> 0 | K7: =IFERROR(INDEX(Borçlar!$C$5:$C$14,MATCH(8,Borçlar!$E$5:$E$14,0)),0) -> 0 | L7: =IFERROR(INDEX(Borçlar!$C$5:$C$14,MATCH(9,Borçlar!$E$5:$E$14,0)),0) -> 0 | M7: =IFERROR(INDEX(Borçlar!$C$5:$C$14,MATCH(10,Borçlar!$E$5:$E$14,0)),0) -> 0
B8: Asgari ödeme | D8: =IFERROR(INDEX(Borçlar!$D$5:$D$14,MATCH(1,Borçlar!$E$5:$E$14,0)),0) -> 1500 | E8: =IFERROR(INDEX(Borçlar!$D$5:$D$14,MATCH(2,Borçlar!$E$5:$E$14,0)),0) -> 3000 | F8: =IFERROR(INDEX(Borçlar!$D$5:$D$14,MATCH(3,Borçlar!$E$5:$E$14,0)),0) -> 7500 | G8: =IFERROR(INDEX(Borçlar!$D$5:$D$14,MATCH(4,Borçlar!$E$5:$E$14,0)),0) -> 2000 | H8: =IFERROR(INDEX(Borçlar!$D$5:$D$14,MATCH(5,Borçlar!$E$5:$E$14,0)),0) -> 0 | I8: =IFERROR(INDEX(Borçlar!$D$5:$D$14,MATCH(6,Borçlar!$E$5:$E$14,0)),0) -> 0 | J8: =IFERROR(INDEX(Borçlar!$D$5:$D$14,MATCH(7,Borçlar!$E$5:$E$14,0)),0) -> 0 | K8: =IFERROR(INDEX(Borçlar!$D$5:$D$14,MATCH(8,Borçlar!$E$5:$E$14,0)),0) -> 0 | L8: =IFERROR(INDEX(Borçlar!$D$5:$D$14,MATCH(9,Borçlar!$E$5:$E$14,0)),0) -> 0 | M8: =IFERROR(INDEX(Borçlar!$D$5:$D$14,MATCH(10,Borçlar!$E$5:$E$14,0)),0) -> 0
A10: Ay | B10: Tarih | C10: Dağıtılacak ek (₺) | D10: Toplam ödeme (₺) | E10: O ayın faizi (₺) | F10: Kalan borç (₺) | N10: ="Borç 1: toplam" -> Borç 1: toplam | O10: asgari | P10: ek | Q10: bakiye | R10: ="Borç 2: toplam" -> Borç 2: toplam | S10: asgari | T10: ek | U10: bakiye | V10: ="Borç 3: toplam" -> Borç 3: toplam | W10: asgari | X10: ek | Y10: bakiye | Z10: ="Borç 4: toplam" -> Borç 4: toplam | AA10: asgari | AB10: ek | AC10: bakiye | AD10: ="Borç 5: toplam" -> Borç 5: toplam | AE10: asgari | AF10: ek | AG10: bakiye | AH10: ="Borç 6: toplam" -> Borç 6: toplam | AI10: asgari | AJ10: ek | AK10: bakiye | AL10: ="Borç 7: toplam" -> Borç 7: toplam | AM10: asgari | AN10: ek | AO10: bakiye | AP10: ="Borç 8: toplam" -> Borç 8: toplam | AQ10: asgari | AR10: ek | AS10: bakiye | AT10: ="Borç 9: toplam" -> Borç 9: toplam | AU10: asgari | AV10: ek | AW10: bakiye | AX10: ="Borç 10: toplam" -> Borç 10: toplam | AY10: asgari | AZ10: ek | BA10: bakiye
A11: 1 | B11: =EDATE(Borçlar!$K$7,0) -> 46296 | C11: =MAX(0,Borçlar!$K$8-(O11+S11+W11+AA11+AE11+AI11+AM11+AQ11+AU11+AY11)) -> 5000 | D11: =O11+P11+S11+T11+W11+X11+AA11+AB11+AE11+AF11+AI11+AJ11+AM11+AN11+AQ11+AR11+AU11+AV11+AY11+AZ11 -> 19000 | E11: =(N11+R11+V11+Z11+AD11+AH11+AL11+AP11+AT11+AX11)-(D$6+E$6+F$6+G$6+H$6+I$6+J$6+K$6+L$6+M$6) -> 8150 | F11: =Q11+U11+Y11+AC11+AG11+AK11+AO11+AS11+AW11+BA11 -> 234150 | N11: =D$6*(1+D$7) -> 26250 | O11: =MIN(N11,D$8) -> 1500 | P11: =MAX(0,MIN(N11-O11,$C11-(0))) -> 5000 | Q11: =ROUND(N11-O11-P11,2) -> 19750 | R11: =E$6*(1+E$7) -> 62700 | S11: =MIN(R11,E$8) -> 3000 | T11: =MAX(0,MIN(R11-S11,$C11-(P11))) -> 0 | U11: =ROUND(R11-S11-T11,2) -> 59700 | V11: =F$6*(1+F$7) -> 124200 | W11: =MIN(V11,F$8) -> 7500 | X11: =MAX(0,MIN(V11-W11,$C11-(P11+T11))) -> 0 | Y11: =ROUND(V11-W11-X11,2) -> 116700 | Z11: =G$6*(1+G$7) -> 40000 | AA11: =MIN(Z11,G$8) -> 2000 | AB11: =MAX(0,MIN(Z11-AA11,$C11-(P11+T11+X11))) -> 0 | AC11: =ROUND(Z11-AA11-AB11,2) -> 38000 | AD11: =H$6*(1+H$7) -> 0 | AE11: =MIN(AD11,H$8) -> 0 | AF11: =MAX(0,MIN(AD11-AE11,$C11-(P11+T11+X11+AB11))) -> 0 | AG11: =ROUND(AD11-AE11-AF11,2) -> 0 | AH11: =I$6*(1+I$7) -> 0 | AI11: =MIN(AH11,I$8) -> 0 | AJ11: =MAX(0,MIN(AH11-AI11,$C11-(P11+T11+X11+AB11+AF11))) -> 0 | AK11: =ROUND(AH11-AI11-AJ11,2) -> 0 | AL11: =J$6*(1+J$7) -> 0 | AM11: =MIN(AL11,J$8) -> 0 | AN11: =MAX(0,MIN(AL11-AM11,$C11-(P11+T11+X11+AB11+AF11+AJ11))) -> 0 | AO11: =ROUND(AL11-AM11-AN11,2) -> 0 | AP11: =K$6*(1+K$7) -> 0 | AQ11: =MIN(AP11,K$8) -> 0 | AR11: =MAX(0,MIN(AP11-AQ11,$C11-(P11+T11+X11+AB11+AF11+AJ11+AN11))) -> 0 | AS11: =ROUND(AP11-AQ11-AR11,2) -> 0 | AT11: =L$6*(1+L$7) -> 0 | AU11: =MIN(AT11,L$8) -> 0 | AV11: =MAX(0,MIN(AT11-AU11,$C11-(P11+T11+X11+AB11+AF11+AJ11+AN11+AR11))) -> 0 | AW11: =ROUND(AT11-AU11-AV11,2) -> 0 | AX11: =M$6*(1+M$7) -> 0 | AY11: =MIN(AX11,M$8) -> 0 | AZ11: =MAX(0,MIN(AX11-AY11,$C11-(P11+T11+X11+AB11+AF11+AJ11+AN11+AR11+AV11))) -> 0 | BA11: =ROUND(AX11-AY11-AZ11,2) -> 0
A12: 2 | B12: =EDATE(Borçlar!$K$7,1) -> 46327 | C12: =MAX(0,Borçlar!$K$8-(O12+S12+W12+AA12+AE12+AI12+AM12+AQ12+AU12+AY12)) -> 5000 | D12: =O12+P12+S12+T12+W12+X12+AA12+AB12+AE12+AF12+AI12+AJ12+AM12+AN12+AQ12+AR12+AU12+AV12+AY12+AZ12 -> 19000 | E12: =(N12+R12+V12+Z12+AD12+AH12+AL12+AP12+AT12+AX12)-(F11) -> 7758.5 | F12: =Q12+U12+Y12+AC12+AG12+AK12+AO12+AS12+AW12+BA12 -> 222908.5 | N12: =Q11*(1+D$7) -> 20737.5 | O12: =MIN(N12,D$8) -> 1500 | P12: =MAX(0,MIN(N12-O12,$C12-(0))) -> 5000 | Q12: =ROUND(N12-O12-P12,2) -> 14237.5 | R12: =U11*(1+E$7) -> 62386.5 | S12: =MIN(R12,E$8) -> 3000 | T12: =MAX(0,MIN(R12-S12,$C12-(P12))) -> 0 | U12: =ROUND(R12-S12-T12,2) -> 59386.5 | V12: =Y11*(1+F$7) -> 120784.5 | W12: =MIN(V12,F$8) -> 7500 | X12: =MAX(0,MIN(V12-W12,$C12-(P12+T12))) -> 0 | Y12: =ROUND(V12-W12-X12,2) -> 113284.5 | Z12: =AC11*(1+G$7) -> 38000 | AA12: =MIN(Z12,G$8) -> 2000 | AB12: =MAX(0,MIN(Z12-AA12,$C12-(P12+T12+X12))) -> 0 | AC12: =ROUND(Z12-AA12-AB12,2) -> 36000 | AD12: =AG11*(1+H$7) -> 0 | AE12: =MIN(AD12,H$8) -> 0 | AF12: =MAX(0,MIN(AD12-AE12,$C12-(P12+T12+X12+AB12))) -> 0 | AG12: =ROUND(AD12-AE12-AF12,2) -> 0 | AH12: =AK11*(1+I$7) -> 0 | AI12: =MIN(AH12,I$8) -> 0 | AJ12: =MAX(0,MIN(AH12-AI12,$C12-(P12+T12+X12+AB12+AF12))) -> 0 | AK12: =ROUND(AH12-AI12-AJ12,2) -> 0 | AL12: =AO11*(1+J$7) -> 0 | AM12: =MIN(AL12,J$8) -> 0 | AN12: =MAX(0,MIN(AL12-AM12,$C12-(P12+T12+X12+AB12+AF12+AJ12))) -> 0 | AO12: =ROUND(AL12-AM12-AN12,2) -> 0 | AP12: =AS11*(1+K$7) -> 0 | AQ12: =MIN(AP12,K$8) -> 0 | AR12: =MAX(0,MIN(AP12-AQ12,$C12-(P12+T12+X12+AB12+AF12+AJ12+AN12))) -> 0 | AS12: =ROUND(AP12-AQ12-AR12,2) -> 0 | AT12: =AW11*(1+L$7) -> 0 | AU12: =MIN(AT12,L$8) -> 0 | AV12: =MAX(0,MIN(AT12-AU12,$C12-(P12+T12+X12+AB12+AF12+AJ12+AN12+AR12))) -> 0 | AW12: =ROUND(AT12-AU12-AV12,2) -> 0 | AX12: =BA11*(1+M$7) -> 0 | AY12: =MIN(AX12,M$8) -> 0 | AZ12: =MAX(0,MIN(AX12-AY12,$C12-(P12+T12+X12+AB12+AF12+AJ12+AN12+AR12+AV12))) -> 0 | BA12: =ROUND(AX12-AY12-AZ12,2) -> 0
A13: 3 | B13: =EDATE(Borçlar!$K$7,2) -> 46357 | C13: =MAX(0,Borçlar!$K$8-(O13+S13+W13+AA13+AE13+AI13+AM13+AQ13+AU13+AY13)) -> 5000 | D13: =O13+P13+S13+T13+W13+X13+AA13+AB13+AE13+AF13+AI13+AJ13+AM13+AN13+AQ13+AR13+AU13+AV13+AY13+AZ13 -> 19000 | E13: =(N13+R13+V13+Z13+AD13+AH13+AL13+AP13+AT13+AX13)-(F12) -> 7349.225 | F13: =Q13+U13+Y13+AC13+AG13+AK13+AO13+AS13+AW13+BA13 -> 211257.73 | N13: =Q12*(1+D$7) -> 14949.375 | O13: =MIN(N13,D$8) -> 1500 | P13: =MAX(0,MIN(N13-O13,$C13-(0))) -> 5000 | Q13: =ROUND(N13-O13-P13,2) -> 8449.38 | R13: =U12*(1+E$7) -> 62058.893 | S13: =MIN(R13,E$8) -> 3000 | T13: =MAX(0,MIN(R13-S13,$C13-(P13))) -> 0 | U13: =ROUND(R13-S13-T13,2) -> 59058.89 | V13: =Y12*(1+F$7) -> 117249.46 | W13: =MIN(V13,F$8) -> 7500 | X13: =MAX(0,MIN(V13-W13,$C13-(P13+T13))) -> 0 | Y13: =ROUND(V13-W13-X13,2) -> 109749.46 | Z13: =AC12*(1+G$7) -> 36000 | AA13: =MIN(Z13,G$8) -> 2000 | AB13: =MAX(0,MIN(Z13-AA13,$C13-(P13+T13+X13))) -> 0 | AC13: =ROUND(Z13-AA13-AB13,2) -> 34000 | AD13: =AG12*(1+H$7) -> 0 | AE13: =MIN(AD13,H$8) -> 0 | AF13: =MAX(0,MIN(AD13-AE13,$C13-(P13+T13+X13+AB13))) -> 0 | AG13: =ROUND(AD13-AE13-AF13,2) -> 0 | AH13: =AK12*(1+I$7) -> 0 | AI13: =MIN(AH13,I$8) -> 0 | AJ13: =MAX(0,MIN(AH13-AI13,$C13-(P13+T13+X13+AB13+AF13))) -> 0 | AK13: =ROUND(AH13-AI13-AJ13,2) -> 0 | AL13: =AO12*(1+J$7) -> 0 | AM13: =MIN(AL13,J$8) -> 0 | AN13: =MAX(0,MIN(AL13-AM13,$C13-(P13+T13+X13+AB13+AF13+AJ13))) -> 0 | AO13: =ROUND(AL13-AM13-AN13,2) -> 0 | AP13: =AS12*(1+K$7) -> 0 | AQ13: =MIN(AP13,K$8) -> 0 | AR13: =MAX(0,MIN(AP13-AQ13,$C13-(P13+T13+X13+AB13+AF13+AJ13+AN13))) -> 0 | AS13: =ROUND(AP13-AQ13-AR13,2) -> 0 | AT13: =AW12*(1+L$7) -> 0 | AU13: =MIN(AT13,L$8) -> 0 | AV13: =MAX(0,MIN(AT13-AU13,$C13-(P13+T13+X13+AB13+AF13+AJ13+AN13+AR13))) -> 0 | AW13: =ROUND(AT13-AU13-AV13,2) -> 0 | AX13: =BA12*(1+M$7) -> 0 | AY13: =MIN(AX13,M$8) -> 0 | AZ13: =MAX(0,MIN(AX13-AY13,$C13-(P13+T13+X13+AB13+AF13+AJ13+AN13+AR13+AV13))) -> 0 | BA13: =ROUND(AX13-AY13-AZ13,2) -> 0
A14: 4 | B14: =EDATE(Borçlar!$K$7,3) -> 46388 | C14: =MAX(0,Borçlar!$K$8-(O14+S14+W14+AA14+AE14+AI14+AM14+AQ14+AU14+AY14)) -> 5000 | D14: =O14+P14+S14+T14+W14+X14+AA14+AB14+AE14+AF14+AI14+AJ14+AM14+AN14+AQ14+AR14+AU14+AV14+AY14+AZ14 -> 19000 | E14: =(N14+R14+V14+Z14+AD14+AH14+AL14+AP14+AT14+AX14)-(F13) -> 6921.3501 | F14: =Q14+U14+Y14+AC14+AG14+AK14+AO14+AS14+AW14+BA14 -> 199179.08 | N14: =Q13*(1+D$7) -> 8871.849 | O14: =MIN(N14,D$8) -> 1500 | P14: =MAX(0,MIN(N14-O14,$C14-(0))) -> 5000 | Q14: =ROUND(N14-O14-P14,2) -> 2371.85 | R14: =U13*(1+E$7) -> 61716.54 | S14: =MIN(R14,E$8) -> 3000 | T14: =MAX(0,MIN(R14-S14,$C14-(P14))) -> 0 | U14: =ROUND(R14-S14-T14,2) -> 58716.54 | V14: =Y13*(1+F$7) -> 113590.69 | W14: =MIN(V14,F$8) -> 7500 | X14: =MAX(0,MIN(V14-W14,$C14-(P14+T14))) -> 0 | Y14: =ROUND(V14-W14-X14,2) -> 106090.69 | Z14: =AC13*(1+G$7) -> 34000 | AA14: =MIN(Z14,G$8) -> 2000 | AB14: =MAX(0,MIN(Z14-AA14,$C14-(P14+T14+X14))) -> 0 | AC14: =ROUND(Z14-AA14-AB14,2) -> 32000 | AD14: =AG13*(1+H$7) -> 0 | AE14: =MIN(AD14,H$8) -> 0 | AF14: =MAX(0,MIN(AD14-AE14,$C14-(P14+T14+X14+AB14))) -> 0 | AG14: =ROUND(AD14-AE14-AF14,2) -> 0 | AH14: =AK13*(1+I$7) -> 0 | AI14: =MIN(AH14,I$8) -> 0 | AJ14: =MAX(0,MIN(AH14-AI14,$C14-(P14+T14+X14+AB14+AF14))) -> 0 | AK14: =ROUND(AH14-AI14-AJ14,2) -> 0 | AL14: =AO13*(1+J$7) -> 0 | AM14: =MIN(AL14,J$8) -> 0 | AN14: =MAX(0,MIN(AL14-AM14,$C14-(P14+T14+X14+AB14+AF14+AJ14))) -> 0 | AO14: =ROUND(AL14-AM14-AN14,2) -> 0 | AP14: =AS13*(1+K$7) -> 0 | AQ14: =MIN(AP14,K$8) -> 0 | AR14: =MAX(0,MIN(AP14-AQ14,$C14-(P14+T14+X14+AB14+AF14+AJ14+AN14))) -> 0 | AS14: =ROUND(AP14-AQ14-AR14,2) -> 0 | AT14: =AW13*(1+L$7) -> 0 | AU14: =MIN(AT14,L$8) -> 0 | AV14: =MAX(0,MIN(AT14-AU14,$C14-(P14+T14+X14+AB14+AF14+AJ14+AN14+AR14))) -> 0 | AW14: =ROUND(AT14-AU14-AV14,2) -> 0 | AX14: =BA13*(1+M$7) -> 0 | AY14: =MIN(AX14,M$8) -> 0 | AZ14: =MAX(0,MIN(AX14-AY14,$C14-(P14+T14+X14+AB14+AF14+AJ14+AN14+AR14+AV14))) -> 0 | BA14: =ROUND(AX14-AY14-AZ14,2) -> 0
A15: 5 | B15: =EDATE(Borçlar!$K$7,4) -> 46419 | C15: =MAX(0,Borçlar!$K$8-(O15+S15+W15+AA15+AE15+AI15+AM15+AQ15+AU15+AY15)) -> 5000 | D15: =O15+P15+S15+T15+W15+X15+AA15+AB15+AE15+AF15+AI15+AJ15+AM15+AN15+AQ15+AR15+AU15+AV15+AY15+AZ15 -> 19000 | E15: =(N15+R15+V15+Z15+AD15+AH15+AL15+AP15+AT15+AX15)-(F14) -> 6474.0109 | F15: =Q15+U15+Y15+AC15+AG15+AK15+AO15+AS15+AW15+BA15 -> 186653.09 | N15: =Q14*(1+D$7) -> 2490.4425 | O15: =MIN(N15,D$8) -> 1500 | P15: =MAX(0,MIN(N15-O15,$C15-(0))) -> 990.4425 | Q15: =ROUND(N15-O15-P15,2) -> 0 | R15: =U14*(1+E$7) -> 61358.784 | S15: =MIN(R15,E$8) -> 3000 | T15: =MAX(0,MIN(R15-S15,$C15-(P15))) -> 4009.5575 | U15: =ROUND(R15-S15-T15,2) -> 54349.23 | V15: =Y14*(1+F$7) -> 109803.86 | W15: =MIN(V15,F$8) -> 7500 | X15: =MAX(0,MIN(V15-W15,$C15-(P15+T15))) -> 0 | Y15: =ROUND(V15-W15-X15,2) -> 102303.86 | Z15: =AC14*(1+G$7) -> 32000 | AA15: =MIN(Z15,G$8) -> 2000 | AB15: =MAX(0,MIN(Z15-AA15,$C15-(P15+T15+X15))) -> 0 | AC15: =ROUND(Z15-AA15-AB15,2) -> 30000 | AD15: =AG14*(1+H$7) -> 0 | AE15: =MIN(AD15,H$8) -> 0 | AF15: =MAX(0,MIN(AD15-AE15,$C15-(P15+T15+X15+AB15))) -> 0 | AG15: =ROUND(AD15-AE15-AF15,2) -> 0 | AH15: =AK14*(1+I$7) -> 0 | AI15: =MIN(AH15,I$8) -> 0 | AJ15: =MAX(0,MIN(AH15-AI15,$C15-(P15+T15+X15+AB15+AF15))) -> 0 | AK15: =ROUND(AH15-AI15-AJ15,2) -> 0 | AL15: =AO14*(1+J$7) -> 0 | AM15: =MIN(AL15,J$8) -> 0 | AN15: =MAX(0,MIN(AL15-AM15,$C15-(P15+T15+X15+AB15+AF15+AJ15))) -> 0 | AO15: =ROUND(AL15-AM15-AN15,2) -> 0 | AP15: =AS14*(1+K$7) -> 0 | AQ15: =MIN(AP15,K$8) -> 0 | AR15: =MAX(0,MIN(AP15-AQ15,$C15-(P15+T15+X15+AB15+AF15+AJ15+AN15))) -> 0 | AS15: =ROUND(AP15-AQ15-AR15,2) -> 0 | AT15: =AW14*(1+L$7) -> 0 | AU15: =MIN(AT15,L$8) -> 0 | AV15: =MAX(0,MIN(AT15-AU15,$C15-(P15+T15+X15+AB15+AF15+AJ15+AN15+AR15))) -> 0 | AW15: =ROUND(AT15-AU15-AV15,2) -> 0 | AX15: =BA14*(1+M$7) -> 0 | AY15: =MIN(AX15,M$8) -> 0 | AZ15: =MAX(0,MIN(AX15-AY15,$C15-(P15+T15+X15+AB15+AF15+AJ15+AN15+AR15+AV15))) -> 0 | BA15: =ROUND(AX15-AY15-AZ15,2) -> 0
A16: 6 | B16: =EDATE(Borçlar!$K$7,5) -> 46447 | C16: =MAX(0,Borçlar!$K$8-(O16+S16+W16+AA16+AE16+AI16+AM16+AQ16+AU16+AY16)) -> 6500 | D16: =O16+P16+S16+T16+W16+X16+AA16+AB16+AE16+AF16+AI16+AJ16+AM16+AN16+AQ16+AR16+AU16+AV16+AY16+AZ16 -> 19000 | E16: =(N16+R16+V16+Z16+AD16+AH16+AL16+AP16+AT16+AX16)-(F15) -> 6026.3504 | F16: =Q16+U16+Y16+AC16+AG16+AK16+AO16+AS16+AW16+BA16 -> 173679.45 | N16: =Q15*(1+D$7) -> 0 | O16: =MIN(N16,D$8) -> 0 | P16: =MAX(0,MIN(N16-O16,$C16-(0))) -> 0 | Q16: =ROUND(N16-O16-P16,2) -> 0 | R16: =U15*(1+E$7) -> 56794.945 | S16: =MIN(R16,E$8) -> 3000 | T16: =MAX(0,MIN(R16-S16,$C16-(P16))) -> 6500 | U16: =ROUND(R16-S16-T16,2) -> 47294.95 | V16: =Y15*(1+F$7) -> 105884.5 | W16: =MIN(V16,F$8) -> 7500 | X16: =MAX(0,MIN(V16-W16,$C16-(P16+T16))) -> 0 | Y16: =ROUND(V16-W16-X16,2) -> 98384.5 | Z16: =AC15*(1+G$7) -> 30000 | AA16: =MIN(Z16,G$8) -> 2000 | AB16: =MAX(0,MIN(Z16-AA16,$C16-(P16+T16+X16))) -> 0 | AC16: =ROUND(Z16-AA16-AB16,2) -> 28000 | AD16: =AG15*(1+H$7) -> 0 | AE16: =MIN(AD16,H$8) -> 0 | AF16: =MAX(0,MIN(AD16-AE16,$C16-(P16+T16+X16+AB16))) -> 0 | AG16: =ROUND(AD16-AE16-AF16,2) -> 0 | AH16: =AK15*(1+I$7) -> 0 | AI16: =MIN(AH16,I$8) -> 0 | AJ16: =MAX(0,MIN(AH16-AI16,$C16-(P16+T16+X16+AB16+AF16))) -> 0 | AK16: =ROUND(AH16-AI16-AJ16,2) -> 0 | AL16: =AO15*(1+J$7) -> 0 | AM16: =MIN(AL16,J$8) -> 0 | AN16: =MAX(0,MIN(AL16-AM16,$C16-(P16+T16+X16+AB16+AF16+AJ16))) -> 0 | AO16: =ROUND(AL16-AM16-AN16,2) -> 0 | AP16: =AS15*(1+K$7) -> 0 | AQ16: =MIN(AP16,K$8) -> 0 | AR16: =MAX(0,MIN(AP16-AQ16,$C16-(P16+T16+X16+AB16+AF16+AJ16+AN16))) -> 0 | AS16: =ROUND(AP16-AQ16-AR16,2) -> 0 | AT16: =AW15*(1+L$7) -> 0 | AU16: =MIN(AT16,L$8) -> 0 | AV16: =MAX(0,MIN(AT16-AU16,$C16-(P16+T16+X16+AB16+AF16+AJ16+AN16+AR16))) -> 0 | AW16: =ROUND(AT16-AU16-AV16,2) -> 0 | AX16: =BA15*(1+M$7) -> 0 | AY16: =MIN(AX16,M$8) -> 0 | AZ16: =MAX(0,MIN(AX16-AY16,$C16-(P16+T16+X16+AB16+AF16+AJ16+AN16+AR16+AV16))) -> 0 | BA16: =ROUND(AX16-AY16-AZ16,2) -> 0
A17: 7 | B17: =EDATE(Borçlar!$K$7,6) -> 46478 | C17: =MAX(0,Borçlar!$K$8-(O17+S17+W17+AA17+AE17+AI17+AM17+AQ17+AU17+AY17)) -> 6500 | D17: =O17+P17+S17+T17+W17+X17+AA17+AB17+AE17+AF17+AI17+AJ17+AM17+AN17+AQ17+AR17+AU17+AV17+AY17+AZ17 -> 19000 | E17: =(N17+R17+V17+Z17+AD17+AH17+AL17+AP17+AT17+AX17)-(F16) -> 5571.7302 | F17: =Q17+U17+Y17+AC17+AG17+AK17+AO17+AS17+AW17+BA17 -> 160251.18 | N17: =Q16*(1+D$7) -> 0 | O17: =MIN(N17,D$8) -> 0 | P17: =MAX(0,MIN(N17-O17,$C17-(0))) -> 0 | Q17: =ROUND(N17-O17-P17,2) -> 0 | R17: =U16*(1+E$7) -> 49423.223 | S17: =MIN(R17,E$8) -> 3000 | T17: =MAX(0,MIN(R17-S17,$C17-(P17))) -> 6500 | U17: =ROUND(R17-S17-T17,2) -> 39923.22 | V17: =Y16*(1+F$7) -> 101827.96 | W17: =MIN(V17,F$8) -> 7500 | X17: =MAX(0,MIN(V17-W17,$C17-(P17+T17))) -> 0 | Y17: =ROUND(V17-W17-X17,2) -> 94327.96 | Z17: =AC16*(1+G$7) -> 28000 | AA17: =MIN(Z17,G$8) -> 2000 | AB17: =MAX(0,MIN(Z17-AA17,$C17-(P17+T17+X17))) -> 0 | AC17: =ROUND(Z17-AA17-AB17,2) -> 26000 | AD17: =AG16*(1+H$7) -> 0 | AE17: =MIN(AD17,H$8) -> 0 | AF17: =MAX(0,MIN(AD17-AE17,$C17-(P17+T17+X17+AB17))) -> 0 | AG17: =ROUND(AD17-AE17-AF17,2) -> 0 | AH17: =AK16*(1+I$7) -> 0 | AI17: =MIN(AH17,I$8) -> 0 | AJ17: =MAX(0,MIN(AH17-AI17,$C17-(P17+T17+X17+AB17+AF17))) -> 0 | AK17: =ROUND(AH17-AI17-AJ17,2) -> 0 | AL17: =AO16*(1+J$7) -> 0 | AM17: =MIN(AL17,J$8) -> 0 | AN17: =MAX(0,MIN(AL17-AM17,$C17-(P17+T17+X17+AB17+AF17+AJ17))) -> 0 | AO17: =ROUND(AL17-AM17-AN17,2) -> 0 | AP17: =AS16*(1+K$7) -> 0 | AQ17: =MIN(AP17,K$8) -> 0 | AR17: =MAX(0,MIN(AP17-AQ17,$C17-(P17+T17+X17+AB17+AF17+AJ17+AN17))) -> 0 | AS17: =ROUND(AP17-AQ17-AR17,2) -> 0 | AT17: =AW16*(1+L$7) -> 0 | AU17: =MIN(AT17,L$8) -> 0 | AV17: =MAX(0,MIN(AT17-AU17,$C17-(P17+T17+X17+AB17+AF17+AJ17+AN17+AR17))) -> 0 | AW17: =ROUND(AT17-AU17-AV17,2) -> 0 | AX17: =BA16*(1+M$7) -> 0 | AY17: =MIN(AX17,M$8) -> 0 | AZ17: =MAX(0,MIN(AX17-AY17,$C17-(P17+T17+X17+AB17+AF17+AJ17+AN17+AR17+AV17))) -> 0 | BA17: =ROUND(AX17-AY17-AZ17,2) -> 0
A18: 8 | B18: =EDATE(Borçlar!$K$7,7) -> 46508 | C18: =MAX(0,Borçlar!$K$8-(O18+S18+W18+AA18+AE18+AI18+AM18+AQ18+AU18+AY18)) -> 6500 | D18: =O18+P18+S18+T18+W18+X18+AA18+AB18+AE18+AF18+AI18+AJ18+AM18+AN18+AQ18+AR18+AU18+AV18+AY18+AZ18 -> 19000 | E18: =(N18+R18+V18+Z18+AD18+AH18+AL18+AP18+AT18+AX18)-(F17) -> 5098.0235 | F18: =Q18+U18+Y18+AC18+AG18+AK18+AO18+AS18+AW18+BA18 -> 146349.2 | N18: =Q17*(1+D$7) -> 0 | O18: =MIN(N18,D$8) -> 0 | P18: =MAX(0,MIN(N18-O18,$C18-(0))) -> 0 | Q18: =ROUND(N18-O18-P18,2) -> 0 | R18: =U17*(1+E$7) -> 41719.765 | S18: =MIN(R18,E$8) -> 3000 | T18: =MAX(0,MIN(R18-S18,$C18-(P18))) -> 6500 | U18: =ROUND(R18-S18-T18,2) -> 32219.76 | V18: =Y17*(1+F$7) -> 97629.439 | W18: =MIN(V18,F$8) -> 7500 | X18: =MAX(0,MIN(V18-W18,$C18-(P18+T18))) -> 0 | Y18: =ROUND(V18-W18-X18,2) -> 90129.44 | Z18: =AC17*(1+G$7) -> 26000 | AA18: =MIN(Z18,G$8) -> 2000 | AB18: =MAX(0,MIN(Z18-AA18,$C18-(P18+T18+X18))) -> 0 | AC18: =ROUND(Z18-AA18-AB18,2) -> 24000 | AD18: =AG17*(1+H$7) -> 0 | AE18: =MIN(AD18,H$8) -> 0 | AF18: =MAX(0,MIN(AD18-AE18,$C18-(P18+T18+X18+AB18))) -> 0 | AG18: =ROUND(AD18-AE18-AF18,2) -> 0 | AH18: =AK17*(1+I$7) -> 0 | AI18: =MIN(AH18,I$8) -> 0 | AJ18: =MAX(0,MIN(AH18-AI18,$C18-(P18+T18+X18+AB18+AF18))) -> 0 | AK18: =ROUND(AH18-AI18-AJ18,2) -> 0 | AL18: =AO17*(1+J$7) -> 0 | AM18: =MIN(AL18,J$8) -> 0 | AN18: =MAX(0,MIN(AL18-AM18,$C18-(P18+T18+X18+AB18+AF18+AJ18))) -> 0 | AO18: =ROUND(AL18-AM18-AN18,2) -> 0 | AP18: =AS17*(1+K$7) -> 0 | AQ18: =MIN(AP18,K$8) -> 0 | AR18: =MAX(0,MIN(AP18-AQ18,$C18-(P18+T18+X18+AB18+AF18+AJ18+AN18))) -> 0 | AS18: =ROUND(AP18-AQ18-AR18,2) -> 0 | AT18: =AW17*(1+L$7) -> 0 | AU18: =MIN(AT18,L$8) -> 0 | AV18: =MAX(0,MIN(AT18-AU18,$C18-(P18+T18+X18+AB18+AF18+AJ18+AN18+AR18))) -> 0 | AW18: =ROUND(AT18-AU18-AV18,2) -> 0 | AX18: =BA17*(1+M$7) -> 0 | AY18: =MIN(AX18,M$8) -> 0 | AZ18: =MAX(0,MIN(AX18-AY18,$C18-(P18+T18+X18+AB18+AF18+AJ18+AN18+AR18+AV18))) -> 0 | BA18: =ROUND(AX18-AY18-AZ18,2) -> 0
A19: 9 | B19: =EDATE(Borçlar!$K$7,8) -> 46539 | C19: =MAX(0,Borçlar!$K$8-(O19+S19+W19+AA19+AE19+AI19+AM19+AQ19+AU19+AY19)) -> 6500 | D19: =O19+P19+S19+T19+W19+X19+AA19+AB19+AE19+AF19+AI19+AJ19+AM19+AN19+AQ19+AR19+AU19+AV19+AY19+AZ19 -> 19000 | E19: =(N19+R19+V19+Z19+AD19+AH19+AL19+AP19+AT19+AX19)-(F18) -> 4604.4196 | F19: =Q19+U19+Y19+AC19+AG19+AK19+AO19+AS19+AW19+BA19 -> 131953.62 | N19: =Q18*(1+D$7) -> 0 | O19: =MIN(N19,D$8) -> 0 | P19: =MAX(0,MIN(N19-O19,$C19-(0))) -> 0 | Q19: =ROUND(N19-O19-P19,2) -> 0 | R19: =U18*(1+E$7) -> 33669.649 | S19: =MIN(R19,E$8) -> 3000 | T19: =MAX(0,MIN(R19-S19,$C19-(P19))) -> 6500 | U19: =ROUND(R19-S19-T19,2) -> 24169.65 | V19: =Y18*(1+F$7) -> 93283.97 | W19: =MIN(V19,F$8) -> 7500 | X19: =MAX(0,MIN(V19-W19,$C19-(P19+T19))) -> 0 | Y19: =ROUND(V19-W19-X19,2) -> 85783.97 | Z19: =AC18*(1+G$7) -> 24000 | AA19: =MIN(Z19,G$8) -> 2000 | AB19: =MAX(0,MIN(Z19-AA19,$C19-(P19+T19+X19))) -> 0 | AC19: =ROUND(Z19-AA19-AB19,2) -> 22000 | AD19: =AG18*(1+H$7) -> 0 | AE19: =MIN(AD19,H$8) -> 0 | AF19: =MAX(0,MIN(AD19-AE19,$C19-(P19+T19+X19+AB19))) -> 0 | AG19: =ROUND(AD19-AE19-AF19,2) -> 0 | AH19: =AK18*(1+I$7) -> 0 | AI19: =MIN(AH19,I$8) -> 0 | AJ19: =MAX(0,MIN(AH19-AI19,$C19-(P19+T19+X19+AB19+AF19))) -> 0 | AK19: =ROUND(AH19-AI19-AJ19,2) -> 0 | AL19: =AO18*(1+J$7) -> 0 | AM19: =MIN(AL19,J$8) -> 0 | AN19: =MAX(0,MIN(AL19-AM19,$C19-(P19+T19+X19+AB19+AF19+AJ19))) -> 0 | AO19: =ROUND(AL19-AM19-AN19,2) -> 0 | AP19: =AS18*(1+K$7) -> 0 | AQ19: =MIN(AP19,K$8) -> 0 | AR19: =MAX(0,MIN(AP19-AQ19,$C19-(P19+T19+X19+AB19+AF19+AJ19+AN19))) -> 0 | AS19: =ROUND(AP19-AQ19-AR19,2) -> 0 | AT19: =AW18*(1+L$7) -> 0 | AU19: =MIN(AT19,L$8) -> 0 | AV19: =MAX(0,MIN(AT19-AU19,$C19-(P19+T19+X19+AB19+AF19+AJ19+AN19+AR19))) -> 0 | AW19: =ROUND(AT19-AU19-AV19,2) -> 0 | AX19: =BA18*(1+M$7) -> 0 | AY19: =MIN(AX19,M$8) -> 0 | AZ19: =MAX(0,MIN(AX19-AY19,$C19-(P19+T19+X19+AB19+AF19+AJ19+AN19+AR19+AV19))) -> 0 | BA19: =ROUND(AX19-AY19-AZ19,2) -> 0
A20: 10 | B20: =EDATE(Borçlar!$K$7,9) -> 46569 | C20: =MAX(0,Borçlar!$K$8-(O20+S20+W20+AA20+AE20+AI20+AM20+AQ20+AU20+AY20)) -> 6500 | D20: =O20+P20+S20+T20+W20+X20+AA20+AB20+AE20+AF20+AI20+AJ20+AM20+AN20+AQ20+AR20+AU20+AV20+AY20+AZ20 -> 19000 | E20: =(N20+R20+V20+Z20+AD20+AH20+AL20+AP20+AT20+AX20)-(F19) -> 4090.0732 | F20: =Q20+U20+Y20+AC20+AG20+AK20+AO20+AS20+AW20+BA20 -> 117043.69 | N20: =Q19*(1+D$7) -> 0 | O20: =MIN(N20,D$8) -> 0 | P20: =MAX(0,MIN(N20-O20,$C20-(0))) -> 0 | Q20: =ROUND(N20-O20-P20,2) -> 0 | R20: =U19*(1+E$7) -> 25257.284 | S20: =MIN(R20,E$8) -> 3000 | T20: =MAX(0,MIN(R20-S20,$C20-(P20))) -> 6500 | U20: =ROUND(R20-S20-T20,2) -> 15757.28 | V20: =Y19*(1+F$7) -> 88786.409 | W20: =MIN(V20,F$8) -> 7500 | X20: =MAX(0,MIN(V20-W20,$C20-(P20+T20))) -> 0 | Y20: =ROUND(V20-W20-X20,2) -> 81286.41 | Z20: =AC19*(1+G$7) -> 22000 | AA20: =MIN(Z20,G$8) -> 2000 | AB20: =MAX(0,MIN(Z20-AA20,$C20-(P20+T20+X20))) -> 0 | AC20: =ROUND(Z20-AA20-AB20,2) -> 20000 | AD20: =AG19*(1+H$7) -> 0 | AE20: =MIN(AD20,H$8) -> 0 | AF20: =MAX(0,MIN(AD20-AE20,$C20-(P20+T20+X20+AB20))) -> 0 | AG20: =ROUND(AD20-AE20-AF20,2) -> 0 | AH20: =AK19*(1+I$7) -> 0 | AI20: =MIN(AH20,I$8) -> 0 | AJ20: =MAX(0,MIN(AH20-AI20,$C20-(P20+T20+X20+AB20+AF20))) -> 0 | AK20: =ROUND(AH20-AI20-AJ20,2) -> 0 | AL20: =AO19*(1+J$7) -> 0 | AM20: =MIN(AL20,J$8) -> 0 | AN20: =MAX(0,MIN(AL20-AM20,$C20-(P20+T20+X20+AB20+AF20+AJ20))) -> 0 | AO20: =ROUND(AL20-AM20-AN20,2) -> 0 | AP20: =AS19*(1+K$7) -> 0 | AQ20: =MIN(AP20,K$8) -> 0 | AR20: =MAX(0,MIN(AP20-AQ20,$C20-(P20+T20+X20+AB20+AF20+AJ20+AN20))) -> 0 | AS20: =ROUND(AP20-AQ20-AR20,2) -> 0 | AT20: =AW19*(1+L$7) -> 0 | AU20: =MIN(AT20,L$8) -> 0 | AV20: =MAX(0,MIN(AT20-AU20,$C20-(P20+T20+X20+AB20+AF20+AJ20+AN20+AR20))) -> 0 | AW20: =ROUND(AT20-AU20-AV20,2) -> 0 | AX20: =BA19*(1+M$7) -> 0 | AY20: =MIN(AX20,M$8) -> 0 | AZ20: =MAX(0,MIN(AX20-AY20,$C20-(P20+T20+X20+AB20+AF20+AJ20+AN20+AR20+AV20))) -> 0 | BA20: =ROUND(AX20-AY20-AZ20,2) -> 0
A21: 11 | B21: =EDATE(Borçlar!$K$7,10) -> 46600 | C21: =MAX(0,Borçlar!$K$8-(O21+S21+W21+AA21+AE21+AI21+AM21+AQ21+AU21+AY21)) -> 6500 | D21: =O21+P21+S21+T21+W21+X21+AA21+AB21+AE21+AF21+AI21+AJ21+AM21+AN21+AQ21+AR21+AU21+AV21+AY21+AZ21 -> 19000 | E21: =(N21+R21+V21+Z21+AD21+AH21+AL21+AP21+AT21+AX21)-(F20) -> 3554.102 | F21: =Q21+U21+Y21+AC21+AG21+AK21+AO21+AS21+AW21+BA21 -> 101597.79 | N21: =Q20*(1+D$7) -> 0 | O21: =MIN(N21,D$8) -> 0 | P21: =MAX(0,MIN(N21-O21,$C21-(0))) -> 0 | Q21: =ROUND(N21-O21-P21,2) -> 0 | R21: =U20*(1+E$7) -> 16466.358 | S21: =MIN(R21,E$8) -> 3000 | T21: =MAX(0,MIN(R21-S21,$C21-(P21))) -> 6500 | U21: =ROUND(R21-S21-T21,2) -> 6966.36 | V21: =Y20*(1+F$7) -> 84131.434 | W21: =MIN(V21,F$8) -> 7500 | X21: =MAX(0,MIN(V21-W21,$C21-(P21+T21))) -> 0 | Y21: =ROUND(V21-W21-X21,2) -> 76631.43 | Z21: =AC20*(1+G$7) -> 20000 | AA21: =MIN(Z21,G$8) -> 2000 | AB21: =MAX(0,MIN(Z21-AA21,$C21-(P21+T21+X21))) -> 0 | AC21: =ROUND(Z21-AA21-AB21,2) -> 18000 | AD21: =AG20*(1+H$7) -> 0 | AE21: =MIN(AD21,H$8) -> 0 | AF21: =MAX(0,MIN(AD21-AE21,$C21-(P21+T21+X21+AB21))) -> 0 | AG21: =ROUND(AD21-AE21-AF21,2) -> 0 | AH21: =AK20*(1+I$7) -> 0 | AI21: =MIN(AH21,I$8) -> 0 | AJ21: =MAX(0,MIN(AH21-AI21,$C21-(P21+T21+X21+AB21+AF21))) -> 0 | AK21: =ROUND(AH21-AI21-AJ21,2) -> 0 | AL21: =AO20*(1+J$7) -> 0 | AM21: =MIN(AL21,J$8) -> 0 | AN21: =MAX(0,MIN(AL21-AM21,$C21-(P21+T21+X21+AB21+AF21+AJ21))) -> 0 | AO21: =ROUND(AL21-AM21-AN21,2) -> 0 | AP21: =AS20*(1+K$7) -> 0 | AQ21: =MIN(AP21,K$8) -> 0 | AR21: =MAX(0,MIN(AP21-AQ21,$C21-(P21+T21+X21+AB21+AF21+AJ21+AN21))) -> 0 | AS21: =ROUND(AP21-AQ21-AR21,2) -> 0 | AT21: =AW20*(1+L$7) -> 0 | AU21: =MIN(AT21,L$8) -> 0 | AV21: =MAX(0,MIN(AT21-AU21,$C21-(P21+T21+X21+AB21+AF21+AJ21+AN21+AR21))) -> 0 | AW21: =ROUND(AT21-AU21-AV21,2) -> 0 | AX21: =BA20*(1+M$7) -> 0 | AY21: =MIN(AX21,M$8) -> 0 | AZ21: =MAX(0,MIN(AX21-AY21,$C21-(P21+T21+X21+AB21+AF21+AJ21+AN21+AR21+AV21))) -> 0 | BA21: =ROUND(AX21-AY21-AZ21,2) -> 0
A22: 12 | B22: =EDATE(Borçlar!$K$7,11) -> 46631 | C22: =MAX(0,Borçlar!$K$8-(O22+S22+W22+AA22+AE22+AI22+AM22+AQ22+AU22+AY22)) -> 6500 | D22: =O22+P22+S22+T22+W22+X22+AA22+AB22+AE22+AF22+AI22+AJ22+AM22+AN22+AQ22+AR22+AU22+AV22+AY22+AZ22 -> 19000 | E22: =(N22+R22+V22+Z22+AD22+AH22+AL22+AP22+AT22+AX22)-(F21) -> 2995.5862 | F22: =Q22+U22+Y22+AC22+AG22+AK22+AO22+AS22+AW22+BA22 -> 85593.38 | N22: =Q21*(1+D$7) -> 0 | O22: =MIN(N22,D$8) -> 0 | P22: =MAX(0,MIN(N22-O22,$C22-(0))) -> 0 | Q22: =ROUND(N22-O22-P22,2) -> 0 | R22: =U21*(1+E$7) -> 7279.8462 | S22: =MIN(R22,E$8) -> 3000 | T22: =MAX(0,MIN(R22-S22,$C22-(P22))) -> 4279.8462 | U22: =ROUND(R22-S22-T22,2) -> 0 | V22: =Y21*(1+F$7) -> 79313.53 | W22: =MIN(V22,F$8) -> 7500 | X22: =MAX(0,MIN(V22-W22,$C22-(P22+T22))) -> 2220.1538 | Y22: =ROUND(V22-W22-X22,2) -> 69593.38 | Z22: =AC21*(1+G$7) -> 18000 | AA22: =MIN(Z22,G$8) -> 2000 | AB22: =MAX(0,MIN(Z22-AA22,$C22-(P22+T22+X22))) -> 0 | AC22: =ROUND(Z22-AA22-AB22,2) -> 16000 | AD22: =AG21*(1+H$7) -> 0 | AE22: =MIN(AD22,H$8) -> 0 | AF22: =MAX(0,MIN(AD22-AE22,$C22-(P22+T22+X22+AB22))) -> 0 | AG22: =ROUND(AD22-AE22-AF22,2) -> 0 | AH22: =AK21*(1+I$7) -> 0 | AI22: =MIN(AH22,I$8) -> 0 | AJ22: =MAX(0,MIN(AH22-AI22,$C22-(P22+T22+X22+AB22+AF22))) -> 0 | AK22: =ROUND(AH22-AI22-AJ22,2) -> 0 | AL22: =AO21*(1+J$7) -> 0 | AM22: =MIN(AL22,J$8) -> 0 | AN22: =MAX(0,MIN(AL22-AM22,$C22-(P22+T22+X22+AB22+AF22+AJ22))) -> 0 | AO22: =ROUND(AL22-AM22-AN22,2) -> 0 | AP22: =AS21*(1+K$7) -> 0 | AQ22: =MIN(AP22,K$8) -> 0 | AR22: =MAX(0,MIN(AP22-AQ22,$C22-(P22+T22+X22+AB22+AF22+AJ22+AN22))) -> 0 | AS22: =ROUND(AP22-AQ22-AR22,2) -> 0 | AT22: =AW21*(1+L$7) -> 0 | AU22: =MIN(AT22,L$8) -> 0 | AV22: =MAX(0,MIN(AT22-AU22,$C22-(P22+T22+X22+AB22+AF22+AJ22+AN22+AR22))) -> 0 | AW22: =ROUND(AT22-AU22-AV22,2) -> 0 | AX22: =BA21*(1+M$7) -> 0 | AY22: =MIN(AX22,M$8) -> 0 | AZ22: =MAX(0,MIN(AX22-AY22,$C22-(P22+T22+X22+AB22+AF22+AJ22+AN22+AR22+AV22))) -> 0 | BA22: =ROUND(AX22-AY22-AZ22,2) -> 0
A23: 13 | B23: =EDATE(Borçlar!$K$7,12) -> 46661 | C23: =MAX(0,Borçlar!$K$8-(O23+S23+W23+AA23+AE23+AI23+AM23+AQ23+AU23+AY23)) -> 9500 | D23: =O23+P23+S23+T23+W23+X23+AA23+AB23+AE23+AF23+AI23+AJ23+AM23+AN23+AQ23+AR23+AU23+AV23+AY23+AZ23 -> 19000 | E23: =(N23+R23+V23+Z23+AD23+AH23+AL23+AP23+AT23+AX23)-(F22) -> 2435.7683 | F23: =Q23+U23+Y23+AC23+AG23+AK23+AO23+AS23+AW23+BA23 -> 69029.15 | N23: =Q22*(1+D$7) -> 0 | O23: =MIN(N23,D$8) -> 0 | P23: =MAX(0,MIN(N23-O23,$C23-(0))) -> 0 | Q23: =ROUND(N23-O23-P23,2) -> 0 | R23: =U22*(1+E$7) -> 0 | S23: =MIN(R23,E$8) -> 0 | T23: =MAX(0,MIN(R23-S23,$C23-(P23))) -> 0 | U23: =ROUND(R23-S23-T23,2) -> 0 | V23: =Y22*(1+F$7) -> 72029.148 | W23: =MIN(V23,F$8) -> 7500 | X23: =MAX(0,MIN(V23-W23,$C23-(P23+T23))) -> 9500 | Y23: =ROUND(V23-W23-X23,2) -> 55029.15 | Z23: =AC22*(1+G$7) -> 16000 | AA23: =MIN(Z23,G$8) -> 2000 | AB23: =MAX(0,MIN(Z23-AA23,$C23-(P23+T23+X23))) -> 0 | AC23: =ROUND(Z23-AA23-AB23,2) -> 14000 | AD23: =AG22*(1+H$7) -> 0 | AE23: =MIN(AD23,H$8) -> 0 | AF23: =MAX(0,MIN(AD23-AE23,$C23-(P23+T23+X23+AB23))) -> 0 | AG23: =ROUND(AD23-AE23-AF23,2) -> 0 | AH23: =AK22*(1+I$7) -> 0 | AI23: =MIN(AH23,I$8) -> 0 | AJ23: =MAX(0,MIN(AH23-AI23,$C23-(P23+T23+X23+AB23+AF23))) -> 0 | AK23: =ROUND(AH23-AI23-AJ23,2) -> 0 | AL23: =AO22*(1+J$7) -> 0 | AM23: =MIN(AL23,J$8) -> 0 | AN23: =MAX(0,MIN(AL23-AM23,$C23-(P23+T23+X23+AB23+AF23+AJ23))) -> 0 | AO23: =ROUND(AL23-AM23-AN23,2) -> 0 | AP23: =AS22*(1+K$7) -> 0 | AQ23: =MIN(AP23,K$8) -> 0 | AR23: =MAX(0,MIN(AP23-AQ23,$C23-(P23+T23+X23+AB23+AF23+AJ23+AN23))) -> 0 | AS23: =ROUND(AP23-AQ23-AR23,2) -> 0 | AT23: =AW22*(1+L$7) -> 0 | AU23: =MIN(AT23,L$8) -> 0 | AV23: =MAX(0,MIN(AT23-AU23,$C23-(P23+T23+X23+AB23+AF23+AJ23+AN23+AR23))) -> 0 | AW23: =ROUND(AT23-AU23-AV23,2) -> 0 | AX23: =BA22*(1+M$7) -> 0 | AY23: =MIN(AX23,M$8) -> 0 | AZ23: =MAX(0,MIN(AX23-AY23,$C23-(P23+T23+X23+AB23+AF23+AJ23+AN23+AR23+AV23))) -> 0 | BA23: =ROUND(AX23-AY23-AZ23,2) -> 0
A24: 14 | B24: =EDATE(Borçlar!$K$7,13) -> 46692 | C24: =MAX(0,Borçlar!$K$8-(O24+S24+W24+AA24+AE24+AI24+AM24+AQ24+AU24+AY24)) -> 9500 | D24: =O24+P24+S24+T24+W24+X24+AA24+AB24+AE24+AF24+AI24+AJ24+AM24+AN24+AQ24+AR24+AU24+AV24+AY24+AZ24 -> 19000 | E24: =(N24+R24+V24+Z24+AD24+AH24+AL24+AP24+AT24+AX24)-(F23) -> 1926.0203 | F24: =Q24+U24+Y24+AC24+AG24+AK24+AO24+AS24+AW24+BA24 -> 51955.17 | N24: =Q23*(1+D$7) -> 0 | O24: =MIN(N24,D$8) -> 0 | P24: =MAX(0,MIN(N24-O24,$C24-(0))) -> 0 | Q24: =ROUND(N24-O24-P24,2) -> 0 | R24: =U23*(1+E$7) -> 0 | S24: =MIN(R24,E$8) -> 0 | T24: =MAX(0,MIN(R24-S24,$C24-(P24))) -> 0 | U24: =ROUND(R24-S24-T24,2) -> 0 | V24: =Y23*(1+F$7) -> 56955.17 | W24: =MIN(V24,F$8) -> 7500 | X24: =MAX(0,MIN(V24-W24,$C24-(P24+T24))) -> 9500 | Y24: =ROUND(V24-W24-X24,2) -> 39955.17 | Z24: =AC23*(1+G$7) -> 14000 | AA24: =MIN(Z24,G$8) -> 2000 | AB24: =MAX(0,MIN(Z24-AA24,$C24-(P24+T24+X24))) -> 0 | AC24: =ROUND(Z24-AA24-AB24,2) -> 12000 | AD24: =AG23*(1+H$7) -> 0 | AE24: =MIN(AD24,H$8) -> 0 | AF24: =MAX(0,MIN(AD24-AE24,$C24-(P24+T24+X24+AB24))) -> 0 | AG24: =ROUND(AD24-AE24-AF24,2) -> 0 | AH24: =AK23*(1+I$7) -> 0 | AI24: =MIN(AH24,I$8) -> 0 | AJ24: =MAX(0,MIN(AH24-AI24,$C24-(P24+T24+X24+AB24+AF24))) -> 0 | AK24: =ROUND(AH24-AI24-AJ24,2) -> 0 | AL24: =AO23*(1+J$7) -> 0 | AM24: =MIN(AL24,J$8) -> 0 | AN24: =MAX(0,MIN(AL24-AM24,$C24-(P24+T24+X24+AB24+AF24+AJ24))) -> 0 | AO24: =ROUND(AL24-AM24-AN24,2) -> 0 | AP24: =AS23*(1+K$7) -> 0 | AQ24: =MIN(AP24,K$8) -> 0 | AR24: =MAX(0,MIN(AP24-AQ24,$C24-(P24+T24+X24+AB24+AF24+AJ24+AN24))) -> 0 | AS24: =ROUND(AP24-AQ24-AR24,2) -> 0 | AT24: =AW23*(1+L$7) -> 0 | AU24: =MIN(AT24,L$8) -> 0 | AV24: =MAX(0,MIN(AT24-AU24,$C24-(P24+T24+X24+AB24+AF24+AJ24+AN24+AR24))) -> 0 | AW24: =ROUND(AT24-AU24-AV24,2) -> 0 | AX24: =BA23*(1+M$7) -> 0 | AY24: =MIN(AX24,M$8) -> 0 | AZ24: =MAX(0,MIN(AX24-AY24,$C24-(P24+T24+X24+AB24+AF24+AJ24+AN24+AR24+AV24))) -> 0 | BA24: =ROUND(AX24-AY24-AZ24,2) -> 0
A25: 15 | B25: =EDATE(Borçlar!$K$7,14) -> 46722 | C25: =MAX(0,Borçlar!$K$8-(O25+S25+W25+AA25+AE25+AI25+AM25+AQ25+AU25+AY25)) -> 9500 | D25: =O25+P25+S25+T25+W25+X25+AA25+AB25+AE25+AF25+AI25+AJ25+AM25+AN25+AQ25+AR25+AU25+AV25+AY25+AZ25 -> 19000 | E25: =(N25+R25+V25+Z25+AD25+AH25+AL25+AP25+AT25+AX25)-(F24) -> 1398.4309 | F25: =Q25+U25+Y25+AC25+AG25+AK25+AO25+AS25+AW25+BA25 -> 34353.6 | N25: =Q24*(1+D$7) -> 0 | O25: =MIN(N25,D$8) -> 0 | P25: =MAX(0,MIN(N25-O25,$C25-(0))) -> 0 | Q25: =ROUND(N25-O25-P25,2) -> 0 | R25: =U24*(1+E$7) -> 0 | S25: =MIN(R25,E$8) -> 0 | T25: =MAX(0,MIN(R25-S25,$C25-(P25))) -> 0 | U25: =ROUND(R25-S25-T25,2) -> 0 | V25: =Y24*(1+F$7) -> 41353.601 | W25: =MIN(V25,F$8) -> 7500 | X25: =MAX(0,MIN(V25-W25,$C25-(P25+T25))) -> 9500 | Y25: =ROUND(V25-W25-X25,2) -> 24353.6 | Z25: =AC24*(1+G$7) -> 12000 | AA25: =MIN(Z25,G$8) -> 2000 | AB25: =MAX(0,MIN(Z25-AA25,$C25-(P25+T25+X25))) -> 0 | AC25: =ROUND(Z25-AA25-AB25,2) -> 10000 | AD25: =AG24*(1+H$7) -> 0 | AE25: =MIN(AD25,H$8) -> 0 | AF25: =MAX(0,MIN(AD25-AE25,$C25-(P25+T25+X25+AB25))) -> 0 | AG25: =ROUND(AD25-AE25-AF25,2) -> 0 | AH25: =AK24*(1+I$7) -> 0 | AI25: =MIN(AH25,I$8) -> 0 | AJ25: =MAX(0,MIN(AH25-AI25,$C25-(P25+T25+X25+AB25+AF25))) -> 0 | AK25: =ROUND(AH25-AI25-AJ25,2) -> 0 | AL25: =AO24*(1+J$7) -> 0 | AM25: =MIN(AL25,J$8) -> 0 | AN25: =MAX(0,MIN(AL25-AM25,$C25-(P25+T25+X25+AB25+AF25+AJ25))) -> 0 | AO25: =ROUND(AL25-AM25-AN25,2) -> 0 | AP25: =AS24*(1+K$7) -> 0 | AQ25: =MIN(AP25,K$8) -> 0 | AR25: =MAX(0,MIN(AP25-AQ25,$C25-(P25+T25+X25+AB25+AF25+AJ25+AN25))) -> 0 | AS25: =ROUND(AP25-AQ25-AR25,2) -> 0 | AT25: =AW24*(1+L$7) -> 0 | AU25: =MIN(AT25,L$8) -> 0 | AV25: =MAX(0,MIN(AT25-AU25,$C25-(P25+T25+X25+AB25+AF25+AJ25+AN25+AR25))) -> 0 | AW25: =ROUND(AT25-AU25-AV25,2) -> 0 | AX25: =BA24*(1+M$7) -> 0 | AY25: =MIN(AX25,M$8) -> 0 | AZ25: =MAX(0,MIN(AX25-AY25,$C25-(P25+T25+X25+AB25+AF25+AJ25+AN25+AR25+AV25))) -> 0 | BA25: =ROUND(AX25-AY25-AZ25,2) -> 0
A26: 16 | B26: =EDATE(Borçlar!$K$7,15) -> 46753 | C26: =MAX(0,Borçlar!$K$8-(O26+S26+W26+AA26+AE26+AI26+AM26+AQ26+AU26+AY26)) -> 9500 | D26: =O26+P26+S26+T26+W26+X26+AA26+AB26+AE26+AF26+AI26+AJ26+AM26+AN26+AQ26+AR26+AU26+AV26+AY26+AZ26 -> 19000 | E26: =(N26+R26+V26+Z26+AD26+AH26+AL26+AP26+AT26+AX26)-(F25) -> 852.376 | F26: =Q26+U26+Y26+AC26+AG26+AK26+AO26+AS26+AW26+BA26 -> 16205.98 | N26: =Q25*(1+D$7) -> 0 | O26: =MIN(N26,D$8) -> 0 | P26: =MAX(0,MIN(N26-O26,$C26-(0))) -> 0 | Q26: =ROUND(N26-O26-P26,2) -> 0 | R26: =U25*(1+E$7) -> 0 | S26: =MIN(R26,E$8) -> 0 | T26: =MAX(0,MIN(R26-S26,$C26-(P26))) -> 0 | U26: =ROUND(R26-S26-T26,2) -> 0 | V26: =Y25*(1+F$7) -> 25205.976 | W26: =MIN(V26,F$8) -> 7500 | X26: =MAX(0,MIN(V26-W26,$C26-(P26+T26))) -> 9500 | Y26: =ROUND(V26-W26-X26,2) -> 8205.98 | Z26: =AC25*(1+G$7) -> 10000 | AA26: =MIN(Z26,G$8) -> 2000 | AB26: =MAX(0,MIN(Z26-AA26,$C26-(P26+T26+X26))) -> 0 | AC26: =ROUND(Z26-AA26-AB26,2) -> 8000 | AD26: =AG25*(1+H$7) -> 0 | AE26: =MIN(AD26,H$8) -> 0 | AF26: =MAX(0,MIN(AD26-AE26,$C26-(P26+T26+X26+AB26))) -> 0 | AG26: =ROUND(AD26-AE26-AF26,2) -> 0 | AH26: =AK25*(1+I$7) -> 0 | AI26: =MIN(AH26,I$8) -> 0 | AJ26: =MAX(0,MIN(AH26-AI26,$C26-(P26+T26+X26+AB26+AF26))) -> 0 | AK26: =ROUND(AH26-AI26-AJ26,2) -> 0 | AL26: =AO25*(1+J$7) -> 0 | AM26: =MIN(AL26,J$8) -> 0 | AN26: =MAX(0,MIN(AL26-AM26,$C26-(P26+T26+X26+AB26+AF26+AJ26))) -> 0 | AO26: =ROUND(AL26-AM26-AN26,2) -> 0 | AP26: =AS25*(1+K$7) -> 0 | AQ26: =MIN(AP26,K$8) -> 0 | AR26: =MAX(0,MIN(AP26-AQ26,$C26-(P26+T26+X26+AB26+AF26+AJ26+AN26))) -> 0 | AS26: =ROUND(AP26-AQ26-AR26,2) -> 0 | AT26: =AW25*(1+L$7) -> 0 | AU26: =MIN(AT26,L$8) -> 0 | AV26: =MAX(0,MIN(AT26-AU26,$C26-(P26+T26+X26+AB26+AF26+AJ26+AN26+AR26))) -> 0 | AW26: =ROUND(AT26-AU26-AV26,2) -> 0 | AX26: =BA25*(1+M$7) -> 0 | AY26: =MIN(AX26,M$8) -> 0 | AZ26: =MAX(0,MIN(AX26-AY26,$C26-(P26+T26+X26+AB26+AF26+AJ26+AN26+AR26+AV26))) -> 0 | BA26: =ROUND(AX26-AY26-AZ26,2) -> 0
A27: 17 | B27: =EDATE(Borçlar!$K$7,16) -> 46784 | C27: =MAX(0,Borçlar!$K$8-(O27+S27+W27+AA27+AE27+AI27+AM27+AQ27+AU27+AY27)) -> 9500 | D27: =O27+P27+S27+T27+W27+X27+AA27+AB27+AE27+AF27+AI27+AJ27+AM27+AN27+AQ27+AR27+AU27+AV27+AY27+AZ27 -> 16493.189 | E27: =(N27+R27+V27+Z27+AD27+AH27+AL27+AP27+AT27+AX27)-(F26) -> 287.2093 | F27: =Q27+U27+Y27+AC27+AG27+AK27+AO27+AS27+AW27+BA27 -> 0 | N27: =Q26*(1+D$7) -> 0 | O27: =MIN(N27,D$8) -> 0 | P27: =MAX(0,MIN(N27-O27,$C27-(0))) -> 0 | Q27: =ROUND(N27-O27-P27,2) -> 0 | R27: =U26*(1+E$7) -> 0 | S27: =MIN(R27,E$8) -> 0 | T27: =MAX(0,MIN(R27-S27,$C27-(P27))) -> 0 | U27: =ROUND(R27-S27-T27,2) -> 0 | V27: =Y26*(1+F$7) -> 8493.1893 | W27: =MIN(V27,F$8) -> 7500 | X27: =MAX(0,MIN(V27-W27,$C27-(P27+T27))) -> 993.1893 | Y27: =ROUND(V27-W27-X27,2) -> 0 | Z27: =AC26*(1+G$7) -> 8000 | AA27: =MIN(Z27,G$8) -> 2000 | AB27: =MAX(0,MIN(Z27-AA27,$C27-(P27+T27+X27))) -> 6000 | AC27: =ROUND(Z27-AA27-AB27,2) -> 0 | AD27: =AG26*(1+H$7) -> 0 | AE27: =MIN(AD27,H$8) -> 0 | AF27: =MAX(0,MIN(AD27-AE27,$C27-(P27+T27+X27+AB27))) -> 0 | AG27: =ROUND(AD27-AE27-AF27,2) -> 0 | AH27: =AK26*(1+I$7) -> 0 | AI27: =MIN(AH27,I$8) -> 0 | AJ27: =MAX(0,MIN(AH27-AI27,$C27-(P27+T27+X27+AB27+AF27))) -> 0 | AK27: =ROUND(AH27-AI27-AJ27,2) -> 0 | AL27: =AO26*(1+J$7) -> 0 | AM27: =MIN(AL27,J$8) -> 0 | AN27: =MAX(0,MIN(AL27-AM27,$C27-(P27+T27+X27+AB27+AF27+AJ27))) -> 0 | AO27: =ROUND(AL27-AM27-AN27,2) -> 0 | AP27: =AS26*(1+K$7) -> 0 | AQ27: =MIN(AP27,K$8) -> 0 | AR27: =MAX(0,MIN(AP27-AQ27,$C27-(P27+T27+X27+AB27+AF27+AJ27+AN27))) -> 0 | AS27: =ROUND(AP27-AQ27-AR27,2) -> 0 | AT27: =AW26*(1+L$7) -> 0 | AU27: =MIN(AT27,L$8) -> 0 | AV27: =MAX(0,MIN(AT27-AU27,$C27-(P27+T27+X27+AB27+AF27+AJ27+AN27+AR27))) -> 0 | AW27: =ROUND(AT27-AU27-AV27,2) -> 0 | AX27: =BA26*(1+M$7) -> 0 | AY27: =MIN(AX27,M$8) -> 0 | AZ27: =MAX(0,MIN(AX27-AY27,$C27-(P27+T27+X27+AB27+AF27+AJ27+AN27+AR27+AV27))) -> 0 | BA27: =ROUND(AX27-AY27-AZ27,2) -> 0
A28: 18 | B28: =EDATE(Borçlar!$K$7,17) -> 46813 | C28: =MAX(0,Borçlar!$K$8-(O28+S28+W28+AA28+AE28+AI28+AM28+AQ28+AU28+AY28)) -> 19000 | D28: =O28+P28+S28+T28+W28+X28+AA28+AB28+AE28+AF28+AI28+AJ28+AM28+AN28+AQ28+AR28+AU28+AV28+AY28+AZ28 -> 0 | E28: =(N28+R28+V28+Z28+AD28+AH28+AL28+AP28+AT28+AX28)-(F27) -> 0 | F28: =Q28+U28+Y28+AC28+AG28+AK28+AO28+AS28+AW28+BA28 -> 0 | N28: =Q27*(1+D$7) -> 0 | O28: =MIN(N28,D$8) -> 0 | P28: =MAX(0,MIN(N28-O28,$C28-(0))) -> 0 | Q28: =ROUND(N28-O28-P28,2) -> 0 | R28: =U27*(1+E$7) -> 0 | S28: =MIN(R28,E$8) -> 0 | T28: =MAX(0,MIN(R28-S28,$C28-(P28))) -> 0 | U28: =ROUND(R28-S28-T28,2) -> 0 | V28: =Y27*(1+F$7) -> 0 | W28: =MIN(V28,F$8) -> 0 | X28: =MAX(0,MIN(V28-W28,$C28-(P28+T28))) -> 0 | Y28: =ROUND(V28-W28-X28,2) -> 0 | Z28: =AC27*(1+G$7) -> 0 | AA28: =MIN(Z28,G$8) -> 0 | AB28: =MAX(0,MIN(Z28-AA28,$C28-(P28+T28+X28))) -> 0 | AC28: =ROUND(Z28-AA28-AB28,2) -> 0 | AD28: =AG27*(1+H$7) -> 0 | AE28: =MIN(AD28,H$8) -> 0 | AF28: =MAX(0,MIN(AD28-AE28,$C28-(P28+T28+X28+AB28))) -> 0 | AG28: =ROUND(AD28-AE28-AF28,2) -> 0 | AH28: =AK27*(1+I$7) -> 0 | AI28: =MIN(AH28,I$8) -> 0 | AJ28: =MAX(0,MIN(AH28-AI28,$C28-(P28+T28+X28+AB28+AF28))) -> 0 | AK28: =ROUND(AH28-AI28-AJ28,2) -> 0 | AL28: =AO27*(1+J$7) -> 0 | AM28: =MIN(AL28,J$8) -> 0 | AN28: =MAX(0,MIN(AL28-AM28,$C28-(P28+T28+X28+AB28+AF28+AJ28))) -> 0 | AO28: =ROUND(AL28-AM28-AN28,2) -> 0 | AP28: =AS27*(1+K$7) -> 0 | AQ28: =MIN(AP28,K$8) -> 0 | AR28: =MAX(0,MIN(AP28-AQ28,$C28-(P28+T28+X28+AB28+AF28+AJ28+AN28))) -> 0 | AS28: =ROUND(AP28-AQ28-AR28,2) -> 0 | AT28: =AW27*(1+L$7) -> 0 | AU28: =MIN(AT28,L$8) -> 0 | AV28: =MAX(0,MIN(AT28-AU28,$C28-(P28+T28+X28+AB28+AF28+AJ28+AN28+AR28))) -> 0 | AW28: =ROUND(AT28-AU28-AV28,2) -> 0 | AX28: =BA27*(1+M$7) -> 0 | AY28: =MIN(AX28,M$8) -> 0 | AZ28: =MAX(0,MIN(AX28-AY28,$C28-(P28+T28+X28+AB28+AF28+AJ28+AN28+AR28+AV28))) -> 0 | BA28: =ROUND(AX28-AY28-AZ28,2) -> 0
A29: 19 | B29: =EDATE(Borçlar!$K$7,18) -> 46844 | C29: =MAX(0,Borçlar!$K$8-(O29+S29+W29+AA29+AE29+AI29+AM29+AQ29+AU29+AY29)) -> 19000 | D29: =O29+P29+S29+T29+W29+X29+AA29+AB29+AE29+AF29+AI29+AJ29+AM29+AN29+AQ29+AR29+AU29+AV29+AY29+AZ29 -> 0 | E29: =(N29+R29+V29+Z29+AD29+AH29+AL29+AP29+AT29+AX29)-(F28) -> 0 | F29: =Q29+U29+Y29+AC29+AG29+AK29+AO29+AS29+AW29+BA29 -> 0 | N29: =Q28*(1+D$7) -> 0 | O29: =MIN(N29,D$8) -> 0 | P29: =MAX(0,MIN(N29-O29,$C29-(0))) -> 0 | Q29: =ROUND(N29-O29-P29,2) -> 0 | R29: =U28*(1+E$7) -> 0 | S29: =MIN(R29,E$8) -> 0 | T29: =MAX(0,MIN(R29-S29,$C29-(P29))) -> 0 | U29: =ROUND(R29-S29-T29,2) -> 0 | V29: =Y28*(1+F$7) -> 0 | W29: =MIN(V29,F$8) -> 0 | X29: =MAX(0,MIN(V29-W29,$C29-(P29+T29))) -> 0 | Y29: =ROUND(V29-W29-X29,2) -> 0 | Z29: =AC28*(1+G$7) -> 0 | AA29: =MIN(Z29,G$8) -> 0 | AB29: =MAX(0,MIN(Z29-AA29,$C29-(P29+T29+X29))) -> 0 | AC29: =ROUND(Z29-AA29-AB29,2) -> 0 | AD29: =AG28*(1+H$7) -> 0 | AE29: =MIN(AD29,H$8) -> 0 | AF29: =MAX(0,MIN(AD29-AE29,$C29-(P29+T29+X29+AB29))) -> 0 | AG29: =ROUND(AD29-AE29-AF29,2) -> 0 | AH29: =AK28*(1+I$7) -> 0 | AI29: =MIN(AH29,I$8) -> 0 | AJ29: =MAX(0,MIN(AH29-AI29,$C29-(P29+T29+X29+AB29+AF29))) -> 0 | AK29: =ROUND(AH29-AI29-AJ29,2) -> 0 | AL29: =AO28*(1+J$7) -> 0 | AM29: =MIN(AL29,J$8) -> 0 | AN29: =MAX(0,MIN(AL29-AM29,$C29-(P29+T29+X29+AB29+AF29+AJ29))) -> 0 | AO29: =ROUND(AL29-AM29-AN29,2) -> 0 | AP29: =AS28*(1+K$7) -> 0 | AQ29: =MIN(AP29,K$8) -> 0 | AR29: =MAX(0,MIN(AP29-AQ29,$C29-(P29+T29+X29+AB29+AF29+AJ29+AN29))) -> 0 | AS29: =ROUND(AP29-AQ29-AR29,2) -> 0 | AT29: =AW28*(1+L$7) -> 0 | AU29: =MIN(AT29,L$8) -> 0 | AV29: =MAX(0,MIN(AT29-AU29,$C29-(P29+T29+X29+AB29+AF29+AJ29+AN29+AR29))) -> 0 | AW29: =ROUND(AT29-AU29-AV29,2) -> 0 | AX29: =BA28*(1+M$7) -> 0 | AY29: =MIN(AX29,M$8) -> 0 | AZ29: =MAX(0,MIN(AX29-AY29,$C29-(P29+T29+X29+AB29+AF29+AJ29+AN29+AR29+AV29))) -> 0 | BA29: =ROUND(AX29-AY29-AZ29,2) -> 0
A30: 20 | B30: =EDATE(Borçlar!$K$7,19) -> 46874 | C30: =MAX(0,Borçlar!$K$8-(O30+S30+W30+AA30+AE30+AI30+AM30+AQ30+AU30+AY30)) -> 19000 | D30: =O30+P30+S30+T30+W30+X30+AA30+AB30+AE30+AF30+AI30+AJ30+AM30+AN30+AQ30+AR30+AU30+AV30+AY30+AZ30 -> 0 | E30: =(N30+R30+V30+Z30+AD30+AH30+AL30+AP30+AT30+AX30)-(F29) -> 0 | F30: =Q30+U30+Y30+AC30+AG30+AK30+AO30+AS30+AW30+BA30 -> 0 | N30: =Q29*(1+D$7) -> 0 | O30: =MIN(N30,D$8) -> 0 | P30: =MAX(0,MIN(N30-O30,$C30-(0))) -> 0 | Q30: =ROUND(N30-O30-P30,2) -> 0 | R30: =U29*(1+E$7) -> 0 | S30: =MIN(R30,E$8) -> 0 | T30: =MAX(0,MIN(R30-S30,$C30-(P30))) -> 0 | U30: =ROUND(R30-S30-T30,2) -> 0 | V30: =Y29*(1+F$7) -> 0 | W30: =MIN(V30,F$8) -> 0 | X30: =MAX(0,MIN(V30-W30,$C30-(P30+T30))) -> 0 | Y30: =ROUND(V30-W30-X30,2) -> 0 | Z30: =AC29*(1+G$7) -> 0 | AA30: =MIN(Z30,G$8) -> 0 | AB30: =MAX(0,MIN(Z30-AA30,$C30-(P30+T30+X30))) -> 0 | AC30: =ROUND(Z30-AA30-AB30,2) -> 0 | AD30: =AG29*(1+H$7) -> 0 | AE30: =MIN(AD30,H$8) -> 0 | AF30: =MAX(0,MIN(AD30-AE30,$C30-(P30+T30+X30+AB30))) -> 0 | AG30: =ROUND(AD30-AE30-AF30,2) -> 0 | AH30: =AK29*(1+I$7) -> 0 | AI30: =MIN(AH30,I$8) -> 0 | AJ30: =MAX(0,MIN(AH30-AI30,$C30-(P30+T30+X30+AB30+AF30))) -> 0 | AK30: =ROUND(AH30-AI30-AJ30,2) -> 0 | AL30: =AO29*(1+J$7) -> 0 | AM30: =MIN(AL30,J$8) -> 0 | AN30: =MAX(0,MIN(AL30-AM30,$C30-(P30+T30+X30+AB30+AF30+AJ30))) -> 0 | AO30: =ROUND(AL30-AM30-AN30,2) -> 0 | AP30: =AS29*(1+K$7) -> 0 | AQ30: =MIN(AP30,K$8) -> 0 | AR30: =MAX(0,MIN(AP30-AQ30,$C30-(P30+T30+X30+AB30+AF30+AJ30+AN30))) -> 0 | AS30: =ROUND(AP30-AQ30-AR30,2) -> 0 | AT30: =AW29*(1+L$7) -> 0 | AU30: =MIN(AT30,L$8) -> 0 | AV30: =MAX(0,MIN(AT30-AU30,$C30-(P30+T30+X30+AB30+AF30+AJ30+AN30+AR30))) -> 0 | AW30: =ROUND(AT30-AU30-AV30,2) -> 0 | AX30: =BA29*(1+M$7) -> 0 | AY30: =MIN(AX30,M$8) -> 0 | AZ30: =MAX(0,MIN(AX30-AY30,$C30-(P30+T30+X30+AB30+AF30+AJ30+AN30+AR30+AV30))) -> 0 | BA30: =ROUND(AX30-AY30-AZ30,2) -> 0
A31: 21 | B31: =EDATE(Borçlar!$K$7,20) -> 46905 | C31: =MAX(0,Borçlar!$K$8-(O31+S31+W31+AA31+AE31+AI31+AM31+AQ31+AU31+AY31)) -> 19000 | D31: =O31+P31+S31+T31+W31+X31+AA31+AB31+AE31+AF31+AI31+AJ31+AM31+AN31+AQ31+AR31+AU31+AV31+AY31+AZ31 -> 0 | E31: =(N31+R31+V31+Z31+AD31+AH31+AL31+AP31+AT31+AX31)-(F30) -> 0 | F31: =Q31+U31+Y31+AC31+AG31+AK31+AO31+AS31+AW31+BA31 -> 0 | N31: =Q30*(1+D$7) -> 0 | O31: =MIN(N31,D$8) -> 0 | P31: =MAX(0,MIN(N31-O31,$C31-(0))) -> 0 | Q31: =ROUND(N31-O31-P31,2) -> 0 | R31: =U30*(1+E$7) -> 0 | S31: =MIN(R31,E$8) -> 0 | T31: =MAX(0,MIN(R31-S31,$C31-(P31))) -> 0 | U31: =ROUND(R31-S31-T31,2) -> 0 | V31: =Y30*(1+F$7) -> 0 | W31: =MIN(V31,F$8) -> 0 | X31: =MAX(0,MIN(V31-W31,$C31-(P31+T31))) -> 0 | Y31: =ROUND(V31-W31-X31,2) -> 0 | Z31: =AC30*(1+G$7) -> 0 | AA31: =MIN(Z31,G$8) -> 0 | AB31: =MAX(0,MIN(Z31-AA31,$C31-(P31+T31+X31))) -> 0 | AC31: =ROUND(Z31-AA31-AB31,2) -> 0 | AD31: =AG30*(1+H$7) -> 0 | AE31: =MIN(AD31,H$8) -> 0 | AF31: =MAX(0,MIN(AD31-AE31,$C31-(P31+T31+X31+AB31))) -> 0 | AG31: =ROUND(AD31-AE31-AF31,2) -> 0 | AH31: =AK30*(1+I$7) -> 0 | AI31: =MIN(AH31,I$8) -> 0 | AJ31: =MAX(0,MIN(AH31-AI31,$C31-(P31+T31+X31+AB31+AF31))) -> 0 | AK31: =ROUND(AH31-AI31-AJ31,2) -> 0 | AL31: =AO30*(1+J$7) -> 0 | AM31: =MIN(AL31,J$8) -> 0 | AN31: =MAX(0,MIN(AL31-AM31,$C31-(P31+T31+X31+AB31+AF31+AJ31))) -> 0 | AO31: =ROUND(AL31-AM31-AN31,2) -> 0 | AP31: =AS30*(1+K$7) -> 0 | AQ31: =MIN(AP31,K$8) -> 0 | AR31: =MAX(0,MIN(AP31-AQ31,$C31-(P31+T31+X31+AB31+AF31+AJ31+AN31))) -> 0 | AS31: =ROUND(AP31-AQ31-AR31,2) -> 0 | AT31: =AW30*(1+L$7) -> 0 | AU31: =MIN(AT31,L$8) -> 0 | AV31: =MAX(0,MIN(AT31-AU31,$C31-(P31+T31+X31+AB31+AF31+AJ31+AN31+AR31))) -> 0 | AW31: =ROUND(AT31-AU31-AV31,2) -> 0 | AX31: =BA30*(1+M$7) -> 0 | AY31: =MIN(AX31,M$8) -> 0 | AZ31: =MAX(0,MIN(AX31-AY31,$C31-(P31+T31+X31+AB31+AF31+AJ31+AN31+AR31+AV31))) -> 0 | BA31: =ROUND(AX31-AY31-AZ31,2) -> 0
A32: 22 | B32: =EDATE(Borçlar!$K$7,21) -> 46935 | C32: =MAX(0,Borçlar!$K$8-(O32+S32+W32+AA32+AE32+AI32+AM32+AQ32+AU32+AY32)) -> 19000 | D32: =O32+P32+S32+T32+W32+X32+AA32+AB32+AE32+AF32+AI32+AJ32+AM32+AN32+AQ32+AR32+AU32+AV32+AY32+AZ32 -> 0 | E32: =(N32+R32+V32+Z32+AD32+AH32+AL32+AP32+AT32+AX32)-(F31) -> 0 | F32: =Q32+U32+Y32+AC32+AG32+AK32+AO32+AS32+AW32+BA32 -> 0 | N32: =Q31*(1+D$7) -> 0 | O32: =MIN(N32,D$8) -> 0 | P32: =MAX(0,MIN(N32-O32,$C32-(0))) -> 0 | Q32: =ROUND(N32-O32-P32,2) -> 0 | R32: =U31*(1+E$7) -> 0 | S32: =MIN(R32,E$8) -> 0 | T32: =MAX(0,MIN(R32-S32,$C32-(P32))) -> 0 | U32: =ROUND(R32-S32-T32,2) -> 0 | V32: =Y31*(1+F$7) -> 0 | W32: =MIN(V32,F$8) -> 0 | X32: =MAX(0,MIN(V32-W32,$C32-(P32+T32))) -> 0 | Y32: =ROUND(V32-W32-X32,2) -> 0 | Z32: =AC31*(1+G$7) -> 0 | AA32: =MIN(Z32,G$8) -> 0 | AB32: =MAX(0,MIN(Z32-AA32,$C32-(P32+T32+X32))) -> 0 | AC32: =ROUND(Z32-AA32-AB32,2) -> 0 | AD32: =AG31*(1+H$7) -> 0 | AE32: =MIN(AD32,H$8) -> 0 | AF32: =MAX(0,MIN(AD32-AE32,$C32-(P32+T32+X32+AB32))) -> 0 | AG32: =ROUND(AD32-AE32-AF32,2) -> 0 | AH32: =AK31*(1+I$7) -> 0 | AI32: =MIN(AH32,I$8) -> 0 | AJ32: =MAX(0,MIN(AH32-AI32,$C32-(P32+T32+X32+AB32+AF32))) -> 0 | AK32: =ROUND(AH32-AI32-AJ32,2) -> 0 | AL32: =AO31*(1+J$7) -> 0 | AM32: =MIN(AL32,J$8) -> 0 | AN32: =MAX(0,MIN(AL32-AM32,$C32-(P32+T32+X32+AB32+AF32+AJ32))) -> 0 | AO32: =ROUND(AL32-AM32-AN32,2) -> 0 | AP32: =AS31*(1+K$7) -> 0 | AQ32: =MIN(AP32,K$8) -> 0 | AR32: =MAX(0,MIN(AP32-AQ32,$C32-(P32+T32+X32+AB32+AF32+AJ32+AN32))) -> 0 | AS32: =ROUND(AP32-AQ32-AR32,2) -> 0 | AT32: =AW31*(1+L$7) -> 0 | AU32: =MIN(AT32,L$8) -> 0 | AV32: =MAX(0,MIN(AT32-AU32,$C32-(P32+T32+X32+AB32+AF32+AJ32+AN32+AR32))) -> 0 | AW32: =ROUND(AT32-AU32-AV32,2) -> 0 | AX32: =BA31*(1+M$7) -> 0 | AY32: =MIN(AX32,M$8) -> 0 | AZ32: =MAX(0,MIN(AX32-AY32,$C32-(P32+T32+X32+AB32+AF32+AJ32+AN32+AR32+AV32))) -> 0 | BA32: =ROUND(AX32-AY32-AZ32,2) -> 0
A33: 23 | B33: =EDATE(Borçlar!$K$7,22) -> 46966 | C33: =MAX(0,Borçlar!$K$8-(O33+S33+W33+AA33+AE33+AI33+AM33+AQ33+AU33+AY33)) -> 19000 | D33: =O33+P33+S33+T33+W33+X33+AA33+AB33+AE33+AF33+AI33+AJ33+AM33+AN33+AQ33+AR33+AU33+AV33+AY33+AZ33 -> 0 | E33: =(N33+R33+V33+Z33+AD33+AH33+AL33+AP33+AT33+AX33)-(F32) -> 0 | F33: =Q33+U33+Y33+AC33+AG33+AK33+AO33+AS33+AW33+BA33 -> 0 | N33: =Q32*(1+D$7) -> 0 | O33: =MIN(N33,D$8) -> 0 | P33: =MAX(0,MIN(N33-O33,$C33-(0))) -> 0 | Q33: =ROUND(N33-O33-P33,2) -> 0 | R33: =U32*(1+E$7) -> 0 | S33: =MIN(R33,E$8) -> 0 | T33: =MAX(0,MIN(R33-S33,$C33-(P33))) -> 0 | U33: =ROUND(R33-S33-T33,2) -> 0 | V33: =Y32*(1+F$7) -> 0 | W33: =MIN(V33,F$8) -> 0 | X33: =MAX(0,MIN(V33-W33,$C33-(P33+T33))) -> 0 | Y33: =ROUND(V33-W33-X33,2) -> 0 | Z33: =AC32*(1+G$7) -> 0 | AA33: =MIN(Z33,G$8) -> 0 | AB33: =MAX(0,MIN(Z33-AA33,$C33-(P33+T33+X33))) -> 0 | AC33: =ROUND(Z33-AA33-AB33,2) -> 0 | AD33: =AG32*(1+H$7) -> 0 | AE33: =MIN(AD33,H$8) -> 0 | AF33: =MAX(0,MIN(AD33-AE33,$C33-(P33+T33+X33+AB33))) -> 0 | AG33: =ROUND(AD33-AE33-AF33,2) -> 0 | AH33: =AK32*(1+I$7) -> 0 | AI33: =MIN(AH33,I$8) -> 0 | AJ33: =MAX(0,MIN(AH33-AI33,$C33-(P33+T33+X33+AB33+AF33))) -> 0 | AK33: =ROUND(AH33-AI33-AJ33,2) -> 0 | AL33: =AO32*(1+J$7) -> 0 | AM33: =MIN(AL33,J$8) -> 0 | AN33: =MAX(0,MIN(AL33-AM33,$C33-(P33+T33+X33+AB33+AF33+AJ33))) -> 0 | AO33: =ROUND(AL33-AM33-AN33,2) -> 0 | AP33: =AS32*(1+K$7) -> 0 | AQ33: =MIN(AP33,K$8) -> 0 | AR33: =MAX(0,MIN(AP33-AQ33,$C33-(P33+T33+X33+AB33+AF33+AJ33+AN33))) -> 0 | AS33: =ROUND(AP33-AQ33-AR33,2) -> 0 | AT33: =AW32*(1+L$7) -> 0 | AU33: =MIN(AT33,L$8) -> 0 | AV33: =MAX(0,MIN(AT33-AU33,$C33-(P33+T33+X33+AB33+AF33+AJ33+AN33+AR33))) -> 0 | AW33: =ROUND(AT33-AU33-AV33,2) -> 0 | AX33: =BA32*(1+M$7) -> 0 | AY33: =MIN(AX33,M$8) -> 0 | AZ33: =MAX(0,MIN(AX33-AY33,$C33-(P33+T33+X33+AB33+AF33+AJ33+AN33+AR33+AV33))) -> 0 | BA33: =ROUND(AX33-AY33-AZ33,2) -> 0
