Workbook

Sheet Başla
B2: EXCEL KLİNİĞİ
B3: RANDEVU | Randevu defteri
B4: Kuaför, usta, danışman ve klinik için: kim, ne zaman, hangi hizmet, geldi mi, ne kazandırdı.
B6: NASIL KULLANILIR
B7: 1. Hizmetler | C7: Hizmetlerini, kaç dakika sürdüğünü ve ücretini yaz.
B8: 2. Müşteriler | C8: Müşterilerini yaz. Randevu girerken açılır listeden seçersin.
B9: 3. Randevular | C9: Tarih, saat, müşteri ve hizmeti gir. Bitiş saati hizmet süresinden hesaplanır. Aynı saate iki randevu yazarsan Çakışıyor uyarısı çıkar.
B10: 4. Gün | C10: Tarihi yaz, o günün programını saat sırasıyla gör ya da yazdır.
B11: 5. Özet | C11: Aylık randevu, gelen, gelmeyen ve ciro; en çok yapılan hizmetler ve en çok harcayan müşteriler.
B13: BİLMEN GEREKENLER
B14: Ciro | C14: Yalnızca durumu Geldi olan randevular ciroya girer. Özel ücret yazmazsan hizmetin liste ücreti kullanılır.
B15: Çakışma | C15: Tek kişinin çalıştığı varsayılır. Birden fazla çalışan varsa her çalışan için ayrı dosya kullan.
B16: Kapasite | C16: 1000 randevu, 300 müşteri, 50 hizmet. Gün sayfası bir günde en çok 30 randevu gösterir.
B18: RENKLER
B19: Sarı hücre | C19: Senin dolduracağın hücre. İçindeki örnekleri silip kendi bilgini yaz.
B20: Beyaz hücre, açık başlık | C20: Formül. Değiştirme, kendiliğinden hesaplanır.

Sheet Randevular
A1: Randevular
A2: Her randevu bir satır. Müşteri gelince Durum sütununu Geldi yap; ciro yalnızca Geldi olanlardan hesaplanır.
A4: Tarih | B4: Saat | C4: Müşteri | D4: Hizmet | E4: Durum | F4: Özel ücret (₺) isteğe bağlı | G4: Tutar (₺) | H4: Bitiş | I4: Çakışma | J4: y
A5: 46300 | B5: 0.41666667 | C5: Müşteri Alfa | D5: Saç kesimi | E5: Geldi | G5: =IF(D5="","",IF(E5="Geldi",IF(F5="",IFERROR(INDEX(Hizmetler!$C$5:$C$54,MATCH(D5,Hizmetler!$A$5:$A$54,0)),0),F5),0)) -> 600 | H5: =IF(OR(B5="",D5=""),"",ROUND((B5+IFERROR(INDEX(Hizmetler!$B$5:$B$54,MATCH(D5,Hizmetler!$A$5:$A$54,0)),0)/1440)*1440,0)/1440) -> 0.4375 | I5: =IF(OR(A5="",H5="",E5="İptal"),"",IF(COUNTIFS($A$5:$A$1004,A5,$B$5:$B$1004,"<"&(H5-0.0003),$H$5:$H$1004,">"&(B5+0.0003),$E$5:$E$1004,"<>İptal")>1,"Çakışıyor","")) | J5: =IF(AND(A5=Gün!$C$3,B5<>"",E5<>"İptal"),B5+ROW()/100000000,"") -> 0.41666672
A6: 46300 | B6: 0.4375 | C6: Müşteri Delta | D6: Fön | E6: Geldi | G6: =IF(D6="","",IF(E6="Geldi",IF(F6="",IFERROR(INDEX(Hizmetler!$C$5:$C$54,MATCH(D6,Hizmetler!$A$5:$A$54,0)),0),F6),0)) -> 400 | H6: =IF(OR(B6="",D6=""),"",ROUND((B6+IFERROR(INDEX(Hizmetler!$B$5:$B$54,MATCH(D6,Hizmetler!$A$5:$A$54,0)),0)/1440)*1440,0)/1440) -> 0.45833333 | I6: =IF(OR(A6="",H6="",E6="İptal"),"",IF(COUNTIFS($A$5:$A$1004,A6,$B$5:$B$1004,"<"&(H6-0.0003),$H$5:$H$1004,">"&(B6+0.0003),$E$5:$E$1004,"<>İptal")>1,"Çakışıyor","")) | J6: =IF(AND(A6=Gün!$C$3,B6<>"",E6<>"İptal"),B6+ROW()/100000000,"") -> 0.43750006
A7: 46300 | B7: 0.45833333 | C7: Müşteri Beta | D7: Boya | E7: Geldi | F7: 2200 | G7: =IF(D7="","",IF(E7="Geldi",IF(F7="",IFERROR(INDEX(Hizmetler!$C$5:$C$54,MATCH(D7,Hizmetler!$A$5:$A$54,0)),0),F7),0)) -> 2200 | H7: =IF(OR(B7="",D7=""),"",ROUND((B7+IFERROR(INDEX(Hizmetler!$B$5:$B$54,MATCH(D7,Hizmetler!$A$5:$A$54,0)),0)/1440)*1440,0)/1440) -> 0.52083333 | I7: =IF(OR(A7="",H7="",E7="İptal"),"",IF(COUNTIFS($A$5:$A$1004,A7,$B$5:$B$1004,"<"&(H7-0.0003),$H$5:$H$1004,">"&(B7+0.0003),$E$5:$E$1004,"<>İptal")>1,"Çakışıyor","")) | J7: =IF(AND(A7=Gün!$C$3,B7<>"",E7<>"İptal"),B7+ROW()/100000000,"") -> 0.4583334
A8: 46300 | B8: 0.52083333 | C8: Müşteri Gama | D8: Saç kesimi | E8: Gelmedi | G8: =IF(D8="","",IF(E8="Geldi",IF(F8="",IFERROR(INDEX(Hizmetler!$C$5:$C$54,MATCH(D8,Hizmetler!$A$5:$A$54,0)),0),F8),0)) -> 0 | H8: =IF(OR(B8="",D8=""),"",ROUND((B8+IFERROR(INDEX(Hizmetler!$B$5:$B$54,MATCH(D8,Hizmetler!$A$5:$A$54,0)),0)/1440)*1440,0)/1440) -> 0.54166667 | I8: =IF(OR(A8="",H8="",E8="İptal"),"",IF(COUNTIFS($A$5:$A$1004,A8,$B$5:$B$1004,"<"&(H8-0.0003),$H$5:$H$1004,">"&(B8+0.0003),$E$5:$E$1004,"<>İptal")>1,"Çakışıyor","")) | J8: =IF(AND(A8=Gün!$C$3,B8<>"",E8<>"İptal"),B8+ROW()/100000000,"") -> 0.52083341
A9: 46301 | B9: 0.58333333 | C9: Müşteri Alfa | D9: Boya | E9: Bekliyor | G9: =IF(D9="","",IF(E9="Geldi",IF(F9="",IFERROR(INDEX(Hizmetler!$C$5:$C$54,MATCH(D9,Hizmetler!$A$5:$A$54,0)),0),F9),0)) -> 0 | H9: =IF(OR(B9="",D9=""),"",ROUND((B9+IFERROR(INDEX(Hizmetler!$B$5:$B$54,MATCH(D9,Hizmetler!$A$5:$A$54,0)),0)/1440)*1440,0)/1440) -> 0.64583333 | I9: =IF(OR(A9="",H9="",E9="İptal"),"",IF(COUNTIFS($A$5:$A$1004,A9,$B$5:$B$1004,"<"&(H9-0.0003),$H$5:$H$1004,">"&(B9+0.0003),$E$5:$E$1004,"<>İptal")>1,"Çakışıyor","")) | J9: =IF(AND(A9=Gün!$C$3,B9<>"",E9<>"İptal"),B9+ROW()/100000000,"")
A10: 46301 | B10: 0.64583333 | C10: Müşteri Delta | D10: Saç kesimi | E10: Bekliyor | G10: =IF(D10="","",IF(E10="Geldi",IF(F10="",IFERROR(INDEX(Hizmetler!$C$5:$C$54,MATCH(D10,Hizmetler!$A$5:$A$54,0)),0),F10),0)) -> 0 | H10: =IF(OR(B10="",D10=""),"",ROUND((B10+IFERROR(INDEX(Hizmetler!$B$5:$B$54,MATCH(D10,Hizmetler!$A$5:$A$54,0)),0)/1440)*1440,0)/1440) -> 0.66666667 | I10: =IF(OR(A10="",H10="",E10="İptal"),"",IF(COUNTIFS($A$5:$A$1004,A10,$B$5:$B$1004,"<"&(H10-0.0003),$H$5:$H$1004,">"&(B10+0.0003),$E$5:$E$1004,"<>İptal")>1,"Çakışıyor","")) | J10: =IF(AND(A10=Gün!$C$3,B10<>"",E10<>"İptal"),B10+ROW()/100000000,"")
A11: 46301 | B11: 0.64583333 | C11: Müşteri Beta | D11: Fön | E11: İptal | G11: =IF(D11="","",IF(E11="Geldi",IF(F11="",IFERROR(INDEX(Hizmetler!$C$5:$C$54,MATCH(D11,Hizmetler!$A$5:$A$54,0)),0),F11),0)) -> 0 | H11: =IF(OR(B11="",D11=""),"",ROUND((B11+IFERROR(INDEX(Hizmetler!$B$5:$B$54,MATCH(D11,Hizmetler!$A$5:$A$54,0)),0)/1440)*1440,0)/1440) -> 0.66666667 | I11: =IF(OR(A11="",H11="",E11="İptal"),"",IF(COUNTIFS($A$5:$A$1004,A11,$B$5:$B$1004,"<"&(H11-0.0003),$H$5:$H$1004,">"&(B11+0.0003),$E$5:$E$1004,"<>İptal")>1,"Çakışıyor","")) | J11: =IF(AND(A11=Gün!$C$3,B11<>"",E11<>"İptal"),B11+ROW()/100000000,"")
A12: 46285 | B12: 0.54166667 | C12: Müşteri Gama | D12: Boya | E12: Geldi | G12: =IF(D12="","",IF(E12="Geldi",IF(F12="",IFERROR(INDEX(Hizmetler!$C$5:$C$54,MATCH(D12,Hizmetler!$A$5:$A$54,0)),0),F12),0)) -> 2500 | H12: =IF(OR(B12="",D12=""),"",ROUND((B12+IFERROR(INDEX(Hizmetler!$B$5:$B$54,MATCH(D12,Hizmetler!$A$5:$A$54,0)),0)/1440)*1440,0)/1440) -> 0.60416667 | I12: =IF(OR(A12="",H12="",E12="İptal"),"",IF(COUNTIFS($A$5:$A$1004,A12,$B$5:$B$1004,"<"&(H12-0.0003),$H$5:$H$1004,">"&(B12+0.0003),$E$5:$E$1004,"<>İptal")>1,"Çakışıyor","")) | J12: =IF(AND(A12=Gün!$C$3,B12<>"",E12<>"İptal"),B12+ROW()/100000000,"")
A13: 46287 | B13: 0.66666667 | C13: Müşteri Delta | D13: Saç kesimi | E13: Geldi | G13: =IF(D13="","",IF(E13="Geldi",IF(F13="",IFERROR(INDEX(Hizmetler!$C$5:$C$54,MATCH(D13,Hizmetler!$A$5:$A$54,0)),0),F13),0)) -> 600 | H13: =IF(OR(B13="",D13=""),"",ROUND((B13+IFERROR(INDEX(Hizmetler!$B$5:$B$54,MATCH(D13,Hizmetler!$A$5:$A$54,0)),0)/1440)*1440,0)/1440) -> 0.6875 | I13: =IF(OR(A13="",H13="",E13="İptal"),"",IF(COUNTIFS($A$5:$A$1004,A13,$B$5:$B$1004,"<"&(H13-0.0003),$H$5:$H$1004,">"&(B13+0.0003),$E$5:$E$1004,"<>İptal")>1,"Çakışıyor","")) | J13: =IF(AND(A13=Gün!$C$3,B13<>"",E13<>"İptal"),B13+ROW()/100000000,"")
G14: =IF(D14="","",IF(E14="Geldi",IF(F14="",IFERROR(INDEX(Hizmetler!$C$5:$C$54,MATCH(D14,Hizmetler!$A$5:$A$54,0)),0),F14),0)) | H14: =IF(OR(B14="",D14=""),"",ROUND((B14+IFERROR(INDEX(Hizmetler!$B$5:$B$54,MATCH(D14,Hizmetler!$A$5:$A$54,0)),0)/1440)*1440,0)/1440) | I14: =IF(OR(A14="",H14="",E14="İptal"),"",IF(COUNTIFS($A$5:$A$1004,A14,$B$5:$B$1004,"<"&(H14-0.0003),$H$5:$H$1004,">"&(B14+0.0003),$E$5:$E$1004,"<>İptal")>1,"Çakışıyor","")) | J14: =IF(AND(A14=Gün!$C$3,B14<>"",E14<>"İptal"),B14+ROW()/100000000,"")
G15: =IF(D15="","",IF(E15="Geldi",IF(F15="",IFERROR(INDEX(Hizmetler!$C$5:$C$54,MATCH(D15,Hizmetler!$A$5:$A$54,0)),0),F15),0)) | H15: =IF(OR(B15="",D15=""),"",ROUND((B15+IFERROR(INDEX(Hizmetler!$B$5:$B$54,MATCH(D15,Hizmetler!$A$5:$A$54,0)),0)/1440)*1440,0)/1440) | I15: =IF(OR(A15="",H15="",E15="İptal"),"",IF(COUNTIFS($A$5:$A$1004,A15,$B$5:$B$1004,"<"&(H15-0.0003),$H$5:$H$1004,">"&(B15+0.0003),$E$5:$E$1004,"<>İptal")>1,"Çakışıyor","")) | J15: =IF(AND(A15=Gün!$C$3,B15<>"",E15<>"İptal"),B15+ROW()/100000000,"")
G16: =IF(D16="","",IF(E16="Geldi",IF(F16="",IFERROR(INDEX(Hizmetler!$C$5:$C$54,MATCH(D16,Hizmetler!$A$5:$A$54,0)),0),F16),0)) | H16: =IF(OR(B16="",D16=""),"",ROUND((B16+IFERROR(INDEX(Hizmetler!$B$5:$B$54,MATCH(D16,Hizmetler!$A$5:$A$54,0)),0)/1440)*1440,0)/1440) | I16: =IF(OR(A16="",H16="",E16="İptal"),"",IF(COUNTIFS($A$5:$A$1004,A16,$B$5:$B$1004,"<"&(H16-0.0003),$H$5:$H$1004,">"&(B16+0.0003),$E$5:$E$1004,"<>İptal")>1,"Çakışıyor","")) | J16: =IF(AND(A16=Gün!$C$3,B16<>"",E16<>"İptal"),B16+ROW()/100000000,"")
G17: =IF(D17="","",IF(E17="Geldi",IF(F17="",IFERROR(INDEX(Hizmetler!$C$5:$C$54,MATCH(D17,Hizmetler!$A$5:$A$54,0)),0),F17),0)) | H17: =IF(OR(B17="",D17=""),"",ROUND((B17+IFERROR(INDEX(Hizmetler!$B$5:$B$54,MATCH(D17,Hizmetler!$A$5:$A$54,0)),0)/1440)*1440,0)/1440) | I17: =IF(OR(A17="",H17="",E17="İptal"),"",IF(COUNTIFS($A$5:$A$1004,A17,$B$5:$B$1004,"<"&(H17-0.0003),$H$5:$H$1004,">"&(B17+0.0003),$E$5:$E$1004,"<>İptal")>1,"Çakışıyor","")) | J17: =IF(AND(A17=Gün!$C$3,B17<>"",E17<>"İptal"),B17+ROW()/100000000,"")
G18: =IF(D18="","",IF(E18="Geldi",IF(F18="",IFERROR(INDEX(Hizmetler!$C$5:$C$54,MATCH(D18,Hizmetler!$A$5:$A$54,0)),0),F18),0)) | H18: =IF(OR(B18="",D18=""),"",ROUND((B18+IFERROR(INDEX(Hizmetler!$B$5:$B$54,MATCH(D18,Hizmetler!$A$5:$A$54,0)),0)/1440)*1440,0)/1440) | I18: =IF(OR(A18="",H18="",E18="İptal"),"",IF(COUNTIFS($A$5:$A$1004,A18,$B$5:$B$1004,"<"&(H18-0.0003),$H$5:$H$1004,">"&(B18+0.0003),$E$5:$E$1004,"<>İptal")>1,"Çakışıyor","")) | J18: =IF(AND(A18=Gün!$C$3,B18<>"",E18<>"İptal"),B18+ROW()/100000000,"")
G19: =IF(D19="","",IF(E19="Geldi",IF(F19="",IFERROR(INDEX(Hizmetler!$C$5:$C$54,MATCH(D19,Hizmetler!$A$5:$A$54,0)),0),F19),0)) | H19: =IF(OR(B19="",D19=""),"",ROUND((B19+IFERROR(INDEX(Hizmetler!$B$5:$B$54,MATCH(D19,Hizmetler!$A$5:$A$54,0)),0)/1440)*1440,0)/1440) | I19: =IF(OR(A19="",H19="",E19="İptal"),"",IF(COUNTIFS($A$5:$A$1004,A19,$B$5:$B$1004,"<"&(H19-0.0003),$H$5:$H$1004,">"&(B19+0.0003),$E$5:$E$1004,"<>İptal")>1,"Çakışıyor","")) | J19: =IF(AND(A19=Gün!$C$3,B19<>"",E19<>"İptal"),B19+ROW()/100000000,"")
G20: =IF(D20="","",IF(E20="Geldi",IF(F20="",IFERROR(INDEX(Hizmetler!$C$5:$C$54,MATCH(D20,Hizmetler!$A$5:$A$54,0)),0),F20),0)) | H20: =IF(OR(B20="",D20=""),"",ROUND((B20+IFERROR(INDEX(Hizmetler!$B$5:$B$54,MATCH(D20,Hizmetler!$A$5:$A$54,0)),0)/1440)*1440,0)/1440) | I20: =IF(OR(A20="",H20="",E20="İptal"),"",IF(COUNTIFS($A$5:$A$1004,A20,$B$5:$B$1004,"<"&(H20-0.0003),$H$5:$H$1004,">"&(B20+0.0003),$E$5:$E$1004,"<>İptal")>1,"Çakışıyor","")) | J20: =IF(AND(A20=Gün!$C$3,B20<>"",E20<>"İptal"),B20+ROW()/100000000,"")
G21: =IF(D21="","",IF(E21="Geldi",IF(F21="",IFERROR(INDEX(Hizmetler!$C$5:$C$54,MATCH(D21,Hizmetler!$A$5:$A$54,0)),0),F21),0)) | H21: =IF(OR(B21="",D21=""),"",ROUND((B21+IFERROR(INDEX(Hizmetler!$B$5:$B$54,MATCH(D21,Hizmetler!$A$5:$A$54,0)),0)/1440)*1440,0)/1440) | I21: =IF(OR(A21="",H21="",E21="İptal"),"",IF(COUNTIFS($A$5:$A$1004,A21,$B$5:$B$1004,"<"&(H21-0.0003),$H$5:$H$1004,">"&(B21+0.0003),$E$5:$E$1004,"<>İptal")>1,"Çakışıyor","")) | J21: =IF(AND(A21=Gün!$C$3,B21<>"",E21<>"İptal"),B21+ROW()/100000000,"")
G22: =IF(D22="","",IF(E22="Geldi",IF(F22="",IFERROR(INDEX(Hizmetler!$C$5:$C$54,MATCH(D22,Hizmetler!$A$5:$A$54,0)),0),F22),0)) | H22: =IF(OR(B22="",D22=""),"",ROUND((B22+IFERROR(INDEX(Hizmetler!$B$5:$B$54,MATCH(D22,Hizmetler!$A$5:$A$54,0)),0)/1440)*1440,0)/1440) | I22: =IF(OR(A22="",H22="",E22="İptal"),"",IF(COUNTIFS($A$5:$A$1004,A22,$B$5:$B$1004,"<"&(H22-0.0003),$H$5:$H$1004,">"&(B22+0.0003),$E$5:$E$1004,"<>İptal")>1,"Çakışıyor","")) | J22: =IF(AND(A22=Gün!$C$3,B22<>"",E22<>"İptal"),B22+ROW()/100000000,"")
G23: =IF(D23="","",IF(E23="Geldi",IF(F23="",IFERROR(INDEX(Hizmetler!$C$5:$C$54,MATCH(D23,Hizmetler!$A$5:$A$54,0)),0),F23),0)) | H23: =IF(OR(B23="",D23=""),"",ROUND((B23+IFERROR(INDEX(Hizmetler!$B$5:$B$54,MATCH(D23,Hizmetler!$A$5:$A$54,0)),0)/1440)*1440,0)/1440) | I23: =IF(OR(A23="",H23="",E23="İptal"),"",IF(COUNTIFS($A$5:$A$1004,A23,$B$5:$B$1004,"<"&(H23-0.0003),$H$5:$H$1004,">"&(B23+0.0003),$E$5:$E$1004,"<>İptal")>1,"Çakışıyor","")) | J23: =IF(AND(A23=Gün!$C$3,B23<>"",E23<>"İptal"),B23+ROW()/100000000,"")
G24: =IF(D24="","",IF(E24="Geldi",IF(F24="",IFERROR(INDEX(Hizmetler!$C$5:$C$54,MATCH(D24,Hizmetler!$A$5:$A$54,0)),0),F24),0)) | H24: =IF(OR(B24="",D24=""),"",ROUND((B24+IFERROR(INDEX(Hizmetler!$B$5:$B$54,MATCH(D24,Hizmetler!$A$5:$A$54,0)),0)/1440)*1440,0)/1440) | I24: =IF(OR(A24="",H24="",E24="İptal"),"",IF(COUNTIFS($A$5:$A$1004,A24,$B$5:$B$1004,"<"&(H24-0.0003),$H$5:$H$1004,">"&(B24+0.0003),$E$5:$E$1004,"<>İptal")>1,"Çakışıyor","")) | J24: =IF(AND(A24=Gün!$C$3,B24<>"",E24<>"İptal"),B24+ROW()/100000000,"")
G25: =IF(D25="","",IF(E25="Geldi",IF(F25="",IFERROR(INDEX(Hizmetler!$C$5:$C$54,MATCH(D25,Hizmetler!$A$5:$A$54,0)),0),F25),0)) | H25: =IF(OR(B25="",D25=""),"",ROUND((B25+IFERROR(INDEX(Hizmetler!$B$5:$B$54,MATCH(D25,Hizmetler!$A$5:$A$54,0)),0)/1440)*1440,0)/1440) | I25: =IF(OR(A25="",H25="",E25="İptal"),"",IF(COUNTIFS($A$5:$A$1004,A25,$B$5:$B$1004,"<"&(H25-0.0003),$H$5:$H$1004,">"&(B25+0.0003),$E$5:$E$1004,"<>İptal")>1,"Çakışıyor","")) | J25: =IF(AND(A25=Gün!$C$3,B25<>"",E25<>"İptal"),B25+ROW()/100000000,"")
... G1004: =IF(D1004="","",IF(E1004="Geldi",IF(F1004="",IFERROR(INDEX(Hizmetler!$C$5:$C$54,MATCH(D1004,Hizmetler!$A$5:$A$54,0)),0),F1004),0)) | H1004: =IF(OR(B1004="",D1004=""),"",ROUND((B1004+IFERROR(INDEX(Hizmetler!$B$5:$B$54,MATCH(D1004,Hizmetler!$A$5:$A$54,0)),0)/1440)*1440,0)/1440) | I1004: =IF(OR(A1004="",H1004="",E1004="İptal"),"",IF(COUNTIFS($A$5:$A$1004,A1004,$B$5:$B$1004,"<"&(H1004-0.0003),$H$5:$H$1004,">"&(B1004+0.0003),$E$5:$E$1004,"<>İptal")>1,"Çakışıyor","")) | J1004: =IF(AND(A1004=Gün!$C$3,B1004<>"",E1004<>"İptal"),B1004+ROW()/100000000,"")

Sheet Gün
A1: Günlük Program
A2: Tarihi yaz; o günün randevuları saat sırasıyla listelenir.
B3: Tarih | C3: 46300
E5: Randevu | F5: Beklenen ciro
E6: =COUNT(Randevular!$J$5:$J$1004) -> 4 | F6: =SUM(H10:H39) -> 3200
B9: Saat | C9: Bitiş | D9: Müşteri | E9: Hizmet | F9: Durum | G9: Telefon | H9: ücret
B10: =IFERROR(INDEX(Randevular!$B$5:$B$1004,MATCH(SMALL(Randevular!$J$5:$J$1004,1),Randevular!$J$5:$J$1004,0)),"") -> 0.41666667 | C10: =IF(B10="","",INDEX(Randevular!$H$5:$H$1004,MATCH(SMALL(Randevular!$J$5:$J$1004,1),Randevular!$J$5:$J$1004,0))) -> 0.4375 | D10: =IF(B10="","",INDEX(Randevular!$C$5:$C$1004,MATCH(SMALL(Randevular!$J$5:$J$1004,1),Randevular!$J$5:$J$1004,0))) -> Müşteri Alfa | E10: =IF(B10="","",INDEX(Randevular!$D$5:$D$1004,MATCH(SMALL(Randevular!$J$5:$J$1004,1),Randevular!$J$5:$J$1004,0))) -> Saç kesimi | F10: =IF(B10="","",INDEX(Randevular!$E$5:$E$1004,MATCH(SMALL(Randevular!$J$5:$J$1004,1),Randevular!$J$5:$J$1004,0))) -> Geldi | G10: =IF(D10="","",IFERROR(INDEX(Müşteriler!$B$5:$B$304,MATCH(D10,Müşteriler!$A$5:$A$304,0))&"","")) | H10: =IF(B10="","",IF(F10="Gelmedi",0,IF(INDEX(Randevular!$F$5:$F$1004,MATCH(SMALL(Randevular!$J$5:$J$1004,1),Randevular!$J$5:$J$1004,0))="",IFERROR(INDEX(Hizmetler!$C$5:$C$54,MATCH(E10,Hizmetler!$A$5:$A$54,0)),0),INDEX(Randevular!$F$5:$F$1004,MATCH(SMALL(Randevular!$J$5:$J$1004,1),Randevular!$J$5:$J$1004,0))))) -> 600
B11: =IFERROR(INDEX(Randevular!$B$5:$B$1004,MATCH(SMALL(Randevular!$J$5:$J$1004,2),Randevular!$J$5:$J$1004,0)),"") -> 0.4375 | C11: =IF(B11="","",INDEX(Randevular!$H$5:$H$1004,MATCH(SMALL(Randevular!$J$5:$J$1004,2),Randevular!$J$5:$J$1004,0))) -> 0.45833333 | D11: =IF(B11="","",INDEX(Randevular!$C$5:$C$1004,MATCH(SMALL(Randevular!$J$5:$J$1004,2),Randevular!$J$5:$J$1004,0))) -> Müşteri Delta | E11: =IF(B11="","",INDEX(Randevular!$D$5:$D$1004,MATCH(SMALL(Randevular!$J$5:$J$1004,2),Randevular!$J$5:$J$1004,0))) -> Fön | F11: =IF(B11="","",INDEX(Randevular!$E$5:$E$1004,MATCH(SMALL(Randevular!$J$5:$J$1004,2),Randevular!$J$5:$J$1004,0))) -> Geldi | G11: =IF(D11="","",IFERROR(INDEX(Müşteriler!$B$5:$B$304,MATCH(D11,Müşteriler!$A$5:$A$304,0))&"","")) | H11: =IF(B11="","",IF(F11="Gelmedi",0,IF(INDEX(Randevular!$F$5:$F$1004,MATCH(SMALL(Randevular!$J$5:$J$1004,2),Randevular!$J$5:$J$1004,0))="",IFERROR(INDEX(Hizmetler!$C$5:$C$54,MATCH(E11,Hizmetler!$A$5:$A$54,0)),0),INDEX(Randevular!$F$5:$F$1004,MATCH(SMALL(Randevular!$J$5:$J$1004,2),Randevular!$J$5:$J$1004,0))))) -> 400
B12: =IFERROR(INDEX(Randevular!$B$5:$B$1004,MATCH(SMALL(Randevular!$J$5:$J$1004,3),Randevular!$J$5:$J$1004,0)),"") -> 0.45833333 | C12: =IF(B12="","",INDEX(Randevular!$H$5:$H$1004,MATCH(SMALL(Randevular!$J$5:$J$1004,3),Randevular!$J$5:$J$1004,0))) -> 0.52083333 | D12: =IF(B12="","",INDEX(Randevular!$C$5:$C$1004,MATCH(SMALL(Randevular!$J$5:$J$1004,3),Randevular!$J$5:$J$1004,0))) -> Müşteri Beta | E12: =IF(B12="","",INDEX(Randevular!$D$5:$D$1004,MATCH(SMALL(Randevular!$J$5:$J$1004,3),Randevular!$J$5:$J$1004,0))) -> Boya | F12: =IF(B12="","",INDEX(Randevular!$E$5:$E$1004,MATCH(SMALL(Randevular!$J$5:$J$1004,3),Randevular!$J$5:$J$1004,0))) -> Geldi | G12: =IF(D12="","",IFERROR(INDEX(Müşteriler!$B$5:$B$304,MATCH(D12,Müşteriler!$A$5:$A$304,0))&"","")) | H12: =IF(B12="","",IF(F12="Gelmedi",0,IF(INDEX(Randevular!$F$5:$F$1004,MATCH(SMALL(Randevular!$J$5:$J$1004,3),Randevular!$J$5:$J$1004,0))="",IFERROR(INDEX(Hizmetler!$C$5:$C$54,MATCH(E12,Hizmetler!$A$5:$A$54,0)),0),INDEX(Randevular!$F$5:$F$1004,MATCH(SMALL(Randevular!$J$5:$J$1004,3),Randevular!$J$5:$J$1004,0))))) -> 2200
B13: =IFERROR(INDEX(Randevular!$B$5:$B$1004,MATCH(SMALL(Randevular!$J$5:$J$1004,4),Randevular!$J$5:$J$1004,0)),"") -> 0.52083333 | C13: =IF(B13="","",INDEX(Randevular!$H$5:$H$1004,MATCH(SMALL(Randevular!$J$5:$J$1004,4),Randevular!$J$5:$J$1004,0))) -> 0.54166667 | D13: =IF(B13="","",INDEX(Randevular!$C$5:$C$1004,MATCH(SMALL(Randevular!$J$5:$J$1004,4),Randevular!$J$5:$J$1004,0))) -> Müşteri Gama | E13: =IF(B13="","",INDEX(Randevular!$D$5:$D$1004,MATCH(SMALL(Randevular!$J$5:$J$1004,4),Randevular!$J$5:$J$1004,0))) -> Saç kesimi | F13: =IF(B13="","",INDEX(Randevular!$E$5:$E$1004,MATCH(SMALL(Randevular!$J$5:$J$1004,4),Randevular!$J$5:$J$1004,0))) -> Gelmedi | G13: =IF(D13="","",IFERROR(INDEX(Müşteriler!$B$5:$B$304,MATCH(D13,Müşteriler!$A$5:$A$304,0))&"","")) | H13: =IF(B13="","",IF(F13="Gelmedi",0,IF(INDEX(Randevular!$F$5:$F$1004,MATCH(SMALL(Randevular!$J$5:$J$1004,4),Randevular!$J$5:$J$1004,0))="",IFERROR(INDEX(Hizmetler!$C$5:$C$54,MATCH(E13,Hizmetler!$A$5:$A$54,0)),0),INDEX(Randevular!$F$5:$F$1004,MATCH(SMALL(Randevular!$J$5:$J$1004,4),Randevular!$J$5:$J$1004,0))))) -> 0
B14: =IFERROR(INDEX(Randevular!$B$5:$B$1004,MATCH(SMALL(Randevular!$J$5:$J$1004,5),Randevular!$J$5:$J$1004,0)),"") | C14: =IF(B14="","",INDEX(Randevular!$H$5:$H$1004,MATCH(SMALL(Randevular!$J$5:$J$1004,5),Randevular!$J$5:$J$1004,0))) | D14: =IF(B14="","",INDEX(Randevular!$C$5:$C$1004,MATCH(SMALL(Randevular!$J$5:$J$1004,5),Randevular!$J$5:$J$1004,0))) | E14: =IF(B14="","",INDEX(Randevular!$D$5:$D$1004,MATCH(SMALL(Randevular!$J$5:$J$1004,5),Randevular!$J$5:$J$1004,0))) | F14: =IF(B14="","",INDEX(Randevular!$E$5:$E$1004,MATCH(SMALL(Randevular!$J$5:$J$1004,5),Randevular!$J$5:$J$1004,0))) | G14: =IF(D14="","",IFERROR(INDEX(Müşteriler!$B$5:$B$304,MATCH(D14,Müşteriler!$A$5:$A$304,0))&"","")) | H14: =IF(B14="","",IF(F14="Gelmedi",0,IF(INDEX(Randevular!$F$5:$F$1004,MATCH(SMALL(Randevular!$J$5:$J$1004,5),Randevular!$J$5:$J$1004,0))="",IFERROR(INDEX(Hizmetler!$C$5:$C$54,MATCH(E14,Hizmetler!$A$5:$A$54,0)),0),INDEX(Randevular!$F$5:$F$1004,MATCH(SMALL(Randevular!$J$5:$J$1004,5),Randevular!$J$5:$J$1004,0)))))
B15: =IFERROR(INDEX(Randevular!$B$5:$B$1004,MATCH(SMALL(Randevular!$J$5:$J$1004,6),Randevular!$J$5:$J$1004,0)),"") | C15: =IF(B15="","",INDEX(Randevular!$H$5:$H$1004,MATCH(SMALL(Randevular!$J$5:$J$1004,6),Randevular!$J$5:$J$1004,0))) | D15: =IF(B15="","",INDEX(Randevular!$C$5:$C$1004,MATCH(SMALL(Randevular!$J$5:$J$1004,6),Randevular!$J$5:$J$1004,0))) | E15: =IF(B15="","",INDEX(Randevular!$D$5:$D$1004,MATCH(SMALL(Randevular!$J$5:$J$1004,6),Randevular!$J$5:$J$1004,0))) | F15: =IF(B15="","",INDEX(Randevular!$E$5:$E$1004,MATCH(SMALL(Randevular!$J$5:$J$1004,6),Randevular!$J$5:$J$1004,0))) | G15: =IF(D15="","",IFERROR(INDEX(Müşteriler!$B$5:$B$304,MATCH(D15,Müşteriler!$A$5:$A$304,0))&"","")) | H15: =IF(B15="","",IF(F15="Gelmedi",0,IF(INDEX(Randevular!$F$5:$F$1004,MATCH(SMALL(Randevular!$J$5:$J$1004,6),Randevular!$J$5:$J$1004,0))="",IFERROR(INDEX(Hizmetler!$C$5:$C$54,MATCH(E15,Hizmetler!$A$5:$A$54,0)),0),INDEX(Randevular!$F$5:$F$1004,MATCH(SMALL(Randevular!$J$5:$J$1004,6),Randevular!$J$5:$J$1004,0)))))
B16: =IFERROR(INDEX(Randevular!$B$5:$B$1004,MATCH(SMALL(Randevular!$J$5:$J$1004,7),Randevular!$J$5:$J$1004,0)),"") | C16: =IF(B16="","",INDEX(Randevular!$H$5:$H$1004,MATCH(SMALL(Randevular!$J$5:$J$1004,7),Randevular!$J$5:$J$1004,0))) | D16: =IF(B16="","",INDEX(Randevular!$C$5:$C$1004,MATCH(SMALL(Randevular!$J$5:$J$1004,7),Randevular!$J$5:$J$1004,0))) | E16: =IF(B16="","",INDEX(Randevular!$D$5:$D$1004,MATCH(SMALL(Randevular!$J$5:$J$1004,7),Randevular!$J$5:$J$1004,0))) | F16: =IF(B16="","",INDEX(Randevular!$E$5:$E$1004,MATCH(SMALL(Randevular!$J$5:$J$1004,7),Randevular!$J$5:$J$1004,0))) | G16: =IF(D16="","",IFERROR(INDEX(Müşteriler!$B$5:$B$304,MATCH(D16,Müşteriler!$A$5:$A$304,0))&"","")) | H16: =IF(B16="","",IF(F16="Gelmedi",0,IF(INDEX(Randevular!$F$5:$F$1004,MATCH(SMALL(Randevular!$J$5:$J$1004,7),Randevular!$J$5:$J$1004,0))="",IFERROR(INDEX(Hizmetler!$C$5:$C$54,MATCH(E16,Hizmetler!$A$5:$A$54,0)),0),INDEX(Randevular!$F$5:$F$1004,MATCH(SMALL(Randevular!$J$5:$J$1004,7),Randevular!$J$5:$J$1004,0)))))
B17: =IFERROR(INDEX(Randevular!$B$5:$B$1004,MATCH(SMALL(Randevular!$J$5:$J$1004,8),Randevular!$J$5:$J$1004,0)),"") | C17: =IF(B17="","",INDEX(Randevular!$H$5:$H$1004,MATCH(SMALL(Randevular!$J$5:$J$1004,8),Randevular!$J$5:$J$1004,0))) | D17: =IF(B17="","",INDEX(Randevular!$C$5:$C$1004,MATCH(SMALL(Randevular!$J$5:$J$1004,8),Randevular!$J$5:$J$1004,0))) | E17: =IF(B17="","",INDEX(Randevular!$D$5:$D$1004,MATCH(SMALL(Randevular!$J$5:$J$1004,8),Randevular!$J$5:$J$1004,0))) | F17: =IF(B17="","",INDEX(Randevular!$E$5:$E$1004,MATCH(SMALL(Randevular!$J$5:$J$1004,8),Randevular!$J$5:$J$1004,0))) | G17: =IF(D17="","",IFERROR(INDEX(Müşteriler!$B$5:$B$304,MATCH(D17,Müşteriler!$A$5:$A$304,0))&"","")) | H17: =IF(B17="","",IF(F17="Gelmedi",0,IF(INDEX(Randevular!$F$5:$F$1004,MATCH(SMALL(Randevular!$J$5:$J$1004,8),Randevular!$J$5:$J$1004,0))="",IFERROR(INDEX(Hizmetler!$C$5:$C$54,MATCH(E17,Hizmetler!$A$5:$A$54,0)),0),INDEX(Randevular!$F$5:$F$1004,MATCH(SMALL(Randevular!$J$5:$J$1004,8),Randevular!$J$5:$J$1004,0)))))
B18: =IFERROR(INDEX(Randevular!$B$5:$B$1004,MATCH(SMALL(Randevular!$J$5:$J$1004,9),Randevular!$J$5:$J$1004,0)),"") | C18: =IF(B18="","",INDEX(Randevular!$H$5:$H$1004,MATCH(SMALL(Randevular!$J$5:$J$1004,9),Randevular!$J$5:$J$1004,0))) | D18: =IF(B18="","",INDEX(Randevular!$C$5:$C$1004,MATCH(SMALL(Randevular!$J$5:$J$1004,9),Randevular!$J$5:$J$1004,0))) | E18: =IF(B18="","",INDEX(Randevular!$D$5:$D$1004,MATCH(SMALL(Randevular!$J$5:$J$1004,9),Randevular!$J$5:$J$1004,0))) | F18: =IF(B18="","",INDEX(Randevular!$E$5:$E$1004,MATCH(SMALL(Randevular!$J$5:$J$1004,9),Randevular!$J$5:$J$1004,0))) | G18: =IF(D18="","",IFERROR(INDEX(Müşteriler!$B$5:$B$304,MATCH(D18,Müşteriler!$A$5:$A$304,0))&"","")) | H18: =IF(B18="","",IF(F18="Gelmedi",0,IF(INDEX(Randevular!$F$5:$F$1004,MATCH(SMALL(Randevular!$J$5:$J$1004,9),Randevular!$J$5:$J$1004,0))="",IFERROR(INDEX(Hizmetler!$C$5:$C$54,MATCH(E18,Hizmetler!$A$5:$A$54,0)),0),INDEX(Randevular!$F$5:$F$1004,MATCH(SMALL(Randevular!$J$5:$J$1004,9),Randevular!$J$5:$J$1004,0)))))
B19: =IFERROR(INDEX(Randevular!$B$5:$B$1004,MATCH(SMALL(Randevular!$J$5:$J$1004,10),Randevular!$J$5:$J$1004,0)),"") | C19: =IF(B19="","",INDEX(Randevular!$H$5:$H$1004,MATCH(SMALL(Randevular!$J$5:$J$1004,10),Randevular!$J$5:$J$1004,0))) | D19: =IF(B19="","",INDEX(Randevular!$C$5:$C$1004,MATCH(SMALL(Randevular!$J$5:$J$1004,10),Randevular!$J$5:$J$1004,0))) | E19: =IF(B19="","",INDEX(Randevular!$D$5:$D$1004,MATCH(SMALL(Randevular!$J$5:$J$1004,10),Randevular!$J$5:$J$1004,0))) | F19: =IF(B19="","",INDEX(Randevular!$E$5:$E$1004,MATCH(SMALL(Randevular!$J$5:$J$1004,10),Randevular!$J$5:$J$1004,0))) | G19: =IF(D19="","",IFERROR(INDEX(Müşteriler!$B$5:$B$304,MATCH(D19,Müşteriler!$A$5:$A$304,0))&"","")) | H19: =IF(B19="","",IF(F19="Gelmedi",0,IF(INDEX(Randevular!$F$5:$F$1004,MATCH(SMALL(Randevular!$J$5:$J$1004,10),Randevular!$J$5:$J$1004,0))="",IFERROR(INDEX(Hizmetler!$C$5:$C$54,MATCH(E19,Hizmetler!$A$5:$A$54,0)),0),INDEX(Randevular!$F$5:$F$1004,MATCH(SMALL(Randevular!$J$5:$J$1004,10),Randevular!$J$5:$J$1004,0)))))
B20: =IFERROR(INDEX(Randevular!$B$5:$B$1004,MATCH(SMALL(Randevular!$J$5:$J$1004,11),Randevular!$J$5:$J$1004,0)),"") | C20: =IF(B20="","",INDEX(Randevular!$H$5:$H$1004,MATCH(SMALL(Randevular!$J$5:$J$1004,11),Randevular!$J$5:$J$1004,0))) | D20: =IF(B20="","",INDEX(Randevular!$C$5:$C$1004,MATCH(SMALL(Randevular!$J$5:$J$1004,11),Randevular!$J$5:$J$1004,0))) | E20: =IF(B20="","",INDEX(Randevular!$D$5:$D$1004,MATCH(SMALL(Randevular!$J$5:$J$1004,11),Randevular!$J$5:$J$1004,0))) | F20: =IF(B20="","",INDEX(Randevular!$E$5:$E$1004,MATCH(SMALL(Randevular!$J$5:$J$1004,11),Randevular!$J$5:$J$1004,0))) | G20: =IF(D20="","",IFERROR(INDEX(Müşteriler!$B$5:$B$304,MATCH(D20,Müşteriler!$A$5:$A$304,0))&"","")) | H20: =IF(B20="","",IF(F20="Gelmedi",0,IF(INDEX(Randevular!$F$5:$F$1004,MATCH(SMALL(Randevular!$J$5:$J$1004,11),Randevular!$J$5:$J$1004,0))="",IFERROR(INDEX(Hizmetler!$C$5:$C$54,MATCH(E20,Hizmetler!$A$5:$A$54,0)),0),INDEX(Randevular!$F$5:$F$1004,MATCH(SMALL(Randevular!$J$5:$J$1004,11),Randevular!$J$5:$J$1004,0)))))
B21: =IFERROR(INDEX(Randevular!$B$5:$B$1004,MATCH(SMALL(Randevular!$J$5:$J$1004,12),Randevular!$J$5:$J$1004,0)),"") | C21: =IF(B21="","",INDEX(Randevular!$H$5:$H$1004,MATCH(SMALL(Randevular!$J$5:$J$1004,12),Randevular!$J$5:$J$1004,0))) | D21: =IF(B21="","",INDEX(Randevular!$C$5:$C$1004,MATCH(SMALL(Randevular!$J$5:$J$1004,12),Randevular!$J$5:$J$1004,0))) | E21: =IF(B21="","",INDEX(Randevular!$D$5:$D$1004,MATCH(SMALL(Randevular!$J$5:$J$1004,12),Randevular!$J$5:$J$1004,0))) | F21: =IF(B21="","",INDEX(Randevular!$E$5:$E$1004,MATCH(SMALL(Randevular!$J$5:$J$1004,12),Randevular!$J$5:$J$1004,0))) | G21: =IF(D21="","",IFERROR(INDEX(Müşteriler!$B$5:$B$304,MATCH(D21,Müşteriler!$A$5:$A$304,0))&"","")) | H21: =IF(B21="","",IF(F21="Gelmedi",0,IF(INDEX(Randevular!$F$5:$F$1004,MATCH(SMALL(Randevular!$J$5:$J$1004,12),Randevular!$J$5:$J$1004,0))="",IFERROR(INDEX(Hizmetler!$C$5:$C$54,MATCH(E21,Hizmetler!$A$5:$A$54,0)),0),INDEX(Randevular!$F$5:$F$1004,MATCH(SMALL(Randevular!$J$5:$J$1004,12),Randevular!$J$5:$J$1004,0)))))
B22: =IFERROR(INDEX(Randevular!$B$5:$B$1004,MATCH(SMALL(Randevular!$J$5:$J$1004,13),Randevular!$J$5:$J$1004,0)),"") | C22: =IF(B22="","",INDEX(Randevular!$H$5:$H$1004,MATCH(SMALL(Randevular!$J$5:$J$1004,13),Randevular!$J$5:$J$1004,0))) | D22: =IF(B22="","",INDEX(Randevular!$C$5:$C$1004,MATCH(SMALL(Randevular!$J$5:$J$1004,13),Randevular!$J$5:$J$1004,0))) | E22: =IF(B22="","",INDEX(Randevular!$D$5:$D$1004,MATCH(SMALL(Randevular!$J$5:$J$1004,13),Randevular!$J$5:$J$1004,0))) | F22: =IF(B22="","",INDEX(Randevular!$E$5:$E$1004,MATCH(SMALL(Randevular!$J$5:$J$1004,13),Randevular!$J$5:$J$1004,0))) | G22: =IF(D22="","",IFERROR(INDEX(Müşteriler!$B$5:$B$304,MATCH(D22,Müşteriler!$A$5:$A$304,0))&"","")) | H22: =IF(B22="","",IF(F22="Gelmedi",0,IF(INDEX(Randevular!$F$5:$F$1004,MATCH(SMALL(Randevular!$J$5:$J$1004,13),Randevular!$J$5:$J$1004,0))="",IFERROR(INDEX(Hizmetler!$C$5:$C$54,MATCH(E22,Hizmetler!$A$5:$A$54,0)),0),INDEX(Randevular!$F$5:$F$1004,MATCH(SMALL(Randevular!$J$5:$J$1004,13),Randevular!$J$5:$J$1004,0)))))
B23: =IFERROR(INDEX(Randevular!$B$5:$B$1004,MATCH(SMALL(Randevular!$J$5:$J$1004,14),Randevular!$J$5:$J$1004,0)),"") | C23: =IF(B23="","",INDEX(Randevular!$H$5:$H$1004,MATCH(SMALL(Randevular!$J$5:$J$1004,14),Randevular!$J$5:$J$1004,0))) | D23: =IF(B23="","",INDEX(Randevular!$C$5:$C$1004,MATCH(SMALL(Randevular!$J$5:$J$1004,14),Randevular!$J$5:$J$1004,0))) | E23: =IF(B23="","",INDEX(Randevular!$D$5:$D$1004,MATCH(SMALL(Randevular!$J$5:$J$1004,14),Randevular!$J$5:$J$1004,0))) | F23: =IF(B23="","",INDEX(Randevular!$E$5:$E$1004,MATCH(SMALL(Randevular!$J$5:$J$1004,14),Randevular!$J$5:$J$1004,0))) | G23: =IF(D23="","",IFERROR(INDEX(Müşteriler!$B$5:$B$304,MATCH(D23,Müşteriler!$A$5:$A$304,0))&"","")) | H23: =IF(B23="","",IF(F23="Gelmedi",0,IF(INDEX(Randevular!$F$5:$F$1004,MATCH(SMALL(Randevular!$J$5:$J$1004,14),Randevular!$J$5:$J$1004,0))="",IFERROR(INDEX(Hizmetler!$C$5:$C$54,MATCH(E23,Hizmetler!$A$5:$A$54,0)),0),INDEX(Randevular!$F$5:$F$1004,MATCH(SMALL(Randevular!$J$5:$J$1004,14),Randevular!$J$5:$J$1004,0)))))
B24: =IFERROR(INDEX(Randevular!$B$5:$B$1004,MATCH(SMALL(Randevular!$J$5:$J$1004,15),Randevular!$J$5:$J$1004,0)),"") | C24: =IF(B24="","",INDEX(Randevular!$H$5:$H$1004,MATCH(SMALL(Randevular!$J$5:$J$1004,15),Randevular!$J$5:$J$1004,0))) | D24: =IF(B24="","",INDEX(Randevular!$C$5:$C$1004,MATCH(SMALL(Randevular!$J$5:$J$1004,15),Randevular!$J$5:$J$1004,0))) | E24: =IF(B24="","",INDEX(Randevular!$D$5:$D$1004,MATCH(SMALL(Randevular!$J$5:$J$1004,15),Randevular!$J$5:$J$1004,0))) | F24: =IF(B24="","",INDEX(Randevular!$E$5:$E$1004,MATCH(SMALL(Randevular!$J$5:$J$1004,15),Randevular!$J$5:$J$1004,0))) | G24: =IF(D24="","",IFERROR(INDEX(Müşteriler!$B$5:$B$304,MATCH(D24,Müşteriler!$A$5:$A$304,0))&"","")) | H24: =IF(B24="","",IF(F24="Gelmedi",0,IF(INDEX(Randevular!$F$5:$F$1004,MATCH(SMALL(Randevular!$J$5:$J$1004,15),Randevular!$J$5:$J$1004,0))="",IFERROR(INDEX(Hizmetler!$C$5:$C$54,MATCH(E24,Hizmetler!$A$5:$A$54,0)),0),INDEX(Randevular!$F$5:$F$1004,MATCH(SMALL(Randevular!$J$5:$J$1004,15),Randevular!$J$5:$J$1004,0)))))
B25: =IFERROR(INDEX(Randevular!$B$5:$B$1004,MATCH(SMALL(Randevular!$J$5:$J$1004,16),Randevular!$J$5:$J$1004,0)),"") | C25: =IF(B25="","",INDEX(Randevular!$H$5:$H$1004,MATCH(SMALL(Randevular!$J$5:$J$1004,16),Randevular!$J$5:$J$1004,0))) | D25: =IF(B25="","",INDEX(Randevular!$C$5:$C$1004,MATCH(SMALL(Randevular!$J$5:$J$1004,16),Randevular!$J$5:$J$1004,0))) | E25: =IF(B25="","",INDEX(Randevular!$D$5:$D$1004,MATCH(SMALL(Randevular!$J$5:$J$1004,16),Randevular!$J$5:$J$1004,0))) | F25: =IF(B25="","",INDEX(Randevular!$E$5:$E$1004,MATCH(SMALL(Randevular!$J$5:$J$1004,16),Randevular!$J$5:$J$1004,0))) | G25: =IF(D25="","",IFERROR(INDEX(Müşteriler!$B$5:$B$304,MATCH(D25,Müşteriler!$A$5:$A$304,0))&"","")) | H25: =IF(B25="","",IF(F25="Gelmedi",0,IF(INDEX(Randevular!$F$5:$F$1004,MATCH(SMALL(Randevular!$J$5:$J$1004,16),Randevular!$J$5:$J$1004,0))="",IFERROR(INDEX(Hizmetler!$C$5:$C$54,MATCH(E25,Hizmetler!$A$5:$A$54,0)),0),INDEX(Randevular!$F$5:$F$1004,MATCH(SMALL(Randevular!$J$5:$J$1004,16),Randevular!$J$5:$J$1004,0)))))
B26: =IFERROR(INDEX(Randevular!$B$5:$B$1004,MATCH(SMALL(Randevular!$J$5:$J$1004,17),Randevular!$J$5:$J$1004,0)),"") | C26: =IF(B26="","",INDEX(Randevular!$H$5:$H$1004,MATCH(SMALL(Randevular!$J$5:$J$1004,17),Randevular!$J$5:$J$1004,0))) | D26: =IF(B26="","",INDEX(Randevular!$C$5:$C$1004,MATCH(SMALL(Randevular!$J$5:$J$1004,17),Randevular!$J$5:$J$1004,0))) | E26: =IF(B26="","",INDEX(Randevular!$D$5:$D$1004,MATCH(SMALL(Randevular!$J$5:$J$1004,17),Randevular!$J$5:$J$1004,0))) | F26: =IF(B26="","",INDEX(Randevular!$E$5:$E$1004,MATCH(SMALL(Randevular!$J$5:$J$1004,17),Randevular!$J$5:$J$1004,0))) | G26: =IF(D26="","",IFERROR(INDEX(Müşteriler!$B$5:$B$304,MATCH(D26,Müşteriler!$A$5:$A$304,0))&"","")) | H26: =IF(B26="","",IF(F26="Gelmedi",0,IF(INDEX(Randevular!$F$5:$F$1004,MATCH(SMALL(Randevular!$J$5:$J$1004,17),Randevular!$J$5:$J$1004,0))="",IFERROR(INDEX(Hizmetler!$C$5:$C$54,MATCH(E26,Hizmetler!$A$5:$A$54,0)),0),INDEX(Randevular!$F$5:$F$1004,MATCH(SMALL(Randevular!$J$5:$J$1004,17),Randevular!$J$5:$J$1004,0)))))
B27: =IFERROR(INDEX(Randevular!$B$5:$B$1004,MATCH(SMALL(Randevular!$J$5:$J$1004,18),Randevular!$J$5:$J$1004,0)),"") | C27: =IF(B27="","",INDEX(Randevular!$H$5:$H$1004,MATCH(SMALL(Randevular!$J$5:$J$1004,18),Randevular!$J$5:$J$1004,0))) | D27: =IF(B27="","",INDEX(Randevular!$C$5:$C$1004,MATCH(SMALL(Randevular!$J$5:$J$1004,18),Randevular!$J$5:$J$1004,0))) | E27: =IF(B27="","",INDEX(Randevular!$D$5:$D$1004,MATCH(SMALL(Randevular!$J$5:$J$1004,18),Randevular!$J$5:$J$1004,0))) | F27: =IF(B27="","",INDEX(Randevular!$E$5:$E$1004,MATCH(SMALL(Randevular!$J$5:$J$1004,18),Randevular!$J$5:$J$1004,0))) | G27: =IF(D27="","",IFERROR(INDEX(Müşteriler!$B$5:$B$304,MATCH(D27,Müşteriler!$A$5:$A$304,0))&"","")) | H27: =IF(B27="","",IF(F27="Gelmedi",0,IF(INDEX(Randevular!$F$5:$F$1004,MATCH(SMALL(Randevular!$J$5:$J$1004,18),Randevular!$J$5:$J$1004,0))="",IFERROR(INDEX(Hizmetler!$C$5:$C$54,MATCH(E27,Hizmetler!$A$5:$A$54,0)),0),INDEX(Randevular!$F$5:$F$1004,MATCH(SMALL(Randevular!$J$5:$J$1004,18),Randevular!$J$5:$J$1004,0)))))
B28: =IFERROR(INDEX(Randevular!$B$5:$B$1004,MATCH(SMALL(Randevular!$J$5:$J$1004,19),Randevular!$J$5:$J$1004,0)),"") | C28: =IF(B28="","",INDEX(Randevular!$H$5:$H$1004,MATCH(SMALL(Randevular!$J$5:$J$1004,19),Randevular!$J$5:$J$1004,0))) | D28: =IF(B28="","",INDEX(Randevular!$C$5:$C$1004,MATCH(SMALL(Randevular!$J$5:$J$1004,19),Randevular!$J$5:$J$1004,0))) | E28: =IF(B28="","",INDEX(Randevular!$D$5:$D$1004,MATCH(SMALL(Randevular!$J$5:$J$1004,19),Randevular!$J$5:$J$1004,0))) | F28: =IF(B28="","",INDEX(Randevular!$E$5:$E$1004,MATCH(SMALL(Randevular!$J$5:$J$1004,19),Randevular!$J$5:$J$1004,0))) | G28: =IF(D28="","",IFERROR(INDEX(Müşteriler!$B$5:$B$304,MATCH(D28,Müşteriler!$A$5:$A$304,0))&"","")) | H28: =IF(B28="","",IF(F28="Gelmedi",0,IF(INDEX(Randevular!$F$5:$F$1004,MATCH(SMALL(Randevular!$J$5:$J$1004,19),Randevular!$J$5:$J$1004,0))="",IFERROR(INDEX(Hizmetler!$C$5:$C$54,MATCH(E28,Hizmetler!$A$5:$A$54,0)),0),INDEX(Randevular!$F$5:$F$1004,MATCH(SMALL(Randevular!$J$5:$J$1004,19),Randevular!$J$5:$J$1004,0)))))
B29: =IFERROR(INDEX(Randevular!$B$5:$B$1004,MATCH(SMALL(Randevular!$J$5:$J$1004,20),Randevular!$J$5:$J$1004,0)),"") | C29: =IF(B29="","",INDEX(Randevular!$H$5:$H$1004,MATCH(SMALL(Randevular!$J$5:$J$1004,20),Randevular!$J$5:$J$1004,0))) | D29: =IF(B29="","",INDEX(Randevular!$C$5:$C$1004,MATCH(SMALL(Randevular!$J$5:$J$1004,20),Randevular!$J$5:$J$1004,0))) | E29: =IF(B29="","",INDEX(Randevular!$D$5:$D$1004,MATCH(SMALL(Randevular!$J$5:$J$1004,20),Randevular!$J$5:$J$1004,0))) | F29: =IF(B29="","",INDEX(Randevular!$E$5:$E$1004,MATCH(SMALL(Randevular!$J$5:$J$1004,20),Randevular!$J$5:$J$1004,0))) | G29: =IF(D29="","",IFERROR(INDEX(Müşteriler!$B$5:$B$304,MATCH(D29,Müşteriler!$A$5:$A$304,0))&"","")) | H29: =IF(B29="","",IF(F29="Gelmedi",0,IF(INDEX(Randevular!$F$5:$F$1004,MATCH(SMALL(Randevular!$J$5:$J$1004,20),Randevular!$J$5:$J$1004,0))="",IFERROR(INDEX(Hizmetler!$C$5:$C$54,MATCH(E29,Hizmetler!$A$5:$A$54,0)),0),INDEX(Randevular!$F$5:$F$1004,MATCH(SMALL(Randevular!$J$5:$J$1004,20),Randevular!$J$5:$J$1004,0)))))
B30: =IFERROR(INDEX(Randevular!$B$5:$B$1004,MATCH(SMALL(Randevular!$J$5:$J$1004,21),Randevular!$J$5:$J$1004,0)),"") | C30: =IF(B30="","",INDEX(Randevular!$H$5:$H$1004,MATCH(SMALL(Randevular!$J$5:$J$1004,21),Randevular!$J$5:$J$1004,0))) | D30: =IF(B30="","",INDEX(Randevular!$C$5:$C$1004,MATCH(SMALL(Randevular!$J$5:$J$1004,21),Randevular!$J$5:$J$1004,0))) | E30: =IF(B30="","",INDEX(Randevular!$D$5:$D$1004,MATCH(SMALL(Randevular!$J$5:$J$1004,21),Randevular!$J$5:$J$1004,0))) | F30: =IF(B30="","",INDEX(Randevular!$E$5:$E$1004,MATCH(SMALL(Randevular!$J$5:$J$1004,21),Randevular!$J$5:$J$1004,0))) | G30: =IF(D30="","",IFERROR(INDEX(Müşteriler!$B$5:$B$304,MATCH(D30,Müşteriler!$A$5:$A$304,0))&"","")) | H30: =IF(B30="","",IF(F30="Gelmedi",0,IF(INDEX(Randevular!$F$5:$F$1004,MATCH(SMALL(Randevular!$J$5:$J$1004,21),Randevular!$J$5:$J$1004,0))="",IFERROR(INDEX(Hizmetler!$C$5:$C$54,MATCH(E30,Hizmetler!$A$5:$A$54,0)),0),INDEX(Randevular!$F$5:$F$1004,MATCH(SMALL(Randevular!$J$5:$J$1004,21),Randevular!$J$5:$J$1004,0)))))
B31: =IFERROR(INDEX(Randevular!$B$5:$B$1004,MATCH(SMALL(Randevular!$J$5:$J$1004,22),Randevular!$J$5:$J$1004,0)),"") | C31: =IF(B31="","",INDEX(Randevular!$H$5:$H$1004,MATCH(SMALL(Randevular!$J$5:$J$1004,22),Randevular!$J$5:$J$1004,0))) | D31: =IF(B31="","",INDEX(Randevular!$C$5:$C$1004,MATCH(SMALL(Randevular!$J$5:$J$1004,22),Randevular!$J$5:$J$1004,0))) | E31: =IF(B31="","",INDEX(Randevular!$D$5:$D$1004,MATCH(SMALL(Randevular!$J$5:$J$1004,22),Randevular!$J$5:$J$1004,0))) | F31: =IF(B31="","",INDEX(Randevular!$E$5:$E$1004,MATCH(SMALL(Randevular!$J$5:$J$1004,22),Randevular!$J$5:$J$1004,0))) | G31: =IF(D31="","",IFERROR(INDEX(Müşteriler!$B$5:$B$304,MATCH(D31,Müşteriler!$A$5:$A$304,0))&"","")) | H31: =IF(B31="","",IF(F31="Gelmedi",0,IF(INDEX(Randevular!$F$5:$F$1004,MATCH(SMALL(Randevular!$J$5:$J$1004,22),Randevular!$J$5:$J$1004,0))="",IFERROR(INDEX(Hizmetler!$C$5:$C$54,MATCH(E31,Hizmetler!$A$5:$A$54,0)),0),INDEX(Randevular!$F$5:$F$1004,MATCH(SMALL(Randevular!$J$5:$J$1004,22),Randevular!$J$5:$J$1004,0)))))
B32: =IFERROR(INDEX(Randevular!$B$5:$B$1004,MATCH(SMALL(Randevular!$J$5:$J$1004,23),Randevular!$J$5:$J$1004,0)),"") | C32: =IF(B32="","",INDEX(Randevular!$H$5:$H$1004,MATCH(SMALL(Randevular!$J$5:$J$1004,23),Randevular!$J$5:$J$1004,0))) | D32: =IF(B32="","",INDEX(Randevular!$C$5:$C$1004,MATCH(SMALL(Randevular!$J$5:$J$1004,23),Randevular!$J$5:$J$1004,0))) | E32: =IF(B32="","",INDEX(Randevular!$D$5:$D$1004,MATCH(SMALL(Randevular!$J$5:$J$1004,23),Randevular!$J$5:$J$1004,0))) | F32: =IF(B32="","",INDEX(Randevular!$E$5:$E$1004,MATCH(SMALL(Randevular!$J$5:$J$1004,23),Randevular!$J$5:$J$1004,0))) | G32: =IF(D32="","",IFERROR(INDEX(Müşteriler!$B$5:$B$304,MATCH(D32,Müşteriler!$A$5:$A$304,0))&"","")) | H32: =IF(B32="","",IF(F32="Gelmedi",0,IF(INDEX(Randevular!$F$5:$F$1004,MATCH(SMALL(Randevular!$J$5:$J$1004,23),Randevular!$J$5:$J$1004,0))="",IFERROR(INDEX(Hizmetler!$C$5:$C$54,MATCH(E32,Hizmetler!$A$5:$A$54,0)),0),INDEX(Randevular!$F$5:$F$1004,MATCH(SMALL(Randevular!$J$5:$J$1004,23),Randevular!$J$5:$J$1004,0)))))
B33: =IFERROR(INDEX(Randevular!$B$5:$B$1004,MATCH(SMALL(Randevular!$J$5:$J$1004,24),Randevular!$J$5:$J$1004,0)),"") | C33: =IF(B33="","",INDEX(Randevular!$H$5:$H$1004,MATCH(SMALL(Randevular!$J$5:$J$1004,24),Randevular!$J$5:$J$1004,0))) | D33: =IF(B33="","",INDEX(Randevular!$C$5:$C$1004,MATCH(SMALL(Randevular!$J$5:$J$1004,24),Randevular!$J$5:$J$1004,0))) | E33: =IF(B33="","",INDEX(Randevular!$D$5:$D$1004,MATCH(SMALL(Randevular!$J$5:$J$1004,24),Randevular!$J$5:$J$1004,0))) | F33: =IF(B33="","",INDEX(Randevular!$E$5:$E$1004,MATCH(SMALL(Randevular!$J$5:$J$1004,24),Randevular!$J$5:$J$1004,0))) | G33: =IF(D33="","",IFERROR(INDEX(Müşteriler!$B$5:$B$304,MATCH(D33,Müşteriler!$A$5:$A$304,0))&"","")) | H33: =IF(B33="","",IF(F33="Gelmedi",0,IF(INDEX(Randevular!$F$5:$F$1004,MATCH(SMALL(Randevular!$J$5:$J$1004,24),Randevular!$J$5:$J$1004,0))="",IFERROR(INDEX(Hizmetler!$C$5:$C$54,MATCH(E33,Hizmetler!$A$5:$A$54,0)),0),INDEX(Randevular!$F$5:$F$1004,MATCH(SMALL(Randevular!$J$5:$J$1004,24),Randevular!$J$5:$J$1004,0)))))
B34: =IFERROR(INDEX(Randevular!$B$5:$B$1004,MATCH(SMALL(Randevular!$J$5:$J$1004,25),Randevular!$J$5:$J$1004,0)),"") | C34: =IF(B34="","",INDEX(Randevular!$H$5:$H$1004,MATCH(SMALL(Randevular!$J$5:$J$1004,25),Randevular!$J$5:$J$1004,0))) | D34: =IF(B34="","",INDEX(Randevular!$C$5:$C$1004,MATCH(SMALL(Randevular!$J$5:$J$1004,25),Randevular!$J$5:$J$1004,0))) | E34: =IF(B34="","",INDEX(Randevular!$D$5:$D$1004,MATCH(SMALL(Randevular!$J$5:$J$1004,25),Randevular!$J$5:$J$1004,0))) | F34: =IF(B34="","",INDEX(Randevular!$E$5:$E$1004,MATCH(SMALL(Randevular!$J$5:$J$1004,25),Randevular!$J$5:$J$1004,0))) | G34: =IF(D34="","",IFERROR(INDEX(Müşteriler!$B$5:$B$304,MATCH(D34,Müşteriler!$A$5:$A$304,0))&"","")) | H34: =IF(B34="","",IF(F34="Gelmedi",0,IF(INDEX(Randevular!$F$5:$F$1004,MATCH(SMALL(Randevular!$J$5:$J$1004,25),Randevular!$J$5:$J$1004,0))="",IFERROR(INDEX(Hizmetler!$C$5:$C$54,MATCH(E34,Hizmetler!$A$5:$A$54,0)),0),INDEX(Randevular!$F$5:$F$1004,MATCH(SMALL(Randevular!$J$5:$J$1004,25),Randevular!$J$5:$J$1004,0)))))
B35: =IFERROR(INDEX(Randevular!$B$5:$B$1004,MATCH(SMALL(Randevular!$J$5:$J$1004,26),Randevular!$J$5:$J$1004,0)),"") | C35: =IF(B35="","",INDEX(Randevular!$H$5:$H$1004,MATCH(SMALL(Randevular!$J$5:$J$1004,26),Randevular!$J$5:$J$1004,0))) | D35: =IF(B35="","",INDEX(Randevular!$C$5:$C$1004,MATCH(SMALL(Randevular!$J$5:$J$1004,26),Randevular!$J$5:$J$1004,0))) | E35: =IF(B35="","",INDEX(Randevular!$D$5:$D$1004,MATCH(SMALL(Randevular!$J$5:$J$1004,26),Randevular!$J$5:$J$1004,0))) | F35: =IF(B35="","",INDEX(Randevular!$E$5:$E$1004,MATCH(SMALL(Randevular!$J$5:$J$1004,26),Randevular!$J$5:$J$1004,0))) | G35: =IF(D35="","",IFERROR(INDEX(Müşteriler!$B$5:$B$304,MATCH(D35,Müşteriler!$A$5:$A$304,0))&"","")) | H35: =IF(B35="","",IF(F35="Gelmedi",0,IF(INDEX(Randevular!$F$5:$F$1004,MATCH(SMALL(Randevular!$J$5:$J$1004,26),Randevular!$J$5:$J$1004,0))="",IFERROR(INDEX(Hizmetler!$C$5:$C$54,MATCH(E35,Hizmetler!$A$5:$A$54,0)),0),INDEX(Randevular!$F$5:$F$1004,MATCH(SMALL(Randevular!$J$5:$J$1004,26),Randevular!$J$5:$J$1004,0)))))
B36: =IFERROR(INDEX(Randevular!$B$5:$B$1004,MATCH(SMALL(Randevular!$J$5:$J$1004,27),Randevular!$J$5:$J$1004,0)),"") | C36: =IF(B36="","",INDEX(Randevular!$H$5:$H$1004,MATCH(SMALL(Randevular!$J$5:$J$1004,27),Randevular!$J$5:$J$1004,0))) | D36: =IF(B36="","",INDEX(Randevular!$C$5:$C$1004,MATCH(SMALL(Randevular!$J$5:$J$1004,27),Randevular!$J$5:$J$1004,0))) | E36: =IF(B36="","",INDEX(Randevular!$D$5:$D$1004,MATCH(SMALL(Randevular!$J$5:$J$1004,27),Randevular!$J$5:$J$1004,0))) | F36: =IF(B36="","",INDEX(Randevular!$E$5:$E$1004,MATCH(SMALL(Randevular!$J$5:$J$1004,27),Randevular!$J$5:$J$1004,0))) | G36: =IF(D36="","",IFERROR(INDEX(Müşteriler!$B$5:$B$304,MATCH(D36,Müşteriler!$A$5:$A$304,0))&"","")) | H36: =IF(B36="","",IF(F36="Gelmedi",0,IF(INDEX(Randevular!$F$5:$F$1004,MATCH(SMALL(Randevular!$J$5:$J$1004,27),Randevular!$J$5:$J$1004,0))="",IFERROR(INDEX(Hizmetler!$C$5:$C$54,MATCH(E36,Hizmetler!$A$5:$A$54,0)),0),INDEX(Randevular!$F$5:$F$1004,MATCH(SMALL(Randevular!$J$5:$J$1004,27),Randevular!$J$5:$J$1004,0)))))
B37: =IFERROR(INDEX(Randevular!$B$5:$B$1004,MATCH(SMALL(Randevular!$J$5:$J$1004,28),Randevular!$J$5:$J$1004,0)),"") | C37: =IF(B37="","",INDEX(Randevular!$H$5:$H$1004,MATCH(SMALL(Randevular!$J$5:$J$1004,28),Randevular!$J$5:$J$1004,0))) | D37: =IF(B37="","",INDEX(Randevular!$C$5:$C$1004,MATCH(SMALL(Randevular!$J$5:$J$1004,28),Randevular!$J$5:$J$1004,0))) | E37: =IF(B37="","",INDEX(Randevular!$D$5:$D$1004,MATCH(SMALL(Randevular!$J$5:$J$1004,28),Randevular!$J$5:$J$1004,0))) | F37: =IF(B37="","",INDEX(Randevular!$E$5:$E$1004,MATCH(SMALL(Randevular!$J$5:$J$1004,28),Randevular!$J$5:$J$1004,0))) | G37: =IF(D37="","",IFERROR(INDEX(Müşteriler!$B$5:$B$304,MATCH(D37,Müşteriler!$A$5:$A$304,0))&"","")) | H37: =IF(B37="","",IF(F37="Gelmedi",0,IF(INDEX(Randevular!$F$5:$F$1004,MATCH(SMALL(Randevular!$J$5:$J$1004,28),Randevular!$J$5:$J$1004,0))="",IFERROR(INDEX(Hizmetler!$C$5:$C$54,MATCH(E37,Hizmetler!$A$5:$A$54,0)),0),INDEX(Randevular!$F$5:$F$1004,MATCH(SMALL(Randevular!$J$5:$J$1004,28),Randevular!$J$5:$J$1004,0)))))
B38: =IFERROR(INDEX(Randevular!$B$5:$B$1004,MATCH(SMALL(Randevular!$J$5:$J$1004,29),Randevular!$J$5:$J$1004,0)),"") | C38: =IF(B38="","",INDEX(Randevular!$H$5:$H$1004,MATCH(SMALL(Randevular!$J$5:$J$1004,29),Randevular!$J$5:$J$1004,0))) | D38: =IF(B38="","",INDEX(Randevular!$C$5:$C$1004,MATCH(SMALL(Randevular!$J$5:$J$1004,29),Randevular!$J$5:$J$1004,0))) | E38: =IF(B38="","",INDEX(Randevular!$D$5:$D$1004,MATCH(SMALL(Randevular!$J$5:$J$1004,29),Randevular!$J$5:$J$1004,0))) | F38: =IF(B38="","",INDEX(Randevular!$E$5:$E$1004,MATCH(SMALL(Randevular!$J$5:$J$1004,29),Randevular!$J$5:$J$1004,0))) | G38: =IF(D38="","",IFERROR(INDEX(Müşteriler!$B$5:$B$304,MATCH(D38,Müşteriler!$A$5:$A$304,0))&"","")) | H38: =IF(B38="","",IF(F38="Gelmedi",0,IF(INDEX(Randevular!$F$5:$F$1004,MATCH(SMALL(Randevular!$J$5:$J$1004,29),Randevular!$J$5:$J$1004,0))="",IFERROR(INDEX(Hizmetler!$C$5:$C$54,MATCH(E38,Hizmetler!$A$5:$A$54,0)),0),INDEX(Randevular!$F$5:$F$1004,MATCH(SMALL(Randevular!$J$5:$J$1004,29),Randevular!$J$5:$J$1004,0)))))
B39: =IFERROR(INDEX(Randevular!$B$5:$B$1004,MATCH(SMALL(Randevular!$J$5:$J$1004,30),Randevular!$J$5:$J$1004,0)),"") | C39: =IF(B39="","",INDEX(Randevular!$H$5:$H$1004,MATCH(SMALL(Randevular!$J$5:$J$1004,30),Randevular!$J$5:$J$1004,0))) | D39: =IF(B39="","",INDEX(Randevular!$C$5:$C$1004,MATCH(SMALL(Randevular!$J$5:$J$1004,30),Randevular!$J$5:$J$1004,0))) | E39: =IF(B39="","",INDEX(Randevular!$D$5:$D$1004,MATCH(SMALL(Randevular!$J$5:$J$1004,30),Randevular!$J$5:$J$1004,0))) | F39: =IF(B39="","",INDEX(Randevular!$E$5:$E$1004,MATCH(SMALL(Randevular!$J$5:$J$1004,30),Randevular!$J$5:$J$1004,0))) | G39: =IF(D39="","",IFERROR(INDEX(Müşteriler!$B$5:$B$304,MATCH(D39,Müşteriler!$A$5:$A$304,0))&"","")) | H39: =IF(B39="","",IF(F39="Gelmedi",0,IF(INDEX(Randevular!$F$5:$F$1004,MATCH(SMALL(Randevular!$J$5:$J$1004,30),Randevular!$J$5:$J$1004,0))="",IFERROR(INDEX(Hizmetler!$C$5:$C$54,MATCH(E39,Hizmetler!$A$5:$A$54,0)),0),INDEX(Randevular!$F$5:$F$1004,MATCH(SMALL(Randevular!$J$5:$J$1004,30),Randevular!$J$5:$J$1004,0)))))

Sheet Özet
A1: Özet
A2: Bu sayfada yalnızca yılı değiştir.
B3: Yıl | C3: 2026
B5: Yıl cirosu | C5: Randevu | D5: Gelen | E5: Gelmeyen | F5: Gelmeme oranı
B6: =F23 -> 6300 | C6: =C23 -> 8 | D6: =D23 -> 5 | E6: =E23 -> 1 | F6: =IF(C23=0,0,E23/C23) -> 0.125
B9: Aylık tablo | I9: En çok yapılan 5 hizmet
B10: Ay | C10: Randevu | D10: Geldi | E10: Gelmedi | F10: Ciro (₺) | I10: Hizmet | J10: Yapılan
B11: Ocak | C11: =COUNTIFS(Randevular!$A$5:$A$1004,">="&DATE($C$3,1,1),Randevular!$A$5:$A$1004,"<"&DATE($C$3,2,1),Randevular!$E$5:$E$1004,"<>İptal",Randevular!$E$5:$E$1004,"<>") -> 0 | D11: =COUNTIFS(Randevular!$A$5:$A$1004,">="&DATE($C$3,1,1),Randevular!$A$5:$A$1004,"<"&DATE($C$3,2,1),Randevular!$E$5:$E$1004,"Geldi") -> 0 | E11: =COUNTIFS(Randevular!$A$5:$A$1004,">="&DATE($C$3,1,1),Randevular!$A$5:$A$1004,"<"&DATE($C$3,2,1),Randevular!$E$5:$E$1004,"Gelmedi") -> 0 | F11: =SUMIFS(Randevular!$G$5:$G$1004,Randevular!$A$5:$A$1004,">="&DATE($C$3,1,1),Randevular!$A$5:$A$1004,"<"&DATE($C$3,2,1)) -> 0 | I11: =IFERROR(IF(LARGE(Hizmetler!$F$5:$F$54,1)<1,"",INDEX(Hizmetler!$A$5:$A$54,MATCH(LARGE(Hizmetler!$F$5:$F$54,1),Hizmetler!$F$5:$F$54,0))),"") -> Boya | J11: =IF(I11="","",INDEX(Hizmetler!$D$5:$D$54,MATCH(I11,Hizmetler!$A$5:$A$54,0))) -> 2
B12: Şubat | C12: =COUNTIFS(Randevular!$A$5:$A$1004,">="&DATE($C$3,2,1),Randevular!$A$5:$A$1004,"<"&DATE($C$3,3,1),Randevular!$E$5:$E$1004,"<>İptal",Randevular!$E$5:$E$1004,"<>") -> 0 | D12: =COUNTIFS(Randevular!$A$5:$A$1004,">="&DATE($C$3,2,1),Randevular!$A$5:$A$1004,"<"&DATE($C$3,3,1),Randevular!$E$5:$E$1004,"Geldi") -> 0 | E12: =COUNTIFS(Randevular!$A$5:$A$1004,">="&DATE($C$3,2,1),Randevular!$A$5:$A$1004,"<"&DATE($C$3,3,1),Randevular!$E$5:$E$1004,"Gelmedi") -> 0 | F12: =SUMIFS(Randevular!$G$5:$G$1004,Randevular!$A$5:$A$1004,">="&DATE($C$3,2,1),Randevular!$A$5:$A$1004,"<"&DATE($C$3,3,1)) -> 0 | I12: =IFERROR(IF(LARGE(Hizmetler!$F$5:$F$54,2)<1,"",INDEX(Hizmetler!$A$5:$A$54,MATCH(LARGE(Hizmetler!$F$5:$F$54,2),Hizmetler!$F$5:$F$54,0))),"") -> Saç kesimi | J12: =IF(I12="","",INDEX(Hizmetler!$D$5:$D$54,MATCH(I12,Hizmetler!$A$5:$A$54,0))) -> 2
B13: Mart | C13: =COUNTIFS(Randevular!$A$5:$A$1004,">="&DATE($C$3,3,1),Randevular!$A$5:$A$1004,"<"&DATE($C$3,4,1),Randevular!$E$5:$E$1004,"<>İptal",Randevular!$E$5:$E$1004,"<>") -> 0 | D13: =COUNTIFS(Randevular!$A$5:$A$1004,">="&DATE($C$3,3,1),Randevular!$A$5:$A$1004,"<"&DATE($C$3,4,1),Randevular!$E$5:$E$1004,"Geldi") -> 0 | E13: =COUNTIFS(Randevular!$A$5:$A$1004,">="&DATE($C$3,3,1),Randevular!$A$5:$A$1004,"<"&DATE($C$3,4,1),Randevular!$E$5:$E$1004,"Gelmedi") -> 0 | F13: =SUMIFS(Randevular!$G$5:$G$1004,Randevular!$A$5:$A$1004,">="&DATE($C$3,3,1),Randevular!$A$5:$A$1004,"<"&DATE($C$3,4,1)) -> 0 | I13: =IFERROR(IF(LARGE(Hizmetler!$F$5:$F$54,3)<1,"",INDEX(Hizmetler!$A$5:$A$54,MATCH(LARGE(Hizmetler!$F$5:$F$54,3),Hizmetler!$F$5:$F$54,0))),"") -> Fön | J13: =IF(I13="","",INDEX(Hizmetler!$D$5:$D$54,MATCH(I13,Hizmetler!$A$5:$A$54,0))) -> 1
B14: Nisan | C14: =COUNTIFS(Randevular!$A$5:$A$1004,">="&DATE($C$3,4,1),Randevular!$A$5:$A$1004,"<"&DATE($C$3,5,1),Randevular!$E$5:$E$1004,"<>İptal",Randevular!$E$5:$E$1004,"<>") -> 0 | D14: =COUNTIFS(Randevular!$A$5:$A$1004,">="&DATE($C$3,4,1),Randevular!$A$5:$A$1004,"<"&DATE($C$3,5,1),Randevular!$E$5:$E$1004,"Geldi") -> 0 | E14: =COUNTIFS(Randevular!$A$5:$A$1004,">="&DATE($C$3,4,1),Randevular!$A$5:$A$1004,"<"&DATE($C$3,5,1),Randevular!$E$5:$E$1004,"Gelmedi") -> 0 | F14: =SUMIFS(Randevular!$G$5:$G$1004,Randevular!$A$5:$A$1004,">="&DATE($C$3,4,1),Randevular!$A$5:$A$1004,"<"&DATE($C$3,5,1)) -> 0 | I14: =IFERROR(IF(LARGE(Hizmetler!$F$5:$F$54,4)<1,"",INDEX(Hizmetler!$A$5:$A$54,MATCH(LARGE(Hizmetler!$F$5:$F$54,4),Hizmetler!$F$5:$F$54,0))),"") | J14: =IF(I14="","",INDEX(Hizmetler!$D$5:$D$54,MATCH(I14,Hizmetler!$A$5:$A$54,0)))
B15: Mayıs | C15: =COUNTIFS(Randevular!$A$5:$A$1004,">="&DATE($C$3,5,1),Randevular!$A$5:$A$1004,"<"&DATE($C$3,6,1),Randevular!$E$5:$E$1004,"<>İptal",Randevular!$E$5:$E$1004,"<>") -> 0 | D15: =COUNTIFS(Randevular!$A$5:$A$1004,">="&DATE($C$3,5,1),Randevular!$A$5:$A$1004,"<"&DATE($C$3,6,1),Randevular!$E$5:$E$1004,"Geldi") -> 0 | E15: =COUNTIFS(Randevular!$A$5:$A$1004,">="&DATE($C$3,5,1),Randevular!$A$5:$A$1004,"<"&DATE($C$3,6,1),Randevular!$E$5:$E$1004,"Gelmedi") -> 0 | F15: =SUMIFS(Randevular!$G$5:$G$1004,Randevular!$A$5:$A$1004,">="&DATE($C$3,5,1),Randevular!$A$5:$A$1004,"<"&DATE($C$3,6,1)) -> 0 | I15: =IFERROR(IF(LARGE(Hizmetler!$F$5:$F$54,5)<1,"",INDEX(Hizmetler!$A$5:$A$54,MATCH(LARGE(Hizmetler!$F$5:$F$54,5),Hizmetler!$F$5:$F$54,0))),"") | J15: =IF(I15="","",INDEX(Hizmetler!$D$5:$D$54,MATCH(I15,Hizmetler!$A$5:$A$54,0)))
B16: Haziran | C16: =COUNTIFS(Randevular!$A$5:$A$1004,">="&DATE($C$3,6,1),Randevular!$A$5:$A$1004,"<"&DATE($C$3,7,1),Randevular!$E$5:$E$1004,"<>İptal",Randevular!$E$5:$E$1004,"<>") -> 0 | D16: =COUNTIFS(Randevular!$A$5:$A$1004,">="&DATE($C$3,6,1),Randevular!$A$5:$A$1004,"<"&DATE($C$3,7,1),Randevular!$E$5:$E$1004,"Geldi") -> 0 | E16: =COUNTIFS(Randevular!$A$5:$A$1004,">="&DATE($C$3,6,1),Randevular!$A$5:$A$1004,"<"&DATE($C$3,7,1),Randevular!$E$5:$E$1004,"Gelmedi") -> 0 | F16: =SUMIFS(Randevular!$G$5:$G$1004,Randevular!$A$5:$A$1004,">="&DATE($C$3,6,1),Randevular!$A$5:$A$1004,"<"&DATE($C$3,7,1)) -> 0
B17: Temmuz | C17: =COUNTIFS(Randevular!$A$5:$A$1004,">="&DATE($C$3,7,1),Randevular!$A$5:$A$1004,"<"&DATE($C$3,8,1),Randevular!$E$5:$E$1004,"<>İptal",Randevular!$E$5:$E$1004,"<>") -> 0 | D17: =COUNTIFS(Randevular!$A$5:$A$1004,">="&DATE($C$3,7,1),Randevular!$A$5:$A$1004,"<"&DATE($C$3,8,1),Randevular!$E$5:$E$1004,"Geldi") -> 0 | E17: =COUNTIFS(Randevular!$A$5:$A$1004,">="&DATE($C$3,7,1),Randevular!$A$5:$A$1004,"<"&DATE($C$3,8,1),Randevular!$E$5:$E$1004,"Gelmedi") -> 0 | F17: =SUMIFS(Randevular!$G$5:$G$1004,Randevular!$A$5:$A$1004,">="&DATE($C$3,7,1),Randevular!$A$5:$A$1004,"<"&DATE($C$3,8,1)) -> 0 | I17: En çok harcayan 5 müşteri
B18: Ağustos | C18: =COUNTIFS(Randevular!$A$5:$A$1004,">="&DATE($C$3,8,1),Randevular!$A$5:$A$1004,"<"&DATE($C$3,9,1),Randevular!$E$5:$E$1004,"<>İptal",Randevular!$E$5:$E$1004,"<>") -> 0 | D18: =COUNTIFS(Randevular!$A$5:$A$1004,">="&DATE($C$3,8,1),Randevular!$A$5:$A$1004,"<"&DATE($C$3,9,1),Randevular!$E$5:$E$1004,"Geldi") -> 0 | E18: =COUNTIFS(Randevular!$A$5:$A$1004,">="&DATE($C$3,8,1),Randevular!$A$5:$A$1004,"<"&DATE($C$3,9,1),Randevular!$E$5:$E$1004,"Gelmedi") -> 0 | F18: =SUMIFS(Randevular!$G$5:$G$1004,Randevular!$A$5:$A$1004,">="&DATE($C$3,8,1),Randevular!$A$5:$A$1004,"<"&DATE($C$3,9,1)) -> 0 | I18: Müşteri | J18: Harcama (₺)
B19: Eylül | C19: =COUNTIFS(Randevular!$A$5:$A$1004,">="&DATE($C$3,9,1),Randevular!$A$5:$A$1004,"<"&DATE($C$3,10,1),Randevular!$E$5:$E$1004,"<>İptal",Randevular!$E$5:$E$1004,"<>") -> 2 | D19: =COUNTIFS(Randevular!$A$5:$A$1004,">="&DATE($C$3,9,1),Randevular!$A$5:$A$1004,"<"&DATE($C$3,10,1),Randevular!$E$5:$E$1004,"Geldi") -> 2 | E19: =COUNTIFS(Randevular!$A$5:$A$1004,">="&DATE($C$3,9,1),Randevular!$A$5:$A$1004,"<"&DATE($C$3,10,1),Randevular!$E$5:$E$1004,"Gelmedi") -> 0 | F19: =SUMIFS(Randevular!$G$5:$G$1004,Randevular!$A$5:$A$1004,">="&DATE($C$3,9,1),Randevular!$A$5:$A$1004,"<"&DATE($C$3,10,1)) -> 3100 | I19: =IFERROR(IF(LARGE(Müşteriler!$H$5:$H$304,1)<1,"",INDEX(Müşteriler!$A$5:$A$304,MATCH(LARGE(Müşteriler!$H$5:$H$304,1),Müşteriler!$H$5:$H$304,0))),"") -> Müşteri Gama | J19: =IF(I19="","",INDEX(Müşteriler!$F$5:$F$304,MATCH(I19,Müşteriler!$A$5:$A$304,0))) -> 2500
B20: Ekim | C20: =COUNTIFS(Randevular!$A$5:$A$1004,">="&DATE($C$3,10,1),Randevular!$A$5:$A$1004,"<"&DATE($C$3,11,1),Randevular!$E$5:$E$1004,"<>İptal",Randevular!$E$5:$E$1004,"<>") -> 6 | D20: =COUNTIFS(Randevular!$A$5:$A$1004,">="&DATE($C$3,10,1),Randevular!$A$5:$A$1004,"<"&DATE($C$3,11,1),Randevular!$E$5:$E$1004,"Geldi") -> 3 | E20: =COUNTIFS(Randevular!$A$5:$A$1004,">="&DATE($C$3,10,1),Randevular!$A$5:$A$1004,"<"&DATE($C$3,11,1),Randevular!$E$5:$E$1004,"Gelmedi") -> 1 | F20: =SUMIFS(Randevular!$G$5:$G$1004,Randevular!$A$5:$A$1004,">="&DATE($C$3,10,1),Randevular!$A$5:$A$1004,"<"&DATE($C$3,11,1)) -> 3200 | I20: =IFERROR(IF(LARGE(Müşteriler!$H$5:$H$304,2)<1,"",INDEX(Müşteriler!$A$5:$A$304,MATCH(LARGE(Müşteriler!$H$5:$H$304,2),Müşteriler!$H$5:$H$304,0))),"") -> Müşteri Beta | J20: =IF(I20="","",INDEX(Müşteriler!$F$5:$F$304,MATCH(I20,Müşteriler!$A$5:$A$304,0))) -> 2200
B21: Kasım | C21: =COUNTIFS(Randevular!$A$5:$A$1004,">="&DATE($C$3,11,1),Randevular!$A$5:$A$1004,"<"&DATE($C$3,12,1),Randevular!$E$5:$E$1004,"<>İptal",Randevular!$E$5:$E$1004,"<>") -> 0 | D21: =COUNTIFS(Randevular!$A$5:$A$1004,">="&DATE($C$3,11,1),Randevular!$A$5:$A$1004,"<"&DATE($C$3,12,1),Randevular!$E$5:$E$1004,"Geldi") -> 0 | E21: =COUNTIFS(Randevular!$A$5:$A$1004,">="&DATE($C$3,11,1),Randevular!$A$5:$A$1004,"<"&DATE($C$3,12,1),Randevular!$E$5:$E$1004,"Gelmedi") -> 0 | F21: =SUMIFS(Randevular!$G$5:$G$1004,Randevular!$A$5:$A$1004,">="&DATE($C$3,11,1),Randevular!$A$5:$A$1004,"<"&DATE($C$3,12,1)) -> 0 | I21: =IFERROR(IF(LARGE(Müşteriler!$H$5:$H$304,3)<1,"",INDEX(Müşteriler!$A$5:$A$304,MATCH(LARGE(Müşteriler!$H$5:$H$304,3),Müşteriler!$H$5:$H$304,0))),"") -> Müşteri Delta | J21: =IF(I21="","",INDEX(Müşteriler!$F$5:$F$304,MATCH(I21,Müşteriler!$A$5:$A$304,0))) -> 1000
B22: Aralık | C22: =COUNTIFS(Randevular!$A$5:$A$1004,">="&DATE($C$3,12,1),Randevular!$A$5:$A$1004,"<"&DATE($C$3,13,1),Randevular!$E$5:$E$1004,"<>İptal",Randevular!$E$5:$E$1004,"<>") -> 0 | D22: =COUNTIFS(Randevular!$A$5:$A$1004,">="&DATE($C$3,12,1),Randevular!$A$5:$A$1004,"<"&DATE($C$3,13,1),Randevular!$E$5:$E$1004,"Geldi") -> 0 | E22: =COUNTIFS(Randevular!$A$5:$A$1004,">="&DATE($C$3,12,1),Randevular!$A$5:$A$1004,"<"&DATE($C$3,13,1),Randevular!$E$5:$E$1004,"Gelmedi") -> 0 | F22: =SUMIFS(Randevular!$G$5:$G$1004,Randevular!$A$5:$A$1004,">="&DATE($C$3,12,1),Randevular!$A$5:$A$1004,"<"&DATE($C$3,13,1)) -> 0 | I22: =IFERROR(IF(LARGE(Müşteriler!$H$5:$H$304,4)<1,"",INDEX(Müşteriler!$A$5:$A$304,MATCH(LARGE(Müşteriler!$H$5:$H$304,4),Müşteriler!$H$5:$H$304,0))),"") -> Müşteri Alfa | J22: =IF(I22="","",INDEX(Müşteriler!$F$5:$F$304,MATCH(I22,Müşteriler!$A$5:$A$304,0))) -> 600
B23: TOPLAM | C23: =SUM(C11:C22) -> 8 | D23: =SUM(D11:D22) -> 5 | E23: =SUM(E11:E22) -> 1 | F23: =SUM(F11:F22) -> 6300 | I23: =IFERROR(IF(LARGE(Müşteriler!$H$5:$H$304,5)<1,"",INDEX(Müşteriler!$A$5:$A$304,MATCH(LARGE(Müşteriler!$H$5:$H$304,5),Müşteriler!$H$5:$H$304,0))),"") | J23: =IF(I23="","",INDEX(Müşteriler!$F$5:$F$304,MATCH(I23,Müşteriler!$A$5:$A$304,0)))

Sheet Hizmetler
A1: Hizmetler
A2: Verdiğin hizmetleri, süresini ve ücretini yaz.
A4: Hizmet | B4: Süre (dakika) | C4: Ücret (₺) | D4: Yapılan | E4: Ciro (₺) | F4: y
A5: Saç kesimi | B5: 30 | C5: 600 | D5: =IF(A5="","",COUNTIFS(Randevular!$D$5:$D$1004,A5,Randevular!$E$5:$E$1004,"Geldi")) -> 2 | E5: =IF(A5="","",SUMIFS(Randevular!$G$5:$G$1004,Randevular!$D$5:$D$1004,A5)) -> 1200 | F5: =IF(A5="","",D5+ROW()/1000000) -> 2.000005
A6: Fön | B6: 30 | C6: 400 | D6: =IF(A6="","",COUNTIFS(Randevular!$D$5:$D$1004,A6,Randevular!$E$5:$E$1004,"Geldi")) -> 1 | E6: =IF(A6="","",SUMIFS(Randevular!$G$5:$G$1004,Randevular!$D$5:$D$1004,A6)) -> 400 | F6: =IF(A6="","",D6+ROW()/1000000) -> 1.000006
A7: Boya | B7: 90 | C7: 2500 | D7: =IF(A7="","",COUNTIFS(Randevular!$D$5:$D$1004,A7,Randevular!$E$5:$E$1004,"Geldi")) -> 2 | E7: =IF(A7="","",SUMIFS(Randevular!$G$5:$G$1004,Randevular!$D$5:$D$1004,A7)) -> 4700 | F7: =IF(A7="","",D7+ROW()/1000000) -> 2.000007
D8: =IF(A8="","",COUNTIFS(Randevular!$D$5:$D$1004,A8,Randevular!$E$5:$E$1004,"Geldi")) | E8: =IF(A8="","",SUMIFS(Randevular!$G$5:$G$1004,Randevular!$D$5:$D$1004,A8)) | F8: =IF(A8="","",D8+ROW()/1000000)
D9: =IF(A9="","",COUNTIFS(Randevular!$D$5:$D$1004,A9,Randevular!$E$5:$E$1004,"Geldi")) | E9: =IF(A9="","",SUMIFS(Randevular!$G$5:$G$1004,Randevular!$D$5:$D$1004,A9)) | F9: =IF(A9="","",D9+ROW()/1000000)
D10: =IF(A10="","",COUNTIFS(Randevular!$D$5:$D$1004,A10,Randevular!$E$5:$E$1004,"Geldi")) | E10: =IF(A10="","",SUMIFS(Randevular!$G$5:$G$1004,Randevular!$D$5:$D$1004,A10)) | F10: =IF(A10="","",D10+ROW()/1000000)
D11: =IF(A11="","",COUNTIFS(Randevular!$D$5:$D$1004,A11,Randevular!$E$5:$E$1004,"Geldi")) | E11: =IF(A11="","",SUMIFS(Randevular!$G$5:$G$1004,Randevular!$D$5:$D$1004,A11)) | F11: =IF(A11="","",D11+ROW()/1000000)
D12: =IF(A12="","",COUNTIFS(Randevular!$D$5:$D$1004,A12,Randevular!$E$5:$E$1004,"Geldi")) | E12: =IF(A12="","",SUMIFS(Randevular!$G$5:$G$1004,Randevular!$D$5:$D$1004,A12)) | F12: =IF(A12="","",D12+ROW()/1000000)
D13: =IF(A13="","",COUNTIFS(Randevular!$D$5:$D$1004,A13,Randevular!$E$5:$E$1004,"Geldi")) | E13: =IF(A13="","",SUMIFS(Randevular!$G$5:$G$1004,Randevular!$D$5:$D$1004,A13)) | F13: =IF(A13="","",D13+ROW()/1000000)
D14: =IF(A14="","",COUNTIFS(Randevular!$D$5:$D$1004,A14,Randevular!$E$5:$E$1004,"Geldi")) | E14: =IF(A14="","",SUMIFS(Randevular!$G$5:$G$1004,Randevular!$D$5:$D$1004,A14)) | F14: =IF(A14="","",D14+ROW()/1000000)
D15: =IF(A15="","",COUNTIFS(Randevular!$D$5:$D$1004,A15,Randevular!$E$5:$E$1004,"Geldi")) | E15: =IF(A15="","",SUMIFS(Randevular!$G$5:$G$1004,Randevular!$D$5:$D$1004,A15)) | F15: =IF(A15="","",D15+ROW()/1000000)
D16: =IF(A16="","",COUNTIFS(Randevular!$D$5:$D$1004,A16,Randevular!$E$5:$E$1004,"Geldi")) | E16: =IF(A16="","",SUMIFS(Randevular!$G$5:$G$1004,Randevular!$D$5:$D$1004,A16)) | F16: =IF(A16="","",D16+ROW()/1000000)
D17: =IF(A17="","",COUNTIFS(Randevular!$D$5:$D$1004,A17,Randevular!$E$5:$E$1004,"Geldi")) | E17: =IF(A17="","",SUMIFS(Randevular!$G$5:$G$1004,Randevular!$D$5:$D$1004,A17)) | F17: =IF(A17="","",D17+ROW()/1000000)
D18: =IF(A18="","",COUNTIFS(Randevular!$D$5:$D$1004,A18,Randevular!$E$5:$E$1004,"Geldi")) | E18: =IF(A18="","",SUMIFS(Randevular!$G$5:$G$1004,Randevular!$D$5:$D$1004,A18)) | F18: =IF(A18="","",D18+ROW()/1000000)
D19: =IF(A19="","",COUNTIFS(Randevular!$D$5:$D$1004,A19,Randevular!$E$5:$E$1004,"Geldi")) | E19: =IF(A19="","",SUMIFS(Randevular!$G$5:$G$1004,Randevular!$D$5:$D$1004,A19)) | F19: =IF(A19="","",D19+ROW()/1000000)
... D54: =IF(A54="","",COUNTIFS(Randevular!$D$5:$D$1004,A54,Randevular!$E$5:$E$1004,"Geldi")) | E54: =IF(A54="","",SUMIFS(Randevular!$G$5:$G$1004,Randevular!$D$5:$D$1004,A54)) | F54: =IF(A54="","",D54+ROW()/1000000)

Sheet Müşteriler
A1: Müşteriler
A2: Müşterilerini yaz. Randevu sayısı, harcama ve son ziyaret kendiliğinden hesaplanır.
A4: Ad | B4: Telefon | C4: Not | D4: Randevu | E4: Gelmedi | F4: Toplam harcama (₺) | G4: Son ziyaret | H4: y
A5: Müşteri Alfa | C5: Örnek | D5: =IF(A5="","",COUNTIFS(Randevular!$C$5:$C$1004,A5,Randevular!$E$5:$E$1004,"<>İptal")) -> 2 | E5: =IF(A5="","",COUNTIFS(Randevular!$C$5:$C$1004,A5,Randevular!$E$5:$E$1004,"Gelmedi")) -> 0 | F5: =IF(A5="","",SUMIFS(Randevular!$G$5:$G$1004,Randevular!$C$5:$C$1004,A5)) -> 600 | G5: =IF(A5="","",IF(SUMPRODUCT(MAX((Randevular!$C$5:$C$1004=A5)*(Randevular!$E$5:$E$1004="Geldi")*Randevular!$A$5:$A$1004))=0,"",SUMPRODUCT(MAX((Randevular!$C$5:$C$1004=A5)*(Randevular!$E$5:$E$1004="Geldi")*Randevular!$A$5:$A$1004)))) -> 46300 | H5: =IF(A5="","",F5+ROW()/1000000) -> 600
